Workbook
Name description_103: [1]Abstract!$B$16
Name description_124: #REF!
Name description_247: [1]Abstract!$B$22
Name description_248: [1]Abstract!$B$23
Name description_261: [2]Abstract!$B$33
Name description_262: [1]Abstract!$B$34
Name description_276: [3]Abstract!$B$40
Name description_3: [1]Abstract!$B$169
Name description_310: #REF!
Name description_312: #REF!
Name description_5: [1]Abstract!$B$171
Name description_6: #REF!
Name description_759: [1]Abstract!$B$278
Name description_781: #REF!
Name description_783: [1]Abstract!$B$301
Name description_784: [3]Abstract!$B$300

Sheet chihaan
A1: Government of Nepal
A2: Shankharapur Municipality Office
A3: Bagmati Province
A4: Sankhu, Kathmandu
A5: Detail Estimated Sheet
A6: Project:- ef]tfª\u] lrxfgkfl6 | H6: F.Y.: 2082/2083
A7: Location:- Shankharapur Municipality 1 | H7: Date:
A8: S.N. | B8: Description of work | C8: No. | D8: Length | E8: Breadth | F8: Height | G8: Quantity | H8: Unit | I8: Rate | J8: Amount | K8: Remark
A9: 1 | B9: g/d k|sf/sf] Sn] / l;N6L df6f]df ;j} lsl;dsf] vGg] sfd
B10: -for foundation | C10: 4 | D10: =Sheet1!B4 -> 1.5 | E10: =Sheet1!C4 -> 1.5 | F10: =Sheet1!D4 -> 1.5 | G10: =PRODUCT(C10:F10) -> 13.5
B11: -for toe wall | C11: 4 | D11: =Sheet1!K4 -> 1.7781164 | E11: 0.23 | F11: 0.5 | G11: =PRODUCT(C11:F11) -> 0.81793356
B12: Sub-total | G12: =SUM(G10:G11) -> 14.317934 | H12: cum | I12: 674.12 | J12: =G12*I12 -> 9652.0054
A14: 2 | B14: ;'Vvf O{6f RofK6f] 5fKg] sfd
B15: =B10 -> -for foundation | C15: =C10 -> 4 | D15: =Sheet1!B4 -> 1.5 | E15: =Sheet1!C4 -> 1.5 | G15: =PRODUCT(C15:F15) -> 9
B16: =B11 -> -for toe wall | C16: =C11 -> 4 | D16: =Sheet1!K4 -> 1.7781164 | E16: =E11 -> 0.23 | G16: =PRODUCT(C16:F16) -> 1.6358671
B17: -for flooring | C17: 1 | D17: =Sheet1!R4 -> 2.9574215 | E17: =D17 -> 2.9574215 | G17: =PRODUCT(C17:F17) -> 8.746342
B18: -deduction for placement of God | C18: -1 | D18: =D17 -> 2.9574215 | E18: =6/3.281 -> 1.8287108 | G18: =PRODUCT(C18:F18) -> -5.4082685
B19: Sub-total | G19: =SUM(G15:G18) -> 13.973941 | H19: sqm | I19: 1017.47 | J19: =G19*I19 -> 14218.065
B20: -13% VAT for brick | J20: =0.13*G19*6360.9/10 -> 1155.5289
B21: -13% VAT for sand | J21: =0.13*G19*2256.3/10 -> 409.88223
A23: 3 | B23: hu leQf kvf{ndf l;d]G6 s+lqm6 ug]{ sfd-lk=;L=;L= +!M#M^_
B24: =B15 -> -for foundation | C24: =C15 -> 4 | D24: =Sheet1!B4 -> 1.5 | E24: =Sheet1!C4 -> 1.5 | F24: 0.075 | G24: =PRODUCT(C24:F24) -> 0.675
B25: =B16 -> -for toe wall | C25: =C16 -> 4 | D25: =Sheet1!K4 -> 1.7781164 | E25: =E16 -> 0.23 | F25: 0.075 | G25: =PRODUCT(C25:F25) -> 0.12269003
B26: Sub-total | G26: =SUM(G24:G25) -> 0.79769003 | H26: cum | I26: 11620.77 | J26: =G26*I26 -> 9269.7724
B27: -13% VAT for cement | J27: =0.13*G26*2866.82 -> 297.28839
B28: -13% VAT for aggregate | J28: =0.13*G26*(2065.63+805.06) -> 297.6897
B29: -13% VAT for sand | J29: =0.13*G26*1350.6 -> 140.05682
B30: -13% VAT for water | J30: =0.13*G26*28 -> 2.9035917
B31: -13% VAT for diesel | J31: =0.13*G26*392.92 -> 40.745688
B32: -13% VAT for petrol | J32: =0.13*G26*14.15 -> 1.4673508
A34: 4 | B34: d]lzgsf] k|of]u u/L hu leQf kvf{ndf l;d]G6 s+lqm6 ug]{ sfd -!M@M$_
B35: =B17 -> -for flooring | C35: =C17 -> 1 | D35: =D17 -> 2.9574215 | E35: =E17 -> 2.9574215 | F35: 0.075 | G35: =PRODUCT(C35:F35) -> 0.65597565
B36: =B18 -> -deduction for placement of God | C36: =C18 -> -1 | D36: =D18 -> 2.9574215 | E36: =E18 -> 1.8287108 | F36: 0.075 | G36: =PRODUCT(C36:F36) -> -0.40562014
B37: Sub-total | G37: =SUM(G35:G36) -> 0.25035551 | H37: cum | I37: 12884.61 | J37: =G37*I37 -> 3225.7331
B38: -13% VAT for cement | J38: =0.13*G37*4169.92 -> 135.71512
B39: -13% VAT for aggregate | J39: =0.13*G37*(1652.5+1106.96) -> 89.809983
B40: -13% VAT for sand | J40: =0.13*G37*1414.16 -> 46.025558
B41: -13% VAT for water | J41: =0.13*G37*36.4 -> 1.1846823
B42: -13% VAT for water | J42: =0.13*G37*392.92 -> 12.788059
B43: -13% VAT for water | J43: =0.13*G37*14.15 -> 0.46052896
...

Sheet Sheet1
B2: Foundation size | E2: Footing size | H2: Plinth size | K2: Toe wall | O2: Column size | R2: Tie beam size | U2: Main beam size
B3: Length | C3: Breadth | D3: Depth from GL | E3: Length in PL area | F3: Breadth in PL area | G3: Depth | H3: Length | I3: Breadth | J3: Depth from GL | K3: Length L1 | L3: Ht. H1 | M3: Length L2 | N3: Ht. H2 | O3: Length/B | P3: Ht. upto plinth | Q3: Ht. above PL upto ceiling | R3: Length | S3: Width | T3: Height | U3: Length | V3: Width | W3: Height
B4: 1.5 | C4: 1.5 | D4: 1.5 | E4: =3.083/3.281 -> 0.93965254 | F4: =3.083/3.281 -> 0.93965254 | G4: 0.35 | H4: =12/3.281 -> 3.6574215 | I4: =12/3.281 -> 3.6574215 | J4: 0.45 | K4: =H4-E4*2 -> 1.7781164 | L4: =0.5-0.055-0.075+J4 -> 0.82 | M4: =E4-1.17/3.281 -> 0.58305395 | N4: =D4-G4+J4 -> 1.6 | O4: 0.35 | P4: =D4-G4+J4-T4 -> 1.37 | Q4: =(9.33-0.42)/3.281 -> 2.7156355 | R4: =H4-O4*2 -> 2.9574215 | S4: 0.23 | T4: 0.23 | U4: =R4+0.6*2 -> 4.1574215 | V4: 0.23 | W4: 0.35
M6: =1.917/3.281 -> 0.58427309
