Workbook
Name description_103: [1]Abstract!$B$16
Name description_124: #REF!
Name description_124: #REF!
Name description_124: #REF!
Name description_124: #REF!
Name description_124: #REF!
Name description_124: #REF!
Name description_247: [1]Abstract!$B$22
Name description_248: [1]Abstract!$B$23
Name description_261: [2]Abstract!$B$33
Name description_262: [1]Abstract!$B$34
Name description_276: [3]Abstract!$B$40
Name description_3: [1]Abstract!$B$169
Name description_310: #REF!
Name description_310: #REF!
Name description_310: #REF!
Name description_310: #REF!
Name description_310: [4]Abstract!$B$60
Name description_310: #REF!
Name description_312: #REF!
Name description_312: #REF!
Name description_312: #REF!
Name description_312: #REF!
Name description_312: [5]Abstract!$B$61
Name description_312: #REF!
Name description_5: [1]Abstract!$B$171
Name description_6: #REF!
Name description_6: #REF!
Name description_6: #REF!
Name description_6: #REF!
Name description_6: [4]Abstract!$B$172
Name description_6: #REF!
Name description_759: [1]Abstract!$B$278
Name description_781: #REF!
Name description_781: #REF!
Name description_781: #REF!
Name description_781: #REF!
Name description_781: [6]Abstract!$B$299
Name description_781: #REF!
Name description_783: [1]Abstract!$B$301
Name description_784: [3]Abstract!$B$300

Sheet estimate
A1: Government of Nepal
A2: Shankharapur Municipality Office
A3: Bagmati Province
A4: Sankhu, Kathmandu
A5: Detail Estimated Sheet
A6: Project:- dnl;d vfg]kfgL | H6: F.Y.: 2082/2083
A7: Location:- Shankharapur Municipality 1 | H7: Date:2082/09/07
A8: S.N. | B8: Description of work | C8: No. | D8: Length | E8: Breadth | F8: Height | G8: Quantity | H8: Unit | I8: Rate | J8: Amount | K8: Remark
A9: 1 | B9: Earthwork in Excavation in ordinary soil (vGg] k'g{] sfo{)
B10: -for pipe laying | C10: 1 | D10: 175 | E10: 0.3 | F10: 0.45 | G10: =PRODUCT(C10:F10) -> 23.625
C11: 1 | D11: 150 | E11: 0.3 | F11: 0.45 | G11: =PRODUCT(C11:F11) -> 20.25 | R11: =480/3.281 -> 146.29686
C12: 1 | D12: 415 | E12: 0.3 | F12: 0.45 | G12: =PRODUCT(C12:F12) -> 56.025 | R12: =160+135+301 -> 596 | S12: =R12/3.281 -> 181.65194
B13: sub-total | G13: =SUM(G10:G12) -> 99.9 | H13: cum | I13: 963.05 | J13: =G13*I13 -> 96208.695 | R13: 1269 | S13: =R13/3.281 -> 386.77233
A15: 2 | B15: Laying and joining of 32 mmØ HDPE pipe with butt-weld joints
B16: -for pipe laying | C16: 1 | D16: =SUM(D20:D22)-100 -> 1900 | G16: =PRODUCT(C16:F16) -> 1900
B17: sub-total | G17: =SUM(G16:G16) -> 1900 | H17: rm | I17: =5319.5/1000 -> 5.3195 | J17: =G17*I17 -> 10107.05
A19: 3 | B19: -High Density Polythene Pipe NS 40 pipe material PE 100, PN 16 | D19: Length (m) | E19: Weight (Kg/m) | F19: Total weight (Kg)
B20: -from source1 to tank 3, 32mm dia pipe | C20: 1 | D20: 400 | E20: 0.338 | F20: =C20*D20*E20 -> 135.2 | G20: =F20 -> 135.2 | Q20: =0.338*287 -> 97.006
B21: -from tank 2 to 2 houses, 32mm dia pipe | C21: 1 | D21: 300 | E21: 0.338 | F21: =C21*D21*E21 -> 101.4 | G21: =F21 -> 101.4
B22: -from tank 3 to daando house, 32mm dia pipe | C22: 1 | D22: 1300 | E22: 0.338 | F22: =C22*D22*E22 -> 439.4 | G22: =F22 -> 439.4
B23: Sub-total | G23: =SUM(G20:G22) -> 676 | H23: kg | I23: 287 | J23: =G23*I23 -> 194012 | Q23: =1.13*287 -> 324.31
B24: -13% VAT for material | J24: =0.13*J23 -> 25221.56
A26: 4 | B26: 32mm GI pipe threaded
B27: -for pipe laying | C27: 1 | D27: 6 | G27: =PRODUCT(C27:F27) -> 6
B28: sub-total | G28: =SUM(G27:G27) -> 6 | H28: rm | I28: 452 | J28: =G28*I28 -> 2712
B29: -13% VAT for material | J29: =0.13*J28 -> 352.56
A31: 5 | B31: Provisional sum for other unforseen works | C31: 1 | G31: =PRODUCT(C31:F31) -> 1 | H31: PS | I31: 7000 | J31: =G31*I31 -> 7000
A33: 6 | B33: Information board (सुचना पाटि) | C33: 1 | G33: =PRODUCT(C33:F33) -> 1 | H33: no. | I33: 500 | J33: =G33*I33 -> 500
B35: Total | J35: =SUM(J9:J33) -> 336113.86
B37: Total Estimated | C37: =J35 -> 336113.86 | E37: 100
B38: Budget allocated | C38: 300000
B39: Municipal payment | C39: =C38-C41-C42 -> 285000 | E39: =C39/C37*100 -> 84.792694
B40: User contribution | C40: =C37-C39 -> 51113.865 | E40: =100-E39 -> 15.207306
B41: Contingencies | C41: =C38*0.03 -> 9000 | E41: 3
B42: Maintanince | C42: =C38*0.02 -> 6000 | E42: 2

Sheet WCR
A1: Government of Nepal
A2: Shankharapur Municipality Office
A3: Bagmati Province
A4: Sankhu, Kathmandu
A5: Work Completion Report
A6: Total Estimated Amount: | C6: =F27 -> 336113.86 | H6: Total Valuated Amount : | J6: =I27 -> 208459.41
A7: Work Started : | I7: Work Finished:
A8: Project:- dnl;d vfg]kfgL | I8: F.Y:2082/2083
A9: =[7]estimate!A7 -> Location:- Shankharapur Municipality 1 | I9: Date:2082/12/09
A11: S.No. | B11: Description | C11: Unit | D11: Estimated | G11: Valuated | J11: Difference | K11: Remarks
D12: Quantity | E12: Rate | F12: Amount | G12: Quantity | H12: Rate | I12: Amount
A13: =estimate!A9 -> 1 | B13: Earthwork in Excavation in ordinary soil (vGg] k'g{] sfo{) | C13: =estimate!H13 -> cum | D13: =estimate!G13 -> 99.9 | E13: =estimate!I13 -> 963.05 | F13: =D13*E13 -> 96208.695 | G13: =V!G16 -> 88.2 | H13: =V!I16 -> 963.05 | I13: =G13*H13 -> 84941.01 | J13: =I13-F13 -> -11267.685 | M13: =1.25*F13 -> 120260.87
A15: =estimate!A15 -> 2 | B15: =estimate!B15 -> Laying and joining of 32 mmØ HDPE pipe with butt-weld joints | C15: =estimate!H17 -> rm | D15: =estimate!G17 -> 1900 | E15: =estimate!I17 -> 5.3195 | F15: =D15*E15 -> 10107.05 | G15: =V!G20 -> 0 | H15: =V!I20 -> 5.3195 | I15: =G15*H15 -> 0 | J15: =I15-F15 -> -10107.05 | M15: =1.25*F15 -> 12633.812
A17: =estimate!A19 -> 3 | B17: =estimate!B19 -> -High Density Polythene Pipe NS 40 pipe material PE 100, PN 16 | C17: =estimate!H23 -> kg | D17: =estimate!G23 -> 676 | E17: =estimate!I23 -> 287 | F17: =D17*E17 -> 194012 | G17: =V!G29 -> 365.04 | H17: =V!I29 -> 287 | I17: =G17*H17 -> 104766.48 | J17: =I17-F17 -> -89245.52 | M17: =1.25*F17 -> 242515
B18: =estimate!B24 -> -13% VAT for material | F18: =estimate!J24 -> 25221.56 | I18: =V!J30 -> 13619.642 | J18: =I18-F18 -> -11601.918 | M18: =1.25*F18 -> 31526.95
A20: =estimate!A26 -> 4 | B20: =estimate!B26 -> 32mm GI pipe threaded | C20: =estimate!H28 -> rm | D20: =estimate!G28 -> 6 | E20: =estimate!I28 -> 452 | F20: =D20*E20 -> 2712 | G20: =V!G34 -> 3 | H20: =V!I34 -> 452 | I20: =G20*H20 -> 1356 | J20: =I20-F20 -> -1356 | M20: =1.25*F20 -> 3390
B21: =estimate!B29 -> -13% VAT for material | F21: =estimate!J29 -> 352.56 | I21: =V!J35 -> 176.28 | J21: =I21-F21 -> -176.28 | M21: =1.25*F21 -> 440.7
A23: =estimate!A31 -> 5 | B23: =estimate!B31 -> Provisional sum for other unforseen works | C23: =estimate!H31 -> PS | D23: =estimate!G31 -> 1 | E23: =estimate!I31 -> 7000 | F23: =D23*E23 -> 7000 | G23: =V!G37 -> 1 | H23: =V!I37 -> 3100 | I23: =G23*H23 -> 3100 | J23: =I23-F23 -> -3900 | M23: =1.25*F23 -> 8750
A25: =estimate!A33 -> 6 | B25: =estimate!B33 -> Information board (सुचना पाटि) | C25: =estimate!H33 -> no. | D25: =estimate!G33 -> 1 | E25: =estimate!I33 -> 500 | F25: =D25*E25 -> 500 | G25: =V!C39 -> 1 | H25: =V!I39 -> 500 | I25: =G25*H25 -> 500 | J25: =I25-F25 -> 0
B27: Total | F27: =SUM(F13:F25) -> 336113.86 | I27: =SUM(I13:I25) -> 208459.41 | J27: =I27-F27 -> -127654.45

Sheet V
A1: Government of Nepal
A2: Shankharapur Municipality Office
A3: Bagmati Province
A4: Sankhu, Kathmandu
A5: Detail Valuated Sheet
A6: Project:- dnl;d vfg]kfgL | H6: F.Y.: 2082/2083
A7: Location:- Shankharapur Municipality 1 | H7: Date:2082/12/09
A8: S.N. | B8: Description of work | C8: No. | D8: Length | E8: Breadth | F8: Height | G8: Quantity | H8: Unit | I8: Rate | J8: Amount | K8: Remark
A9: 1 | B9: Earthwork in Excavation in ordinary soil (vGg] k'g{] sfo{)
B10: -for pipe laying source 1 to tank 2 | C10: 1 | D10: =90+38+40-1 -> 167 | E10: 0.3 | F10: 0.3 | G10: =PRODUCT(C10:F10) -> 15.03
B11: -for pipe laying water tank 1 to tank 2 | C11: 1 | D11: =40+43-2 -> 81 | E11: 0.3 | F11: 0.3 | G11: =PRODUCT(C11:F11) -> 7.29
B12: -for pipe laying tank 2 to destination 1 | C12: 1 | D12: =50+30+2+50+38-20 -> 150 | E12: 0.3 | F12: 0.3 | G12: =PRODUCT(C12:F12) -> 13.5
B13: -for pipe laying tank 2 to destination 2 | C13: 1 | D13: =36+35-15 -> 56 | E13: 0.3 | F13: 0.3 | G13: =PRODUCT(C13:F13) -> 5.04
B14: -for pipe laying tank 2 to destination 3 | C14: 1 | D14: =23-15 -> 8 | E14: 0.3 | F14: 0.3 | G14: =PRODUCT(C14:F14) -> 0.72
B15: -for pipe laying tank 2 to destination 4 | C15: 1 | D15: =36+11+23+30-0.7+50+25+30.7-8+8+50+9+50+50+40+20+50+50+42-3-40-5 -> 518 | E15: 0.3 | F15: 0.3 | G15: =PRODUCT(C15:F15) -> 46.62
B16: sub-total | G16: =SUM(G10:G15) -> 88.2 | H16: cum | I16: 963.05 | J16: =G16*I16 -> 84941.01
A18: 2 | B18: Laying and joining of 32 mmØ HDPE pipe with butt-weld joints
B19: -for pipe laying | C19: 0 | D19: =(SUM(D10:D15))-1*3 -> 977 | G19: =PRODUCT(C19:F19) -> 0
B20: sub-total | G20: =SUM(G19:G19) -> 0 | H20: rm | I20: =5319.5/1000 -> 5.3195 | J20: =G20*I20 -> 0
A22: 3 | B22: -High Density Polythene Pipe NS 40 pipe material PE 100, PN 16 | D22: Length (m) | E22: Weight (Kg/m) | F22: Total weight (Kg)
B23: -for pipe laying source 1 to tank 2 | C23: 1 | D23: 168 | E23: 0.338 | F23: =C23*D23*E23 -> 56.784 | G23: =F23 -> 56.784
B24: -for pipe laying water tank 1 to tank 2 | C24: 1 | D24: 83 | E24: 0.338 | F24: =C24*D24*E24 -> 28.054 | G24: =F24 -> 28.054
B25: -for pipe laying tank 2 to destination 1 | C25: 1 | D25: 170 | E25: 0.338 | F25: =C25*D25*E25 -> 57.46 | G25: =F25 -> 57.46
B26: -for pipe laying tank 2 to destination 2 | C26: 1 | D26: 71 | E26: 0.338 | F26: =C26*D26*E26 -> 23.998 | G26: =F26 -> 23.998
B27: -for pipe laying tank 2 to destination 3 | C27: 1 | D27: 23 | E27: 0.338 | F27: =C27*D27*E27 -> 7.774 | G27: =F27 -> 7.774
B28: -for pipe laying tank 2 to destination 4 | C28: 1 | D28: 565 | E28: 0.338 | F28: =C28*D28*E28 -> 190.97 | G28: =F28 -> 190.97
B29: Sub-total | G29: =SUM(G23:G28) -> 365.04 | H29: kg | I29: 287 | J29: =G29*I29 -> 104766.48
B30: -13% VAT for material | J30: =0.13*J29 -> 13619.642
A32: 4 | B32: 32mm GI pipe threaded
B33: -for pipe laying | C33: 1 | D33: 3 | G33: =PRODUCT(C33:F33) -> 3
B34: sub-total | G34: =SUM(G33:G33) -> 3 | H34: rm | I34: 452 | J34: =G34*I34 -> 1356
B35: -13% VAT for material | J35: =0.13*J34 -> 176.28
A37: 5 | B37: Provisional sum for other unforseen works | C37: 1 | G37: =PRODUCT(C37:F37) -> 1 | H37: PS | I37: 3100 | J37: =G37*I37 -> 3100
A39: 6 | B39: Information board (सुचना पाटि) | C39: 1 | G39: =PRODUCT(C39:F39) -> 1 | H39: no. | I39: 500 | J39: =G39*I39 -> 500
B41: Total | J41: =SUM(J9:J39) -> 208459.41
B43: Total Valuated | C43: =J41 -> 208459.41 | E43: 100
B44: Budget allocated | C44: 300000
B45: Municipal payment | C45: =84.79%*C43 -> 176752.74 | E45: =C45/C43*100 -> 84.79
B46: User contribution | C46: =C43-C45 -> 31706.677 | E46: =100-E45 -> 15.21
B47: Contingencies | C47: =C44*0.03 -> 9000 | E47: 3
...

Sheet M
A1: Government of Nepal
A2: Shankharapur Municipality Office
A3: Bagmati Province
A4: Sankhu, Kathmandu
A5: Detail Quantity Measurement Sheet
A6: Project:- dnl;d vfg]kfgL | K6: F.Y.: 2082/2083
A7: Location:- Shankharapur Municipality 1 | K7: Date:2082/12/09
A8: S.N. | B8: Description of work | C8: No. | D8: Length | E8: Breadth | F8: Height | G8: Quantity | H8: Unit | I8: Rate | J8: Amount | K8: Remark
A9: 1 | B9: Earthwork in Excavation in ordinary soil (vGg] k'g{] sfo{)
B10: -for pipe laying source 1 to tank 2 | C10: 1 | D10: =90+38+40-1 -> 167 | E10: 0.3 | F10: 0.3 | G10: =PRODUCT(C10:F10) -> 15.03
B11: -for pipe laying water tank 1 to tank 2 | C11: 1 | D11: =40+43-2 -> 81 | E11: 0.3 | F11: 0.3 | G11: =PRODUCT(C11:F11) -> 7.29
B12: -for pipe laying tank 2 to destination 1 | C12: 1 | D12: =50+30+2+50+38-20 -> 150 | E12: 0.3 | F12: 0.3 | G12: =PRODUCT(C12:F12) -> 13.5
B13: -for pipe laying tank 2 to destination 2 | C13: 1 | D13: =36+35-15 -> 56 | E13: 0.3 | F13: 0.3 | G13: =PRODUCT(C13:F13) -> 5.04
B14: -for pipe laying tank 2 to destination 3 | C14: 1 | D14: =23-15 -> 8 | E14: 0.3 | F14: 0.3 | G14: =PRODUCT(C14:F14) -> 0.72
B15: -for pipe laying tank 2 to destination 4 | C15: 1 | D15: =36+11+23+30-0.7+50+25+30.7-8+8+50+9+50+50+40+20+50+50+42-3-40-5 -> 518 | E15: 0.3 | F15: 0.3 | G15: =PRODUCT(C15:F15) -> 46.62
B16: sub-total | G16: =SUM(G10:G15) -> 88.2 | H16: cum | I16: 963.05 | J16: =G16*I16 -> 84941.01
A18: 2 | B18: Laying and joining of 32 mmØ HDPE pipe with butt-weld joints
B19: -for pipe laying | C19: 0 | D19: =(SUM(D10:D15))-1*3 -> 977 | G19: =PRODUCT(C19:F19) -> 0
B20: sub-total | G20: =SUM(G19:G19) -> 0 | H20: rm | I20: =5319.5/1000 -> 5.3195 | J20: =G20*I20 -> 0
A22: 3 | B22: -High Density Polythene Pipe NS 40 pipe material PE 100, PN 16 | D22: Length (m) | E22: Weight (Kg/m) | F22: Total weight (Kg)
B23: -for pipe laying source 1 to tank 2 | C23: 1 | D23: 168 | E23: 0.338 | F23: =C23*D23*E23 -> 56.784 | G23: =F23 -> 56.784
B24: -for pipe laying water tank 1 to tank 2 | C24: 1 | D24: 83 | E24: 0.338 | F24: =C24*D24*E24 -> 28.054 | G24: =F24 -> 28.054
B25: -for pipe laying tank 2 to destination 1 | C25: 1 | D25: 170 | E25: 0.338 | F25: =C25*D25*E25 -> 57.46 | G25: =F25 -> 57.46
B26: -for pipe laying tank 2 to destination 2 | C26: 1 | D26: 71 | E26: 0.338 | F26: =C26*D26*E26 -> 23.998 | G26: =F26 -> 23.998
B27: -for pipe laying tank 2 to destination 3 | C27: 1 | D27: 23 | E27: 0.338 | F27: =C27*D27*E27 -> 7.774 | G27: =F27 -> 7.774
B28: -for pipe laying tank 2 to destination 4 | C28: 1 | D28: 565 | E28: 0.338 | F28: =C28*D28*E28 -> 190.97 | G28: =F28 -> 190.97
B29: Sub-total | G29: =SUM(G23:G28) -> 365.04 | H29: kg | I29: 287 | J29: =G29*I29 -> 104766.48
B30: -13% VAT for material | J30: =0.13*J29 -> 13619.642
A32: 4 | B32: 32mm GI pipe threaded
B33: -for pipe laying | C33: 1 | D33: 3 | G33: =PRODUCT(C33:F33) -> 3
B34: sub-total | G34: =SUM(G33:G33) -> 3 | H34: rm | I34: 452 | J34: =G34*I34 -> 1356
B35: -13% VAT for material | J35: =0.13*J34 -> 176.28
A37: 5 | B37: Provisional sum for other unforseen works | C37: 1 | G37: =PRODUCT(C37:F37) -> 1 | H37: PS | I37: 3100 | J37: =G37*I37 -> 3100
A39: 6 | B39: Information board (सुचना पाटि) | C39: 1 | G39: =PRODUCT(C39:F39) -> 1 | H39: no. | I39: 500 | J39: =G39*I39 -> 500
B41: Total | J41: =SUM(J9:J39) -> 208459.41
B43: Total Valuated | C43: =J41 -> 208459.41 | E43: 100
B44: Budget allocated | C44: 300000
B45: Municipal payment | C45: =84.79%*C43 -> 176752.74 | E45: =C45/C43*100 -> 84.79
B46: User contribution | C46: =C43-C45 -> 31706.677 | E46: =100-E45 -> 15.21
B47: Contingencies | C47: =C44*0.03 -> 9000 | E47: 3
...

Sheet original estimate
A1: Government of Nepal
A2: Shankharapur Municipality Office
A3: Bagmati Province
A4: Sankhu, Kathmandu
A5: Detail Estimated Sheet
A6: Project:- dnl;d vfg]kfgL | H6: F.Y.: 2082/2083
A7: Location:- Shankharapur Municipality 1 | H7: Date:2082/09/07
A8: S.N. | B8: Description of work | C8: No. | D8: Length | E8: Breadth | F8: Height | G8: Quantity | H8: Unit | I8: Rate | J8: Amount | K8: Remark
A9: 1 | B9: Earthwork in Excavation in ordinary soil (vGg] k'g{] sfo{)
B10: -for pipe laying | C10: 1 | D10: 175 | E10: 0.3 | F10: 0.45 | G10: =PRODUCT(C10:F10) -> 23.625
C11: 1 | D11: 150 | E11: 0.3 | F11: 0.45 | G11: =PRODUCT(C11:F11) -> 20.25 | R11: =480/3.281 -> 146.29686
C12: 1 | D12: 415 | E12: 0.3 | F12: 0.45 | G12: =PRODUCT(C12:F12) -> 56.025 | R12: =160+135+301 -> 596 | S12: =R12/3.281 -> 181.65194
B13: sub-total | G13: =SUM(G10:G12) -> 99.9 | H13: cum | I13: 963.05 | J13: =G13*I13 -> 96208.695 | R13: 1269 | S13: =R13/3.281 -> 386.77233
A15: 2 | B15: Laying and joining of 32 mmØ HDPE pipe with butt-weld joints
B16: -for pipe laying | C16: 1 | D16: =SUM(D20:D22)-100 -> 1900 | G16: =PRODUCT(C16:F16) -> 1900
B17: sub-total | G17: =SUM(G16:G16) -> 1900 | H17: rm | I17: =5319.5/1000 -> 5.3195 | J17: =G17*I17 -> 10107.05
A19: 3 | B19: -High Density Polythene Pipe NS 40 pipe material PE 100, PN 16 | D19: Length (m) | E19: Weight (Kg/m) | F19: Total weight (Kg)
B20: -from source1 to tank 3, 32mm dia pipe | C20: 1 | D20: 400 | E20: 0.338 | F20: =C20*D20*E20 -> 135.2 | G20: =F20 -> 135.2 | Q20: =0.338*287 -> 97.006
B21: -from tank 2 to 2 houses, 32mm dia pipe | C21: 1 | D21: 300 | E21: 0.338 | F21: =C21*D21*E21 -> 101.4 | G21: =F21 -> 101.4
B22: -from tank 3 to daando house, 32mm dia pipe | C22: 1 | D22: 1300 | E22: 0.338 | F22: =C22*D22*E22 -> 439.4 | G22: =F22 -> 439.4
B23: Sub-total | G23: =SUM(G20:G22) -> 676 | H23: kg | I23: 287 | J23: =G23*I23 -> 194012 | Q23: =1.13*287 -> 324.31
B24: -13% VAT for material | J24: =0.13*J23 -> 25221.56
A26: 4 | B26: 32mm GI pipe threaded
B27: -for pipe laying | C27: 1 | D27: 6 | G27: =PRODUCT(C27:F27) -> 6
B28: sub-total | G28: =SUM(G27:G27) -> 6 | H28: rm | I28: 452 | J28: =G28*I28 -> 2712
A30: 5 | B30: Provisional sum for other unforseen works | C30: 1 | G30: =PRODUCT(C30:F30) -> 1 | H30: PS | I30: 7000 | J30: =G30*I30 -> 7000
A32: 6 | B32: Information board (सुचना पाटि) | C32: 1 | G32: =PRODUCT(C32:F32) -> 1 | H32: no. | I32: 500 | J32: =G32*I32 -> 500
B34: Total | J34: =SUM(J9:J32) -> 335761.3
B36: Total Estimated | C36: =J34 -> 335761.3 | E36: 100
B37: Budget allocated | C37: 300000
B38: Municipal payment | C38: =C37-C40-C41 -> 285000 | E38: =C38/C36*100 -> 84.881729
B39: User contribution | C39: =C36-C38 -> 50761.305 | E39: =100-E38 -> 15.118271
B40: Contingencies | C40: =C37*0.03 -> 9000 | E40: 3
B41: Maintanince | C41: =C37*0.02 -> 6000 | E41: 2
