Workbook

Sheet Estimate
A1: Government of Nepal
A2: Shankharapur Municipality Office
A3: Bagmati Province
A4: Sankhu, Kathmandu
A5: Detail Estimated Sheet
A6: Project:-Nanglebhare Police Chauki Marmat | H6: F.Y.: 2082/2083
A7: Location:- Shankharapur Municipality 9 | H7: Date:
A8: S.N. | B8: Description of work | C8: No. | D8: Length | E8: Breadth | F8: Height | G8: Quantity | H8: Unit | I8: Rate | J8: Amount | K8: Remark
A9: 1 | B9: UPVC sliding window without net (frame 60 X 60mm sash 66 X 42mm white colour with 5mm Glass)
B10: Ground Floor
B11: -Lobby | C11: 1 | D11: 1.81 | E11: 1.33 | G11: =PRODUCT(C11:F11) -> 2.4073
B12: -main door attached window | C12: 2 | D12: 0.67 | E12: 2.04 | G12: =PRODUCT(C12:F12) -> 2.7336
B13: -traffic room | C13: 1 | D13: 1.2 | E13: 1.32 | G13: =PRODUCT(C13:F13) -> 1.584
B14: -store room | C14: 3 | D14: 0.62 | E14: 1.22 | G14: =PRODUCT(C14:F14) -> 2.2692
B15: -Rooms | C15: 1 | D15: 0.62 | E15: 1.22 | G15: =PRODUCT(C15:F15) -> 0.7564
C16: 1 | D16: 1.81 | E16: 1.32 | G16: =PRODUCT(C16:F16) -> 2.3892
B17: -room near staircase | C17: 1 | D17: 1.81 | E17: 1.32 | G17: =PRODUCT(C17:F17) -> 2.3892
B18: -toilet | C18: 2 | D18: 0.9 | E18: 0.55 | G18: =PRODUCT(C18:F18) -> 0.99
B19: First Floor
B20: -Civil barrack room | C20: 1 | D20: 0.62 | E20: 1.2 | G20: =PRODUCT(C20:F20) -> 0.744
C21: 1 | D21: 1.8 | E21: 1.31 | G21: =PRODUCT(C21:F21) -> 2.358
B22: -balcony passage | C22: 1 | D22: 0.45 | E22: 1.27 | G22: =PRODUCT(C22:F22) -> 0.5715
B23: -Civil barrack 2nd room | C23: 2 | D23: 1.8 | E23: 1.32 | G23: =PRODUCT(C23:F23) -> 4.752
C24: 3 | D24: 0.6 | E24: 1.22 | G24: =PRODUCT(C24:F24) -> 2.196
B25: Second Floor
B26: -attched window to door at balcony | C26: 1 | D26: 0.715 | E26: 1.38 | G26: =PRODUCT(C26:F26) -> 0.9867
C27: 1 | D27: 0.715 | E27: 0.52 | G27: =PRODUCT(C27:F27) -> 0.3718
C28: 1 | D28: 0.79 | E28: 2.03 | G28: =PRODUCT(C28:F28) -> 1.6037
B29: -Head room | C29: 1 | D29: 1.8 | E29: 1.32 | G29: =PRODUCT(C29:F29) -> 2.376
C30: 1 | D30: 1.8 | E30: 1.32 | G30: =PRODUCT(C30:F30) -> 2.376
C31: 1 | D31: 1.8 | E31: 1.32 | G31: =PRODUCT(C31:F31) -> 2.376
B32: Sub-total | G32: =SUM(G11:G31) -> 36.2306 | H32: m2 | I32: 6997 | J32: =G32*I32 -> 253505.51
B33: -13% VAT for materials | J33: =0.13*J32 -> 32955.716
A35: 2 | B35: UPVC Single Door with full pannel (frame 60*60mm sash 60X100mm White Colour With Panel)
B36: Ground Floor
B37: -Jail toilet door | C37: 2 | D37: 0.74 | E37: 1.89 | G37: =PRODUCT(C37:F37) -> 2.7972
B38: -store room | C38: 1 | D38: 0.98 | E38: 2.02 | G38: =PRODUCT(C38:F38) -> 1.9796
B39: -Staircase area | C39: 1 | D39: 0.97 | E39: 2.05 | G39: =PRODUCT(C39:F39) -> 1.9885
B40: -Room near staircase | C40: 1 | D40: 0.98 | E40: 2.05 | G40: =PRODUCT(C40:F40) -> 2.009
B41: -at staircase landing | C41: 1 | D41: 0.91 | E41: 1.96 | G41: =PRODUCT(C41:F41) -> 1.7836
...

Sheet Valuation
A1: Government of Nepal
A2: Shankharapur Municipality Office
A3: Bagmati Province
A4: Sankhu, Kathmandu
A5: Detail Valuated Sheet
A6: Project:-Nanglebhare Police Chauki Marmat | H6: F.Y.: 2082/2083
A7: Location:- Shankharapur Municipality 9 | H7: Date:
A8: S.N. | B8: Description of work | C8: No. | D8: Length | E8: Breadth | F8: Height | G8: Quantity | H8: Unit | I8: Rate | J8: Amount | K8: Remark
A9: 1 | B9: UPVC sliding window without net (frame 60 X 60mm sash 66 X 42mm white colour with 5mm Glass)
B10: Ground Floor
B11: -Lobby | C11: 1 | D11: 1.81 | E11: 1.33 | G11: =PRODUCT(C11:F11) -> 2.4073
B12: -main door attached window | C12: 2 | D12: 0.67 | E12: 2.04 | G12: =PRODUCT(C12:F12) -> 2.7336
B13: -traffic room | C13: 1 | D13: 1.2 | E13: 1.32 | G13: =PRODUCT(C13:F13) -> 1.584
B14: -store room | C14: 3 | D14: 0.62 | E14: 1.22 | G14: =PRODUCT(C14:F14) -> 2.2692
B15: -Rooms | C15: 1 | D15: 0.62 | E15: 1.22 | G15: =PRODUCT(C15:F15) -> 0.7564
C16: 1 | D16: 1.81 | E16: 1.32 | G16: =PRODUCT(C16:F16) -> 2.3892
B17: -room near staircase | C17: 1 | D17: 1.81 | E17: 1.32 | G17: =PRODUCT(C17:F17) -> 2.3892
B18: -toilet | C18: 2 | D18: 0.9 | E18: 0.55 | G18: =PRODUCT(C18:F18) -> 0.99
B19: First Floor
B20: -Civil barrack room | C20: 1 | D20: 0.62 | E20: 1.2 | G20: =PRODUCT(C20:F20) -> 0.744
C21: 1 | D21: 1.8 | E21: 1.31 | G21: =PRODUCT(C21:F21) -> 2.358
B22: -balcony passage | C22: 1 | D22: 0.45 | E22: 1.27 | G22: =PRODUCT(C22:F22) -> 0.5715
B23: -Civil barrack 2nd room | C23: 2 | D23: 1.8 | E23: 1.32 | G23: =PRODUCT(C23:F23) -> 4.752
C24: 3 | D24: 0.6 | E24: 1.22 | G24: =PRODUCT(C24:F24) -> 2.196
B25: Second Floor
B26: -attched window to door at balcony | C26: 1 | D26: 0.715 | E26: 1.38 | G26: =PRODUCT(C26:F26) -> 0.9867
C27: 1 | D27: 0.715 | E27: 0.52 | G27: =PRODUCT(C27:F27) -> 0.3718
C28: 1 | D28: 0.79 | E28: 2.03 | G28: =PRODUCT(C28:F28) -> 1.6037
B29: -Head room | C29: 1 | D29: 1.8 | E29: 1.32 | G29: =PRODUCT(C29:F29) -> 2.376
C30: 1 | D30: 1.8 | E30: 1.32 | G30: =PRODUCT(C30:F30) -> 2.376
C31: 1 | D31: 1.8 | E31: 1.32 | G31: =PRODUCT(C31:F31) -> 2.376
B32: Sub-total | G32: =SUM(G11:G31) -> 36.2306 | H32: m2 | I32: 6997 | J32: =G32*I32 -> 253505.51
B33: -13% VAT for materials | J33: =0.13*J32 -> 32955.716
A35: 2 | B35: UPVC Single Door with full pannel (frame 60*60mm sash 60X100mm White Colour With Panel)
B36: Ground Floor
B37: -Jail toilet door | C37: 2 | D37: 0.74 | E37: 1.89 | G37: =PRODUCT(C37:F37) -> 2.7972
B38: -store room | C38: 1 | D38: 0.98 | E38: 2.02 | G38: =PRODUCT(C38:F38) -> 1.9796
B39: -Staircase area | C39: 1 | D39: 0.97 | E39: 2.05 | G39: =PRODUCT(C39:F39) -> 1.9885
B40: -Room near staircase | C40: 1 | D40: 0.98 | E40: 2.05 | G40: =PRODUCT(C40:F40) -> 2.009
B41: -at staircase landing | C41: 1 | D41: 0.91 | E41: 1.96 | G41: =PRODUCT(C41:F41) -> 1.7836
...

Sheet Sheet2
A1: Government of Nepal
A2: Shankharapur Municipality Office
A3: Bagmati Province
A4: Sankhu, Kathmandu
A5: Work Completion Report
A6: Total Estimated Amount: | C6: =F33 -> 0 | H6: Total Valuated Amount : | J6: =I33 -> 0
A7: Work Started : | I7: Work Finished:
A8: ='[1]kalimasta mandir final (2)'!A6:F6 -> Project:- कालीमस्ट मन्दिर निर्माण | I8: F.Y:2081/2082
A9: ='[1]kalimasta mandir final (2)'!A7:F7 -> Location:- Shankharapur Municipality 9 | I9: Date:2081/08/10
A11: S.No. | B11: Description | C11: Unit | D11: Estimated | G11: Valuated | J11: Difference | K11: Remarks
D12: Quantity | E12: Rate | F12: Amount | G12: Quantity | H12: Rate | I12: Amount
A13: =Estimate!A9 -> 1 | B13: =Estimate!B9 -> UPVC sliding window without net (frame 60 X 60mm sash 66 X 42mm white colour with 5mm Glass) | C13: =Estimate!H32 -> m2 | D13: =Estimate!G32 -> 36.2306 | E13: =Estimate!I32 -> 6997 | F13: =D13*E13 -> 253505.51 | G13: =Valuation!G32 -> 36.2306 | H13: =Valuation!I32 -> 6997 | I13: =G13*H13 -> 253505.51 | J13: =I13-F13 -> 0
B14: =Estimate!B33 -> -13% VAT for materials | F14: =Estimate!J33 -> 32955.716 | I14: =Valuation!J33 -> 32955.716 | J14: =I14-F14 -> 0
A16: =Estimate!A35 -> 2 | B16: =Estimate!B35 -> UPVC Single Door with full pannel (frame 60*60mm sash 60X100mm White Colour With Panel) | C16: =Estimate!H50 -> m2 | D16: =Estimate!G50 -> 22.237 | E16: =Estimate!I50 -> 8744 | F16: =D16*E16 -> 194440.33 | G16: =Valuation!G50 -> 22.237 | H16: =Valuation!I50 -> 8744 | I16: =G16*H16 -> 194440.33 | J16: =I16-F16 -> 0
B17: =Estimate!B51 -> -13% VAT for materials | F17: =Estimate!J51 -> 25277.243 | I17: =Valuation!J51 -> 25277.243 | J17: =I17-F17 -> 0
A19: =Estimate!A53 -> 3 | B19: =Estimate!B53 -> UPVC Door with half pannel half glass (frame 60*60mm sash 60X104mm White Colour With 5mm glass) | C19: =Estimate!H56 -> m2 | D19: =Estimate!G56 -> 2.4888 | E19: =Estimate!I56 -> 8624 | F19: =D19*E19 -> 21463.411 | G19: =Valuation!G56 -> 2.4888 | H19: =Valuation!I56 -> 8624 | I19: =G19*H19 -> 21463.411 | J19: =I19-F19 -> 0
B20: =Estimate!B57 -> -13% VAT for materials | F20: =Estimate!J57 -> 2790.2435 | I20: =Valuation!J57 -> 2790.2435 | J20: =I20-F20 -> 0
A22: =Estimate!A59 -> 4 | B22: =Estimate!B59 -> 5mm glass for affected openings | C22: =Estimate!H70 -> m2 | D22: =Estimate!G70 -> 9.9328 | E22: =Estimate!I70 -> 742.44 | F22: =D22*E22 -> 7374.508 | G22: =Valuation!G70 -> 9.9328 | H22: =Valuation!I70 -> 742.44 | I22: =G22*H22 -> 7374.508 | J22: =I22-F22 -> 0
B23: =Estimate!B71 -> -13% VAT for materials | F23: =Estimate!J71 -> 958.68604 | I23: =Valuation!J71 -> 958.68604 | J23: =I23-F23 -> 0
A25: =Estimate!A73 -> 5 | B25: =Estimate!B73 -> Information board (सुचना पाटि) | C25: =Estimate!H73 -> no. | D25: =Estimate!G73 -> 1 | E25: =Estimate!I73 -> 500 | F25: =D25*E25 -> 500 | G25: =Valuation!G73 -> 0 | H25: =Valuation!I73 -> 500 | I25: =G25*H25 -> 0 | J25: =I25-F25 -> -500
B27: Total | F27: =SUM(F13:F25) -> 539265.64 | I27: =SUM(I13:I25) -> 538765.64 | J27: =I27-F27 -> -500
