Workbook

Sheet Estimate
A1: Government of Nepal
A2: Shankharapur Municipality Office
A3: Bagmati Province
A4: Sankhu, Kathmandu
A5: Detail Estimated Sheet
A6: Project:-Nanglebhare Police Chauki Marmat | H6: F.Y.: 2082/2083
A7: Location:- Shankharapur Municipality 9 | H7: Date:
A8: S.N. | B8: Description of work | C8: No. | D8: Length | E8: Breadth | F8: Height | G8: Quantity | H8: Unit | I8: Rate | J8: Amount | K8: Remark
A9: 1 | B9: UPVC sliding window without net (frame 60 X 60mm sash 66 X 42mm white colour with 5mm Glass)
B10: Ground Floor
B11: -Lobby | C11: 1 | D11: 1.81 | E11: 1.33 | G11: =PRODUCT(C11:F11) -> 2.4073
B12: -main door attached window | C12: 2 | D12: 0.67 | E12: 2.04 | G12: =PRODUCT(C12:F12) -> 2.7336
B13: -traffic room | C13: 1 | D13: 1.2 | E13: 1.32 | G13: =PRODUCT(C13:F13) -> 1.584
B14: -store room | C14: 3 | D14: 0.62 | E14: 1.22 | G14: =PRODUCT(C14:F14) -> 2.2692
B15: -Rooms | C15: 1 | D15: 0.62 | E15: 1.22 | G15: =PRODUCT(C15:F15) -> 0.7564
B16: -room near staircase | C16: 1 | D16: 1.81 | E16: 1.32 | G16: =PRODUCT(C16:F16) -> 2.3892
B17: -toilet | C17: 2 | D17: 0.9 | E17: 0.55 | G17: =PRODUCT(C17:F17) -> 0.99
B18: First Floor
B19: -Civil barrack room | C19: 1 | D19: 0.62 | E19: 1.2 | G19: =PRODUCT(C19:F19) -> 0.744
B20: -balcony passage | C20: 1 | D20: 0.45 | E20: 1.27 | G20: =PRODUCT(C20:F20) -> 0.5715
B21: -Civil barrack 2nd room | C21: 2 | D21: 1.8 | E21: 1.32 | G21: =PRODUCT(C21:F21) -> 4.752
C22: 3 | D22: 0.6 | E22: 1.22 | G22: =PRODUCT(C22:F22) -> 2.196
B23: Second Floor
B24: -attched window to door at balcony | C24: 1 | D24: 0.715 | E24: 1.38 | G24: =PRODUCT(C24:F24) -> 0.9867
C25: 1 | D25: 0.715 | E25: 0.52 | G25: =PRODUCT(C25:F25) -> 0.3718
C26: 1 | D26: 0.79 | E26: 2.03 | G26: =PRODUCT(C26:F26) -> 1.6037
B27: -Head room | C27: 1 | D27: 1.8 | E27: 1.32 | G27: =PRODUCT(C27:F27) -> 2.376
C28: 1 | D28: 1.8 | E28: 1.32 | G28: =PRODUCT(C28:F28) -> 2.376
B29: Sub-total | G29: =SUM(G11:G28) -> 29.1074 | H29: m2 | I29: =6997-850.04+742.44 -> 6889.4 | J29: =G29*I29 -> 200532.52
B30: -13% VAT for materials | J30: =0.13*J29 -> 26069.228
A32: 2 | B32: UPVC Single Door with full pannel (frame 60*60mm sash 60X100mm White Colour With Panel)
B33: Ground Floor
B34: -Jail toilet door | C34: 2 | D34: 0.74 | E34: 1.89 | G34: =PRODUCT(C34:F34) -> 2.7972
B35: -store room | C35: 1 | D35: 0.98 | E35: 2.02 | G35: =PRODUCT(C35:F35) -> 1.9796
B36: -Staircase area | C36: 1 | D36: 0.97 | E36: 2.05 | G36: =PRODUCT(C36:F36) -> 1.9885
B37: -Room near staircase | C37: 1 | D37: 0.98 | E37: 2.05 | G37: =PRODUCT(C37:F37) -> 2.009
B38: -at staircase landing | C38: 1 | D38: 0.91 | E38: 1.96 | G38: =PRODUCT(C38:F38) -> 1.7836
B39: First Floor
B40: -Civil barrack room | C40: 1 | D40: 0.93 | E40: 2 | G40: =PRODUCT(C40:F40) -> 1.86
B41: -Civil barrack 2nd room | C41: 1 | D41: 0.95 | E41: 2.06 | G41: =PRODUCT(C41:F41) -> 1.957
...

Sheet Valuation
A1: Government of Nepal
A2: Shankharapur Municipality Office
A3: Bagmati Province
A4: Sankhu, Kathmandu
A5: Detail Valuated Sheet
A6: Project:-Nanglebhare Police Chauki Marmat | H6: F.Y.: 2082/2083
A7: Location:- Shankharapur Municipality 9 | H7: Date:
A8: S.N. | B8: Description of work | C8: No. | D8: Length | E8: Breadth | F8: Height | G8: Quantity | H8: Unit | I8: Rate | J8: Amount | K8: Remark
A9: 1 | B9: UPVC sliding window without net (frame 60 X 60mm sash 66 X 42mm white colour with 5mm Glass)
B10: Ground Floor
B11: -Lobby | C11: 1 | D11: 1.81 | E11: 1.33 | G11: =PRODUCT(C11:F11) -> 2.4073
B12: -main door attached window | C12: 2 | D12: 0.67 | E12: 2.04 | G12: =PRODUCT(C12:F12) -> 2.7336
B13: -traffic room | C13: 1 | D13: 1.2 | E13: 1.32 | G13: =PRODUCT(C13:F13) -> 1.584
B14: -store room | C14: 3 | D14: 0.62 | E14: 1.22 | G14: =PRODUCT(C14:F14) -> 2.2692
B15: -Rooms | C15: 1 | D15: 0.62 | E15: 1.22 | G15: =PRODUCT(C15:F15) -> 0.7564
B16: -room near staircase | C16: 1 | D16: 1.81 | E16: 1.32 | G16: =PRODUCT(C16:F16) -> 2.3892
B17: -toilet | C17: 2 | D17: 0.9 | E17: 0.55 | G17: =PRODUCT(C17:F17) -> 0.99
B18: First Floor
B19: -Civil barrack room | C19: 1 | D19: 0.62 | E19: 1.2 | G19: =PRODUCT(C19:F19) -> 0.744
B20: -balcony passage | C20: 1 | D20: 0.45 | E20: 1.27 | G20: =PRODUCT(C20:F20) -> 0.5715
B21: -Civil barrack 2nd room | C21: 2 | D21: 1.8 | E21: 1.32 | G21: =PRODUCT(C21:F21) -> 4.752
C22: 3 | D22: 0.6 | E22: 1.22 | G22: =PRODUCT(C22:F22) -> 2.196
B23: Second Floor
B24: -attched window to door at balcony | C24: 1 | D24: 0.715 | E24: 1.38 | G24: =PRODUCT(C24:F24) -> 0.9867
C25: 1 | D25: 0.715 | E25: 0.52 | G25: =PRODUCT(C25:F25) -> 0.3718
C26: 1 | D26: 0.79 | E26: 2.03 | G26: =PRODUCT(C26:F26) -> 1.6037
B27: -Head room | C27: 1 | D27: 1.8 | E27: 1.32 | G27: =PRODUCT(C27:F27) -> 2.376
C28: 1 | D28: 1.8 | E28: 1.32 | G28: =PRODUCT(C28:F28) -> 2.376
B29: Sub-total | G29: =SUM(G11:G28) -> 29.1074 | H29: m2 | I29: =6997-850.04+742.44 -> 6889.4 | J29: =G29*I29 -> 200532.52
B30: -13% VAT for materials | J30: =0.13*J29 -> 26069.228
A32: 2 | B32: UPVC Single Door with full pannel (frame 60*60mm sash 60X100mm White Colour With Panel)
B33: Ground Floor
B34: -Jail toilet door | C34: 2 | D34: 0.74 | E34: 1.89 | G34: =PRODUCT(C34:F34) -> 2.7972
B35: -store room | C35: 1 | D35: 0.98 | E35: 2.02 | G35: =PRODUCT(C35:F35) -> 1.9796
B36: -Staircase area | C36: 1 | D36: 0.97 | E36: 2.05 | G36: =PRODUCT(C36:F36) -> 1.9885
B37: -Room near staircase | C37: 1 | D37: 0.98 | E37: 2.05 | G37: =PRODUCT(C37:F37) -> 2.009
B38: -at staircase landing | C38: 1 | D38: 0.91 | E38: 1.96 | G38: =PRODUCT(C38:F38) -> 1.7836
B39: First Floor
B40: -Civil barrack room | C40: 1 | D40: 0.93 | E40: 2 | G40: =PRODUCT(C40:F40) -> 1.86
B41: -Civil barrack 2nd room | C41: 1 | D41: 0.95 | E41: 2.06 | G41: =PRODUCT(C41:F41) -> 1.957
...

Sheet WCR
A1: Government of Nepal
A2: Shankharapur Municipality Office
A3: Bagmati Province
A4: Sankhu, Kathmandu
A5: Work Completion Report
A6: Total Estimated Amount: | C6: =F33 -> 0 | H6: Total Valuated Amount : | J6: =I33 -> 0
A7: Work Started : | I7: Work Finished:
A8: =Estimate!A6 -> Project:-Nanglebhare Police Chauki Marmat | I8: F.Y:2082/2083
A9: ='[1]kalimasta mandir final (2)'!A7:F7 -> Location:- Shankharapur Municipality 9 | I9: Date:
A11: S.No. | B11: Description | C11: Unit | D11: Estimated | G11: Valuated | J11: Difference | K11: Remarks
D12: Quantity | E12: Rate | F12: Amount | G12: Quantity | H12: Rate | I12: Amount
A13: =Estimate!A9 -> 1 | B13: =Estimate!B9 -> UPVC sliding window without net (frame 60 X 60mm sash 66 X 42mm white colour with 5mm Glass) | C13: =Estimate!H29 -> m2 | D13: =Estimate!G29 -> 29.1074 | E13: =Estimate!I29 -> 6889.4 | F13: =D13*E13 -> 200532.52 | G13: =Valuation!G29 -> 29.1074 | H13: =Valuation!I29 -> 6889.4 | I13: =G13*H13 -> 200532.52 | J13: =I13-F13 -> 0
B14: =Estimate!B30 -> -13% VAT for materials | F14: =Estimate!J30 -> 26069.228 | I14: =Valuation!J30 -> 26069.228 | J14: =I14-F14 -> 0
A16: =Estimate!A32 -> 2 | B16: =Estimate!B32 -> UPVC Single Door with full pannel (frame 60*60mm sash 60X100mm White Colour With Panel) | C16: =Estimate!H47 -> m2 | D16: =Estimate!G47 -> 22.237 | E16: =Estimate!I47 -> 8744 | F16: =D16*E16 -> 194440.33 | G16: =Valuation!G47 -> 22.237 | H16: =Valuation!I47 -> 8744 | I16: =G16*H16 -> 194440.33 | J16: =I16-F16 -> 0
B17: =Estimate!B48 -> -13% VAT for materials | F17: =Estimate!J48 -> 25277.243 | I17: =Valuation!J48 -> 25277.243 | J17: =I17-F17 -> 0
A19: =Estimate!A50 -> 3 | B19: =Estimate!B50 -> UPVC Door with half pannel half glass (frame 60*60mm sash 60X104mm White Colour With 5mm glass) | C19: =Estimate!H53 -> m2 | D19: =Estimate!G53 -> 2.4888 | E19: =Estimate!I53 -> 8516.4 | F19: =D19*E19 -> 21195.616 | G19: =Valuation!G53 -> 2.4888 | H19: =Valuation!I53 -> 8516.4 | I19: =G19*H19 -> 21195.616 | J19: =I19-F19 -> 0
B20: =Estimate!B54 -> -13% VAT for materials | F20: =Estimate!J54 -> 2755.4301 | I20: =Valuation!J54 -> 2755.4301 | J20: =I20-F20 -> 0
A22: =Estimate!A56 -> 4 | B22: =Estimate!B56 -> 4mm glass for affected openings | C22: =Estimate!H67 -> m2 | D22: =Estimate!G67 -> 9.9328 | E22: =Estimate!I67 -> 742.44 | F22: =D22*E22 -> 7374.508 | G22: =Valuation!G67 -> 9.9328 | H22: =Valuation!I67 -> 742.44 | I22: =G22*H22 -> 7374.508 | J22: =I22-F22 -> 0
B23: =Estimate!B68 -> -13% VAT for materials | F23: =Estimate!J68 -> 958.68604 | I23: =Valuation!J68 -> 958.68604 | J23: =I23-F23 -> 0
A25: =Estimate!A70 -> 5 | B25: =Estimate!B70 -> Information board (सुचना पाटि) | C25: =Estimate!H70 -> no. | D25: =Estimate!G70 -> 1 | E25: =Estimate!I70 -> 500 | F25: =D25*E25 -> 500 | G25: =Valuation!G70 -> 0 | H25: =Valuation!I70 -> 500 | I25: =G25*H25 -> 0 | J25: =I25-F25 -> -500
B27: Total | F27: =SUM(F13:F25) -> 479103.56 | I27: =SUM(I13:I25) -> 478603.56 | J27: =I27-F27 -> -500

Sheet Measure
A1: Government of Nepal
A2: Shankharapur Municipality Office
A3: Bagmati Province
A4: Sankhu, Kathmandu
A5: Detail Quantity Measurement Sheet
A6: Project:-Nanglebhare Police Chauki Marmat | K6: F.Y.: 2082/2083
A7: Location:- Shankharapur Municipality 9 | K7: Date:
A8: S.N. | B8: Description of work | C8: No. | D8: Length | E8: Breadth | F8: Height | G8: Quantity | H8: Unit | I8: Rate | J8: Amount | K8: Remark
A9: 1 | B9: UPVC sliding window without net (frame 60 X 60mm sash 66 X 42mm white colour with 5mm Glass)
B10: Ground Floor
B11: -Lobby | C11: 1 | D11: 1.81 | E11: 1.33 | G11: =PRODUCT(C11:F11) -> 2.4073
B12: -main door attached window | C12: 2 | D12: 0.67 | E12: 2.04 | G12: =PRODUCT(C12:F12) -> 2.7336
B13: -traffic room | C13: 1 | D13: 1.2 | E13: 1.32 | G13: =PRODUCT(C13:F13) -> 1.584
B14: -store room | C14: 3 | D14: 0.62 | E14: 1.22 | G14: =PRODUCT(C14:F14) -> 2.2692
B15: -Rooms | C15: 1 | D15: 0.62 | E15: 1.22 | G15: =PRODUCT(C15:F15) -> 0.7564
B16: -room near staircase | C16: 1 | D16: 1.81 | E16: 1.32 | G16: =PRODUCT(C16:F16) -> 2.3892
B17: -toilet | C17: 2 | D17: 0.9 | E17: 0.55 | G17: =PRODUCT(C17:F17) -> 0.99
B18: First Floor
B19: -Civil barrack room | C19: 1 | D19: 0.62 | E19: 1.2 | G19: =PRODUCT(C19:F19) -> 0.744
B20: -balcony passage | C20: 1 | D20: 0.45 | E20: 1.27 | G20: =PRODUCT(C20:F20) -> 0.5715
B21: -Civil barrack 2nd room | C21: 2 | D21: 1.8 | E21: 1.32 | G21: =PRODUCT(C21:F21) -> 4.752
C22: 3 | D22: 0.6 | E22: 1.22 | G22: =PRODUCT(C22:F22) -> 2.196
B23: Second Floor
B24: -attched window to door at balcony | C24: 1 | D24: 0.715 | E24: 1.38 | G24: =PRODUCT(C24:F24) -> 0.9867
C25: 1 | D25: 0.715 | E25: 0.52 | G25: =PRODUCT(C25:F25) -> 0.3718
C26: 1 | D26: 0.79 | E26: 2.03 | G26: =PRODUCT(C26:F26) -> 1.6037
B27: -Head room | C27: 1 | D27: 1.8 | E27: 1.32 | G27: =PRODUCT(C27:F27) -> 2.376
C28: 1 | D28: 1.8 | E28: 1.32 | G28: =PRODUCT(C28:F28) -> 2.376
B29: Sub-total | G29: =SUM(G11:G28) -> 29.1074 | H29: m2 | I29: =6997-850.04+742.44 -> 6889.4 | J29: =G29*I29 -> 200532.52
B30: -13% VAT for materials | J30: =0.13*J29 -> 26069.228
A32: 2 | B32: UPVC Single Door with full pannel (frame 60*60mm sash 60X100mm White Colour With Panel)
B33: Ground Floor
B34: -Jail toilet door | C34: 2 | D34: 0.74 | E34: 1.89 | G34: =PRODUCT(C34:F34) -> 2.7972
B35: -store room | C35: 1 | D35: 0.98 | E35: 2.02 | G35: =PRODUCT(C35:F35) -> 1.9796
B36: -Staircase area | C36: 1 | D36: 0.97 | E36: 2.05 | G36: =PRODUCT(C36:F36) -> 1.9885
B37: -Room near staircase | C37: 1 | D37: 0.98 | E37: 2.05 | G37: =PRODUCT(C37:F37) -> 2.009
B38: -at staircase landing | C38: 1 | D38: 0.91 | E38: 1.96 | G38: =PRODUCT(C38:F38) -> 1.7836
B39: First Floor
B40: -Civil barrack room | C40: 1 | D40: 0.93 | E40: 2 | G40: =PRODUCT(C40:F40) -> 1.86
B41: -Civil barrack 2nd room | C41: 1 | D41: 0.95 | E41: 2.06 | G41: =PRODUCT(C41:F41) -> 1.957
...
