Workbook

Sheet two way slab design
A1: Dimension of Slab
A2: c-c length along longer span, ly | D2: 4217.38 | E2: mm
A3: c-c length along shorter span, lx | D3: 3657.42 | E3: mm | G3: =D3*2 -> 7314.84 | M3: =12/3.281*1000 -> 3657.4215
A4: support width | D4: 230 | E4: mm | M4: =13.833/3.28*1000 -> 4217.378
A5: clear span ly | D5: =D2-D4 -> 3987.38 | E5: mm
A6: clear span lx | D6: =D3-D4 -> 3427.42 | E6: mm
A7: ly+.5d | D7: =D5+0.5*D12 -> 4039.88
A8: lx+.5d | D8: =D6+0.5*D12 -> 3479.92
A9: effective span
A10: along longer span, ly | D10: =MIN(D2,D7) -> 4039.88 | E10: mm | H10: IS 456 Cl. 22.2.b.2
A11: along shorter span, lx | D11: =MIN(D3,D8) -> 3479.92 | E11: mm | H11: IS 456 Cl. 22.2.b.2 | J11: =D11/1000 -> 3.47992
A12: thickness of slab | D12: ='Input values and Results'!B5 -> 105 | E12: mm
A13: clear cover | D13: ='Input values and Results'!B6 -> 20 | E13: mm
A14: total thickness | D14: =D12+D13 -> 125 | E14: mm
A15: Reinforced used, Fy | D15: ='Input values and Results'!B8 -> 500 | E15: N/mm2
A16: fck | D16: 20 | E16: N/mm2
A17: self wt. of concrete (γ) | D17: ='Input values and Results'!B10 -> 25 | E17: KN/m3
B19: ly/lx | D19: =D10/D11 -> 1.1609117 | E19: <2
A20: type of slab | C20: =IF(D10/D11<2,"<2 two way slab",">2 so one way slab") -> <2 two way slab
A21: ='Input values and Results'!A12 -> Two Adjacent Edge Discontinuous | T21: =A21 -> Two Adjacent Edge Discontinuous
J22: for | L22: (l/d)basic
J23: cantilever | L23: 7
A24: Load Calculation | J24: simply supported | L24: 20
A25: Self Weight | D25: =D17*D14/1000 -> 3.125 | E25: KN/m2 | J25: continuous | L25: 26
A26: live load | D26: 2 | E26: KN/m2 | J26: one conti. & one discont. | L26: 23
A27: Wall and plaster load | D27: 1.5 | E27: KN/m2
A28: floor finish | D28: 1.25 | E28: KN/m2
C29: FOS | D29: =SUM(D25:D28) -> 7.875 | K29: =25*0.16 -> 4
A30: total load | C30: 1.5 | D30: =D29*C30 -> 11.8125 | E30: KN/m2
C31: Main Bar | D31: Dist. Bar
A32: provide the reinforcement of dia | C32: 8 | D32: 8 | E32: mm
A33: S. No. | B33: Description | C33: Shorter Direction | E33: Longer Direction
C34: Support | D34: mid | E34: Support | F34: mid
A35: 1 | B35: αx & αy | C35: ='alpha value'!L8 -> 0.057263822 | D35: ='alpha value'!L9 -> 0.043045587 | E35: ='alpha value'!M8 -> 0.047 | F35: ='alpha value'!M9 -> 0.035
A36: 2 | B36: BM | C36: =C35*$D$30*$D$11*$D$11/10^6 -> 8.1914479 | D36: =D35*$D$30*$D$11*$D$11/10^6 -> 6.1575646 | E36: =E35*$D$30*$D$11*$D$11/10^6 -> 6.7232336 | F36: =F35*$D$30*$D$11*$D$11/10^6 -> 5.0066633
A37: 3 | B37: Ast required | C37: ='steel area calculation'!L7 -> 187.7314 | D37: ='steel area calculation'!L8 -> 139.44103 | E37: ='steel area calculation'!L9 -> 152.75148 | F37: ='steel area calculation'!L10 -> 112.63492
A38: 4 | B38: Ast min | C38: =0.12%*1000*$D$14 -> 150 | D38: =0.12%*1000*$D$14 -> 150 | E38: =0.12%*1000*$D$14 -> 150 | F38: =0.12%*1000*$D$14 -> 150
B39: Ast required 1 | C39: =IF(C37>C38,C37,C38) -> 187.7314 | D39: =IF(D37>D38,D37,D38) -> 150 | E39: =IF(E37>E38,E37,E38) -> 152.75148 | F39: =IF(F37>F38,F37,F38) -> 150
A40: 5 | B40: Spacing reqd | C40: =1000/(C39/(22*$C$32*$C$32/(4*7))) -> 267.8599 | D40: =1000/(D39/(22*$C$32*$C$32/(4*7))) -> 335.2381 | E40: =1000/(E39/(22*$D$32*$D$32/(4*7))) -> 329.19951 | F40: =1000/(F39/(22*$D$32*$D$32/(4*7))) -> 335.2381
C41: 300 | D41: 300 | E41: 300 | F41: 300
...

Sheet Sheet1
A1: Dimension of Slab
A2: c-c length along longer span, ly | D2: 5224 | E2: mm
A3: c-c length along shorter span, lx | D3: =6313/2 -> 3156.5 | E3: mm | G3: =D3*2 -> 6313
A4: support width | D4: 230 | E4: mm
A5: clear span ly | D5: =D2-D4 -> 4994 | E5: mm
A6: clear span lx | D6: =D3-D4 -> 2926.5 | E6: mm
A7: ly+.5d | D7: =D5+0.5*D12 -> 5046.5
A8: lx+.5d | D8: =D6+0.5*D12 -> 2979
A9: effective span
A10: along longer span, ly | D10: =MIN(D2,D7) -> 5046.5 | E10: mm | H10: IS 456 Cl. 22.2.b.2
A11: along shorter span, lx | D11: =MIN(D3,D8) -> 2979 | E11: mm | H11: IS 456 Cl. 22.2.b.2 | J11: =D11/1000 -> 2.979
A12: thickness of slab | D12: ='Input values and Results'!B5 -> 105 | E12: mm
A13: clear cover | D13: ='Input values and Results'!B6 -> 20 | E13: mm
A14: total thickness | D14: =D12+D13 -> 125 | E14: mm
A15: Reinforced used, Fy | D15: ='Input values and Results'!B8 -> 500 | E15: N/mm2
A16: fck | D16: 20 | E16: N/mm2
A17: self wt. of concrete (γ) | D17: ='Input values and Results'!B10 -> 25 | E17: KN/m3
B19: ly/lx | D19: =D10/D11 -> 1.6940248 | E19: <2
A20: type of slab | C20: =IF(D10/D11<2,"<2 two way slab",">2 so one way slab") -> <2 two way slab
A21: ='Input values and Results'!A12 -> Two Adjacent Edge Discontinuous | T21: =A21 -> Two Adjacent Edge Discontinuous
J22: for | L22: (l/d)basic
J23: cantilever | L23: 7
A24: Load Calculation | J24: simply supported | L24: 20
A25: Self Weight | D25: =D17*D14/1000 -> 3.125 | E25: KN/m2 | J25: continuous | L25: 26
A26: live load | D26: 2 | E26: KN/m2 | J26: one conti. & one discont. | L26: 23
A27: Wall and plaster load | D27: 1.5 | E27: KN/m2
A28: floor finish | D28: 1.5 | E28: KN/m2
C29: FOS | D29: =SUM(D25:D28) -> 8.125 | K29: =25*0.16 -> 4
A30: total load | C30: 1.5 | D30: =D29*C30 -> 12.1875 | E30: KN/m2
C31: Main Bar | D31: Dist. Bar
A32: provide the reinforcement of dia | C32: 10 | D32: 8 | E32: mm
A33: S. No. | B33: Description | C33: Shorter Direction | E33: Longer Direction
C34: Support | D34: mid | E34: Support | F34: mid
A35: 1 | B35: αx & αy | C35: ='alpha value'!L8 -> 0.057263822 | D35: ='alpha value'!L9 -> 0.043045587 | E35: ='alpha value'!M8 -> 0.047 | F35: ='alpha value'!M9 -> 0.035
A36: 2 | B36: BM | C36: =C35*$D$30*$D$11*$D$11/10^6 -> 6.1934975 | D36: =D35*$D$30*$D$11*$D$11/10^6 -> 4.6556923 | E36: =E35*$D$30*$D$11*$D$11/10^6 -> 5.0833907 | F36: =F35*$D$30*$D$11*$D$11/10^6 -> 3.7855037
A37: 3 | B37: Ast required | C37: ='steel area calculation'!L7 -> 187.7314 | D37: ='steel area calculation'!L8 -> 139.44103 | E37: ='steel area calculation'!L9 -> 152.75148 | F37: ='steel area calculation'!L10 -> 112.63492
A38: 4 | B38: Ast min | C38: =0.12%*1000*$D$14 -> 150 | D38: =0.12%*1000*$D$14 -> 150 | E38: =0.12%*1000*$D$14 -> 150 | F38: =0.12%*1000*$D$14 -> 150
B39: Ast required 1 | C39: =IF(C37>C38,C37,C38) -> 187.7314 | D39: =IF(D37>D38,D37,D38) -> 150 | E39: =IF(E37>E38,E37,E38) -> 152.75148 | F39: =IF(F37>F38,F37,F38) -> 150
A40: 5 | B40: Spacing reqd | C40: =1000/(C39/(22*$C$32*$C$32/(4*7))) -> 418.5311 | D40: =1000/(D39/(22*$C$32*$C$32/(4*7))) -> 523.80952 | E40: =1000/(E39/(22*$D$32*$D$32/(4*7))) -> 329.19951 | F40: =1000/(F39/(22*$D$32*$D$32/(4*7))) -> 335.2381
C41: 300 | D41: 300 | E41: 300 | F41: 300
...

Sheet Slab design print
A1: Design of Two way Slab by Limit State Method
A2: (As per IS 456:2000)
A4: 1 | B4: Data
B5: Longer span of slab, ly | C5: ='two way slab design'!D2/1000 -> 4.21738 | D5: m | E5: =11.5/3.28 -> 3.5060976
B6: Shorter span of slab, lx | C6: ='two way slab design'!D3/1000 -> 3.65742 | D6: m | E6: =11.58/3.28 -> 3.5304878
B8: Materials used
B9: Concrete | C9: M20 | D9: ='two way slab design'!D16 -> 20 | E9: N/mm2
B10: Steel | C10: Fe500 | D10: ='two way slab design'!D15 -> 500 | E10: N/mm2
A13: 2 | B13: Effective span
B14: Longer span of slab, ly | C14: ='two way slab design'!D10/1000 -> 4.03988 | D14: m | H14: =3.6/3.42 -> 1.0526316
B15: Shorter span of slab, lx | C15: ='two way slab design'!D11/1000 -> 3.47992 | D15: m
B16: ly/lx | C16: ='two way slab design'!D19 -> 1.1609117
B17: type of slab | C17: =IF(C16<2,"<2 two way slab",">2 so one way slab") -> <2 two way slab
B18: Support Condition :
B19: ='Input values and Results'!A12 -> Two Adjacent Edge Discontinuous
A22: 3 | B22: Calculation of loads
B23: i) Dead load
A24: i | B24: Slab thickness | C24: ='two way slab design'!D14 -> 125 | D24: mm
B25: Self weight of concrete | C25: ='two way slab design'!D17 -> 25 | D25: KN/m3
B26: Dead load of slab = 25 * 0.125 | C26: =C24*C25/1000 -> 3.125 | D26: KN/m2
A27: ii | B27: Screeding thickness | C27: 30 | D27: mm
B28: Self weight of screeding | C28: 20.4 | D28: KN/m3
B29: Dead load of screeding = 20.4 * 0.03 | C29: =C28*C27/1000 -> 0.612 | D29: KN/m2
A30: iii | B30: marble flooring thickness | C30: 19 | D30: mm
B31: Self weight of marble | C31: 27 | D31: KN/m3
B32: Dead load of marble = 27 * 0.019 | C32: =C30*C31/1000 -> 0.513 | D32: KN/m2
A33: iv | B33: Cement plaster thickness | C33: 12.5 | D33: mm
B34: Self weight of plaster | C34: 20.4 | D34: KN/m3
B35: Dead load of plaster = 20.4 * 0.0125 | C35: =C33*C34/1000 -> 0.255 | D35: KN/m2
B36: Total dead load on slab | C36: =C26+C29+C32+C35 -> 4.505 | D36: KN/m2
B38: ii) Live load
B39: For Residential Building | C39: ='two way slab design'!D26 -> 2 | D39: KN/m2
B41: Total design load (DL+LL) | C41: =C36+C39 -> 6.505 | D41: KN/m2
B42: Factored load = 1.5 * design load | C42: =1.5*C41 -> 9.7575 | D42: KN/m2
A44: 4 | B44: Calculation of moments
B45: As per code, | C45: Shorter Direction | E45: Longer Direction
B46: -ve moment at support | C46: Support, αx1 | D46: ='two way slab design'!C35 -> 0.057263822 | E46: Support, αy1 | F46: ='two way slab design'!E35 -> 0.047
B47: +ve moment at mid | C47: mid, αx2 | D47: ='two way slab design'!D35 -> 0.043045587 | E47: mid, αy2 | F47: ='two way slab design'!F35 -> 0.035
B48: Along shorter span,
B49: Mx = αx1*wu*lx | C49: ='two way slab design'!C36 -> 8.1914479 | D49: KNm
...

Sheet calculation for τc
A1: calculation for τc
A2: 100*Ast/(bd) | C2: ='two way slab design'!D68 -> 0.15963719 | G2: Values are incomplete
A3: concrete grade | C3: ='two way slab design'!D63 -> 20
A4: Required τc | D4: =I34 -> 0.28770975
G5: and above | I5: final τc
A6: 100*Ast/(bd) | B6: 15 | C6: 20 | D6: 25 | E6: 30 | F6: 35 | G6: 40
A7: 0 | B7: 0.28 | C7: 0.28 | D7: 0.29 | E7: 0.29 | F7: 0.29 | G7: 0.3
A8: =IF(AND($C$2>=A7,$C$2<=A9),$C$2,0) -> 0 | B8: =IF($A$8=0,0,((B9-B7)/($A$9-$A$7)*($A$8-$A$7)+B7)) -> 0 | C8: =IF($A$8=0,0,((C9-C7)/($A$9-$A$7)*($A$8-$A$7)+C7)) -> 0 | D8: =IF($A$8=0,0,((D9-D7)/($A$9-$A$7)*($A$8-$A$7)+D7)) -> 0 | E8: =IF($A$8=0,0,((E9-E7)/($A$9-$A$7)*($A$8-$A$7)+E7)) -> 0 | F8: =IF($A$8=0,0,((F9-F7)/($A$9-$A$7)*($A$8-$A$7)+F7)) -> 0 | G8: =IF($A$8=0,0,((G9-G7)/($A$9-$A$7)*($A$8-$A$7)+G7)) -> 0 | I8: =IF($C$3=$B$6,B8,IF($C$3=$C$6,C8,IF($C$3=$D$6,D8,IF($C$3=$E$6,E8,IF($C$3=$F$6,F8,IF($C$3=$G$6,G8,"ERROR")))))) -> 0
A9: 0.15 | B9: 0.28 | C9: 0.28 | D9: 0.29 | E9: 0.29 | F9: 0.29 | G9: 0.3
A10: =IF(AND($C$2>=A9,$C$2<=A11),$C$2,0) -> 0.15963719 | B10: =IF($A$10=0,0,(B11-B9)/($A$11-$A$9)*($A$10-$A$9)+B9) -> 0.28674603 | C10: =IF($A$10=0,0,(C11-C9)/($A$11-$A$9)*($A$10-$A$9)+C9) -> 0.28770975 | D10: =IF($A$10=0,0,(D11-D9)/($A$11-$A$9)*($A$10-$A$9)+D9) -> 0.29674603 | E10: =IF($A$10=0,0,(E11-E9)/($A$11-$A$9)*($A$10-$A$9)+E9) -> 0.29770975 | F10: =IF($A$10=0,0,(F11-F9)/($A$11-$A$9)*($A$10-$A$9)+F9) -> 0.29770975 | G10: =IF($A$10=0,0,(G11-G9)/($A$11-$A$9)*($A$10-$A$9)+G9) -> 0.30770975 | I10: =IF($C$3=$B$6,B10,IF($C$3=$C$6,C10,IF($C$3=$D$6,D10,IF($C$3=$E$6,E10,IF($C$3=$F$6,F10,IF($C$3=$G$6,G10,"ERROR")))))) -> 0.28770975
A11: 0.25 | B11: 0.35 | C11: 0.36 | D11: 0.36 | E11: 0.37 | F11: 0.37 | G11: 0.38
A12: =IF(AND($C$2>=A11,$C$2<=A13),$C$2,0) -> 0 | B12: =IF($A$12=0,0,(B13-B11)/($A$13-$A$11)*($A$12-$A$11)+B11) -> 0 | C12: =IF($A$12=0,0,(C13-C11)/($A$13-$A$11)*($A$12-$A$11)+C11) -> 0 | D12: =IF($A$12=0,0,(D13-D11)/($A$13-$A$11)*($A$12-$A$11)+D11) -> 0 | E12: =IF($A$12=0,0,(E13-E11)/($A$13-$A$11)*($A$12-$A$11)+E11) -> 0 | F12: =IF($A$12=0,0,(F13-F11)/($A$13-$A$11)*($A$12-$A$11)+F11) -> 0 | G12: =IF($A$12=0,0,(G13-G11)/($A$13-$A$11)*($A$12-$A$11)+G11) -> 0 | I12: =IF($C$3=$B$6,B12,IF($C$3=$C$6,C12,IF($C$3=$D$6,D12,IF($C$3=$E$6,E12,IF($C$3=$F$6,F12,IF($C$3=$G$6,G12,"ERROR")))))) -> 0
A13: 0.5 | B13: 0.46 | C13: 0.48 | D13: 0.49 | E13: 0.5 | F13: 0.5 | G13: 0.51
A14: =IF(AND($C$2>=A13,$C$2<=A15),$C$2,0) -> 0 | B14: =IF($A$14=0,0,(B15-B13)/($A$15-$A$13)*($A$14-$A$13)+B13) -> 0 | C14: =IF($A$14=0,0,(C15-C13)/($A$15-$A$13)*($A$14-$A$13)+C13) -> 0 | D14: =IF($A$14=0,0,(D15-D13)/($A$15-$A$13)*($A$14-$A$13)+D13) -> 0 | E14: =IF($A$14=0,0,(E15-E13)/($A$15-$A$13)*($A$14-$A$13)+E13) -> 0 | F14: =IF($A$14=0,0,(F15-F13)/($A$15-$A$13)*($A$14-$A$13)+F13) -> 0 | G14: =IF($A$14=0,0,(G15-G13)/($A$15-$A$13)*($A$14-$A$13)+G13) -> 0 | I14: =IF($C$3=$B$6,B14,IF($C$3=$C$6,C14,IF($C$3=$D$6,D14,IF($C$3=$E$6,E14,IF($C$3=$F$6,F14,IF($C$3=$G$6,G14,"ERROR")))))) -> 0
A15: 0.75 | B15: 0.54 | C15: 0.56 | D15: 0.57 | E15: 0.59 | F15: 0.59 | G15: 0.6
A16: =IF(AND($C$2>=A15,$C$2<=A17),$C$2,0) -> 0 | B16: =IF($A$16=0,0,(B17-B15)/($A$17-$A$15)*($A$16-$A$15)+B15) -> 0 | C16: =IF($A$16=0,0,(C17-C15)/($A$17-$A$15)*($A$16-$A$15)+C15) -> 0 | D16: =IF($A$16=0,0,(D17-D15)/($A$17-$A$15)*($A$16-$A$15)+D15) -> 0 | E16: =IF($A$16=0,0,(E17-E15)/($A$17-$A$15)*($A$16-$A$15)+E15) -> 0 | F16: =IF($A$16=0,0,(F17-F15)/($A$17-$A$15)*($A$16-$A$15)+F15) -> 0 | G16: =IF($A$16=0,0,(G17-G15)/($A$17-$A$15)*($A$16-$A$15)+G15) -> 0 | I16: =IF($C$3=$B$6,B16,IF($C$3=$C$6,C16,IF($C$3=$D$6,D16,IF($C$3=$E$6,E16,IF($C$3=$F$6,F16,IF($C$3=$G$6,G16,"ERROR")))))) -> 0
A17: 1 | B17: 0.6 | C17: 0.62 | D17: 0.64 | E17: 0.66 | F17: 0.67 | G17: 0.68
A18: =IF(AND($C$2>=A17,$C$2<=A19),$C$2,0) -> 0 | B18: =IF($A$18=0,0,(B19-B17)/($A$19-$A$17)*($A$18-$A$17)+B17) -> 0 | C18: =IF($A$18=0,0,(C19-C17)/($A$19-$A$17)*($A$18-$A$17)+C17) -> 0 | D18: =IF($A$18=0,0,(D19-D17)/($A$19-$A$17)*($A$18-$A$17)+D17) -> 0 | E18: =IF($A$18=0,0,(E19-E17)/($A$19-$A$17)*($A$18-$A$17)+E17) -> 0 | F18: =IF($A$18=0,0,(F19-F17)/($A$19-$A$17)*($A$18-$A$17)+F17) -> 0 | G18: =IF($A$18=0,0,(G19-G17)/($A$19-$A$17)*($A$18-$A$17)+G17) -> 0 | I18: =IF($C$3=$B$6,B18,IF($C$3=$C$6,C18,IF($C$3=$D$6,D18,IF($C$3=$E$6,E18,IF($C$3=$F$6,F18,IF($C$3=$G$6,G18,"ERROR")))))) -> 0
A19: 1.25 | B19: 0.64 | C19: 0.67 | D19: 0.7 | E19: 0.71 | F19: 0.73 | G19: 0.74
A20: =IF(AND($C$2>=A19,$C$2<=A21),$C$2,0) -> 0 | B20: =IF($A$20=0,0,(B21-B19)/($A$21-$A$19)*($A$20-$A$19)+B19) -> 0 | C20: =IF($A$20=0,0,(C21-C19)/($A$21-$A$19)*($A$20-$A$19)+C19) -> 0 | D20: =IF($A$20=0,0,(D21-D19)/($A$21-$A$19)*($A$20-$A$19)+D19) -> 0 | E20: =IF($A$20=0,0,(E21-E19)/($A$21-$A$19)*($A$20-$A$19)+E19) -> 0 | F20: =IF($A$20=0,0,(F21-F19)/($A$21-$A$19)*($A$20-$A$19)+F19) -> 0 | G20: =IF($A$20=0,0,(G21-G19)/($A$21-$A$19)*($A$20-$A$19)+G19) -> 0 | I20: =IF($C$3=$B$6,B20,IF($C$3=$C$6,C20,IF($C$3=$D$6,D20,IF($C$3=$E$6,E20,IF($C$3=$F$6,F20,IF($C$3=$G$6,G20,"ERROR")))))) -> 0
A21: 1.5 | B21: 0.68 | C21: 0.72 | D21: 0.74 | E21: 0.76 | F21: 0.78 | G21: 0.79
A22: =IF(AND($C$2>=A21,$C$2<=A23),$C$2,0) -> 0 | B22: =IF($A$22=0,0,(B23-B21)/($A$23-$A$21)*($A$22-$A$21)+B21) -> 0 | C22: =IF($A$22=0,0,(C23-C21)/($A$23-$A$21)*($A$22-$A$21)+C21) -> 0 | D22: =IF($A$22=0,0,(D23-D21)/($A$23-$A$21)*($A$22-$A$21)+D21) -> 0 | E22: =IF($A$22=0,0,(E23-E21)/($A$23-$A$21)*($A$22-$A$21)+E21) -> 0 | F22: =IF($A$22=0,0,(F23-F21)/($A$23-$A$21)*($A$22-$A$21)+F21) -> 0 | G22: =IF($A$22=0,0,(G23-G21)/($A$23-$A$21)*($A$22-$A$21)+G21) -> 0 | I22: =IF($C$3=$B$6,B22,IF($C$3=$C$6,C22,IF($C$3=$D$6,D22,IF($C$3=$E$6,E22,IF($C$3=$F$6,F22,IF($C$3=$G$6,G22,"ERROR")))))) -> 0
A23: 1.75 | B23: 0.71 | C23: 0.75 | D23: 0.78 | E23: 0.8 | F23: 0.82 | G23: 0.84
A24: =IF(AND($C$2>=A23,$C$2<=A25),$C$2,0) -> 0 | B24: =IF($A$24=0,0,(B25-B23)/($A$25-$A$23)*($A$24-$A$23)+B23) -> 0 | C24: =IF($A$24=0,0,(C25-C23)/($A$25-$A$23)*($A$24-$A$23)+C23) -> 0 | D24: =IF($A$24=0,0,(D25-D23)/($A$25-$A$23)*($A$24-$A$23)+D23) -> 0 | E24: =IF($A$24=0,0,(E25-E23)/($A$25-$A$23)*($A$24-$A$23)+E23) -> 0 | F24: =IF($A$24=0,0,(F25-F23)/($A$25-$A$23)*($A$24-$A$23)+F23) -> 0 | G24: =IF($A$24=0,0,(G25-G23)/($A$25-$A$23)*($A$24-$A$23)+G23) -> 0 | I24: =IF($C$3=$B$6,B24,IF($C$3=$C$6,C24,IF($C$3=$D$6,D24,IF($C$3=$E$6,E24,IF($C$3=$F$6,F24,IF($C$3=$G$6,G24,"ERROR")))))) -> 0
A25: 2 | B25: 0.71 | C25: 0.79 | D25: 0.82 | E25: 0.84 | F25: 0.86 | G25: 0.88
A26: =IF(AND($C$2>=A25,$C$2<=A27),$C$2,0) -> 0 | B26: =IF($A$26=0,0,(B27-B25)/($A$27-$A$25)*($A$26-$A$25)+B25) -> 0 | C26: =IF($A$26=0,0,(C27-C25)/($A$27-$A$25)*($A$26-$A$25)+C25) -> 0 | D26: =IF($A$26=0,0,(D27-D25)/($A$27-$A$25)*($A$26-$A$25)+D25) -> 0 | E26: =IF($A$26=0,0,(E27-E25)/($A$27-$A$25)*($A$26-$A$25)+E25) -> 0 | F26: =IF($A$26=0,0,(F27-F25)/($A$27-$A$25)*($A$26-$A$25)+F25) -> 0 | G26: =IF($A$26=0,0,(G27-G25)/($A$27-$A$25)*($A$26-$A$25)+G25) -> 0 | I26: =IF($C$3=$B$6,B26,IF($C$3=$C$6,C26,IF($C$3=$D$6,D26,IF($C$3=$E$6,E26,IF($C$3=$F$6,F26,IF($C$3=$G$6,G26,"ERROR")))))) -> 0
A27: 2.25 | B27: 0.71 | C27: 0.81 | D27: 0.85 | E27: 0.88 | F27: 0.9 | G27: 0.92
A28: =IF(AND($C$2>=A27,$C$2<=A29),$C$2,0) -> 0 | B28: =IF($A$28=0,0,(B29-B27)/($A$29-$A$27)*($A$28-$A$27)+B27) -> 0 | C28: =IF($A$28=0,0,(C29-C27)/($A$29-$A$27)*($A$28-$A$27)+C27) -> 0 | D28: =IF($A$28=0,0,(D29-D27)/($A$29-$A$27)*($A$28-$A$27)+D27) -> 0 | E28: =IF($A$28=0,0,(E29-E27)/($A$29-$A$27)*($A$28-$A$27)+E27) -> 0 | F28: =IF($A$28=0,0,(F29-F27)/($A$29-$A$27)*($A$28-$A$27)+F27) -> 0 | G28: =IF($A$28=0,0,(G29-G27)/($A$29-$A$27)*($A$28-$A$27)+G27) -> 0 | I28: =IF($C$3=$B$6,B28,IF($C$3=$C$6,C28,IF($C$3=$D$6,D28,IF($C$3=$E$6,E28,IF($C$3=$F$6,F28,IF($C$3=$G$6,G28,"ERROR")))))) -> 0
A29: 2.5 | B29: 0.71 | C29: 0.82 | D29: 0.88 | E29: 0.91 | F29: 0.93 | G29: 0.95
A30: =IF(AND($C$2>=A29,$C$2<=A31),$C$2,0) -> 0 | B30: =IF($A$30=0,0,(B31-B29)/($A$31-$A$29)*($A$30-$A$29)+B29) -> 0 | C30: =IF($A$30=0,0,(C31-C29)/($A$31-$A$29)*($A$30-$A$29)+C29) -> 0 | D30: =IF($A$30=0,0,(D31-D29)/($A$31-$A$29)*($A$30-$A$29)+D29) -> 0 | E30: =IF($A$30=0,0,(E31-E29)/($A$31-$A$29)*($A$30-$A$29)+E29) -> 0 | F30: =IF($A$30=0,0,(F31-F29)/($A$31-$A$29)*($A$30-$A$29)+F29) -> 0 | G30: =IF($A$30=0,0,(G31-G29)/($A$31-$A$29)*($A$30-$A$29)+G29) -> 0 | I30: =IF($C$3=$B$6,B30,IF($C$3=$C$6,C30,IF($C$3=$D$6,D30,IF($C$3=$E$6,E30,IF($C$3=$F$6,F30,IF($C$3=$G$6,G30,"ERROR")))))) -> 0
A31: 2.75 | B31: 0.71 | C31: 0.82 | D31: 0.9 | E31: 0.94 | F31: 0.96 | G31: 0.98
A32: =IF(AND($C$2>=A31,$C$2<=A33),$C$2,0) -> 0 | B32: =IF($A$32=0,0,(B33-B31)/($A$33-$A$31)*($A$32-$A$31)+B31) -> 0 | C32: =IF($A$32=0,0,(C33-C31)/($A$33-$A$31)*($A$32-$A$31)+C31) -> 0 | D32: =IF($A$32=0,0,(D33-D31)/($A$33-$A$31)*($A$32-$A$31)+D31) -> 0 | E32: =IF($A$32=0,0,(E33-E31)/($A$33-$A$31)*($A$32-$A$31)+E31) -> 0 | F32: =IF($A$32=0,0,(F33-F31)/($A$33-$A$31)*($A$32-$A$31)+F31) -> 0 | G32: =IF($A$32=0,0,(G33-G31)/($A$33-$A$31)*($A$32-$A$31)+G31) -> 0 | I32: =IF($C$3=$B$6,B32,IF($C$3=$C$6,C32,IF($C$3=$D$6,D32,IF($C$3=$E$6,E32,IF($C$3=$F$6,F32,IF($C$3=$G$6,G32,"ERROR")))))) -> 0
A33: 3 | B33: 0.71 | C33: 0.82 | D33: 0.92 | E33: 0.96 | F33: 0.99 | G33: 1.01
I34: =MAX(I8:I32) -> 0.28770975
A36: depth,D | C36: 130
D37: or more | P37: or less
A38: overall depth | C38: =IF(C36>D38,C36,0) -> 0 | D38: 300 | E38: =IF(AND($C$36<=D38,$C$36>=F38),$C$36,0) -> 0 | F38: 275 | G38: =IF(AND($C$36<=F38,$C$36>=H38),$C$36,0) -> 0 | H38: 250 | I38: =IF(AND($C$36<=H38,$C$36>=J38),$C$36,0) -> 0 | J38: 225 | K38: =IF(AND($C$36<=J38,$C$36>=L38),$C$36,0) -> 0 | L38: 200 | M38: =IF(AND($C$36<=L38,$C$36>=N38),$C$36,0) -> 0 | N38: 175 | O38: =IF(AND($C$36<=N38,$C$36>=P38),$C$36,0) -> 0 | P38: 150 | Q38: =IF(C36<P38,C36,0) -> 130
B39: k | C39: =IF(C38=0,0,D39) -> 0 | D39: 1 | E39: =IF(E38=0,0,(F39-D39)/(F38-D38)*(E38-D38)+D39) -> 0 | F39: 1.05 | G39: =IF(G38=0,0,(H39-F39)/(H38-F38)*(G38-F38)+F39) -> 0 | H39: 1.1 | I39: =IF(I38=0,0,(J39-H39)/(J38-H38)*(I38-H38)+H39) -> 0 | J39: 1.15 | K39: =IF(K38=0,0,(L39-J39)/(L38-J38)*(K38-J38)+J39) -> 0 | L39: 1.2 | M39: =IF(M38=0,0,(N39-L39)/(N38-L38)*(M38-L38)+L39) -> 0 | N39: 1.25 | O39: =IF(O38=0,0,(P39-N39)/(P38-N38)*(O38-N38)+N39) -> 0 | P39: 1.3 | Q39: =IF(Q38=0,0,P39) -> 1.3
C40: =C39 -> 0 | E40: =E39 -> 0 | G40: =G39 -> 0 | I40: =I39 -> 0 | K40: =K39 -> 0 | M40: =M39 -> 0 | O40: =O39 -> 0 | Q40: =Q39 -> 1.3 | S40: =MAX(C40:Q40) -> 1.3
A42: required K | B42: =S40 -> 1.3

Sheet Input values and Results
A2: Dimension of Slab | B2: =(G2*12+H2)*25.4 -> 4216.4 | C2: =(I2*12+J2)*25.4 -> 3657.6 | D2: mm | G2: 13 | H2: 10 | I2: 12
A3: along longer span, ly | B3: =IF(B2>C2,B2,C2) -> 4216.4 | C3: mm
A4: along shorter span, lx | B4: =IF(B2<C2,B2,C2) -> 3657.6 | C4: mm
A5: thickness of slab | B5: 105 | C5: mm
A6: clear cover | B6: 20 | C6: mm
A7: total thickness | B7: =B5+B6 -> 125 | C7: mm
A8: Reinforced used, Fy | B8: 500 | C8: N/mm2
A9: fck | B9: 20 | C9: N/mm2
A10: self wt. of concrete (γ) | B10: 25 | C10: N/mm3
A11: Type of the slab
A12: Two Adjacent Edge Discontinuous

Sheet alpha value
B1: Calculation of αx and αy
B2: Ratio of longer span to shorter span, ly/lx | I2: ='two way slab design'!D10/'two way slab design'!D11 -> 1.1609117
B3: Select The Data as | I3: =P3 -> 4 | P3: =IF('two way slab design'!T21=W5,B5,IF('two way slab design'!T21=W6,B6,IF('two way slab design'!T21=W7,B7,IF('two way slab design'!T21=W8,B8,IF('two way slab design'!T21=W9,B9,IF('two way slab design'!T21=W10,B10,IF('two way slab design'!T21=W11,B11,IF('two way slab design'!T21=W12,B12,IF('two way slab design'!T21=W13,B13,"ERROR"))))))))) -> 4
B4: S.No
B5: 1 | C5: Interior Pannels | W5: Interior Pannels
B6: 2 | C6: One Short Edge Discontinious | W6: One Short Edge Discontinuous
B7: 3 | C7: One Long Edge Discontinious | L7: αx | M7: αy | W7: One Long Edge Discontinuous
B8: 4 | C8: Two Adjacent Edge Discontinious | J8: support | L8: =IF($I$3=$A$17,R17,IF($I$3=$A$20,R20,IF($I$3=$A$23,R23,IF($I$3=$A$26,R26,IF($I$3=$A$29,R29,IF($I$3=$A$32,R32,IF($I$3=$A$35,R35,IF($I$3=$A$38,R38,IF($I$3=$A$41,R41,0))))))))) -> 0.057263822 | M8: =IF($I$3=$A$17,S17,IF($I$3=$A$20,S20,IF($I$3=$A$23,S23,IF($I$3=$A$26,S26,IF($I$3=$A$29,S29,IF($I$3=$A$32,S32,IF($I$3=$A$35,S35,IF($I$3=$A$38,S38,IF($I$3=$A$41,S41,0))))))))) -> 0.047 | W8: Two Adjacent Edge Discontinuous
B9: 5 | C9: Two Short Edge Discontinious | J9: mid span | L9: =IF($I$3=$A$17,R18,IF($I$3=$A$20,R21,IF($I$3=$A$23,R24,IF($I$3=$A$26,R27,IF($I$3=$A$29,R30,IF($I$3=$A$32,R33,IF($I$3=$A$35,R36,IF($I$3=$A$38,R39,IF($I$3=$A$41,R42,0))))))))) -> 0.043045587 | M9: =IF($I$3=$A$17,S18,IF($I$3=$A$20,S21,IF($I$3=$A$23,S24,IF($I$3=$A$26,S27,IF($I$3=$A$29,S30,IF($I$3=$A$32,S33,IF($I$3=$A$35,S36,IF($I$3=$A$38,S39,IF($I$3=$A$41,S42,0))))))))) -> 0.035 | W9: Two Short Edge Discontinuous
B10: 6 | C10: Two Long Edge Discontinious | W10: Two Long Edge Discontinuous
B11: 7 | C11: Three Edge Discontionious (One Long Edge Continious ) | W11: Three Edge Discontinuous (One Long Edge Continuous )
B12: 8 | C12: Three Edge Discontionious (One Short Edge Continious ) | W12: Three Edge Discontinuous (One Short Edge Continuous )
B13: 9 | C13: Four Edge Discontinious | R13: REQD ANS | W13: Four Edge Discontinuous
B15: ly/lx | R15: αx | S15: αy
B16: 1 | C16: =IF(AND($I$2>=B16,$I$2<=D16),$I$2,0) -> 0 | D16: 1.1 | E16: =IF(AND($I$2>=D16,$I$2<=F16),$I$2,0) -> 1.1609117 | F16: 1.2 | G16: =IF(AND($I$2>=F16,$I$2<=H16),$I$2,0) -> 0 | H16: 1.3 | I16: =IF(AND($I$2>=H16,$I$2<=J16),$I$2,0) -> 0 | J16: 1.4 | K16: =IF(AND($I$2>=J16,$I$2<=L16),$I$2,0) -> 0 | L16: 1.5 | M16: =IF(AND($I$2>=L16,$I$2<=N16),$I$2,0) -> 0 | N16: 1.75 | O16: =IF(AND($I$2>=N16,$I$2<=P16),$I$2,0) -> 0 | P16: 2 | Q16: =IF(AND($I$2>=P16),$I$2,0) -> 0
A17: 1 | B17: 0.032 | C17: =IF($C$16>0,(((D17-B17)/($D$16-$B$16))*($C$16-$B$16))+B17,0) -> 0 | D17: 0.037 | E17: =IF($E$16>0,(((F17-D17)/($F$16-$D$16))*($E$16-$D$16))+D17,0) -> 0.040654705 | F17: 0.043 | G17: =IF($G$16>0,(((H17-F17)/($H$16-$F$16))*($G$16-$F$16))+F17,0) -> 0 | H17: 0.047 | I17: =IF($I$16>0,(((J17-H17)/($J$16-$H$16))*($I$16-$H$16))+H17,0) -> 0 | J17: 0.051 | K17: =IF($K$16>0,(((L17-J17)/($L$16-$J$16))*($K$16-$J$16))+J17,0) -> 0 | L17: 0.053 | M17: =IF($M$16>0,(((N17-L17)/($N$16-$L$16))*($M$16-$L$16))+L17,0) -> 0 | N17: 0.06 | O17: =IF($O$16>0,(((P17-N17)/($P$16-$N$16))*($O$16-$N$16))+N17,0) -> 0 | P17: 0.065 | Q17: =IF($Q$16>0,(((#REF!-P17)/(#REF!-$P$16))*($Q$16-$P$16))+P17,0) -> 0 | R17: =MAX(C17,E17,G17,I17,K17,M17,O17) -> 0.040654705 | S17: 0.032
B18: 0.024 | C18: =IF($C$16>0,(((D18-B18)/($D$16-$B$16))*($C$16-$B$16))+B18,0) -> 0 | D18: 0.028 | E18: =IF($E$16>0,(((F18-D18)/($F$16-$D$16))*($E$16-$D$16))+D18,0) -> 0.03043647 | F18: 0.032 | G18: =IF($G$16>0,(((H18-F18)/($H$16-$F$16))*($G$16-$F$16))+F18,0) -> 0 | H18: 0.036 | I18: =IF($I$16>0,(((J18-H18)/($J$16-$H$16))*($I$16-$H$16))+H18,0) -> 0 | J18: 0.039 | K18: =IF($K$16>0,(((L18-J18)/($L$16-$J$16))*($K$16-$J$16))+J18,0) -> 0 | L18: 0.041 | M18: =IF($M$16>0,(((N18-L18)/($N$16-$L$16))*($M$16-$L$16))+L18,0) -> 0 | N18: 0.045 | O18: =IF($O$16>0,(((P18-N18)/($P$16-$N$16))*($O$16-$N$16))+N18,0) -> 0 | P18: 0.049 | Q18: =IF($Q$16>0,(((#REF!-P18)/(#REF!-$P$16))*($Q$16-$P$16))+P18,0) -> 0 | R18: =MAX(C18,E18,G18,I18,K18,M18,O18) -> 0.03043647 | S18: 0.024
R19: =MAX(C19,E19,G19,I19,K19,M19,O19) -> 0
A20: 2 | B20: 0.037 | C20: =IF($C$16>0,(((D20-B20)/($D$16-$B$16))*($C$16-$B$16))+B20,0) -> 0 | D20: 0.043 | E20: =IF($E$16>0,(((F20-D20)/($F$16-$D$16))*($E$16-$D$16))+D20,0) -> 0.046045587 | F20: 0.048 | G20: =IF($G$16>0,(((H20-F20)/($H$16-$F$16))*($G$16-$F$16))+F20,0) -> 0 | H20: 0.051 | I20: =IF($I$16>0,(((J20-H20)/($J$16-$H$16))*($I$16-$H$16))+H20,0) -> 0 | J20: 0.055 | K20: =IF($K$16>0,(((L20-J20)/($L$16-$J$16))*($K$16-$J$16))+J20,0) -> 0 | L20: 0.057 | M20: =IF($M$16>0,(((N20-L20)/($N$16-$L$16))*($M$16-$L$16))+L20,0) -> 0 | N20: 0.064 | O20: =IF($O$16>0,(((P20-N20)/($P$16-$N$16))*($O$16-$N$16))+N20,0) -> 0 | P20: 0.068 | Q20: =IF($Q$16>0,(((#REF!-P20)/(#REF!-$P$16))*($Q$16-$P$16))+P20,0) -> 0 | R20: =MAX(C20,E20,G20,I20,K20,M20,O20) -> 0.046045587 | S20: 0.037
B21: 0.028 | C21: =IF($C$16>0,(((D21-B21)/($D$16-$B$16))*($C$16-$B$16))+B21,0) -> 0 | D21: 0.032 | E21: =IF($E$16>0,(((F21-D21)/($F$16-$D$16))*($E$16-$D$16))+D21,0) -> 0.03443647 | F21: 0.036 | G21: =IF($G$16>0,(((H21-F21)/($H$16-$F$16))*($G$16-$F$16))+F21,0) -> 0 | H21: 0.039 | I21: =IF($I$16>0,(((J21-H21)/($J$16-$H$16))*($I$16-$H$16))+H21,0) -> 0 | J21: 0.041 | K21: =IF($K$16>0,(((L21-J21)/($L$16-$J$16))*($K$16-$J$16))+J21,0) -> 0 | L21: 0.044 | M21: =IF($M$16>0,(((N21-L21)/($N$16-$L$16))*($M$16-$L$16))+L21,0) -> 0 | N21: 0.048 | O21: =IF($O$16>0,(((P21-N21)/($P$16-$N$16))*($O$16-$N$16))+N21,0) -> 0 | P21: 0.052 | Q21: =IF($Q$16>0,(((#REF!-P21)/(#REF!-$P$16))*($Q$16-$P$16))+P21,0) -> 0 | R21: =MAX(C21,E21,G21,I21,K21,M21,O21) -> 0.03443647 | S21: 0.028
R22: =MAX(C22,E22,G22,I22,K22,M22,O22) -> 0
A23: 3 | B23: 0.037 | C23: =IF($C$16>0,(((D23-B23)/($D$16-$B$16))*($C$16-$B$16))+B23,0) -> 0 | D23: 0.044 | E23: =IF($E$16>0,(((F23-D23)/($F$16-$D$16))*($E$16-$D$16))+D23,0) -> 0.04887294 | F23: 0.052 | G23: =IF($G$16>0,(((H23-F23)/($H$16-$F$16))*($G$16-$F$16))+F23,0) -> 0 | H23: 0.057 | I23: =IF($I$16>0,(((J23-H23)/($J$16-$H$16))*($I$16-$H$16))+H23,0) -> 0 | J23: 0.063 | K23: =IF($K$16>0,(((L23-J23)/($L$16-$J$16))*($K$16-$J$16))+J23,0) -> 0 | L23: 0.067 | M23: =IF($M$16>0,(((N23-#REF!)/($N$16-$L$16))*($M$16-$L$16))+#REF!,0) -> 0 | N23: 0.077 | O23: =IF($O$16>0,(((P23-N23)/($P$16-$N$16))*($O$16-$N$16))+N23,0) -> 0 | P23: 0.085 | Q23: =IF($Q$16>0,(((#REF!-P23)/(#REF!-$P$16))*($Q$16-$P$16))+P23,0) -> 0 | R23: =MAX(C23,E23,G23,I23,K23,M23,O23) -> 0.04887294 | S23: 0.037
B24: 0.028 | C24: =IF($C$16>0,(((D24-B24)/($D$16-$B$16))*($C$16-$B$16))+B24,0) -> 0 | D24: 0.033 | E24: =IF($E$16>0,(((F24-D24)/($F$16-$D$16))*($E$16-$D$16))+D24,0) -> 0.036654705 | F24: 0.039 | G24: =IF($G$16>0,(((H24-F24)/($H$16-$F$16))*($G$16-$F$16))+F24,0) -> 0 | H24: 0.044 | I24: =IF($I$16>0,(((J24-H24)/($J$16-$H$16))*($I$16-$H$16))+H24,0) -> 0 | J24: 0.047 | K24: =IF($K$16>0,(((L24-J24)/($L$16-$J$16))*($K$16-$J$16))+J24,0) -> 0 | L24: 0.051 | M24: =IF($M$16>0,(((N24-L24)/($N$16-$L$16))*($M$16-$L$16))+L24,0) -> 0 | N24: 0.059 | O24: =IF($O$16>0,(((P24-N24)/($P$16-$N$16))*($O$16-$N$16))+N24,0) -> 0 | P24: 0.065 | Q24: =IF($Q$16>0,(((#REF!-P24)/(#REF!-$P$16))*($Q$16-$P$16))+P24,0) -> 0 | R24: =MAX(C24,E24,G24,I24,K24,M24,O24) -> 0.036654705 | S24: 0.028
R25: =MAX(C25,E25,G25,I25,K25,M25,O25) -> 0
A26: 4 | B26: 0.047 | C26: =IF($C$16>0,(((D26-B26)/($D$16-$B$16))*($C$16-$B$16))+B26,0) -> 0 | D26: 0.053 | E26: =IF($E$16>0,(((F26-D26)/($F$16-$D$16))*($E$16-$D$16))+D26,0) -> 0.057263822 | F26: 0.06 | G26: =IF($G$16>0,(((H26-F26)/($H$16-$F$16))*($G$16-$F$16))+F26,0) -> 0 | H26: 0.065 | I26: =IF($I$16>0,(((J26-H26)/($J$16-$H$16))*($I$16-$H$16))+H26,0) -> 0 | J26: 0.071 | K26: =IF($K$16>0,(((L26-J26)/($L$16-$J$16))*($K$16-$J$16))+J26,0) -> 0 | L26: 0.075 | M26: =IF($M$16>0,(((N26-L26)/($N$16-$L$16))*($M$16-$L$16))+L26,0) -> 0 | N26: 0.084 | O26: =IF($O$16>0,(((P26-N26)/($P$16-$N$16))*($O$16-$N$16))+N26,0) -> 0 | P26: 0.091 | Q26: =IF($Q$16>0,(((#REF!-P26)/(#REF!-$P$16))*($Q$16-$P$16))+P26,0) -> 0 | R26: =MAX(C26,E26,G26,I26,K26,M26,O26) -> 0.057263822 | S26: 0.047
B27: 0.035 | C27: =IF($C$16>0,(((D27-B27)/($D$16-$B$16))*($C$16-$B$16))+B27,0) -> 0 | D27: 0.04 | E27: =IF($E$16>0,(((F27-D27)/($F$16-$D$16))*($E$16-$D$16))+D27,0) -> 0.043045587 | F27: 0.045 | G27: =IF($G$16>0,(((H27-F27)/($H$16-$F$16))*($G$16-$F$16))+F27,0) -> 0 | H27: 0.049 | I27: =IF($I$16>0,(((J27-H27)/($J$16-$H$16))*($I$16-$H$16))+H27,0) -> 0 | J27: 0.053 | K27: =IF($K$16>0,(((L27-J27)/($L$16-$J$16))*($K$16-$J$16))+J27,0) -> 0 | L27: 0.056 | M27: =IF($M$16>0,(((N27-L27)/($N$16-$L$16))*($M$16-$L$16))+L27,0) -> 0 | N27: 0.063 | O27: =IF($O$16>0,(((P27-N27)/($P$16-$N$16))*($O$16-$N$16))+N27,0) -> 0 | P27: 0.069 | Q27: =IF($Q$16>0,(((#REF!-P27)/(#REF!-$P$16))*($Q$16-$P$16))+P27,0) -> 0 | R27: =MAX(C27,E27,G27,I27,K27,M27,O27) -> 0.043045587 | S27: 0.035
R28: =MAX(C28,E28,G28,I28,K28,M28,O28) -> 0
A29: 5 | B29: 0.045 | C29: =IF($C$16>0,(((D29-B29)/($D$16-$B$16))*($C$16-$B$16))+B29,0) -> 0 | D29: 0.049 | E29: =IF($E$16>0,(((F29-D29)/($F$16-$D$16))*($E$16-$D$16))+D29,0) -> 0.050827352 | F29: 0.052 | G29: =IF($G$16>0,(((H29-F29)/($H$16-$F$16))*($G$16-$F$16))+F29,0) -> 0 | H29: 0.056 | I29: =IF($I$16>0,(((J29-H29)/($J$16-$H$16))*($I$16-$H$16))+H29,0) -> 0 | J29: 0.059 | K29: =IF($K$16>0,(((L29-J29)/($L$16-$J$16))*($K$16-$J$16))+J29,0) -> 0 | L29: 0.06 | M29: =IF($M$16>0,(((N29-L29)/($N$16-$L$16))*($M$16-$L$16))+L29,0) -> 0 | N29: 0.065 | O29: =IF($O$16>0,(((P29-N29)/($P$16-$N$16))*($O$16-$N$16))+N29,0) -> 0 | P29: 0.069 | Q29: =IF($Q$16>0,(((#REF!-P29)/(#REF!-$P$16))*($Q$16-$P$16))+P29,0) -> 0 | R29: =MAX(C29,E29,G29,I29,K29,M29,O29) -> 0.050827352
B30: 0.035 | C30: =IF($C$16>0,(((D30-B30)/($D$16-$B$16))*($C$16-$B$16))+B30,0) -> 0 | D30: 0.037 | E30: =IF($E$16>0,(((F30-D30)/($F$16-$D$16))*($E$16-$D$16))+D30,0) -> 0.038827352 | F30: 0.04 | G30: =IF($G$16>0,(((H30-F30)/($H$16-$F$16))*($G$16-$F$16))+F30,0) -> 0 | H30: 0.043 | I30: =IF($I$16>0,(((J30-H30)/($J$16-$H$16))*($I$16-$H$16))+H30,0) -> 0 | J30: 0.044 | K30: =IF($K$16>0,(((L30-J30)/($L$16-$J$16))*($K$16-$J$16))+J30,0) -> 0 | L30: 0.045 | M30: =IF($M$16>0,(((N30-L30)/($N$16-$L$16))*($M$16-$L$16))+L30,0) -> 0 | N30: 0.049 | O30: =IF($O$16>0,(((P30-N30)/($P$16-$N$16))*($O$16-$N$16))+N30,0) -> 0 | P30: 0.052 | Q30: =IF($Q$16>0,(((#REF!-P30)/(#REF!-$P$16))*($Q$16-$P$16))+P30,0) -> 0 | R30: =MAX(C30,E30,G30,I30,K30,M30,O30) -> 0.038827352 | S30: 0.035
R31: =MAX(C31,E31,G31,I31,K31,M31,O31) -> 0
A32: 6 | C32: =IF($C$16>0,(((D32-B32)/($D$16-$B$16))*($C$16-$B$16))+B32,0) -> 0 | E32: =IF($E$16>0,(((F32-D32)/($F$16-$D$16))*($E$16-$D$16))+D32,0) -> 0 | G32: =IF($G$16>0,(((H32-F32)/($H$16-$F$16))*($G$16-$F$16))+F32,0) -> 0 | I32: =IF($I$16>0,(((J32-H32)/($J$16-$H$16))*($I$16-$H$16))+H32,0) -> 0 | K32: =IF($K$16>0,(((L32-J32)/($L$16-$J$16))*($K$16-$J$16))+J32,0) -> 0 | M32: =IF($M$16>0,(((N32-L32)/($N$16-$L$16))*($M$16-$L$16))+L32,0) -> 0 | O32: =IF($O$16>0,(((P32-N32)/($P$16-$N$16))*($O$16-$N$16))+N32,0) -> 0 | Q32: =IF($Q$16>0,(((#REF!-P32)/(#REF!-$P$16))*($Q$16-$P$16))+P32,0) -> 0 | R32: =MAX(C32,E32,G32,I32,K32,M32,O32) -> 0 | S32: 0.045
B33: 0.035 | C33: =IF($C$16>0,(((D33-B33)/($D$16-$B$16))*($C$16-$B$16))+B33,0) -> 0 | D33: 0.043 | E33: =IF($E$16>0,(((F33-D33)/($F$16-$D$16))*($E$16-$D$16))+D33,0) -> 0.04787294 | F33: 0.051 | G33: =IF($G$16>0,(((H33-F33)/($H$16-$F$16))*($G$16-$F$16))+F33,0) -> 0 | H33: 0.057 | I33: =IF($I$16>0,(((J33-H33)/($J$16-$H$16))*($I$16-$H$16))+H33,0) -> 0 | J33: 0.063 | K33: =IF($K$16>0,(((L33-J33)/($L$16-$J$16))*($K$16-$J$16))+J33,0) -> 0 | L33: 0.068 | M33: =IF($M$16>0,(((N33-L33)/($N$16-$L$16))*($M$16-$L$16))+L33,0) -> 0 | N33: 0.08 | O33: =IF($O$16>0,(((P33-N33)/($P$16-$N$16))*($O$16-$N$16))+N33,0) -> 0 | P33: 0.088 | Q33: =IF($Q$16>0,(((#REF!-P33)/(#REF!-$P$16))*($Q$16-$P$16))+P33,0) -> 0 | R33: =MAX(C33,E33,G33,I33,K33,M33,O33) -> 0.04787294 | S33: 0.035
R34: =MAX(C34,E34,G34,I34,K34,M34,O34) -> 0
A35: 7 | B35: 0.057 | C35: =IF($C$16>0,(((D35-B35)/($D$16-$B$16))*($C$16-$B$16))+B35,0) -> 0 | D35: 0.064 | E35: =IF($E$16>0,(((F35-D35)/($F$16-$D$16))*($E$16-$D$16))+D35,0) -> 0.068263822 | F35: 0.071 | G35: =IF($G$16>0,(((H35-F35)/($H$16-$F$16))*($G$16-$F$16))+F35,0) -> 0 | H35: 0.076 | I35: =IF($I$16>0,(((J35-H35)/($J$16-$H$16))*($I$16-$H$16))+H35,0) -> 0 | J35: 0.08 | K35: =IF($K$16>0,(((L35-J35)/($L$16-$J$16))*($K$16-$J$16))+J35,0) -> 0 | L35: 0.084 | M35: =IF($M$16>0,(((N35-L35)/($N$16-$L$16))*($M$16-$L$16))+L35,0) -> 0 | N35: 0.091 | O35: =IF($O$16>0,(((P35-N35)/($P$16-$N$16))*($O$16-$N$16))+N35,0) -> 0 | P35: 0.097 | Q35: =IF($Q$16>0,(((#REF!-P35)/(#REF!-$P$16))*($Q$16-$P$16))+P35,0) -> 0 | R35: =MAX(C35,E35,G35,I35,K35,M35,O35) -> 0.068263822
B36: 0.043 | C36: =IF($C$16>0,(((D36-B36)/($D$16-$B$16))*($C$16-$B$16))+B36,0) -> 0 | D36: 0.048 | E36: =IF($E$16>0,(((F36-D36)/($F$16-$D$16))*($E$16-$D$16))+D36,0) -> 0.051045587 | F36: 0.053 | G36: =IF($G$16>0,(((H36-F36)/($H$16-$F$16))*($G$16-$F$16))+F36,0) -> 0 | H36: 0.057 | I36: =IF($I$16>0,(((J36-H36)/($J$16-$H$16))*($I$16-$H$16))+H36,0) -> 0 | J36: 0.06 | K36: =IF($K$16>0,(((L36-J36)/($L$16-$J$16))*($K$16-$J$16))+J36,0) -> 0 | L36: 0.064 | M36: =IF($M$16>0,(((N36-L36)/($N$16-$L$16))*($M$16-$L$16))+L36,0) -> 0 | N36: 0.096 | O36: =IF($O$16>0,(((P36-N36)/($P$16-$N$16))*($O$16-$N$16))+N36,0) -> 0 | P36: 0.073 | Q36: =IF($Q$16>0,(((#REF!-P36)/(#REF!-$P$16))*($Q$16-$P$16))+P36,0) -> 0 | R36: =MAX(C36,E36,G36,I36,K36,M36,O36) -> 0.051045587 | S36: 0.043
R37: =MAX(C37,E37,G37,I37,K37,M37,O37) -> 0
A38: 8 | C38: =IF($C$16>0,(((D38-B38)/($D$16-$B$16))*($C$16-$B$16))+B38,0) -> 0 | E38: =IF($E$16>0,(((F38-D38)/($F$16-$D$16))*($E$16-$D$16))+D38,0) -> 0 | G38: =IF($G$16>0,(((H38-F38)/($H$16-$F$16))*($G$16-$F$16))+F38,0) -> 0 | I38: =IF($I$16>0,(((J38-H38)/($J$16-$H$16))*($I$16-$H$16))+H38,0) -> 0 | K38: =IF($K$16>0,(((L38-J38)/($L$16-$J$16))*($K$16-$J$16))+J38,0) -> 0 | M38: =IF($M$16>0,(((N38-L38)/($N$16-$L$16))*($M$16-$L$16))+L38,0) -> 0 | O38: =IF($O$16>0,(((P38-N38)/($P$16-$N$16))*($O$16-$N$16))+N38,0) -> 0 | Q38: =IF($Q$16>0,(((#REF!-P38)/(#REF!-$P$16))*($Q$16-$P$16))+P38,0) -> 0 | R38: =MAX(C38,E38,G38,I38,K38,M38,O38) -> 0 | S38: 0.057
B39: 0.043 | C39: =IF($C$16>0,(((D39-B39)/($D$16-$B$16))*($C$16-$B$16))+B39,0) -> 0 | D39: 0.051 | E39: =IF($E$16>0,(((F39-D39)/($F$16-$D$16))*($E$16-$D$16))+D39,0) -> 0.05587294 | F39: 0.059 | G39: =IF($G$16>0,(((H39-F39)/($H$16-$F$16))*($G$16-$F$16))+F39,0) -> 0 | H39: 0.065 | I39: =IF($I$16>0,(((J39-H39)/($J$16-$H$16))*($I$16-$H$16))+H39,0) -> 0 | J39: 0.071 | K39: =IF($K$16>0,(((L39-J39)/($L$16-$J$16))*($K$16-$J$16))+J39,0) -> 0 | L39: 0.076 | M39: =IF($M$16>0,(((N39-L39)/($N$16-$L$16))*($M$16-$L$16))+L39,0) -> 0 | N39: 0.087 | O39: =IF($O$16>0,(((P39-N39)/($P$16-$N$16))*($O$16-$N$16))+N39,0) -> 0 | P39: 0.096 | Q39: =IF($Q$16>0,(((#REF!-P39)/(#REF!-$P$16))*($Q$16-$P$16))+P39,0) -> 0 | R39: =MAX(C39,E39,G39,I39,K39,M39,O39) -> 0.05587294 | S39: 0.043
R40: =MAX(C40,E40,G40,I40,K40,M40,O40) -> 0
A41: 9 | C41: =IF($C$16>0,(((D41-B41)/($D$16-$B$16))*($C$16-$B$16))+B41,0) -> 0 | E41: =IF($E$16>0,(((F41-D41)/($F$16-$D$16))*($E$16-$D$16))+D41,0) -> 0 | G41: =IF($G$16>0,(((H41-F41)/($H$16-$F$16))*($G$16-$F$16))+F41,0) -> 0 | I41: =IF($I$16>0,(((J41-H41)/($J$16-$H$16))*($I$16-$H$16))+H41,0) -> 0 | K41: =IF($K$16>0,(((L41-J41)/($L$16-$J$16))*($K$16-$J$16))+J41,0) -> 0 | M41: =IF($M$16>0,(((N41-L41)/($N$16-$L$16))*($M$16-$L$16))+L41,0) -> 0 | O41: =IF($O$16>0,(((P41-N41)/($P$16-$N$16))*($O$16-$N$16))+N41,0) -> 0 | Q41: =IF($Q$16>0,(((#REF!-P41)/(#REF!-$P$16))*($Q$16-$P$16))+P41,0) -> 0 | R41: =MAX(C41,E41,G41,I41,K41,M41,O41) -> 0
...

Sheet steel area calculation
A1: calculation of area of steel
B2: depth of slab | D2: ='two way slab design'!D12 -> 105
C3: fck | D3: ='two way slab design'!D16 -> 20
C4: fy | D4: ='two way slab design'!D15 -> 500
C5: b | D5: 1000
B6: Mumax | F6: A | G6: B | H6: C | I6: B2-4AC | J6: taking +ve | K6: taking -ve | L6: Ast reqd
B7: ='two way slab design'!C36 -> 8.1914479 | F7: =0.416*0.87*0.87*$D$4*$D$4/(0.362*$D$3*$D$5) -> 10.872597 | G7: =-0.87*$D$4*$D$2 -> -45675 | H7: =B7*10^6 -> 8191447.9 | I7: =G7*G7-4*F7*H7 -> 1.7299564e+09 | J7: =IF(I7>0,((-G7+SQRT(I7))/(2*F7)),"cant solve") -> 4013.197 | K7: =IF(I7>0,((-G7-SQRT(I7))/(2*F7)),"cant solve") -> 187.7314 | L7: =IF(J7>K7,K7,J7) -> 187.7314
B8: ='two way slab design'!D36 -> 6.1575646 | F8: =0.416*0.87*0.87*$D$4*$D$4/(0.362*$D$3*$D$5) -> 10.872597 | G8: =-0.87*$D$4*$D$2 -> -45675 | H8: =B8*10^6 -> 6157564.6 | I8: =G8*G8-4*F8*H8 -> 1.8184108e+09 | J8: =IF(I8>0,((-G8+SQRT(I8))/(2*F8)),"cant solve") -> 4061.4873 | K8: =IF(I8>0,((-G8-SQRT(I8))/(2*F8)),"cant solve") -> 139.44103 | L8: =IF(J8>K8,K8,J8) -> 139.44103
B9: ='two way slab design'!E36 -> 6.7232336 | F9: =0.416*0.87*0.87*$D$4*$D$4/(0.362*$D$3*$D$5) -> 10.872597 | G9: =-0.87*$D$4*$D$2 -> -45675 | H9: =B9*10^6 -> 6723233.6 | I9: =G9*G9-4*F9*H9 -> 1.7938096e+09 | J9: =IF(I9>0,((-G9+SQRT(I9))/(2*F9)),"cant solve") -> 4048.1769 | K9: =IF(I9>0,((-G9-SQRT(I9))/(2*F9)),"cant solve") -> 152.75148 | L9: =IF(J9>K9,K9,J9) -> 152.75148
B10: ='two way slab design'!F36 -> 5.0066633 | F10: =0.416*0.87*0.87*$D$4*$D$4/(0.362*$D$3*$D$5) -> 10.872597 | G10: =-0.87*$D$4*$D$2 -> -45675 | H10: =B10*10^6 -> 5006663.3 | I10: =G10*G10-4*F10*H10 -> 1.8684639e+09 | J10: =IF(I10>0,((-G10+SQRT(I10))/(2*F10)),"cant solve") -> 4088.2935 | K10: =IF(I10>0,((-G10-SQRT(I10))/(2*F10)),"cant solve") -> 112.63492 | L10: =IF(J10>K10,K10,J10) -> 112.63492
