Workbook
Name description_103: [1]Abstract!$B$16
Name description_124: #REF!
Name description_124: #REF!
Name description_124: #REF!
Name description_124: #REF!
Name description_124: #REF!
Name description_247: [1]Abstract!$B$22
Name description_248: [1]Abstract!$B$23
Name description_261: [2]Abstract!$B$33
Name description_262: [1]Abstract!$B$34
Name description_276: [3]Abstract!$B$40
Name description_3: [1]Abstract!$B$169
Name description_310: #REF!
Name description_310: #REF!
Name description_310: #REF!
Name description_310: [5]Abstract!$B$60
Name description_310: #REF!
Name description_312: #REF!
Name description_312: #REF!
Name description_312: #REF!
Name description_312: [6]Abstract!$B$61
Name description_312: #REF!
Name description_5: [1]Abstract!$B$171
Name description_6: #REF!
Name description_6: #REF!
Name description_6: #REF!
Name description_6: [5]Abstract!$B$172
Name description_6: #REF!
Name description_759: [1]Abstract!$B$278
Name description_781: #REF!
Name description_781: #REF!
Name description_781: #REF!
Name description_781: [7]Abstract!$B$299
Name description_781: #REF!
Name description_783: [1]Abstract!$B$301
Name description_784: [3]Abstract!$B$300

Sheet estimate
A1: Government of Nepal
A2: Shankharapur Municipality Office
A3: Bagmati Province
A4: Sankhu, Kathmandu
A5: Detail Estimated Sheet
A6: Project:-तिनघरे बाटो स्तरोन्नति | H6: F.Y.: 2082/2083
A7: Location:- Shankharapur Municipality 1 | H7: Date:
A8: S.N. | B8: Description of work | C8: No. | D8: Length | E8: Breadth | F8: Height | G8: Quantity | H8: Unit | I8: Rate | J8: Amount | K8: Remark
A9: 1 | B9: Earthwork Excavation in Cutting., Roadway Excavation in all types of Soil by Mechanical Means ., Road way Excavation in all types of soil as per Drawing and technical specifications including removal of stumps and other deleterious matter and backfilling, all lifts and lead as per Drawing and instruction of the Engineer.
B10: -for masonary wall | C10: 1 | D10: 18.5 | E10: =F10/2 -> 1.5 | F10: 3 | G10: =PRODUCT(C10:F10) -> 83.25 | M10: =7 -> 7 | N10: =2 -> 2 | P10: =PI()*M10*SQRT(M10^2+N10^2) -> 160.09798
B11: Sub-total | G11: =SUM(G10:G10) -> 83.25 | H11: m3 | I11: 62.95 | J11: =G11*I11 -> 5240.5875
B12: -13% VAT for materials | J12: =0.13*G11*(18612)/360 -> 559.52325
A14: 2 | B14: Providing and laying of hand pack locally available Stone soling with 150 to 200 mm thick stones and packing with smaller stone on prepared surface as per Drawing and Technical Specifications.
B15: =B10 -> -for masonary wall | C15: 1 | D15: =D10 -> 18.5 | E15: =E10 -> 1.5 | F15: 0.15 | G15: =PRODUCT(C15:F15) -> 4.1625 | M15: =7 -> 7 | N15: =2 -> 2 | P15: =PI()*M15*SQRT(M15^2+N15^2) -> 160.09798
B16: Sub-total | G16: =SUM(G15:G15) -> 4.1625 | H16: m3 | I16: 4458.52 | J16: =G16*I16 -> 18558.59
B17: -13% VAT for materials | J17: =0.13*G16*(14817.6)/5 -> 1603.6348
A19: 3 | B19: Providing and laying of Plain/Reinforced Cement Concrete in Foundation complete as per Drawing and Technical Specifications, PCC Grade M 15
B20: =B15 -> -for masonary wall | C20: 1 | D20: =D15 -> 18.5 | E20: =E15 -> 1.5 | F20: 0.05 | G20: =PRODUCT(C20:F20) -> 1.3875 | M20: =7 -> 7 | N20: =2 -> 2 | P20: =PI()*M20*SQRT(M20^2+N20^2) -> 160.09798
C21: 1 | D21: =D20 -> 18.5 | E21: 0.45 | F21: 0.05 | G21: =PRODUCT(C21:F21) -> 0.41625
B22: Sub-total | G22: =SUM(G20:G21) -> 1.80375 | H22: m3 | I22: 10964.46 | J22: =G22*I22 -> 19777.145
B23: -13% VAT for cement | J23: =0.13*G22*(53818.03)/15 -> 841.31035
B24: -13% VAT for sand | J24: =0.13*G22*(21432.6)/15 -> 335.04512
B25: -13% VAT for aggregate | J25: =0.13*G22*(25719.12+13573.98+4286.52)/15 -> 681.25841
B26: -13% VAT for formworks | J26: =0.13*G22*(6325.7)/15 -> 98.886505
B27: -13% VAT for water | J27: =0.13*G22*(310)/5 -> 14.538225
A29: 4 | B29: Random Rubble Masonry, Providing and laying of Stone Masonry Work in Cement Mortar 1:6 in Foundation complete as per Drawing and Technical Specifications., Using Concrete Mixer
B30: =B20 -> -for masonary wall | C30: 1 | D30: =D10 -> 18.5 | E30: =((F30/2)+0.45)/2 -> 0.975 | F30: 3 | G30: =PRODUCT(C30:F30) -> 54.1125 | M30: =7 -> 7 | N30: =2 -> 2 | P30: =PI()*M30*SQRT(M30^2+N30^2) -> 160.09798
B31: Sub-total | G31: =SUM(G30:G30) -> 54.1125 | H31: m3 | I31: 8987.83 | J31: =G31*I31 -> 486353.95
B32: -13% VAT for cement | J32: =0.13*G31*(5863.95)/5 -> 8250.1379
B33: -13% VAT for sand | J33: =0.13*G31*(6604.416)/5 -> 9291.918
B34: -13% VAT for stone | J34: =0.13*G31*(14808.78)/5 -> 20834.843
B35: -13% VAT for water | J35: =0.13*G31*(310)/5 -> 436.14675
A37: 5 | B37: Information board (सुचना पाटि) | C37: 1 | G37: =PRODUCT(C37:F37) -> 1 | H37: no. | I37: 500 | J37: =G37*I37 -> 500
B39: Total | J39: =SUM(J9:J37) -> 573377.51
B41: Total Estimated | C41: =J39 -> 573377.51 | E41: 100
B42: Budget allocated | C42: 500000
B43: Municipal payment | C43: =C42-C45-C46 -> 475000 | E43: =C43/C41*100 -> 82.842453
B44: User contribution | C44: =C41-C43 -> 98377.515 | E44: =100-E43 -> 17.157547
B45: Contingencies | C45: =C42*0.03 -> 15000 | E45: 3
B46: Maintanince | C46: =C42*0.02 -> 10000 | E46: 2

Sheet valuation
A1: Government of Nepal
A2: Shankharapur Municipality Office
A3: Bagmati Province
A4: Sankhu, Kathmandu
A5: Detail Valuated Sheet
A6: Project:-तिनघरे बाटो स्तरोन्नति | H6: F.Y.: 2082/2083
A7: Location:- Shankharapur Municipality 1 | H7: Date:
A8: S.N. | B8: Description of work | C8: No. | D8: Length | E8: Breadth | F8: Height | G8: Quantity | H8: Unit | I8: Rate | J8: Amount | K8: Remark
A9: 1 | B9: Earthwork Excavation in Cutting., Roadway Excavation in all types of Soil by Mechanical Means ., Road way Excavation in all types of soil as per Drawing and technical specifications including removal of stumps and other deleterious matter and backfilling, all lifts and lead as per Drawing and instruction of the Engineer.
B10: -for masonary wall section 1 | C10: 1 | D10: =D34 -> 7.9 | E10: =E22 -> 1.95 | F10: 3 | G10: =PRODUCT(C10:F10) -> 46.215 | M10: =7 -> 7 | N10: =2 -> 2 | P10: =PI()*M10*SQRT(M10^2+N10^2) -> 160.09798
B11: -for masonary wall section 2 | C11: 1 | D11: =D35 -> 3.15 | E11: =E24 -> 2 | F11: 3 | G11: =PRODUCT(C11:F11) -> 18.9 | M11: =7 -> 7 | N11: =2 -> 2 | P11: =PI()*M11*SQRT(M11^2+N11^2) -> 160.09798
B12: Sub-total | G12: =SUM(G10:G11) -> 65.115 | H12: m3 | I12: 62.95 | J12: =G12*I12 -> 4098.9893
B13: -13% VAT for materials | J13: =0.13*G12*(18612)/360 -> 437.63792
A15: 2 | B15: Providing and laying of hand pack locally available Stone soling with 150 to 200 mm thick stones and packing with smaller stone on prepared surface as per Drawing and Technical Specifications.
B16: =B10 -> -for masonary wall section 1 | C16: 1 | D16: =D34 -> 7.9 | E16: =E22 -> 1.95 | F16: 0.15 | G16: =PRODUCT(C16:F16) -> 2.31075 | M16: =7 -> 7 | N16: =2 -> 2 | P16: =PI()*M16*SQRT(M16^2+N16^2) -> 160.09798
B17: =B11 -> -for masonary wall section 2 | C17: 1 | D17: =D35 -> 3.15 | E17: =E24 -> 2 | F17: 0.15 | G17: =PRODUCT(C17:F17) -> 0.945 | M17: =7 -> 7 | N17: =2 -> 2 | P17: =PI()*M17*SQRT(M17^2+N17^2) -> 160.09798
B18: Sub-total | G18: =SUM(G16:G17) -> 3.25575 | H18: m3 | I18: 4458.52 | J18: =G18*I18 -> 14515.826
B19: -13% VAT for materials | J19: =0.13*G18*(14817.6)/5 -> 1254.3024
A21: 3 | B21: Providing and laying of Plain/Reinforced Cement Concrete in Foundation complete as per Drawing and Technical Specifications, PCC Grade M 15
B22: =B16 -> -for masonary wall section 1 | C22: 1 | D22: =D34 -> 7.9 | E22: =F34/2 -> 1.95 | F22: 0.05 | G22: =PRODUCT(C22:F22) -> 0.77025 | M22: =7 -> 7 | N22: =2 -> 2 | P22: =PI()*M22*SQRT(M22^2+N22^2) -> 160.09798
C23: 1 | D23: =D22 -> 7.9 | E23: 0.5 | F23: 0.05 | G23: =PRODUCT(C23:F23) -> 0.1975
B24: =B11 -> -for masonary wall section 2 | C24: 1 | D24: =D35 -> 3.15 | E24: =F35/2 -> 2 | F24: 0.05 | G24: =PRODUCT(C24:F24) -> 0.315 | M24: =7 -> 7 | N24: =2 -> 2 | P24: =PI()*M24*SQRT(M24^2+N24^2) -> 160.09798
C25: 1 | D25: =D24 -> 3.15 | E25: 0.5 | F25: 0.05 | G25: =PRODUCT(C25:F25) -> 0.07875
B26: Sub-total | G26: =SUM(G22:G25) -> 1.3615 | H26: m3 | I26: 10964.46 | J26: =G26*I26 -> 14928.112
B27: -13% VAT for cement | J27: =0.13*G26*(53818.03)/15 -> 635.03481
B28: -13% VAT for sand | J28: =0.13*G26*(21432.6)/15 -> 252.89754
B29: -13% VAT for aggregate | J29: =0.13*G26*(25719.12+13573.98+4286.52)/15 -> 514.22499
B30: -13% VAT for formworks | J30: =0.13*G26*(6325.7)/15 -> 74.641151
B31: -13% VAT for water | J31: =0.13*G26*(310)/5 -> 10.97369
A33: 4 | B33: Random Rubble Masonry, Providing and laying of Stone Masonry Work in Cement Mortar 1:6 in Foundation complete as per Drawing and Technical Specifications., Using Concrete Mixer
B34: =B22 -> -for masonary wall section 1 | C34: 1 | D34: =7.5+0.4 -> 7.9 | E34: =((F34/2)+0.5)/2 -> 1.225 | F34: 3.9 | G34: =PRODUCT(C34:F34) -> 37.74225 | M34: =7 -> 7 | N34: =2 -> 2 | P34: =PI()*M34*SQRT(M34^2+N34^2) -> 160.09798
B35: =B11 -> -for masonary wall section 2 | C35: 1 | D35: 3.15 | E35: =((F35/2)+0.5)/2 -> 1.25 | F35: 4 | G35: =PRODUCT(C35:F35) -> 15.75 | M35: =7 -> 7 | N35: =2 -> 2 | P35: =PI()*M35*SQRT(M35^2+N35^2) -> 160.09798
B36: Sub-total | G36: =SUM(G34:G35) -> 53.49225 | H36: m3 | I36: 8987.83 | J36: =G36*I36 -> 480779.25
B37: -13% VAT for cement | J37: =0.13*G36*(5863.95)/5 -> 8155.5729
B38: -13% VAT for sand | J38: =0.13*G36*(6604.416)/5 -> 9185.4119
B39: -13% VAT for stone | J39: =0.13*G36*(14808.78)/5 -> 20596.029
B40: -13% VAT for water | J40: =0.13*G36*(310)/5 -> 431.14754
A42: 5 | B42: Information board (सुचना पाटि) | C42: 1 | G42: =PRODUCT(C42:F42) -> 1 | H42: no. | I42: 500 | J42: =G42*I42 -> 500
B44: Total | J44: =SUM(J9:J42) -> 556370.05
B46: Total Valuated | C46: =J44 -> 556370.05 | E46: 100
...

Sheet WCR
A1: Government of Nepal
A2: Shankharapur Municipality Office
A3: Bagmati Province
A4: Sankhu, Kathmandu
A5: Work Completion Report
A6: Total Estimated Amount: | C6: =F34 -> 573362.98 | H6: Total Valuated Amount : | J6: =I34 -> 556359.08
A7: Work Started : | I7: Work Finished:
A8: =estimate!A6 -> Project:-तिनघरे बाटो स्तरोन्नति | I8: F.Y:2082/2083
A9: =estimate!A7 -> Location:- Shankharapur Municipality 1 | I9: Date:2082/10/13
A11: S.No. | B11: Description | C11: Unit | D11: Estimated | G11: Valuated | J11: Difference | K11: Remarks
D12: Quantity | E12: Rate | F12: Amount | G12: Quantity | H12: Rate | I12: Amount
A13: =estimate!A9 -> 1 | B13: =estimate!B9 -> Earthwork Excavation in Cutting., Roadway Excavation in all types of Soil by Mechanical Means ., Road way Excavation in all types of soil as per Drawing and technical specifications including removal of stumps and other deleterious matter and backfilling, all lifts and lead as per Drawing and instruction of the Engineer. | C13: =estimate!H11 -> m3 | D13: =estimate!G11 -> 83.25 | E13: =estimate!I11 -> 62.95 | F13: =D13*E13 -> 5240.5875 | G13: =valuation!G12 -> 65.115 | H13: =valuation!I12 -> 62.95 | I13: =G13*H13 -> 4098.9893 | J13: =I13-F13 -> -1141.5983
B14: =estimate!B12 -> -13% VAT for materials | F14: =estimate!J12 -> 559.52325 | I14: =valuation!J13 -> 437.63792 | J14: =I14-F14 -> -121.88533
A16: =estimate!A14 -> 2 | B16: =estimate!B14 -> Providing and laying of hand pack locally available Stone soling with 150 to 200 mm thick stones and packing with smaller stone on prepared surface as per Drawing and Technical Specifications. | C16: =estimate!H16 -> m3 | D16: =estimate!G16 -> 4.1625 | E16: =estimate!I16 -> 4458.52 | F16: =D16*E16 -> 18558.59 | G16: =valuation!G18 -> 3.25575 | H16: =valuation!I18 -> 4458.52 | I16: =G16*H16 -> 14515.826 | J16: =I16-F16 -> -4042.763
B17: =estimate!B17 -> -13% VAT for materials | F17: =estimate!J17 -> 1603.6348 | I17: =valuation!J19 -> 1254.3024 | J17: =I17-F17 -> -349.33233
A19: =estimate!A19 -> 3 | B19: =estimate!B19 -> Providing and laying of Plain/Reinforced Cement Concrete in Foundation complete as per Drawing and Technical Specifications, PCC Grade M 15 | C19: =estimate!H22 -> m3 | D19: =estimate!G22 -> 1.80375 | E19: =estimate!I22 -> 10964.46 | F19: =D19*E19 -> 19777.145 | G19: =valuation!G26 -> 1.3615 | H19: =valuation!I26 -> 10964.46 | I19: =G19*H19 -> 14928.112 | J19: =I19-F19 -> -4849.0324
B20: =estimate!B23 -> -13% VAT for cement | F20: =estimate!J23 -> 841.31035 | I20: =valuation!J27 -> 635.03481 | J20: =I20-F20 -> -206.27554
B21: =estimate!B24 -> -13% VAT for sand | F21: =estimate!J24 -> 335.04512 | I21: =valuation!J28 -> 252.89754 | J21: =I21-F21 -> -82.147584
B22: =estimate!B25 -> -13% VAT for aggregate | F22: =estimate!J25 -> 681.25841 | I22: =valuation!J29 -> 514.22499 | J22: =I22-F22 -> -167.03342
B23: =estimate!B26 -> -13% VAT for formworks | F23: =estimate!J26 -> 98.886505 | I23: =valuation!J30 -> 74.641151 | J23: =I23-F23 -> -24.245354
B24: =estimate!B27 -> -13% VAT for water
A26: =estimate!A29 -> 4 | B26: =estimate!B29 -> Random Rubble Masonry, Providing and laying of Stone Masonry Work in Cement Mortar 1:6 in Foundation complete as per Drawing and Technical Specifications., Using Concrete Mixer | C26: =estimate!H31 -> m3 | D26: =estimate!G31 -> 54.1125 | E26: =estimate!I31 -> 8987.83 | F26: =D26*E26 -> 486353.95 | G26: =valuation!G36 -> 53.49225 | H26: =valuation!I36 -> 8987.83 | I26: =G26*H26 -> 480779.25 | J26: =I26-F26 -> -5574.7016
B27: =estimate!B32 -> -13% VAT for cement | F27: =estimate!J32 -> 8250.1379 | I27: =valuation!J37 -> 8155.5729 | J27: =I27-F27 -> -94.56499
B28: =estimate!B33 -> -13% VAT for sand | F28: =estimate!J33 -> 9291.918 | I28: =valuation!J38 -> 9185.4119 | J28: =I28-F28 -> -106.50611
B29: =estimate!B34 -> -13% VAT for stone | F29: =estimate!J34 -> 20834.843 | I29: =valuation!J39 -> 20596.029 | J29: =I29-F29 -> -238.81379
B30: =estimate!B35 -> -13% VAT for water | F30: =estimate!J35 -> 436.14675 | I30: =valuation!J40 -> 431.14754 | J30: =I30-F30 -> -4.999215
A32: =estimate!A37 -> 5 | B32: =estimate!B37 -> Information board (सुचना पाटि) | C32: =estimate!H37 -> no. | D32: =estimate!G37 -> 1 | E32: =estimate!I37 -> 500 | F32: =D32*E32 -> 500 | G32: =valuation!G42 -> 1 | H32: =valuation!I42 -> 500 | I32: =G32*H32 -> 500 | J32: =I32-F32 -> 0
B34: Total | F34: =SUM(F13:F32) -> 573362.98 | I34: =SUM(I13:I32) -> 556359.08 | J34: =I34-F34 -> -17003.899

Sheet measure
A1: Government of Nepal
A2: Shankharapur Municipality Office
A3: Bagmati Province
A4: Sankhu, Kathmandu
A5: Detail Quantity Measurement Sheet
A6: Project:-तिनघरे बाटो स्तरोन्नति | H6: F.Y.: 2082/2083
A7: Location:- Shankharapur Municipality 1 | H7: Date:
A8: S.N. | B8: Description of work | C8: No. | D8: Length | E8: Breadth | F8: Height | G8: Quantity | H8: Unit | I8: Rate | J8: Amount | K8: Remark
A9: 1 | B9: Earthwork Excavation in Cutting., Roadway Excavation in all types of Soil by Mechanical Means ., Road way Excavation in all types of soil as per Drawing and technical specifications including removal of stumps and other deleterious matter and backfilling, all lifts and lead as per Drawing and instruction of the Engineer.
B10: -for masonary wall section 1 | C10: 1 | D10: =D34 -> 7.9 | E10: =E22 -> 1.95 | F10: 3 | G10: =PRODUCT(C10:F10) -> 46.215 | M10: =7 -> 7 | N10: =2 -> 2 | P10: =PI()*M10*SQRT(M10^2+N10^2) -> 160.09798
B11: -for masonary wall section 2 | C11: 1 | D11: =D35 -> 3.15 | E11: =E24 -> 2 | F11: 3 | G11: =PRODUCT(C11:F11) -> 18.9 | M11: =7 -> 7 | N11: =2 -> 2 | P11: =PI()*M11*SQRT(M11^2+N11^2) -> 160.09798
B12: Sub-total | G12: =SUM(G10:G11) -> 65.115 | H12: m3 | I12: 62.95 | J12: =G12*I12 -> 4098.9893
B13: -13% VAT for materials | J13: =0.13*G12*(18612)/360 -> 437.63792
A15: 2 | B15: Providing and laying of hand pack locally available Stone soling with 150 to 200 mm thick stones and packing with smaller stone on prepared surface as per Drawing and Technical Specifications.
B16: =B10 -> -for masonary wall section 1 | C16: 1 | D16: =D34 -> 7.9 | E16: =E22 -> 1.95 | F16: 0.15 | G16: =PRODUCT(C16:F16) -> 2.31075 | M16: =7 -> 7 | N16: =2 -> 2 | P16: =PI()*M16*SQRT(M16^2+N16^2) -> 160.09798
B17: =B11 -> -for masonary wall section 2 | C17: 1 | D17: =D35 -> 3.15 | E17: =E24 -> 2 | F17: 0.15 | G17: =PRODUCT(C17:F17) -> 0.945 | M17: =7 -> 7 | N17: =2 -> 2 | P17: =PI()*M17*SQRT(M17^2+N17^2) -> 160.09798
B18: Sub-total | G18: =SUM(G16:G17) -> 3.25575 | H18: m3 | I18: 4458.52 | J18: =G18*I18 -> 14515.826
B19: -13% VAT for materials | J19: =0.13*G18*(14817.6)/5 -> 1254.3024
A21: 3 | B21: Providing and laying of Plain/Reinforced Cement Concrete in Foundation complete as per Drawing and Technical Specifications, PCC Grade M 15
B22: =B16 -> -for masonary wall section 1 | C22: 1 | D22: =D34 -> 7.9 | E22: =F34/2 -> 1.95 | F22: 0.05 | G22: =PRODUCT(C22:F22) -> 0.77025 | M22: =7 -> 7 | N22: =2 -> 2 | P22: =PI()*M22*SQRT(M22^2+N22^2) -> 160.09798
C23: 1 | D23: =D22 -> 7.9 | E23: 0.5 | F23: 0.05 | G23: =PRODUCT(C23:F23) -> 0.1975
B24: =B11 -> -for masonary wall section 2 | C24: 1 | D24: =D35 -> 3.15 | E24: =F35/2 -> 2 | F24: 0.05 | G24: =PRODUCT(C24:F24) -> 0.315 | M24: =7 -> 7 | N24: =2 -> 2 | P24: =PI()*M24*SQRT(M24^2+N24^2) -> 160.09798
C25: 1 | D25: =D24 -> 3.15 | E25: 0.5 | F25: 0.05 | G25: =PRODUCT(C25:F25) -> 0.07875
B26: Sub-total | G26: =SUM(G22:G25) -> 1.3615 | H26: m3 | I26: 10964.46 | J26: =G26*I26 -> 14928.112
B27: -13% VAT for cement | J27: =0.13*G26*(53818.03)/15 -> 635.03481
B28: -13% VAT for sand | J28: =0.13*G26*(21432.6)/15 -> 252.89754
B29: -13% VAT for aggregate | J29: =0.13*G26*(25719.12+13573.98+4286.52)/15 -> 514.22499
B30: -13% VAT for formworks | J30: =0.13*G26*(6325.7)/15 -> 74.641151
B31: -13% VAT for water | J31: =0.13*G26*(310)/5 -> 10.97369
A33: 4 | B33: Random Rubble Masonry, Providing and laying of Stone Masonry Work in Cement Mortar 1:6 in Foundation complete as per Drawing and Technical Specifications., Using Concrete Mixer
B34: =B22 -> -for masonary wall section 1 | C34: 1 | D34: =7.5+0.4 -> 7.9 | E34: =((F34/2)+0.45)/2 -> 1.2 | F34: 3.9 | G34: =PRODUCT(C34:F34) -> 36.972 | M34: =7 -> 7 | N34: =2 -> 2 | P34: =PI()*M34*SQRT(M34^2+N34^2) -> 160.09798
B35: =B11 -> -for masonary wall section 2 | C35: 1 | D35: 3.15 | E35: =((F35/2)+0.45)/2 -> 1.225 | F35: 4 | G35: =PRODUCT(C35:F35) -> 15.435 | M35: =7 -> 7 | N35: =2 -> 2 | P35: =PI()*M35*SQRT(M35^2+N35^2) -> 160.09798
B36: Sub-total | G36: =SUM(G34:G35) -> 52.407 | H36: m3 | I36: 8987.83 | J36: =G36*I36 -> 471025.21
B37: -13% VAT for cement | J37: =0.13*G36*(5863.95)/5 -> 7990.1127
B38: -13% VAT for sand | J38: =0.13*G36*(6604.416)/5 -> 8999.0584
B39: -13% VAT for stone | J39: =0.13*G36*(14808.78)/5 -> 20178.177
B40: -13% VAT for water | J40: =0.13*G36*(310)/5 -> 422.40042
A42: 5 | B42: Information board (सुचना पाटि) | C42: 1 | G42: =PRODUCT(C42:F42) -> 1 | H42: no. | I42: 500 | J42: =G42*I42 -> 500
B44: Total | J44: =SUM(J9:J42) -> 545837.6
B46: Total Estimated | C46: =J44 -> 545837.6 | E46: 100
...
