Workbook
Name description_103: [1]Abstract!$B$16
Name description_124: #REF!
Name description_124: #REF!
Name description_124: #REF!
Name description_124: #REF!
Name description_124: #REF!
Name description_124: #REF!
Name description_124: #REF!
Name description_247: [1]Abstract!$B$22
Name description_248: [1]Abstract!$B$23
Name description_261: [2]Abstract!$B$33
Name description_262: [1]Abstract!$B$34
Name description_276: [3]Abstract!$B$40
Name description_3: [1]Abstract!$B$169
Name description_310: #REF!
Name description_310: #REF!
Name description_310: #REF!
Name description_310: #REF!
Name description_310: #REF!
Name description_310: [4]Abstract!$B$60
Name description_310: #REF!
Name description_312: #REF!
Name description_312: #REF!
Name description_312: #REF!
Name description_312: #REF!
Name description_312: #REF!
Name description_312: [5]Abstract!$B$61
Name description_312: #REF!
Name description_5: [1]Abstract!$B$171
Name description_6: #REF!
Name description_6: #REF!
Name description_6: #REF!
Name description_6: #REF!
Name description_6: #REF!
Name description_6: [4]Abstract!$B$172
Name description_6: #REF!
Name description_759: [1]Abstract!$B$278
Name description_781: #REF!
Name description_781: #REF!
Name description_781: #REF!
Name description_781: #REF!
Name description_781: #REF!
Name description_781: [6]Abstract!$B$299
Name description_781: #REF!
Name description_783: [1]Abstract!$B$301
Name description_784: [3]Abstract!$B$300

Sheet initial 2 storey
A1: Government of Nepal
A2: Shankharapur Municipality Office
A3: Bagmati Province
A4: Sankhu, Kathmandu
A5: Detail Estimated Sheet
A6: Project:- k~rkfn] led;]g dlGb/ cw'/f] | H6: F.Y.: 2082/2083
A7: Location:- Shankharapur Municipality 1 | H7: Date:
A8: S.N. | B8: Description of work | C8: No. | D8: Length | E8: Breadth | F8: Height | G8: Quantity | H8: Unit | I8: Rate | J8: Amount | K8: Remark | M8: Water tap size
A9: 1 | B9: g/d k|sf/sf] Sn] / l;N6L df6f]df ;j} lsl;dsf] vGg] sfd | M9: length | N9: Breadth | O9: thickness | P9: Height 1 | Q9: Height 2 | R9: Width of stand tap
B10: -for stand tap | C10: 1 | D10: =5.5/3.281 -> 1.6763182 | E10: =5.5/3.281 -> 1.6763182 | F10: 0.15 | G10: =PRODUCT(C10:F10) -> 0.4215064 | M10: =5.5/3.281 -> 1.6763182 | N10: =5.5/3.281 -> 1.6763182 | O10: 0.23 | P10: =TRUNC(2/3.281,1) -> 0.6 | Q10: =TRUNC(4/3.281,1) -> 1.2 | R10: =1.17/3.281 -> 0.3565986
B11: Sub-total | G11: =SUM(G10) -> 0.4215064 | H11: cum | I11: 674.12 | J11: =G11*I11 -> 284.1459
A13: 2 | B13: ;'Vvf O{6f RofK6f] 5fKg] sfd
B14: =B10 -> -for stand tap | C14: =C10 -> 1 | D14: =D10 -> 1.6763182 | E14: =E10 -> 1.6763182 | G14: =PRODUCT(C14:F14) -> 2.8100427
B15: Sub-total | G15: =SUM(G14) -> 2.8100427 | H15: sqm | I15: 1017.47 | J15: =G15*I15 -> 2859.1341
B16: -13% VAT for brick | J16: =0.13*G15*6360.9/10 -> 232.36721
B17: -13% VAT for sand | J17: =0.13*G15*2256.3/10 -> 82.423891
A19: 3 | B19: d]lzgsf] k|of]u u/L hu leQf kvf{ndf l;d]G6 s+lqm6 ug]{ sfd -!M@M$_
B20: -for lintel | C20: =2 -> 2 | D20: =15/3.281 -> 4.5717769 | E20: 0.35 | F20: 0.1 | G20: =PRODUCT(C20:F20) -> 0.32002438
C21: =2 -> 2 | D21: =9.75/3.281 -> 2.971655 | E21: 0.35 | F21: 0.1 | G21: =PRODUCT(C21:F21) -> 0.20801585
B22: =B14 -> -for stand tap | C22: =C14 -> 1 | D22: =D14 -> 1.6763182 | E22: =E14 -> 1.6763182 | F22: 0.1 | G22: =PRODUCT(C22:F22) -> 0.28100427
B23: Sub-total | G23: =SUM(G20:G22) -> 0.8090445 | H23: cum | I23: 12884.61 | J23: =G23*I23 -> 10424.223
B24: -13% VAT for cement | J24: =0.13*G23*4169.92 -> 438.57461
B25: -13% VAT for aggregate | J25: =0.13*G23*(1652.5+1106.96) -> 290.22837
B26: -13% VAT for sand | J26: =0.13*G23*1414.16 -> 148.73539
B27: -13% VAT for water | J27: =0.13*G23*36.4 -> 3.8283986
B28: -13% VAT for water | J28: =0.13*G23*392.92 -> 41.325669
B29: -13% VAT for water | J29: =0.13*G23*14.15 -> 1.4882374
A31: 4 | B31: d]lzgsf] k|of]u u/L ;'k/ :6«Sr/df l;d]G6 s+lqm6 ug]{ sfd -!M!=%M#_
B32: -beam | C32: 2 | D32: =15/3.281 -> 4.5717769 | E32: 0.23 | F32: 0.23 | G32: =PRODUCT(C32:F32) -> 0.483694
C33: =2*2 -> 4 | D33: =9.75/3.281 -> 2.971655 | E33: 0.23 | F33: 0.23 | G33: =PRODUCT(C33:F33) -> 0.62880219
B34: -upper beam | C34: 2 | D34: =8.17/3.281 -> 2.4900945 | E34: 0.23 | F34: 0.23 | G34: =PRODUCT(C34:F34) -> 0.263452
C35: 2 | D35: =3.75/3.281 -> 1.1429442 | E35: 0.23 | F35: 0.23 | G35: =PRODUCT(C35:F35) -> 0.1209235
B36: -slab | C36: 2 | D36: =((17.667+8.17)/2)/3.281 -> 3.9373667 | E36: =6.33/3.281 -> 1.9292899 | F36: 0.075 | G36: =PRODUCT(C36:F36) -> 1.1394482
C37: 2 | D37: =((14.75+5.25)/2)/3.281 -> 3.0478513 | E37: =6.33/3.281 -> 1.9292899 | F37: 0.075 | G37: =PRODUCT(C37:F37) -> 0.88202828
B38: -column | C38: 4 | D38: 0.23 | E38: 0.23 | F38: =2.25/3.281 -> 0.68576653 | G38: =PRODUCT(C38:F38) -> 0.1451082
B39: Sub-total | G39: =SUM(G32:G38) -> 3.6634564 | H39: cum | I39: 13957.29 | J39: =G39*I39 -> 51131.923
B40: -13% VAT for cement | J40: =0.13*G39*5212.4 -> 2482.402
B41: -13% VAT for aggregate | J41: =0.13*G39*(1912.03+921.59) -> 1349.5096
B42: -13% VAT for sand | J42: =0.13*G39*1350.6 -> 643.22235
B43: -13% VAT for water | J43: =0.13*G39*56 -> 26.669963
...

Sheet Sheet1
B2: Foundation size | E2: Footing size | H2: Plinth size | K2: Toe wall | O2: Column size | R2: Tie beam size | U2: Tie beam size
B3: Length | C3: Breadth | D3: Depth from GL | E3: Length in PL area | F3: Breadth in PL area | G3: Depth | H3: Length | I3: Breadth | J3: Depth from GL | K3: Length L1 | L3: Ht. H1 | M3: Length L2 | N3: Ht. H2 | O3: Length/B | P3: Ht. upto plinth | Q3: Ht. above PL upto ceiling | R3: Length | S3: Width | T3: Height | U3: Length | V3: Width | W3: Height
B4: 1.5 | C4: 1.5 | D4: 1.5 | E4: =3.083/3.281 -> 0.93965254 | F4: =3.083/3.281 -> 0.93965254 | G4: 0.35 | H4: =14/3.281 -> 4.2669918 | I4: =14/3.281 -> 4.2669918 | J4: 0.45 | K4: =H4-E4*2 -> 2.3876867 | L4: =0.5-0.055-0.075+J4 -> 0.82 | M4: =E4-1.17/3.281 -> 0.58305395 | N4: =D4-G4+J4 -> 1.6 | O4: 0.35 | P4: =D4-G4+J4-T4 -> 1.37 | Q4: =(10.5-0.42)/3.281 -> 3.0722341 | R4: =H4-O4*2 -> 3.5669918 | S4: 0.23 | T4: 0.23 | U4: =K4-R4*2 -> -4.7462969 | V4: 0.23 | W4: 0.35

Sheet 2.5' ht
A1: Government of Nepal
A2: Shankharapur Municipality Office
A3: Bagmati Province
A4: Sankhu, Kathmandu
A5: Detail Estimated Sheet
A6: Project:- k~rkfn] led;]g dlGb/ cw'/f] | H6: F.Y.: 2082/2083
A7: Location:- Shankharapur Municipality 1 | H7: Date:
A8: S.N. | B8: Description of work | C8: No. | D8: Length | E8: Breadth | F8: Height | G8: Quantity | H8: Unit | I8: Rate | J8: Amount | K8: Remark | M8: Water tap size
A9: 1 | B9: g/d k|sf/sf] Sn] / l;N6L df6f]df ;j} lsl;dsf] vGg] sfd | M9: length | N9: Breadth | O9: thickness | P9: Height 1 | Q9: Height 2 | R9: Width of stand tap
B10: -for stand tap | C10: 1 | D10: =5.5/3.281 -> 1.6763182 | E10: =5.5/3.281 -> 1.6763182 | F10: 0.15 | G10: =PRODUCT(C10:F10) -> 0.4215064 | M10: =5.5/3.281 -> 1.6763182 | N10: =5.5/3.281 -> 1.6763182 | O10: 0.23 | P10: =TRUNC(2/3.281,1) -> 0.6 | Q10: =TRUNC(4/3.281,1) -> 1.2 | R10: =1.17/3.281 -> 0.3565986
B11: Sub-total | G11: =SUM(G10) -> 0.4215064 | H11: cum | I11: 674.12 | J11: =G11*I11 -> 284.1459
A13: 2 | B13: ;'Vvf O{6f RofK6f] 5fKg] sfd
B14: =B10 -> -for stand tap | C14: =C10 -> 1 | D14: =D10 -> 1.6763182 | E14: =E10 -> 1.6763182 | G14: =PRODUCT(C14:F14) -> 2.8100427
B15: Sub-total | G15: =SUM(G14) -> 2.8100427 | H15: sqm | I15: 1017.47 | J15: =G15*I15 -> 2859.1341
B16: -13% VAT for brick | J16: =0.13*G15*6360.9/10 -> 232.36721
B17: -13% VAT for sand | J17: =0.13*G15*2256.3/10 -> 82.423891
A19: 3 | B19: d]lzgsf] k|of]u u/L hu leQf kvf{ndf l;d]G6 s+lqm6 ug]{ sfd -!M@M$_
B20: -for lintel | C20: =2 -> 2 | D20: =15/3.281 -> 4.5717769 | E20: 0.35 | F20: 0.1 | G20: =PRODUCT(C20:F20) -> 0.32002438
C21: =2 -> 2 | D21: =9.75/3.281 -> 2.971655 | E21: 0.35 | F21: 0.1 | G21: =PRODUCT(C21:F21) -> 0.20801585
B22: =B14 -> -for stand tap | C22: =C14 -> 1 | D22: =D14 -> 1.6763182 | E22: =E14 -> 1.6763182 | F22: 0.1 | G22: =PRODUCT(C22:F22) -> 0.28100427
B23: Sub-total | G23: =SUM(G20:G22) -> 0.8090445 | H23: cum | I23: 12884.61 | J23: =G23*I23 -> 10424.223
B24: -13% VAT for cement | J24: =0.13*G23*4169.92 -> 438.57461
B25: -13% VAT for aggregate | J25: =0.13*G23*(1652.5+1106.96) -> 290.22837
B26: -13% VAT for sand | J26: =0.13*G23*1414.16 -> 148.73539
B27: -13% VAT for water | J27: =0.13*G23*36.4 -> 3.8283986
B28: -13% VAT for water | J28: =0.13*G23*392.92 -> 41.325669
B29: -13% VAT for water | J29: =0.13*G23*14.15 -> 1.4882374
A31: 4 | B31: d]lzgsf] k|of]u u/L ;'k/ :6«Sr/df l;d]G6 s+lqm6 ug]{ sfd -!M!=%M#_
B32: -beam | C32: 2 | D32: =15/3.281 -> 4.5717769 | E32: 0.23 | F32: 0.35 | G32: =PRODUCT(C32:F32) -> 0.73605608
C33: =2*2 -> 4 | D33: =9.75/3.281 -> 2.971655 | E33: 0.23 | F33: 0.35 | G33: =PRODUCT(C33:F33) -> 0.9568729
B34: -upper beam | C34: 2 | D34: =8.17/3.281 -> 2.4900945 | E34: 0.23 | F34: 0.23 | G34: =PRODUCT(C34:F34) -> 0.263452
C35: 2 | D35: =3.75/3.281 -> 1.1429442 | E35: 0.23 | F35: 0.23 | G35: =PRODUCT(C35:F35) -> 0.1209235
B36: -slab | C36: 2 | D36: =((18.25+8.17)/2)/3.281 -> 4.0262115 | E36: =6.17/3.281 -> 1.8805242 | F36: 0.075 | G36: =PRODUCT(C36:F36) -> 1.1357082
C37: 2 | D37: =((15.25+5.25)/2)/3.281 -> 3.1240475 | E37: =6.33/3.281 -> 1.9292899 | F37: 0.075 | G37: =PRODUCT(C37:F37) -> 0.90407898
B38: -column | C38: 4 | D38: 0.23 | E38: 0.23 | F38: =(2.25-0.5)/3.281 -> 0.53337397 | G38: =PRODUCT(C38:F38) -> 0.11286193
B39: Sub-total | G39: =SUM(G32:G38) -> 4.2299536 | H39: cum | I39: 13957.29 | J39: =G39*I39 -> 59038.69
B40: -13% VAT for cement | J40: =0.13*G39*5212.4 -> 2866.2673
B41: -13% VAT for aggregate | J41: =0.13*G39*(1912.03+921.59) -> 1558.1906
B42: -13% VAT for sand | J42: =0.13*G39*1350.6 -> 742.6868
B43: -13% VAT for water | J43: =0.13*G39*56 -> 30.794063
...

Sheet total slope
A1: Government of Nepal
A2: Shankharapur Municipality Office
A3: Bagmati Province
A4: Sankhu, Kathmandu
A5: Detail Estimated Sheet
A6: Project:- k~rkfn] led;]g dlGb/ cw'/f] | H6: F.Y.: 2082/2083
A7: Location:- Shankharapur Municipality 1 | H7: Date:
A8: S.N. | B8: Description of work | C8: No. | D8: Length | E8: Breadth | F8: Height | G8: Quantity | H8: Unit | I8: Rate | J8: Amount | K8: Remark | M8: Water tap size
A9: 1 | B9: g/d k|sf/sf] Sn] / l;N6L df6f]df ;j} lsl;dsf] vGg] sfd | M9: length | N9: Breadth | O9: thickness | P9: Height 1 | Q9: Height 2 | R9: Width of stand tap
B10: -for stand tap | C10: 1 | D10: =5.5/3.281 -> 1.6763182 | E10: =5.5/3.281 -> 1.6763182 | F10: 0.15 | G10: =PRODUCT(C10:F10) -> 0.4215064 | M10: =5.5/3.281 -> 1.6763182 | N10: =5.5/3.281 -> 1.6763182 | O10: 0.23 | P10: =TRUNC(2/3.281,1) -> 0.6 | Q10: =TRUNC(4/3.281,1) -> 1.2 | R10: =1.17/3.281 -> 0.3565986
B11: Sub-total | G11: =SUM(G10) -> 0.4215064 | H11: cum | I11: 674.12 | J11: =G11*I11 -> 284.1459
A13: 2 | B13: ;'Vvf O{6f RofK6f] 5fKg] sfd
B14: =B10 -> -for stand tap | C14: =C10 -> 1 | D14: =D10 -> 1.6763182 | E14: =E10 -> 1.6763182 | G14: =PRODUCT(C14:F14) -> 2.8100427
B15: Sub-total | G15: =SUM(G14) -> 2.8100427 | H15: sqm | I15: 1017.47 | J15: =G15*I15 -> 2859.1341
B16: -13% VAT for brick | J16: =0.13*G15*6360.9/10 -> 232.36721
B17: -13% VAT for sand | J17: =0.13*G15*2256.3/10 -> 82.423891
A19: 3 | B19: d]lzgsf] k|of]u u/L hu leQf kvf{ndf l;d]G6 s+lqm6 ug]{ sfd -!M@M$_
B20: -for lintel | C20: =2 -> 2 | D20: =15/3.281 -> 4.5717769 | E20: 0.35 | F20: 0.1 | G20: =PRODUCT(C20:F20) -> 0.32002438
C21: =2 -> 2 | D21: =9.75/3.281 -> 2.971655 | E21: 0.35 | F21: 0.1 | G21: =PRODUCT(C21:F21) -> 0.20801585
B22: =B14 -> -for stand tap | C22: =C14 -> 1 | D22: =D14 -> 1.6763182 | E22: =E14 -> 1.6763182 | F22: 0.1 | G22: =PRODUCT(C22:F22) -> 0.28100427
B23: Sub-total | G23: =SUM(G20:G22) -> 0.8090445 | H23: cum | I23: 12884.61 | J23: =G23*I23 -> 10424.223
B24: -13% VAT for cement | J24: =0.13*G23*4169.92 -> 438.57461
B25: -13% VAT for aggregate | J25: =0.13*G23*(1652.5+1106.96) -> 290.22837
B26: -13% VAT for sand | J26: =0.13*G23*1414.16 -> 148.73539
B27: -13% VAT for water | J27: =0.13*G23*36.4 -> 3.8283986
B28: -13% VAT for diesel | J28: =0.13*G23*392.92 -> 41.325669
B29: -13% VAT for petrol | J29: =0.13*G23*14.15 -> 1.4882374
A31: 4 | B31: d]lzgsf] k|of]u u/L ;'k/ :6«Sr/df l;d]G6 s+lqm6 ug]{ sfd -!M!=%M#_
B32: -beam | C32: 2 | D32: =15/3.281 -> 4.5717769 | E32: 0.23 | F32: 0.35 | G32: =PRODUCT(C32:F32) -> 0.73605608
C33: =2*2 -> 4 | D33: =9.75/3.281 -> 2.971655 | E33: 0.23 | F33: 0.35 | G33: =PRODUCT(C33:F33) -> 0.9568729
B34: -upper beam | C34: 2 | D34: =5/3.281 -> 1.5239256 | E34: 0.23 | F34: 0.23 | G34: =PRODUCT(C34:F34) -> 0.16123133
C35: 2 | D35: =3.75/3.281 -> 1.1429442 | E35: 0.23 | F35: 0.23 | G35: =PRODUCT(C35:F35) -> 0.1209235
B36: -slab | C36: 2 | D36: =((18.25)/2)/3.281 -> 2.7811643 | E36: =10.5/3.281 -> 3.2002438 | F36: 0.075 | G36: =PRODUCT(C36:F36) -> 1.3350606
C37: 2 | D37: =((15.25)/2)/3.281 -> 2.3239866 | E37: =9.5/3.281 -> 2.8954587 | F37: 0.075 | G37: =PRODUCT(C37:F37) -> 1.0093511
B38: -column | C38: 4 | D38: 0.23 | E38: 0.23 | F38: =(2.667/3.281) -> 0.81286193 | G38: =PRODUCT(C38:F38) -> 0.17200158
B39: Sub-total | G39: =SUM(G32:G38) -> 4.4914971 | H39: cum | I39: 13957.29 | J39: =G39*I39 -> 62689.127
B40: -13% VAT for cement | J40: =0.13*G39*5212.4 -> 3043.4923
B41: -13% VAT for aggregate | J41: =0.13*G39*(1912.03+921.59) -> 1654.5355
B42: -13% VAT for sand | J42: =0.13*G39*1350.6 -> 788.60807
B43: -13% VAT for water | J43: =0.13*G39*56 -> 32.698099
...

Sheet WCR
A1: Government of Nepal
A2: Shankharapur Municipality Office
A3: Bagmati Province
A4: Sankhu, Kathmandu
A5: Work Completion Report
A6: Total Estimated Amount: | C6: =F101 -> 615013.61 | H6: Total Valuated Amount : | J6: =I101 -> 383357.49
A7: Work Started : | I7: Work Finished:
A8: Project:- k~rkfn] led;]g dlGb/ cw'/f] | I8: F.Y:2082/2083
A9: =[7]estimate!A7 -> Location:- Shankharapur Municipality 1 | I9: Date:2083/06/20
A11: S.No. | B11: Description | C11: Unit | D11: Estimated | G11: Valuated | J11: Difference | K11: Remarks
D12: Quantity | E12: Rate | F12: Amount | G12: Quantity | H12: Rate | I12: Amount
A13: ='total slope'!A9 -> 1 | B13: ='total slope'!B9 -> g/d k|sf/sf] Sn] / l;N6L df6f]df ;j} lsl;dsf] vGg] sfd | C13: ='total slope'!H11 -> cum | D13: ='total slope'!G11 -> 0.4215064 | E13: ='total slope'!I11 -> 674.12 | F13: =D13*E13 -> 284.1459 | G13: =V!G11 -> 0 | H13: =V!I11 -> 674.12 | I13: =G13*H13 -> 0 | J13: =I13-F13 -> -284.1459 | M13: =1.25*F13 -> 355.18237
A15: ='total slope'!A13 -> 2 | B15: ='total slope'!B13 -> ;'Vvf O{6f RofK6f] 5fKg] sfd | C15: ='total slope'!H15 -> sqm | D15: ='total slope'!G15 -> 2.8100427 | E15: ='total slope'!I15 -> 1017.47 | F15: =D15*E15 -> 2859.1341 | G15: =V!G15 -> 0 | H15: =V!I15 -> 1017.47 | I15: =G15*H15 -> 0 | J15: =I15-F15 -> -2859.1341 | M15: =1.25*F15 -> 3573.9177
B16: ='total slope'!B16 -> -13% VAT for brick | F16: ='total slope'!J16 -> 232.36721 | I16: =V!J16 -> 0 | J16: =I16-F16 -> -232.36721
B17: ='total slope'!B17 -> -13% VAT for sand | F17: ='total slope'!J17 -> 82.423891 | I17: =V!J17 -> 0 | J17: =I17-F17 -> -82.423891
A19: ='total slope'!A19 -> 3 | B19: ='total slope'!B19 -> d]lzgsf] k|of]u u/L hu leQf kvf{ndf l;d]G6 s+lqm6 ug]{ sfd -!M@M$_ | C19: ='total slope'!H23 -> cum | D19: ='total slope'!G23 -> 0.8090445 | E19: ='total slope'!I23 -> 12884.61 | F19: =D19*E19 -> 10424.223 | G19: =V!G23 -> 0 | H19: =V!I23 -> 12884.61 | I19: =G19*H19 -> 0 | J19: =I19-F19 -> -10424.223 | M19: =1.25*F19 -> 13030.279
B20: ='total slope'!B24 -> -13% VAT for cement | F20: ='total slope'!J24 -> 438.57461 | I20: =V!J24 -> 0 | J20: =I20-F20 -> -438.57461 | M20: =1.25*F20 -> 548.21826
B21: ='total slope'!B25 -> -13% VAT for aggregate | F21: ='total slope'!J25 -> 290.22837 | I21: =V!J25 -> 0 | J21: =I21-F21 -> -290.22837
B22: ='total slope'!B26 -> -13% VAT for sand | F22: ='total slope'!J26 -> 148.73539 | I22: =V!J26 -> 0 | J22: =I22-F22 -> -148.73539
B23: ='total slope'!B27 -> -13% VAT for water | F23: ='total slope'!J27 -> 3.8283986 | I23: =V!J27 -> 0 | J23: =I23-F23 -> -3.8283986
B24: ='total slope'!B28 -> -13% VAT for diesel | F24: ='total slope'!J28 -> 41.325669 | I24: =V!J28 -> 0 | J24: =I24-F24 -> -41.325669
B25: ='total slope'!B29 -> -13% VAT for petrol | F25: ='total slope'!J29 -> 1.4882374 | I25: =V!J29 -> 0 | J25: =I25-F25 -> -1.4882374
A27: ='total slope'!A31 -> 4 | B27: ='total slope'!B31 -> d]lzgsf] k|of]u u/L ;'k/ :6«Sr/df l;d]G6 s+lqm6 ug]{ sfd -!M!=%M#_ | C27: ='total slope'!H39 -> cum | D27: ='total slope'!G39 -> 4.4914971 | E27: ='total slope'!I39 -> 13957.29 | F27: =D27*E27 -> 62689.127 | G27: =V!G42 -> 5.4160946 | H27: =V!I42 -> 13957.29 | I27: =G27*H27 -> 75594.003 | J27: =I27-F27 -> 12904.876 | M27: =1.25*F27 -> 78361.409
B28: ='total slope'!B40 -> -13% VAT for cement | F28: ='total slope'!J40 -> 3043.4923 | I28: =V!J43 -> 3670.0107 | J28: =I28-F28 -> 626.5184 | M28: =1.25*F28 -> 3804.3654
B29: ='total slope'!B41 -> -13% VAT for aggregate | F29: ='total slope'!J41 -> 1654.5355 | I29: =V!J44 -> 1995.13 | J29: =I29-F29 -> 340.59455
B30: ='total slope'!B42 -> -13% VAT for sand | F30: ='total slope'!J42 -> 788.60807 | I30: =V!J45 -> 950.94706 | J30: =I30-F30 -> 162.33899
B31: ='total slope'!B43 -> -13% VAT for water | F31: ='total slope'!J43 -> 32.698099 | I31: =V!J46 -> 39.429169 | J31: =I31-F31 -> 6.7310702
B32: ='total slope'!B44 -> -13% VAT for diesel | F32: ='total slope'!J44 -> 229.42387 | I32: =V!J47 -> 276.65195 | J32: =I32-F32 -> 47.228073
B33: ='total slope'!B45 -> -13% VAT for petrol | F33: ='total slope'!J45 -> 8.2621088 | I33: =V!J48 -> 9.962906 | J33: =I33-F33 -> 1.7007972
A35: ='total slope'!A47 -> 5 | B35: ='total slope'!B47 -> kmnfd]sf] kfOk / KnfOaf]8{af6 kmdf{ agfpg] sfd | C35: ='total slope'!H55 -> sqm | D35: ='total slope'!G55 -> 50.578396 | E35: ='total slope'!I55 -> 922.71 | F35: =D35*E35 -> 46669.192 | G35: =V!G62 -> 64.794743 | H35: =V!I62 -> 922.71 | I35: =G35*H35 -> 59786.757 | J35: =I35-F35 -> 13117.566 | M35: =1.25*F35 -> 58336.49
B36: ='total slope'!B56 -> -13% VAT for plyboard | F36: ='total slope'!J56 -> 1319.1162 | I36: =V!J63 -> 1689.8875 | J36: =I36-F36 -> 370.77123 | M36: =1.25*F36 -> 1648.8953
B37: ='total slope'!B57 -> -13% VAT for wood | F37: ='total slope'!J57 -> 876.35796 | I37: =V!J64 -> 1122.6807 | J37: =I37-F37 -> 246.32273
B38: ='total slope'!B58 -> -13% VAT for iron props | F38: ='total slope'!J58 -> 666.56661 | I38: =V!J65 -> 853.92214 | J38: =I38-F38 -> 187.35553
B39: ='total slope'!B59 -> -13% VAT for nails | F39: ='total slope'!J59 -> 216.98132 | I39: =V!J66 -> 277.96945 | J39: =I39-F39 -> 60.988128
A41: ='total slope'!A61 -> 6 | B41: ='total slope'!B61 -> cf/=;L=;L= nflu kmnfd] 808L sf6\g], df]8\g] #) dL6/ ;Dd | C41: ='total slope'!H79 -> MT | D41: ='total slope'!G79 -> 0.45424961 | E41: ='total slope'!I79 -> 132360 | F41: =D41*E41 -> 60124.479 | G41: =V!G93 -> 0.56765163 | H41: =V!I93 -> 132360 | I41: =G41*H41 -> 75134.37 | J41: =I41-F41 -> 15009.891 | M41: =1.25*F41 -> 75155.599
B42: ='total slope'!B80 -> -13% VAT for TMT rod | F42: ='total slope'!J80 -> 6200.5072 | I42: =V!J94 -> 7748.4448 | J42: =I42-F42 -> 1547.9376 | M42: =1.25*F42 -> 7750.634
B43: ='total slope'!B81 -> -13% VAT for binding wire | F43: ='total slope'!J81 -> 70.86294 | I43: =V!J95 -> 88.553655 | J43: =I43-F43 -> 17.690715
A45: ='total slope'!A83 -> 7 | B45: ='total slope'!B83 -> l;d]G6 s+qmL6 ˆnf]l/Ë -!M@M$_ -#* dL=dL=_ | C45: ='total slope'!H86 -> sqm | D45: ='total slope'!G86 -> 18.104237 | E45: ='total slope'!I86 -> 689.98 | F45: =D45*E45 -> 12491.561 | G45: =V!G100 -> 0 | H45: =V!I100 -> 689.98 | I45: =G45*H45 -> 0 | J45: =I45-F45 -> -12491.561 | M45: =1.25*F45 -> 15614.451
B46: ='total slope'!B87 -> -13% VAT for cement | F46: ='total slope'!J87 -> 398.69856 | I46: =V!J101 -> 0 | J46: =I46-F46 -> -398.69856 | M46: =1.25*F46 -> 498.3732
B47: ='total slope'!B88 -> -13% VAT for sand | F47: ='total slope'!J88 -> 111.0923 | I47: =V!J102 -> 0 | J47: =I47-F47 -> -111.0923
...

Sheet V
A1: Government of Nepal
A2: Shankharapur Municipality Office
A3: Bagmati Province
A4: Sankhu, Kathmandu
A5: Detail Valuated Sheet
A6: Project:- k~rkfn] led;]g dlGb/ cw'/f] | H6: F.Y.: 2082/2083
A7: Location:- Shankharapur Municipality 1 | H7: Date: 2083/06/20
A8: S.N. | B8: Description of work | C8: No. | D8: Length | E8: Breadth | F8: Height | G8: Quantity | H8: Unit | I8: Rate | J8: Amount | K8: Remark | M8: Water tap size
A9: 1 | B9: g/d k|sf/sf] Sn] / l;N6L df6f]df ;j} lsl;dsf] vGg] sfd | M9: length | N9: Breadth | O9: thickness | P9: Height 1 | Q9: Height 2 | R9: Width of stand tap
B10: -for stand tap | C10: 0 | D10: =5.5/3.281 -> 1.6763182 | E10: =5.5/3.281 -> 1.6763182 | F10: 0.15 | G10: =PRODUCT(C10:F10) -> 0 | M10: =5.5/3.281 -> 1.6763182 | N10: =5.5/3.281 -> 1.6763182 | O10: 0.23 | P10: =TRUNC(2/3.281,1) -> 0.6 | Q10: =TRUNC(4/3.281,1) -> 1.2 | R10: =1.17/3.281 -> 0.3565986
B11: Sub-total | G11: =SUM(G10) -> 0 | H11: cum | I11: 674.12 | J11: =G11*I11 -> 0
A13: 2 | B13: ;'Vvf O{6f RofK6f] 5fKg] sfd
B14: =B10 -> -for stand tap | C14: =C10 -> 0 | D14: =D10 -> 1.6763182 | E14: =E10 -> 1.6763182 | G14: =PRODUCT(C14:F14) -> 0
B15: Sub-total | G15: =SUM(G14) -> 0 | H15: sqm | I15: 1017.47 | J15: =G15*I15 -> 0
B16: -13% VAT for brick | J16: =0.13*G15*6360.9/10 -> 0
B17: -13% VAT for sand | J17: =0.13*G15*2256.3/10 -> 0
A19: 3 | B19: d]lzgsf] k|of]u u/L hu leQf kvf{ndf l;d]G6 s+lqm6 ug]{ sfd -!M@M$_
B20: -for lintel | C20: 0 | D20: =15/3.281 -> 4.5717769 | E20: 0.35 | F20: 0.1 | G20: =PRODUCT(C20:F20) -> 0
C21: 0 | D21: =9.75/3.281 -> 2.971655 | E21: 0.35 | F21: 0.1 | G21: =PRODUCT(C21:F21) -> 0
B22: =B14 -> -for stand tap | C22: =C14 -> 0 | D22: =D14 -> 1.6763182 | E22: =E14 -> 1.6763182 | F22: 0.1 | G22: =PRODUCT(C22:F22) -> 0
B23: Sub-total | G23: =SUM(G20:G22) -> 0 | H23: cum | I23: 12884.61 | J23: =G23*I23 -> 0
B24: -13% VAT for cement | J24: =0.13*G23*4169.92 -> 0
B25: -13% VAT for aggregate | J25: =0.13*G23*(1652.5+1106.96) -> 0
B26: -13% VAT for sand | J26: =0.13*G23*1414.16 -> 0
B27: -13% VAT for water | J27: =0.13*G23*36.4 -> 0
B28: -13% VAT for water | J28: =0.13*G23*392.92 -> 0
B29: -13% VAT for water | J29: =0.13*G23*14.15 -> 0
A31: 4 | B31: d]lzgsf] k|of]u u/L ;'k/ :6«Sr/df l;d]G6 s+lqm6 ug]{ sfd -!M!=%M#_
B32: -beam | C32: 2 | D32: =15/3.281 -> 4.5717769 | E32: 0.23 | F32: 0.3 | G32: =PRODUCT(C32:F32) -> 0.63090521
C33: 2 | D33: =(12-1.17*2)/3.281 -> 2.9442243 | E33: 0.23 | F33: 0.3 | G33: =PRODUCT(C33:F33) -> 0.40630296
C34: 2 | D34: =(12-1.17*2)/3.281 -> 2.9442243 | E34: 0.23 | F34: 0.3 | G34: =PRODUCT(C34:F34) -> 0.40630296
B35: -upper beam | C35: 2 | D35: =(3+1.5)/3.281 -> 1.3715331 | E35: 0.23 | F35: 0.23 | G35: =PRODUCT(C35:F35) -> 0.1451082
C36: 2 | D36: =39/12/3.281 -> 0.99055166 | E36: 0.23 | F36: 0.23 | G36: =PRODUCT(C36:F36) -> 0.10480037
B37: -slab | C37: 2 | D37: =((16.75+4.5)/2)/3.281 -> 3.238342 | E37: =((8.333+7.75)/2/3.281) -> 2.4509296 | F37: 0.075 | G37: =PRODUCT(C37:F37) -> 1.1905422 | M37: =((7*12+8.5+8*12+4.5)/2)/12/3.281 -> 2.4509804 | N37: =CONVERT(M37,"m","ft") -> 8.0412743 | O37: =16.083/2/3.281 -> 2.4509296
C38: 2 | D38: =(4.75+19.5)/2/3.281 -> 3.6955197 | E38: =7/3.281 -> 2.1334959 | F38: 0.075 | G38: =PRODUCT(C38:F38) -> 1.1826564 | M38: =(4.75+19.5)/2/3.281 -> 3.6955197 | N38: =CONVERT(M38,"m","ft") -> 12.124408
B39: -column | C39: 4 | D39: 0.23 | E39: 0.23 | F39: =(4/3.281) -> 1.2191405 | G39: =PRODUCT(C39:F39) -> 0.25797013
B40: -cantilever | C40: 2 | D40: 6 | E40: =28/12/3.281 -> 0.7111653 | F40: 0.075 | G40: =PRODUCT(C40:F40) -> 0.64004877
C41: 2 | D41: =5.1-(28/12/3.281) -> 4.3888347 | E41: =27/12/3.281 -> 0.68576653 | F41: 0.075 | G41: =PRODUCT(C41:F41) -> 0.45145739
B42: Sub-total | G42: =SUM(G32:G41) -> 5.4160946 | H42: cum | I42: 13957.29 | J42: =G42*I42 -> 75594.003
B43: -13% VAT for cement | J43: =0.13*G42*5212.4 -> 3670.0107
...

Sheet M
A1: Government of Nepal
A2: Shankharapur Municipality Office
A3: Bagmati Province
A4: Sankhu, Kathmandu
A5: Detail Quantity Measurement Sheet
A6: Project:- k~rkfn] led;]g dlGb/ cw'/f] | K6: F.Y.: 2082/2083
A7: Location:- Shankharapur Municipality 1 | K7: Date: 2083/06/20
A8: S.N. | B8: Description of work | C8: No. | D8: Length | E8: Breadth | F8: Height | G8: Quantity | H8: Unit | I8: Rate | J8: Amount | K8: Remark | M8: Water tap size
A9: 1 | B9: g/d k|sf/sf] Sn] / l;N6L df6f]df ;j} lsl;dsf] vGg] sfd | M9: length | N9: Breadth | O9: thickness | P9: Height 1 | Q9: Height 2 | R9: Width of stand tap
B10: -for stand tap | C10: 0 | D10: =5.5/3.281 -> 1.6763182 | E10: =5.5/3.281 -> 1.6763182 | F10: 0.15 | G10: =PRODUCT(C10:F10) -> 0 | M10: =5.5/3.281 -> 1.6763182 | N10: =5.5/3.281 -> 1.6763182 | O10: 0.23 | P10: =TRUNC(2/3.281,1) -> 0.6 | Q10: =TRUNC(4/3.281,1) -> 1.2 | R10: =1.17/3.281 -> 0.3565986
B11: Sub-total | G11: =SUM(G10) -> 0 | H11: cum | I11: 674.12 | J11: =G11*I11 -> 0
A13: 2 | B13: ;'Vvf O{6f RofK6f] 5fKg] sfd
B14: =B10 -> -for stand tap | C14: =C10 -> 0 | D14: =D10 -> 1.6763182 | E14: =E10 -> 1.6763182 | G14: =PRODUCT(C14:F14) -> 0
B15: Sub-total | G15: =SUM(G14) -> 0 | H15: sqm | I15: 1017.47 | J15: =G15*I15 -> 0
B16: -13% VAT for brick | J16: =0.13*G15*6360.9/10 -> 0
B17: -13% VAT for sand | J17: =0.13*G15*2256.3/10 -> 0
A19: 3 | B19: d]lzgsf] k|of]u u/L hu leQf kvf{ndf l;d]G6 s+lqm6 ug]{ sfd -!M@M$_
B20: -for lintel | C20: 0 | D20: =15/3.281 -> 4.5717769 | E20: 0.35 | F20: 0.1 | G20: =PRODUCT(C20:F20) -> 0
C21: 0 | D21: =9.75/3.281 -> 2.971655 | E21: 0.35 | F21: 0.1 | G21: =PRODUCT(C21:F21) -> 0
B22: =B14 -> -for stand tap | C22: =C14 -> 0 | D22: =D14 -> 1.6763182 | E22: =E14 -> 1.6763182 | F22: 0.1 | G22: =PRODUCT(C22:F22) -> 0
B23: Sub-total | G23: =SUM(G20:G22) -> 0 | H23: cum | I23: 12884.61 | J23: =G23*I23 -> 0
B24: -13% VAT for cement | J24: =0.13*G23*4169.92 -> 0
B25: -13% VAT for aggregate | J25: =0.13*G23*(1652.5+1106.96) -> 0
B26: -13% VAT for sand | J26: =0.13*G23*1414.16 -> 0
B27: -13% VAT for water | J27: =0.13*G23*36.4 -> 0
B28: -13% VAT for water | J28: =0.13*G23*392.92 -> 0
B29: -13% VAT for water | J29: =0.13*G23*14.15 -> 0
A31: 4 | B31: d]lzgsf] k|of]u u/L ;'k/ :6«Sr/df l;d]G6 s+lqm6 ug]{ sfd -!M!=%M#_
B32: -beam | C32: 2 | D32: =15/3.281 -> 4.5717769 | E32: 0.23 | F32: 0.3 | G32: =PRODUCT(C32:F32) -> 0.63090521
C33: 2 | D33: =(12-1.17*2)/3.281 -> 2.9442243 | E33: 0.23 | F33: 0.3 | G33: =PRODUCT(C33:F33) -> 0.40630296
C34: 2 | D34: =(12-1.17*2)/3.281 -> 2.9442243 | E34: 0.23 | F34: 0.3 | G34: =PRODUCT(C34:F34) -> 0.40630296
B35: -upper beam | C35: 2 | D35: =(3+1.5)/3.281 -> 1.3715331 | E35: 0.23 | F35: 0.23 | G35: =PRODUCT(C35:F35) -> 0.1451082
C36: 2 | D36: =39/12/3.281 -> 0.99055166 | E36: 0.23 | F36: 0.23 | G36: =PRODUCT(C36:F36) -> 0.10480037
B37: -slab | C37: 2 | D37: =((16.75+4.5)/2)/3.281 -> 3.238342 | E37: =((8.333+7.75)/2/3.281) -> 2.4509296 | F37: 0.075 | G37: =PRODUCT(C37:F37) -> 1.1905422 | M37: =((7*12+8.5+8*12+4.5)/2)/12/3.281 -> 2.4509804 | N37: =CONVERT(M37,"m","ft") -> 8.0412743 | O37: =16.083/2/3.281 -> 2.4509296
C38: 2 | D38: =(4.75+19.5)/2/3.281 -> 3.6955197 | E38: =7/3.281 -> 2.1334959 | F38: 0.075 | G38: =PRODUCT(C38:F38) -> 1.1826564 | M38: =(4.75+19.5)/2/3.281 -> 3.6955197 | N38: =CONVERT(M38,"m","ft") -> 12.124408
B39: -column | C39: 4 | D39: 0.23 | E39: 0.23 | F39: =(4/3.281) -> 1.2191405 | G39: =PRODUCT(C39:F39) -> 0.25797013
B40: -cantilever | C40: 2 | D40: 6 | E40: =28/12/3.281 -> 0.7111653 | F40: 0.075 | G40: =PRODUCT(C40:F40) -> 0.64004877
C41: 2 | D41: =5.1-(28/12/3.281) -> 4.3888347 | E41: =27/12/3.281 -> 0.68576653 | F41: 0.075 | G41: =PRODUCT(C41:F41) -> 0.45145739
B42: Sub-total | G42: =SUM(G32:G41) -> 5.4160946 | H42: cum | I42: 13957.29 | J42: =G42*I42 -> 75594.003
B43: -13% VAT for cement | J43: =0.13*G42*5212.4 -> 3670.0107
...

Sheet 2.667'column height
A1: Government of Nepal
A2: Shankharapur Municipality Office
A3: Bagmati Province
A4: Sankhu, Kathmandu
A5: Detail Estimated Sheet
A6: Project:- k~rkfn] led;]g dlGb/ cw'/f] | H6: F.Y.: 2082/2083
A7: Location:- Shankharapur Municipality 1 | H7: Date:
A8: S.N. | B8: Description of work | C8: No. | D8: Length | E8: Breadth | F8: Height | G8: Quantity | H8: Unit | I8: Rate | J8: Amount | K8: Remark | M8: Water tap size
A9: 1 | B9: g/d k|sf/sf] Sn] / l;N6L df6f]df ;j} lsl;dsf] vGg] sfd | M9: length | N9: Breadth | O9: thickness | P9: Height 1 | Q9: Height 2 | R9: Width of stand tap
B10: -for stand tap | C10: 1 | D10: =5.5/3.281 -> 1.6763182 | E10: =5.5/3.281 -> 1.6763182 | F10: 0.15 | G10: =PRODUCT(C10:F10) -> 0.4215064 | M10: =5.5/3.281 -> 1.6763182 | N10: =5.5/3.281 -> 1.6763182 | O10: 0.23 | P10: =TRUNC(2/3.281,1) -> 0.6 | Q10: =TRUNC(4/3.281,1) -> 1.2 | R10: =1.17/3.281 -> 0.3565986
B11: Sub-total | G11: =SUM(G10) -> 0.4215064 | H11: cum | I11: 674.12 | J11: =G11*I11 -> 284.1459
A13: 2 | B13: ;'Vvf O{6f RofK6f] 5fKg] sfd
B14: =B10 -> -for stand tap | C14: =C10 -> 1 | D14: =D10 -> 1.6763182 | E14: =E10 -> 1.6763182 | G14: =PRODUCT(C14:F14) -> 2.8100427
B15: Sub-total | G15: =SUM(G14) -> 2.8100427 | H15: sqm | I15: 1017.47 | J15: =G15*I15 -> 2859.1341
B16: -13% VAT for brick | J16: =0.13*G15*6360.9/10 -> 232.36721
B17: -13% VAT for sand | J17: =0.13*G15*2256.3/10 -> 82.423891
A19: 3 | B19: d]lzgsf] k|of]u u/L hu leQf kvf{ndf l;d]G6 s+lqm6 ug]{ sfd -!M@M$_
B20: -for lintel | C20: =2 -> 2 | D20: =15/3.281 -> 4.5717769 | E20: 0.35 | F20: 0.1 | G20: =PRODUCT(C20:F20) -> 0.32002438
C21: =2 -> 2 | D21: =9.75/3.281 -> 2.971655 | E21: 0.35 | F21: 0.1 | G21: =PRODUCT(C21:F21) -> 0.20801585
B22: =B14 -> -for stand tap | C22: =C14 -> 1 | D22: =D14 -> 1.6763182 | E22: =E14 -> 1.6763182 | F22: 0.1 | G22: =PRODUCT(C22:F22) -> 0.28100427
B23: Sub-total | G23: =SUM(G20:G22) -> 0.8090445 | H23: cum | I23: 12884.61 | J23: =G23*I23 -> 10424.223
B24: -13% VAT for cement | J24: =0.13*G23*4169.92 -> 438.57461
B25: -13% VAT for aggregate | J25: =0.13*G23*(1652.5+1106.96) -> 290.22837
B26: -13% VAT for sand | J26: =0.13*G23*1414.16 -> 148.73539
B27: -13% VAT for water | J27: =0.13*G23*36.4 -> 3.8283986
B28: -13% VAT for water | J28: =0.13*G23*392.92 -> 41.325669
B29: -13% VAT for water | J29: =0.13*G23*14.15 -> 1.4882374
A31: 4 | B31: d]lzgsf] k|of]u u/L ;'k/ :6«Sr/df l;d]G6 s+lqm6 ug]{ sfd -!M!=%M#_
B32: -beam | C32: 2 | D32: =15/3.281 -> 4.5717769 | E32: 0.23 | F32: 0.35 | G32: =PRODUCT(C32:F32) -> 0.73605608
C33: =2*2 -> 4 | D33: =9.75/3.281 -> 2.971655 | E33: 0.23 | F33: 0.35 | G33: =PRODUCT(C33:F33) -> 0.9568729
B34: -upper beam | C34: 2 | D34: =5/3.281 -> 1.5239256 | E34: 0.23 | F34: 0.23 | G34: =PRODUCT(C34:F34) -> 0.16123133
C35: 2 | D35: =3.75/3.281 -> 1.1429442 | E35: 0.23 | F35: 0.23 | G35: =PRODUCT(C35:F35) -> 0.1209235
B36: -slab | C36: 2 | D36: =((18.25+6.5)/2)/3.281 -> 3.7717159 | E36: =6.917/3.281 -> 2.1081987 | F36: 0.075 | G36: =PRODUCT(C36:F36) -> 1.192729
C37: 2 | D37: =((15.25+5.25)/2)/3.281 -> 3.1240475 | E37: =6.25/3.281 -> 1.904907 | F37: 0.075 | G37: =PRODUCT(C37:F37) -> 0.89265302
B38: -column | C38: 4 | D38: 0.23 | E38: 0.23 | F38: =(2.667/3.281) -> 0.81286193 | G38: =PRODUCT(C38:F38) -> 0.17200158
B39: Sub-total | G39: =SUM(G32:G38) -> 4.2324674 | H39: cum | I39: 13957.29 | J39: =G39*I39 -> 59073.775
B40: -13% VAT for cement | J40: =0.13*G39*5212.4 -> 2867.9707
B41: -13% VAT for aggregate | J41: =0.13*G39*(1912.03+921.59) -> 1559.1166
B42: -13% VAT for sand | J42: =0.13*G39*1350.6 -> 743.12817
B43: -13% VAT for water | J43: =0.13*G39*56 -> 30.812363
...
