Workbook
Name description_103: [1]Abstract!$B$16
Name description_124: #REF!
Name description_247: [1]Abstract!$B$22
Name description_248: [1]Abstract!$B$23
Name description_261: [2]Abstract!$B$33
Name description_262: [1]Abstract!$B$34
Name description_276: [3]Abstract!$B$40
Name description_3: [1]Abstract!$B$169
Name description_310: #REF!
Name description_312: #REF!
Name description_5: [1]Abstract!$B$171
Name description_6: #REF!
Name description_759: [1]Abstract!$B$278
Name description_781: #REF!
Name description_783: [1]Abstract!$B$301
Name description_784: [3]Abstract!$B$300

Sheet bhotange chihaanpaati
A1: Government of Nepal
A2: Shankharapur Municipality Office
A3: Bagmati Province
A4: Sankhu, Kathmandu
A5: Detail Estimated Sheet
A6: Project:- k~rkfn] led;]g dlGb/ cw'/f] | H6: F.Y.: 2082/2083
A7: Location:- Shankharapur Municipality 1 | H7: Date:
A8: S.N. | B8: Description of work | C8: No. | D8: Length | E8: Breadth | F8: Height | G8: Quantity | H8: Unit | I8: Rate | J8: Amount | K8: Remark
A9: 3 | B9: d]lzgsf] k|of]u u/L hu leQf kvf{ndf l;d]G6 s+lqm6 ug]{ sfd -!M@M$_
B10: -for lintel | C10: =2 -> 2 | D10: =15/3.281 -> 4.5717769 | E10: 0.35 | F10: 0.1 | G10: =PRODUCT(C10:F10) -> 0.32002438
C11: =2 -> 2 | D11: =9.75/3.281 -> 2.971655 | E11: 0.35 | F11: 0.1 | G11: =PRODUCT(C11:F11) -> 0.20801585
B12: Sub-total | G12: =SUM(G10:G11) -> 0.52804023 | H12: cum | I12: 12884.61 | J12: =G12*I12 -> 6803.5924
B13: -13% VAT for cement | J13: =0.13*G12*4169.92 -> 286.24512
B14: -13% VAT for aggregate | J14: =0.13*G12*(1652.5+1106.96) -> 189.42377
B15: -13% VAT for sand | J15: =0.13*G12*1414.16 -> 97.075339
B16: -13% VAT for water | J16: =0.13*G12*36.4 -> 2.4986864
B17: -13% VAT for water | J17: =0.13*G12*392.92 -> 26.972084
B18: -13% VAT for water | J18: =0.13*G12*14.15 -> 0.97133001
A20: 4 | B20: d]lzgsf] k|of]u u/L ;'k/ :6«Sr/df l;d]G6 s+lqm6 ug]{ sfd -!M!=%M#_
B21: -beam | C21: 2 | D21: =15/3.281 -> 4.5717769 | E21: 0.23 | F21: 0.23 | G21: =PRODUCT(C21:F21) -> 0.483694
C22: =2*2 -> 4 | D22: =9.75/3.281 -> 2.971655 | E22: 0.23 | F22: 0.23 | G22: =PRODUCT(C22:F22) -> 0.62880219
B23: -upper beam | C23: 2 | D23: =8.17/3.281 -> 2.4900945 | E23: 0.23 | F23: 0.23 | G23: =PRODUCT(C23:F23) -> 0.263452
C24: 2 | D24: =3.75/3.281 -> 1.1429442 | E24: 0.23 | F24: 0.23 | G24: =PRODUCT(C24:F24) -> 0.1209235
B25: -slab | C25: 2 | D25: =((17.667+8.17)/2)/3.281 -> 3.9373667 | E25: =6.33/3.281 -> 1.9292899 | F25: 0.075 | G25: =PRODUCT(C25:F25) -> 1.1394482
C26: 2 | D26: =((14.75+5.25)/2)/3.281 -> 3.0478513 | E26: =6.33/3.281 -> 1.9292899 | F26: 0.075 | G26: =PRODUCT(C26:F26) -> 0.88202828
B27: -column | C27: 4 | D27: 0.23 | E27: 0.23 | F27: =2.25/3.281 -> 0.68576653 | G27: =PRODUCT(C27:F27) -> 0.1451082
B28: Sub-total | G28: =SUM(G21:G27) -> 3.6634564 | H28: cum | I28: 13957.29 | J28: =G28*I28 -> 51131.923
B29: -13% VAT for cement | J29: =0.13*G28*5212.4 -> 2482.402
B30: -13% VAT for aggregate | J30: =0.13*G28*(1912.03+921.59) -> 1349.5096
B31: -13% VAT for sand | J31: =0.13*G28*1350.6 -> 643.22235
B32: -13% VAT for water | J32: =0.13*G28*56 -> 26.669963
B33: -13% VAT for diesel | J33: =0.13*G28*392.92 -> 187.12789
B34: -13% VAT for petrol | J34: =0.13*G28*14.15 -> 6.738928
A36: 5 | B36: kmnfd]sf] kfOk / KnfOaf]8{af6 kmdf{ agfpg] sfd
B37: =B21 -> -beam | C37: =C21 -> 2 | D37: =D21 -> 4.5717769 | F37: =0.23*2 -> 0.46 | G37: =PRODUCT(C37:F37) -> 4.2060347
C38: =C22 -> 4 | D38: =D22 -> 2.971655 | F38: =0.23*2 -> 0.46 | G38: =PRODUCT(C38:F38) -> 5.4678452
B39: =B23 -> -upper beam | C39: =C23 -> 2 | D39: =D23 -> 2.4900945 | F39: =0.23*2 -> 0.46 | G39: =PRODUCT(C39:F39) -> 2.2908869
C40: =C24 -> 2 | D40: =D24 -> 1.1429442 | F40: =0.23*2 -> 0.46 | G40: =PRODUCT(C40:F40) -> 1.0515087
B41: =B25 -> -slab | C41: =C25 -> 2 | D41: =D25 -> 3.9373667 | E41: =E25 -> 1.9292899 | G41: =PRODUCT(C41:F41) -> 15.192643
C42: =C26 -> 2 | D42: =D26 -> 3.0478513 | E42: =E26 -> 1.9292899 | G42: =PRODUCT(C42:F42) -> 11.760377
...

Sheet chihaan
A1: Government of Nepal
A2: Shankharapur Municipality Office
A3: Bagmati Province
A4: Sankhu, Kathmandu
A5: Detail Estimated Sheet
A6: Project:- ef]tfª\u] lrxfgkfl6 | H6: F.Y.: 2082/2083
A7: Location:- Shankharapur Municipality 1 | H7: Date:
A8: S.N. | B8: Description of work | C8: No. | D8: Length | E8: Breadth | F8: Height | G8: Quantity | H8: Unit | I8: Rate | J8: Amount | K8: Remark
A9: 1 | B9: Earthwork Excavation in Cutting., Roadway Excavation in all types of Soil by Mechanical Means ., Road way Excavation in all types of soil as per Drawing and technical specifications including removal of stumps and other deleterious matter and backfilling, all lifts and lead as per Drawing and instruction of the Engineer.
B10: -for wall | C10: 0.5 | D10: 7.5 | E10: 3 | F10: 1.5 | G10: =PRODUCT(C10:F10) -> 16.875
B11: Sub-total | G11: =SUM(G10:G10) -> 16.875 | H11: m3 | I11: 62.95 | J11: =G11*I11 -> 1062.2812
B12: -13% VAT for materials | J12: =0.13*G11*(18612)/360 -> 113.41688
A14: 2 | B14: Providing and laying of hand pack locally available Stone soling with 150 to 200 mm thick stones and packing with smaller stone on prepared surface as per Drawing and Technical Specifications.
B15: =B10 -> -for wall | C15: 1 | D15: =D29 -> 7.6 | E15: =E20 -> 1.25 | F15: 0.15 | G15: =PRODUCT(C15:F15) -> 1.425
B16: Sub-total | G16: =SUM(G15:G15) -> 1.425 | H16: m3 | I16: 4458.52 | J16: =G16*I16 -> 6353.391
B17: -13% VAT for materials | J17: =0.13*G16*(14817.6)/5 -> 548.99208
A19: 3 | B19: Providing and laying of Plain/Reinforced Cement Concrete in Foundation complete as per Drawing and Technical Specifications, PCC Grade M 15
B20: =B15 -> -for wall | C20: 1 | D20: =D29 -> 7.6 | E20: =F29/2 -> 1.25 | F20: 0.05 | G20: =PRODUCT(C20:F20) -> 0.475
B21: Sub-total | G21: =SUM(G20:G20) -> 0.475 | H21: m3 | I21: 10964.46 | J21: =G21*I21 -> 5208.1185
B22: -13% VAT for cement | J22: =0.13*G21*(53818.03)/15 -> 221.55089
B23: -13% VAT for sand | J23: =0.13*G21*(21432.6)/15 -> 88.23087
B24: -13% VAT for aggregate | J24: =0.13*G21*(25719.12+13573.98+4286.52)/15 -> 179.40277
B25: -13% VAT for formworks | J25: =0.13*G21*(6325.7)/15 -> 26.040798
B26: -13% VAT for water | J26: =0.13*G21*(310)/5 -> 3.8285
A28: 4 | B28: Providing and laying Plum concrete ( Boulder mixed concrete) including form work and 110mm dia PN6 HDPE pipe for Weep hole as per Drawing and Specifications, 60% M 15 concrete and 40% boulders/stones, using Mechanical Aids
B29: =B20 -> -for wall | C29: 1 | D29: 7.6 | E29: =((F29/2)+0.45)/2 -> 0.85 | F29: 2.5 | G29: =PRODUCT(C29:F29) -> 16.15
B30: Sub-total | G30: =SUM(G29:G29) -> 16.15 | H30: m3 | I30: 9860.43 | J30: =G30*I30 -> 159245.94
B31: -13% VAT for cement | J31: =0.13*G30*(22152.7)/10 -> 4650.9594
B32: -13% VAT for sand | J32: =0.13*G30*(9525.6)/10 -> 1999.8997
B33: -13% VAT for boulder | J33: =0.13*G30*(11331.936)/10 -> 2379.14
B34: -13% VAT for aggregate | J34: =0.13*G30*(10954.44+5228.496+2286.144)/10 -> 3877.5833
B35: -13% VAT for formwork and 110mm PN6 HDPEpipe | J35: =0.13*G30*(3564.01)/10 -> 748.2639
A37: 5 | B37: g/d k|sf/sf] Sn] / l;N6L df6f]df ;j} lsl;dsf] vGg] sfd
B38: -for foundation | C38: 4 | D38: =Sheet1!B4 -> 1.5 | E38: =Sheet1!C4 -> 1.5 | F38: =Sheet1!D4 -> 1.5 | G38: =PRODUCT(C38:F38) -> 13.5
B39: -for toe wall | C39: 4 | D39: =Sheet1!K4 -> 2.3876867 | E39: 0.23 | F39: 0.5 | G39: =PRODUCT(C39:F39) -> 1.0983359
B40: Sub-total | G40: =SUM(G38:G39) -> 14.598336 | H40: cum | I40: 674.12 | J40: =G40*I40 -> 9841.0302
A42: 6 | B42: ;'Vvf O{6f RofK6f] 5fKg] sfd
B43: =B38 -> -for foundation | C43: =C38 -> 4 | D43: =Sheet1!B4 -> 1.5 | E43: =Sheet1!C4 -> 1.5 | G43: =PRODUCT(C43:F43) -> 9
B44: =B39 -> -for toe wall | C44: =C39 -> 4 | D44: =Sheet1!K4 -> 2.3876867 | E44: =E39 -> 0.23 | G44: =PRODUCT(C44:F44) -> 2.1966717
B45: -for flooring | C45: 1 | D45: =Sheet1!R4 -> 3.5669918 | E45: =D45 -> 3.5669918 | G45: =PRODUCT(C45:F45) -> 12.72343
...

Sheet Sheet1
B2: Foundation size | E2: Footing size | H2: Plinth size | K2: Toe wall | O2: Column size | R2: Tie beam size | U2: Tie beam size
B3: Length | C3: Breadth | D3: Depth from GL | E3: Length in PL area | F3: Breadth in PL area | G3: Depth | H3: Length | I3: Breadth | J3: Depth from GL | K3: Length L1 | L3: Ht. H1 | M3: Length L2 | N3: Ht. H2 | O3: Length/B | P3: Ht. upto plinth | Q3: Ht. above PL upto ceiling | R3: Length | S3: Width | T3: Height | U3: Length | V3: Width | W3: Height
B4: 1.5 | C4: 1.5 | D4: 1.5 | E4: =3.083/3.281 -> 0.93965254 | F4: =3.083/3.281 -> 0.93965254 | G4: 0.35 | H4: =14/3.281 -> 4.2669918 | I4: =14/3.281 -> 4.2669918 | J4: 0.45 | K4: =H4-E4*2 -> 2.3876867 | L4: =0.5-0.055-0.075+J4 -> 0.82 | M4: =E4-1.17/3.281 -> 0.58305395 | N4: =D4-G4+J4 -> 1.6 | O4: 0.35 | P4: =D4-G4+J4-T4 -> 1.37 | Q4: =(10.5-0.42)/3.281 -> 3.0722341 | R4: =H4-O4*2 -> 3.5669918 | S4: 0.23 | T4: 0.23 | U4: =K4-R4*2 -> -4.7462969 | V4: 0.23 | W4: 0.35
