Workbook
Name description_262: [1]Abstract!$B$34
Name description_6: [1]Abstract!$B$172

Sheet WCR
A1: Government of Nepal
A2: Shankharapur Municipality Office
A3: Sankhu, Kathmandu
A4: Work Completion Report
A6: Total Estimated Amount: | C6: =E51 -> #REF! | G6: Total Valuated Amount : | I6: =H51 -> #REF!
A8: Project: | B8: =#REF! -> #REF! | J8: Fiscal Year:079/80
A9: Location:Shankharapur-1 | J9: Date:2079/12/21
A10: S.No. | B10: Description | C10: Estimated | F10: Valuated | I10: Difference | J10: Remarks
C11: Quantity | D11: Rate | E11: Amount (Rs) | F11: Quantity | G11: Rate | H11: Amount(Rs)
A12: 1 | B12: Earthwork in excavaiton | C12: =#REF! -> #REF! | D12: =#REF! -> #REF! | E12: =#REF! -> #REF! | F12: =#REF! -> #REF! | G12: =#REF! -> #REF! | H12: =#REF! -> #REF! | I12: =F12-C12 -> #REF!
A14: 2 | B14: Dismantle the rcc work on the base of water tank | C14: =#REF! -> #REF! | D14: =#REF! -> #REF! | E14: =#REF! -> #REF! | F14: =#REF! -> #REF! | G14: =#REF! -> #REF! | H14: =#REF! -> #REF! | I14: =F14-C14 -> #REF!
A16: 3 | B16: stone soling | C16: =#REF! -> #REF! | D16: =#REF! -> #REF! | E16: =#REF! -> #REF! | F16: =#REF! -> #REF! | G16: =#REF! -> #REF! | H16: =#REF! -> #REF! | I16: =F16-C16 -> #REF!
B17: vat on stone | E17: =#REF! -> #REF! | H17: =#REF! -> #REF!
A19: 4 | B19: Dry Stone Masonry work | C19: =#REF! -> #REF! | D19: =#REF! -> #REF! | E19: =#REF! -> #REF! | F19: =#REF! -> #REF! | G19: =#REF! -> #REF! | H19: =#REF! -> #REF! | I19: =F19-C19 -> #REF!
B20: vat on stone | E20: =#REF! -> #REF! | H20: =#REF! -> #REF!
A22: 5 | B22: Brick Masonry work in 1:6 | C22: =#REF! -> #REF! | D22: =#REF! -> #REF! | E22: =#REF! -> #REF! | F22: =#REF! -> #REF! | G22: =#REF! -> #REF! | H22: =#REF! -> #REF! | I22: =F22-C22 -> #REF!
B23: vat on cement | E23: =#REF! -> #REF! | H23: =#REF! -> #REF!
B24: vat on brick | E24: =#REF! -> #REF! | H24: =#REF! -> #REF!
B25: vat on sand | E25: =#REF! -> #REF! | H25: =#REF! -> #REF!
A27: 6 | B27: RCC works 1:1.5:3 ratio in water collection chamber with all work complete | C27: =#REF! -> #REF! | D27: =#REF! -> #REF! | E27: =#REF! -> #REF! | F27: =#REF! -> #REF! | G27: =#REF! -> #REF! | H27: =#REF! -> #REF! | I27: =F27-C27 -> #REF!
B28: vat on cement | E28: =#REF! -> #REF! | H28: =#REF! -> #REF!
B29: vat on aggregate | E29: =#REF! -> #REF! | H29: =#REF! -> #REF!
B30: vat on sand | E30: =#REF! -> #REF! | H30: =#REF! -> #REF!
A32: 7 | B32: 3mm punning all complete work | C32: =#REF! -> #REF! | D32: =#REF! -> #REF! | E32: =#REF! -> #REF! | F32: =#REF! -> #REF! | G32: =#REF! -> #REF! | H32: =#REF! -> #REF! | I32: =F32-C32 -> #REF!
B33: vat on cement | E33: =#REF! -> #REF! | H33: =#REF! -> #REF!
A35: 8 | B35: plastering work | C35: =#REF! -> #REF! | D35: =#REF! -> #REF! | E35: =#REF! -> #REF! | F35: =#REF! -> #REF! | G35: =#REF! -> #REF! | H35: =#REF! -> #REF! | I35: =F35-C35 -> #REF!
B36: vat on cement | E36: =#REF! -> #REF! | H36: =#REF! -> #REF!
B37: vat on sand | E37: =#REF! -> #REF! | H37: =#REF! -> #REF!
A39: 9 | B39: tap and fittings | C39: =#REF! -> #REF! | D39: =#REF! -> #REF! | E39: =#REF! -> #REF! | F39: =#REF! -> #REF! | G39: =#REF! -> #REF! | H39: =#REF! -> #REF! | I39: =F39-C39 -> #REF!
A41: 10 | B41: Iron frame for barbed wire | C41: =#REF! -> #REF! | D41: =#REF! -> #REF! | E41: =#REF! -> #REF! | F41: =#REF! -> #REF! | G41: =#REF! -> #REF! | H41: =#REF! -> #REF! | I41: =F41-C41 -> #REF!
B42: Vat on iron frame | E42: =#REF! -> #REF! | H42: =#REF! -> #REF!
A44: 11 | B44: Barbed wire | C44: =#REF! -> #REF! | D44: =#REF! -> #REF! | E44: =#REF! -> #REF! | F44: =#REF! -> #REF! | G44: =#REF! -> #REF! | H44: =#REF! -> #REF! | I44: =F44-C44 -> #REF!
B45: vat on barbed wire | E45: =#REF! -> #REF! | H45: =#REF! -> #REF!
A47: 12 | B47: Roof top PVC Water Tank | C47: =#REF! -> #REF! | D47: =#REF! -> #REF! | E47: =#REF! -> #REF! | F47: =#REF! -> #REF! | G47: =#REF! -> #REF! | H47: =#REF! -> #REF! | I47: =F47-C47 -> #REF!
B48: vat on pvc water tank | E48: =#REF! -> #REF! | H48: =#REF! -> #REF!
A50: 12 | B50: Information Board | C50: 1 | D50: 500 | E50: 500 | F50: =#REF! -> #REF! | G50: =#REF! -> #REF! | H50: =#REF! -> #REF! | I50: =F50-C50 -> #REF!
B51: Total | E51: =SUM(E12:E50) -> #REF! | H51: =SUM(H12:H50) -> #REF!

Sheet Sheet1
A1: 152 | B1: ;'Vvf O{6f RofK6f] 5fKg] sfd .
A2: H 15 | B2: b/ ljZn]if0fsf] nflu !) j=dL= lnOPsf]
B3: ;|f]t ;fwg | C3: tx÷lsl;d | D3: kl/df0f | E3: PsfO{ | F3: b/ k|lt PsfO{ | G3: /sd | H3: k|To]s ;|f]t ;fwgsf] hDdf
B4: >lds | C4: s_ l;kfn' | D4: 0.5 | E4: hjfg | F4: 1330 | G4: =FLOOR(D4*F4,0.01) -> 665
C5: v_ HofdL | D5: 1 | E5: hjfg | F5: 1000 | G5: =FLOOR(D5*F5,0.01) -> 1000 | H5: =SUM(G4+G5) -> 1665
B6: lgdf{0f ;fdu|L | C6: O{6f | D6: =420*0 -> 0 | E6: uf]6f | F6: 15.145 | G6: =FLOOR(D6*F6,0.01) -> 0
C7: jfn'jf vf]nfsf] | D7: =0.71*0 -> 0 | E7: 3=dL= | F7: 3389.76 | G7: =FLOOR(D7*F7,0.01) -> 0 | H7: =SUM(G6:G7) -> 0
F8: jf:tljs b//]6 | H8: =SUM(H7,H5) -> 1665
B9: b/ k|lt j=dL=sf] | F9: !%Ü 7]s]bf/ cf]e/x]8 | H9: =FLOOR(H8*0.15,0.01) -> 249.75
B10: =+H10 -> 1914.75 | C10: Ö ?= | D10: =INT(B10/B11*100)/100 -> 191.47 | E10: k}= | F10: hDdf b/ /]6 | H10: =SUM(H8:H9) -> 1914.75
B11: 10

Sheet Size of water tank
A1: Length | B1: Breadth | C1: Height | D1: Slab thickness | E1: Cover for slab | F1: Shear wall thickness | G1: Cover for shear wall | H1: Soiling thickness | I1: PCC | J1: Vertical rebar | K1: Opening | M1: Fillet
K2: Length | L2: Breadth | M2: Length | N2: Height
A3: =26/3.281 -> 7.9244133 | B3: =12.5/3.281 -> 3.8098141 | C3: =6/3.281 -> 1.8287108 | D3: 0.125 | E3: 0.025 | F3: =8/12/3.281 -> 0.20319008 | G3: =1.5/12/3.281 -> 0.038098141 | H3: 0.15 | I3: 0.075 | J3: 8 | K3: =2/3.281 -> 0.60957025 | L3: =2/3.281 -> 0.60957025 | M3: =1/3.281 -> 0.30478513 | N3: =1/3.281 -> 0.30478513
J4: =57*J3/1000 -> 0.456 | M4: =SQRT(('Size of water tank'!M3)^2+('Size of water tank'!N3)^2) -> 0.43103126
F11: =7.5*3.281 -> 24.6075
F12: =3.5*3.281 -> 11.4835

Sheet estimated
A1: Government of Nepal
A2: Shankharapur Municipality
A3: Shankhu, Kathmandu
A4: Detail Estimate Sheet
A5: Project:-k+rkfn] If]qdf l;FrfO 6ØfÍL | J5: F.Y.:-2083/084
A6: Location:- Shankharapur Municipality- 1 | H6: Date: 2082/06/14
A8: S.N. | B8: Description of work | C8: No. | D8: Length | E8: Breadth | F8: Height | G8: Quantity | H8: Unit | I8: Rate | J8: Amount | K8: Remark
A9: A. | B9: kfgL 6\ofÍL dd{t
A10: 1 | B10: g/d k|sf/sf] Sn] / l;N6L df6f]df ;j} lsl;dsf] vGg] sfd
C11: 1 | D11: ='Size of water tank'!A3+0.15 -> 8.0744133 | E11: ='Size of water tank'!B3+0.15 -> 3.9598141 | F11: 0.3 | G11: =PRODUCT(C11:F11) -> 9.5919526
G12: =SUM(G11) -> 9.5919526 | H12: cum | I12: 721 | J12: =G12*I12 -> 6915.7978
A14: 2 | B14: husf] vf8ndf 9'+uf eg]{ / n]en ug]{ sfddf
B15: -for flooring | C15: =C11 -> 1 | D15: =D11 -> 8.0744133 | E15: =E11 -> 3.9598141 | F15: ='Size of water tank'!H3 -> 0.15 | G15: =PRODUCT(C15:F15) -> 4.7959763
G16: =SUM(G15) -> 4.7959763 | H16: sqm | I16: 4805.01 | J16: =G16*I16 -> 23044.714
A18: 3 | B18: hu leQf kvf{ndf l;d]G6 s+lqm6 ug]{ sfd -lk=;L=;L= !M@M$_
B19: =B15 -> -for flooring | C19: =C11 -> 1 | D19: =D11 -> 8.0744133 | E19: =E11 -> 3.9598141 | F19: ='Size of water tank'!I3 -> 0.075 | G19: =PRODUCT(C19:F19) -> 2.3979882
G20: =SUM(G19) -> 2.3979882 | H20: cum | I20: 13944.36 | J20: =G20*I20 -> 33438.41
A22: 4 | B22: cf/=;L=;L= nflu !) ld=ld= kmnfd] 808L sf6\g], df]8\g] #) dL6/ ;Dd
B23: -Along long length | C23: =TRUNC(('Size of water tank'!A3-'Size of water tank'!G3*2)/0.15,0)+1-6 -> 47 | D23: =('Size of water tank'!B3-'Size of water tank'!G3*2)+(('Size of water tank'!C3+'Size of water tank'!D3-'Size of water tank'!E3*2)*2) -> 7.5410393 | F23: =10*10/162 -> 0.61728395 | G23: =PRODUCT(C23:F23) -> 218.78324
C24: =TRUNC(('Size of water tank'!A3-'Size of water tank'!F3*2+'Size of water tank'!G3*2)/0.15,0)+1-6 -> 45 | D24: =('Size of water tank'!B3-'Size of water tank'!F3*2+'Size of water tank'!G3*2)+(('Size of water tank'!C3+'Size of water tank'!D3-'Size of water tank'!E3*2)*2) -> 7.2870517 | F24: =10*10/162 -> 0.61728395 | G24: =PRODUCT(C24:F24) -> 202.4181
B25: -Along short length | C25: =TRUNC(('Size of water tank'!B3-'Size of water tank'!G3*2)/0.15,0)+1-4 -> 21 | D25: =('Size of water tank'!A3-'Size of water tank'!G3*2)+(('Size of water tank'!C3+'Size of water tank'!D3-'Size of water tank'!E3*2)*2) -> 11.655639 | F25: =10*10/162 -> 0.61728395 | G25: =PRODUCT(C25:F25) -> 151.09161
C26: =TRUNC(('Size of water tank'!B3-'Size of water tank'!F3*2+'Size of water tank'!G3*2)/0.15,0)+1-4 -> 20 | D26: =('Size of water tank'!A3-'Size of water tank'!F3*2+'Size of water tank'!G3*2)+(('Size of water tank'!C3+'Size of water tank'!D3-'Size of water tank'!E3*2)*2) -> 11.401651 | F26: =10*10/162 -> 0.61728395 | G26: =PRODUCT(C26:F26) -> 140.76112
B27: -binder | C27: =TRUNC(('Size of water tank'!C3-'Size of water tank'!E3)/0.15,0)+1 -> 13 | D27: =('Size of water tank'!A3-'Size of water tank'!G3*2)*2+('Size of water tank'!B3-'Size of water tank'!G3*2)*2 -> 23.16367 | F27: =8*8/162 -> 0.39506173 | G27: =PRODUCT(C27:F27) -> 118.96403
C28: =TRUNC(('Size of water tank'!C3+'Size of water tank'!E3)/0.15,0)+1 -> 13 | D28: =('Size of water tank'!A3-'Size of water tank'!F3*2+'Size of water tank'!G3*2)*2+('Size of water tank'!B3-'Size of water tank'!F3*2+'Size of water tank'!G3*2)*2 -> 22.147719 | F28: =8*8/162 -> 0.39506173 | G28: =PRODUCT(C28:F28) -> 113.74631
B29: -for fillet | C29: =2*(TRUNC(((('Size of water tank'!A3-'Size of water tank'!F3*2)+('Size of water tank'!A3-'Size of water tank'!F3*2-'Size of water tank'!M3*2))/2)/0.15,0)+1)-6 -> 92 | D29: =(2*57*('Size of water tank'!J3/1000))+SQRT(('Size of water tank'!M3)^2+('Size of water tank'!N3)^2) -> 1.3430313 | F29: =8*8/162 -> 0.39506173 | G29: =PRODUCT(C29:F29) -> 48.813383
C30: =2*(TRUNC(((('Size of water tank'!B3-'Size of water tank'!F3*2)+('Size of water tank'!B3-'Size of water tank'!F3*2-'Size of water tank'!M3*2))/2)/0.15,0)+1)-4 -> 38 | D30: =(2*57*('Size of water tank'!J3/1000))+SQRT(('Size of water tank'!M3)^2+('Size of water tank'!N3)^2) -> 1.3430313 | F30: =8*8/162 -> 0.39506173 | G30: =PRODUCT(C30:F30) -> 20.16205
B31: -binder | C31: =TRUNC(((SQRT(('Size of water tank'!M3)^2+('Size of water tank'!N3)^2))/0.15)+1)-2 -> 1 | D31: =(((('Size of water tank'!A3-'Size of water tank'!F3*2)+('Size of water tank'!A3-'Size of water tank'!F3*2-'Size of water tank'!M3*2))/2)+((('Size of water tank'!B3-'Size of water tank'!F3*2)+('Size of water tank'!B3-'Size of water tank'!F3*2-'Size of water tank'!M3*2))/2))*2 -> 20.623794 | F31: =8*8/162 -> 0.39506173 | G31: =PRODUCT(C31:F31) -> 8.1476715
B32: -for column | C32: 6 | D32: =F38+0.9 -> 2.7287108 | F32: =16*16/162 -> 1.5802469 | G32: =PRODUCT(C32:F32) -> 25.872221
B33: -stirrups | C33: =C27 -> 13 | D33: =(4*0.3+0.05*2) -> 1.3 | F33: =8*8/162 -> 0.39506173 | G33: =PRODUCT(C33:F33) -> 6.6765432
C34: =C33 -> 13 | D34: =(4*0.23+0.05*2) -> 1.02 | F34: =8*8/162 -> 0.39506173 | G34: =PRODUCT(C34:F34) -> 5.2385185
G35: =SUM(G23:G34) -> 1060.6748 | H35: kg | I35: =134160/1000 -> 134.16 | J35: =G35*I35 -> 142300.13
A37: 5 | B37: kmnfd]sf] kfOk / KnfOaf]8{af6 kmdf{ agfpg] sfd
B38: -For shear wall | C38: 1 | D38: =('Size of water tank'!A3+'Size of water tank'!B3)*2 -> 23.468455 | F38: ='Size of water tank'!C3 -> 1.8287108 | G38: =PRODUCT(C38:F38) -> 42.917016
C39: 1 | D39: =(('Size of water tank'!A3-'Size of water tank'!F3*2)+('Size of water tank'!B3-'Size of water tank'!F3*2))*2 -> 21.842934 | F39: ='Size of water tank'!C3-'Size of water tank'!N3 -> 1.5239256 | G39: =PRODUCT(C39:F39) -> 33.287007
B40: -for column | C40: 6 | D40: =14/12/3.281 -> 0.35558265 | E40: =14/12/3.281 -> 0.35558265 | F40: =F38 -> 1.8287108 | G40: =PRODUCT(C40:F40) -> 1.3873224
G41: =SUM(G38:G40) -> 77.591345 | H41: sqm | I41: 954.03 | J41: =G41*I41 -> 74024.471
A43: 6 | B43: d]lzgsf] k|of]u u/L ;'k/ :6«Sr/df l;d]G6 s+lqm6 ug]{ sfd -!M!=%M#_
B44: -floor | C44: 1 | D44: ='Size of water tank'!A3 -> 7.9244133 | E44: ='Size of water tank'!B3 -> 3.8098141 | F44: ='Size of water tank'!D3 -> 0.125 | G44: =PRODUCT(C44:F44) -> 3.7738177
B45: -shear wall | C45: 2 | D45: ='Size of water tank'!A3-(14/12/3.281)*3 -> 6.8576653 | E45: ='Size of water tank'!F3 -> 0.20319008 | F45: ='Size of water tank'!C3 -> 1.8287108 | G45: =PRODUCT(C45:F45) -> 5.0962863
C46: 2 | D46: ='Size of water tank'!B3-'Size of water tank'!F3*2-(14/12/3.281)*2 -> 2.6922686 | E46: ='Size of water tank'!F3 -> 0.20319008 | F46: ='Size of water tank'!C3 -> 1.8287108 | G46: =PRODUCT(C46:F46) -> 2.0007642
...
