Workbook
Name \A: #REF!
Name \A: #REF!
Name \A: #REF!
Name \A: #REF!
Name \A: #REF!
Name \A: #REF!
Name \A: #REF!
Name \A: #REF!
Name \A: #REF!
Name \A: #REF!
Name \b: '[1]Water Demand'!#REF!
Name \b: '[1]Water Demand'!#REF!
Name \b: '[1]Water Demand'!#REF!
Name \b: '[1]Water Demand'!#REF!
Name \b: '[1]Water Demand'!#REF!
Name \b: '[1]Water Demand'!#REF!
Name \b: '[1]Water Demand'!#REF!
Name \b: '[1]Water Demand'!#REF!
Name \b: '[1]Water Demand'!#REF!
Name \b: '[1]Water Demand'!#REF!
Name \berr: '[1]Water Demand'!#REF!
Name \berr: '[1]Water Demand'!#REF!
Name \berr: '[1]Water Demand'!#REF!
Name \berr: '[1]Water Demand'!#REF!
Name \berr: '[1]Water Demand'!#REF!
Name \berr: '[1]Water Demand'!#REF!
Name \berr: '[1]Water Demand'!#REF!
Name \berr: '[1]Water Demand'!#REF!
Name \berr: '[1]Water Demand'!#REF!
Name \berr: '[1]Water Demand'!#REF!
Name \c: '[1]Water Demand'!#REF!
Name \c: '[1]Water Demand'!#REF!
Name \c: '[1]Water Demand'!#REF!
Name \c: '[1]Water Demand'!#REF!
Name \c: '[1]Water Demand'!#REF!
Name \c: '[1]Water Demand'!#REF!
Name \c: '[1]Water Demand'!#REF!
Name \c: '[1]Water Demand'!#REF!
Name \c: '[1]Water Demand'!#REF!
Name \c: '[1]Water Demand'!#REF!
Name \cerr: '[1]Water Demand'!#REF!
Name \cerr: '[1]Water Demand'!#REF!
Name \cerr: '[1]Water Demand'!#REF!
Name \cerr: '[1]Water Demand'!#REF!
Name \cerr: '[1]Water Demand'!#REF!
Name \cerr: '[1]Water Demand'!#REF!
Name \cerr: '[1]Water Demand'!#REF!
Name \cerr: '[1]Water Demand'!#REF!
Name \cerr: '[1]Water Demand'!#REF!
Name \cerr: '[1]Water Demand'!#REF!
Name \e: #REF!
Name \e: #REF!
Name \e: #REF!
Name \e: #REF!
Name \e: #REF!
Name \e: #REF!
Name \e: #REF!
Name \e: #REF!
Name \e: #REF!
Name \e: #REF!

Sheet SUMMARY
A1: Nepal Government
A2: Ministry of Physical Planning and Work
A3: Department of Water Supply and Sewerage
A4: Drinking Water Quality Improvement Project
A6: Summary of Cost
A7: Project: …………………... Water Quality Improvement Project
A8: Q = | B8: 8.0 LPS
A10: S.N. | B10: Description of Works | C10: No. | D10: Quantity | F10: Total Amount
F11: (NRs.)
A12: 1 | B12: Land Acquisition | C12: 1 | D12: Ropani | E12: 100000 | F12: =E12*C12 -> 100000
A13: 2 | B13: Site Development | C13: 1 | D13: job | E13: =COST_ALL!$G$213 -> 493305.6 | F13: =E13*C13 -> 493305.6
A14: 3 | B14: Intake Maintenance | C14: 1 | D14: No. | E14: …………. | F14: …………….
A15: 4 | B15: Plain Sedimentation Tank | C15: 1 | D15: No. | E15: =COST_ALL!G45 -> 2384849.5 | F15: =E15*C15 -> 2384849.5
A16: 5 | B16: Horizontal Roughing Filter | C16: 1 | D16: No. | E16: =COST_ALL!G97 -> 3462456.4 | F16: =E16*C16 -> 3462456.4
A17: 6 | B17: Slow Sand Filter | C17: 1 | D17: No. | E17: =COST_ALL!G160 -> 10288656 | F17: =E17*C17 -> 10288656
A18: 7 | B18: Disinfection Chamber | C18: 1 | D18: No. | E18: =COST_ALL!G179 -> 24637.46 | F18: =E18*C18 -> 24637.46
A19: 8 | B19: Sand Wash Platform | C19: 1 | D19: No. | E19: =COST_ALL!G196 -> 80287.86 | F19: =E19*C19 -> 80287.86
A20: 9 | B20: Pipes and Fittings Procurement | C20: 1 | D20: job | E20: =COST_ALL!G426 -> 3775975.6 | F20: =E20*C20 -> 3775975.6
A21: 10 | B21: Pipe Line Relaying and Jointing | C21: 1 | D21: job | E21: 27334 | F21: =E21*C21 -> 27334
A22: 8 | B22: Chlorine Dosing Unit with accessories and Fitting | C22: 1 | D22: No. | E22: 70000 | F22: =E22*C22 -> 70000
A23: 11 | B23: Compound Wall with Barbed Wire Fencing
B24: and Gate | C24: 1 | D24: job | E24: =COST_ALL!G233 -> 3067323 | F24: =E24*C24 -> 3067323
A25: 13 | B25: Chaukidar Quarters | C25: 1 | D25: No. | E25: =COST_ALL!G297 -> 1251857.9 | F25: =E25*C25 -> 1251857.9
A26: 12 | B26: Reservoir Maintenance | C26: 1 | D26: No. | E26: 500000 | F26: …………….
A27: 13 | B27: Protection Works | C27: 1 | D27: job | E27: =COST_ALL!G357 -> 4519468.6 | F27: =E27*C27 -> 4519468.6
A28: 14 | B28: Training and Orientation / Water Quality Campaigns | C28: 1 | D28: package | E28: 94350 | F28: =E28*C28 -> 94350
B29: Sub Total | F29: =ROUND(SUM(F12:F28),2) -> 29640502
B30: 2.5 % Contingencies | F30: =ROUND((F29*0.025),2) -> 741012.55
B31: Grand Total | F31: =ROUND(SUM(F29:F30),2) -> 30381515

Sheet Salient feature
A1: Salient Features ( Schemewise ) of Project
B3: District: Kathmandu
A4: 1 | B4: Name of Project | C4: ='Entry for Rates'!F4 -> 0
A5: 2 | B5: Name of District | D5: Kathmandu | E5: Kathmandu
A6: 3 | B6: Name of Municipality | D6: Shankharapur | E6: Shankharapur
A7: 4 | B7: Wards Covered | D7: 3 | E7: 4
A8: 5 | B8: Number of Schemes | D8: 1 | E8: 1
A9: Sn | B9: Parameters | C9: Unit | D9: ='sum cost_All'!D3:F3 -> Fedi (Sc-1) | E9: Damai Kholsi (Sc-2)
A10: A. | B10: General Parameter
A11: 1 | B11: Households(Survey year:2017) | C11: No. | D11: 133 | E11: 134
A12: 2 | B12: Population(Survey year:2017) | C12: No. | D12: 857 | E12: 763
A13: 3 | B13: Households(Base year:2019) | C13: No. | D13: =D11*(1+1.31/100)^2 -> 136.50742 | E13: =E11*(1+1.31/100)^2 -> 137.5338
A14: 4 | B14: Population(Base year:2019) | C14: No. | D14: 898 | E14: 788
A15: 5 | B15: Households(Design year:2039) | C15: No. | D15: =D11*(1+1.31/100)^22 -> 177.09348 | E15: =E11*(1+1.31/100)^22 -> 178.42501
A16: 6 | B16: Population(Design year:2039) | C16: No. | D16: 1155 | E16: 1023
A17: 1 | B17: Design Period | C17: Yrs. | D17: 20 | E17: 20
A18: 2 | B18: Annual growth rate | C18: % | D18: 3.5 | E18: 3.5
A19: B. | B19: Source Information
A20: 1 | B20: Source Name | D20: Fedi | E20: Damai Kholsi
A21: =A20+1 -> 2 | B21: Source Type & Number | C21: Type/No. | D21: Spring | E21: Spring
A22: =A21+1 -> 3 | B22: Tapped Discharge source - | C22: Lps | D22: 20 | E22: 12
A23: =A22+1 -> 4 | B23: Approximate Distance from Project Site | C23: km | D23: 1 | E23: 1.02
A24: 4 | B24: Water Quality of Source | D24: Fair | E24: Fair
A25: C. | B25: Water provision & Demand
A26: 1 | B26: Provision for Domestic use | C26: lpcd | D26: 69300 | E26: 61380
A27: 3 | B27: Provision for Institutional use | C27: lpcd | D27: 4320 | E27: 2000
A28: 4 | B28: Provision for Live Stock | C28: Yes/No | D28: No | E28: No
A29: 5 | B29: Total Water Demand (Design Year) | C29: Lpd | D29: =D26+D27 -> 73620 | E29: =E26+E27 -> 63380
A30: C. | B30: Project Components
A31: 1 | B31: Actual Length of Transmission Main | C31: km | D31: ='pip-line'!F18/1000 -> 0.11 | E31: ='pip-line'!F19/1000 -> 0
A32: 2 | B32: Actual Length of Distribution Pipe Line | C32: km | D32: ='pip-line'!F42/1000 -> 0 | E32: ='pip-line'!F41/1000 -> 2.175
A33: 3 | B33: Institutional connections | C33: No. | D33: 2 | E33: 1
A34: 4 | B34: Number of Private Connection Provided | C34: No. | D34: =D33+D13 -> 138.50742 | E34: =E33+E13 -> 138.5338
A35: 5 | B35: Reservoir Number/ Capacity | C35: m³/no | D35: 20,4 | E35: 20,2
A36: 6 | B36: Total Number of CC, DC, IC, VC & AVC | C36: No. | D36: =SUM('sum cost_All'!E34:E36) -> 12 | E36: =SUM('sum cost_All'!H34:H36) -> 6
A37: 7 | B37: Crossing | C37: No. | D37: No | E37: No
A38: 8 | B38: Institutional latrine | C38: No. | D38: No | E38: No
A39: E. | B39: Project Cost Data
A40: 1 | B40: Total Estimated Cost(without physical & price adjustment contingencies | C40: NRs. | D40: ='sum cost_All'!F54 -> 39436766 | E40: ='sum cost_All'!I54 -> 20106828
A41: =A40+1 -> 2 | B41: Average Per Capita Cost at Base Year | C41: NRs. | D41: =D40/D14 -> 43916.221 | E41: =E40/E14 -> 25516.279
...

Sheet sum cost_All
A1: Summary of Cost ( With Schemewise Cost )
B2: Name of Scheme: Sankhu Drinking Water Supply Project
A3: Sn | B3: Items | C3: Unit | D3: Fedi (Sc-1) | G3: Damai Kholsi (Sc-2) | J3: Total
D4: Unit Rate | E4: Qty | F4: Amount | G4: Unit Rate | H4: Qty | I4: Amount | J4: Qty | K4: Amount
A5: A | B5: Community Education Awareness
B6: Program
A7: 1 | B7: Pre-construction Training | C7: no | J7: 1 | K7: 25000
A8: 2 | B8: Appraisal & Comm. Preparation | C8: no | J8: 1 | K8: 14000
A9: 3 | B9: VMWs Training | C9: no | J9: 1 | K9: 15000
A10: 4 | B10: Pre-handover Training | C10: no | J10: 1 | K10: 15000
A11: 5 | B11: Motivators/Volunteers Training | C11: no | J11: 1 | K11: 10000
B12: Total A | K12: =SUM(K7:K11) -> 79000
A13: B | B13: Water Supply & Sanitation
A14: B1 | B14: Civil Works
A15: 1 | B15: Detailed Survey & Design Work | C15: % | D15: 150000 | E15: 0 | F15: =D15*E15 -> 0 | G15: ='[59]sum cost_All'!D16 -> 150000 | H15: 0 | I15: =H15*G15 -> 0 | J15: =E15+H15 -> 0 | K15: =F15+I15 -> 0
A16: =A15+1 -> 2 | B16: Stream intake(without VC) | C16: no | D16: =Cost_In_1!F30 -> 1665211.5 | E16: =FittingsSummary!P6 -> 1 | F16: =E16*D16 -> 1665211.5 | G16: =int!J64 -> 264382.25 | H16: 1 | I16: =H16*G16 -> 264382.25 | J16: =E16+H16 -> 2 | K16: =F16+I16 -> 1929593.8
A17: 3 | B17: Collection Chamber | C17: no | D17: ='CC-DC'!J52 -> 237257.56 | E17: 1 | F17: =D17*E17 -> 237257.56 | G17: ='[59]sum cost_All'!D18 -> 155943.49 | H17: 1 | I17: =H17*G17 -> 155943.49 | J17: =E17+H17 -> 2 | K17: =F17+I17 -> 393201.05
A18: 4 | B18: Plain Sedimentation Tank | C18: no | F18: Existing | G18: =COST_ALL!G45 -> 2384849.5 | H18: 1 | I18: =H18*G18 -> 2384849.5 | J18: =E18+H18 -> 1 | K18: =I18 -> 2384849.5
A19: 5 | B19: Horizontal Roughing Filter | C19: no | F19: Existing | G19: =COST_ALL!G97 -> 3462456.4 | H19: 1 | I19: =H19*G19 -> 3462456.4 | J19: =E19+H19 -> 1 | K19: =I19 -> 3462456.4
A20: 6 | B20: Slow Sand Filter | C20: no | F20: Existing | G20: =COST_ALL!G160 -> 10288656 | H20: 1 | I20: =H20*G20 -> 10288656 | J20: =E20+H20 -> 1 | K20: =I20 -> 10288656
A21: 7 | B21: Disinfection Chamber | C21: no | F21: Existing | G21: =COST_ALL!G179 -> 24637.46 | H21: 1 | I21: =H21*G21 -> 24637.46 | J21: =E21+H21 -> 1 | K21: =I21 -> 24637.46
A22: 8 | B22: Sand Wash Platform | C22: no | G22: =COST_ALL!G196 -> 80287.86 | H22: 1 | I22: =H22*G22 -> 80287.86 | J22: =E22+H22 -> 1 | K22: =F22+I22 -> 80287.86
A23: 9 | B23: 400 cum Reservoir at Fedi and Damai Kholsi | C23: no | D23: ='Cost RVT-400'!F42 -> 7691591.2 | E23: 1 | F23: =D23*E23 -> 7691591.2 | G23: ='Cost RVT-400'!F42 -> 7691591.2 | H23: 1 | I23: =H23*G23 -> 7691591.2 | K23: =F23+I23 -> 15383182
A24: 9 | B24: Pipes and Fittings Procurement | C24: no | J24: 1 | K24: =COST_ALL!G426 -> 3775975.6
A25: 10 | B25: Pipe Line Relaying and Jointing | C25: no | G25: =COST_ALL!G340 -> 174399.24 | H25: 1 | I25: =H25*G25 -> 174399.24 | J25: =E25+H25 -> 1 | K25: =F25+I25 -> 174399.24
A26: 12 | B26: Chlorine Dosing Unit with accessories and Fitting | C26: no
A27: 13 | B27: Compound Wall with Barbed Wire Fencing and Gate | C27: no | G27: =COST_ALL!G233 -> 3067323 | H27: 1 | I27: =H27*G27 -> 3067323 | J27: =E27+H27 -> 1 | K27: =F27+I27 -> 3067323
A28: 14 | B28: Retaining wall | C28: no | D28: =COST_ALL!$G$310 -> 26921.87 | E28: 100 | F28: =D28*E28 -> 2692187 | G28: =COST_ALL!$G$310 -> 26921.87 | H28: 50 | I28: =G28*H28 -> 1346093.5 | J28: =E28+H28 -> 150 | K28: =F28+I28 -> 4038280.5
A29: 15 | B29: PCC pitching in river | C29: m | E29: 50 | F29: =Cost_In_1!F49 -> 231671.29 | K29: =F29+I29 -> 231671.29
A30: 15 | B30: Chaukidar Quarters | C30: no | D30: =COST_ALL!G297 -> 1251857.9 | E30: 1 | F30: =D30*E30 -> 1251857.9 | G30: =COST_ALL!G297 -> 1251857.9 | H30: 1 | I30: =G30*H30 -> 1251857.9 | K30: =F30+I30 -> 2503715.8
A31: 16 | B31: WTP Maintenance including plaster in RVT | C31: no | D31: 500000 | E31: 1 | F31: =D31*E31 -> 500000 | J31: =E31+H31 -> 1 | K31: =F31+I31 -> 500000
A32: 17 | B32: Protection Works | C32: no | G32: =COST_ALL!G354+COST_ALL!G355+COST_ALL!G356 -> 481188.08 | H32: 1 | I32: =G32*H32 -> 481188.08 | J32: =E32+H32 -> 1 | K32: =F32+I32 -> 481188.08
A33: =A32+1 -> 18 | B33: Private Connection (including institution) | C33: no | D33: =Private_Con!J25 -> 13011.509 | E33: 0 | F33: =D33*E33 -> 0 | G33: ='[59]sum cost_All'!D24 -> 9723.79 | H33: ='[59]sum cost_All'!E24 -> 139 | I33: =G33*H33 -> 1351606.8 | J33: =E33+H33 -> 139 | K33: =F33+I33 -> 1351606.8
A34: 18 | B34: Distribution Chamber (Two chamber) | C34: no | D34: ='CC-DC'!J103 -> 115359.08 | E34: =FittingsSummary!J6 -> 1 | F34: =D34*E34 -> 115359.08 | G34: ='[59]sum cost_All'!D25 -> 79374.31 | H34: 1 | I34: =G34*H34 -> 79374.31 | J34: =E34+H34 -> 2 | K34: =F34+I34 -> 194733.39
A35: 19 | B35: Air Valve Chamber at Junction | C35: no | D35: ='vc-bpt'!J24 -> 19814.482 | E35: 4 | F35: =D35*E35 -> 79257.928 | G35: ='[59]sum cost_All'!D26 -> 12956.91 | H35: 2 | I35: =G35*H35 -> 25913.82 | J35: =E35+H35 -> 6 | K35: =F35+I35 -> 105171.75
A36: 20 | B36: Washout Valve Chamber | C36: no | D36: ='vc-bpt'!J62 -> 43416.613 | E36: 7 | F36: =D36*E36 -> 303916.29 | G36: ='[59]sum cost_All'!D27 -> 28436.44 | H36: 3 | I36: =G36*H36 -> 85309.32 | J36: =E36+H36 -> 10 | K36: =F36+I36 -> 389225.61
A37: 21 | B37: Sectional Valve Chamber at Junction | C37: no | D37: ='vc-bpt'!J62 -> 43416.613 | E37: =FittingsSummary!S6 -> 6 | F37: =D37*E37 -> 260499.68 | G37: ='[59]sum cost_All'!D28 -> 28436.44 | H37: 1 | I37: =G37*H37 -> 28436.44 | J37: =E37+H37 -> 7 | K37: =F37+I37 -> 288936.12
A38: 22 | B38: BPC/IC | C38: no | D38: ='vc-bpt'!J114 -> 60794.113 | E38: 1 | F38: =D38*E38 -> 60794.113 | G38: ='[59]sum cost_All'!D29 -> 43505.51 | H38: 1 | I38: =G38*H38 -> 43505.51 | J38: =E38+H38 -> 2 | K38: =F38+I38 -> 104299.62
A39: 23 | B39: Roof Truss in existing | C39: no | D39: =Abstract_TRUSS!$F$15 -> 2819891.3 | E39: 1 | F39: =D39*E39 -> 2819891.3 | G39: =Abstract_TRUSS!$F$15 -> 2819891.3 | H39: 1 | I39: =G39*H39 -> 2819891.3 | J39: =E39+H39 -> 2 | K39: =F39+I39 -> 5639782.7
A40: 24 | B40: Sump Well System | D40: ='Sump well'!$I$55 -> 2095279.7 | E40: 1 | F40: =D40*E40 -> 2095279.7 | J40: =E40+H40 -> 1 | K40: =F40+I40 -> 2095279.7
...

Sheet COST_ALL
A1: Abstract of Cost
A3: Component: Plain Sedimentation Tank
A5: S.N. | B5: Description of Works | C5: No. | D5: Quantity | E5: Unit | F5: Unit Rate | G5: Total Amount
A6: 1 | B6: Site Clearence | C6: 1 | D6: =Qnty_ALL!G6 -> 84 | E6: m2 | F6: =Rates!F7 -> 149.5 | G6: =ROUND((C6*D6*F6),2) -> 12558
A7: 2 | B7: Earth Work in Excavation in
B8: Foundation in Boulder Mixed Soil | C8: 1 | D8: =Qnty_ALL!G13 -> 142.92 | E8: m 3 | F8: =Rates!F10 -> 1883.36 | G8: =ROUND((C8*D8*F8),2) -> 269169.81
A9: 3 | B9: Earth Filling in Foundation | C9: 1 | D9: =Qnty_ALL!G25 -> 30.13 | E9: m 3 | F9: =Rates!F16 -> 710.7 | G9: =ROUND((C9*D9*F9),2) -> 21413.39
A10: 4 | B10: Stone Soling with sand packing on
B11: Base of Foundation, | C11: 1 | D11: =Qnty_ALL!G30 -> 15.02 | E11: m 3 | F11: =Rates!F20 -> 11802.3 | G11: =ROUND((C11*D11*F11),2) -> 177270.55
A12: 5 | B12: Laying of P.C.C. 1:3:6 on Base of
B13: Foundation | C13: 1 | D13: =Qnty_ALL!G35 -> 7.8 | E13: m 3 | F13: =Rates!F31 -> 14810.58 | G13: =ROUND((C13*D13*F13),2) -> 115522.52
A14: 6 | B14: Laying of One Layer Tarfelt Over
B15: Lean Concrete | C15: 1 | D15: =Qnty_ALL!G38 -> 72.04 | E15: m 2 | F15: =Analysis!$R$192 -> 912.3 | G15: =ROUND((C15*D15*F15),2) -> 65722.09
A16: 7 | B16: P.C.C (1: 1.5:3) Works for R.C.C | C16: 1 | D16: =Qnty_ALL!G62 -> 27.78 | E16: m 3 | F16: =Rates!F33 -> 17163.13 | G16: =ROUND((C16*D16*F16),2) -> 476791.75
A17: 8 | B17: Centring and Shuttering Works for
B18: P.C.C. and R.C.C Works | C18: 1 | D18: =Qnty_ALL!G83 -> 191.39 | E18: m 2 | F18: =Rates!F40 -> 1322.68 | G18: =ROUND((C18*D18*F18),2) -> 253147.73
A19: 9 | B19: Reiforcement Works with Deformed
B20: bars Bars Including supplying,
B21: Cutting, Bending and Placing in
B22: Position | C22: 1 | D22: =Qnty_ALL!G131 -> 5003.04 | E22: kg | F22: =Rates!F39 -> 125.35 | G22: =ROUND((C22*D22*F22),2) -> 627131.06
A23: 10 | B23: Brick Masonry Work in 1:6
B24: Cement Sand mortar | C24: 1 | D24: =Qnty_ALL!G138 -> 2.62 | E24: m 2 | F24: =Rates!F28 -> 19440.44 | G24: =ROUND((C24*D24*F24),2) -> 50933.95
A25: 11 | B25: 12.5 mm Thick Cement Sand Plaster
B26: in 1:3 Mortar with 2% Water Proof
B27: Compound | C27: 1 | D27: =Qnty_ALL!G174 -> 171.55 | E27: m 2 | F27: =Rates!F65 -> 497.69 | G27: =ROUND((C27*D27*F27),2) -> 85378.72
A28: 12 | B28: 20 mm Thick Cement Sand Plaster in
B29: 1:4 Mortar in Base Slab | C29: 1 | D29: =Qnty_ALL!G178 -> 96 | E29: m 2 | F29: =Rates!F62 -> 637.57 | G29: =ROUND((C29*D29*F29),2) -> 61206.72
A30: 13 | B30: 3 mm Thick Punning in 1: 1 Cement
B31: Sand Mortar | C31: 1 | D31: =Qnty_ALL!G184 -> 7.8 | E31: m 2 | F31: =Rates!F67 -> 346.26 | G31: =ROUND((C31*D31*F31),2) -> 2700.83
A32: 14 | B32: Two Coat of Enamel Paint of
B33: Appropriate Colour on Exposed
B34: Surface of Tank | C34: 1 | D34: =Qnty_ALL!G187 -> 68.89 | E34: m 2 | F34: =Rates!F70 -> 400.29 | G34: =ROUND((C34*D34*F34),2) -> 27575.98
A35: 15 | B35: Installation of 4 inch dia. Pipe
B36: Pieces and Fittings for Inlet, Outlet and
B37: W/O Complete as per Drawing and
B38: Specification | D38: lump sum | G38: 2000
A39: 16 | B39: Standard Manhole Cover (60cm dia)
B40: including M.S. Angle of 1.5" in
B41: Size including Fixing all Complete as
B42: per Drawing and Specification | C42: 1 | D42: =Qnty_ALL!G194 -> 2 | E42: No. | F42: 6500 | G42: =ROUND((C42*D42*F42),2) -> 13000
...

Sheet Cost RVT-400
A1: COST ESTIMATE OF CIRCULAR RCC RESERVOIR 400 Cu m
A3: Type of Building :- Circular RCC Reservoir 400 cu m | G3: Civil Works
A4: S.No. | B4: Description | C4: Unit | D4: Quantity | E4: Rate | F4: Amount | G4: Remarks
A6: 1 | B6: Site Clearance | C6: m2 | D6: =[60]QTY.Reservoir_400m3!G7 -> 153.93804 | E6: =Rates!F7 -> 149.5 | F6: =D6*E6 -> 23013.737
F7: =D7*E7 -> 0
A8: 2 | B8: Earthwork in excavation in foundation | C8: m3 | D8: =[60]QTY.Reservoir_400m3!G9 -> 207.81635 | E8: =Rates!F10 -> 1883.36 | F8: =D8*E8 -> 391393.01
F9: =D9*E9 -> 0
A10: 3 | B10: Stone soling | C10: m3 | D10: =[60]QTY.Reservoir_400m3!G11 -> 30.349356 | E10: =Rates!F19 -> 5523.35 | F10: =D10*E10 -> 167630.11
F11: =D11*E11 -> 0 | I11: 1810.191 | J11: 1.578 | K11: =I11*J11 -> 2856.4814
A12: 4 | B12: Plain Cement Concrete P.C.C. (M10) in 1:3:6 | C12: m3 | D12: =[60]QTY.Reservoir_400m3!G14 -> 22.762017 | E12: =Rates!F31 -> 14810.58 | F12: =D12*E12 -> 337118.67 | I12: 2278.72 | J12: 0.888 | K12: =I12*J12 -> 2023.5034
F13: =D13*E13 -> 0 | I13: 3731.636 | J13: 0.62 | K13: =I13*J13 -> 2313.6143
A14: 5 | B14: Cement Concrete work for R.C.C (1:1.5:3) (M20) | C14: m3 | D14: =[60]QTY.Reservoir_400m3!G25 -> 202.75931 | E14: =Rates!F33 -> 17163.13 | F14: =D14*E14 -> 3479984.3 | I14: 2218.933 | J14: 0.395 | K14: =I14*J14 -> 876.47854
F15: =D15*E15 -> 0 | K15: =SUM(K11:K14) -> 8070.0776
A16: 6 | B16: Reinforcement Bar for RCC | C16: Kg | D16: =[60]QTY.Reservoir_400m3!G26 -> 12562 | E16: =Rates!F39 -> 125.35 | F16: =D16*E16 -> 1574646.7
F17: =D17*E17 -> 0 | K17: =0.1*K15 -> 807.00776
A18: 7 | B18: Erecting, centering and shuttering of formwork for RCC | C18: m2 | D18: =[60]QTY.Reservoir_400m3!G41 -> 524.22406 | E18: =Rates!F40 -> 1322.68 | F18: =D18*E18 -> 693380.68 | K18: =K15+K17 -> 8877.0854
F19: =D19*E19 -> 0
A20: 8 | B20: 12.5 mm thick outside cement plaster in 1:4 C/M | C20: m2 | D20: =[60]QTY.Reservoir_400m3!G51 -> 320.40604 | E20: =Rates!F60 -> 503.61 | F20: =D20*E20 -> 161359.68
F21: =D21*E21 -> 0
A22: 9 | B22: 20 mm thick cement plaster inside tank 1:3 C/M | C22: m2 | D22: =[60]QTY.Reservoir_400m3!G55 -> 270.39688 | E22: =Rates!F61 -> 649.91 | F22: =D22*E22 -> 175733.64 | I22: 3179.6555 | J22: -0.084 | K22: =I22*J22 -> -267.09106
F23: =D23*E23 -> 0 | I23: 3447.5697 | J23: -0.4657 | K23: =I23*J23 -> -1605.5332
A24: 10 | B24: 12.5 mm thick Cement Sand plaster in 1:4 C/M in Ceiling | C24: m2 | D24: =[60]QTY.Reservoir_400m3!G58 -> 111.5944 | E24: =Rates!F62 -> 637.57 | F24: =D24*E24 -> 71149.24 | I24: 3715.4839 | J24: -0.8474 | K24: =I24*J24 -> -3148.5011
F25: =D25*E25 -> 0 | I25: 3983.3981 | J25: -1.2291 | K25: =I25*J25 -> -4895.9946
A26: 11-a | B26: Providing Crystalline Water Proof Treatment | C26: m2 | D26: =[60]QTY.Reservoir_400m3!G59 -> 381.99128 | E26: 893.56089 | F26: =D26*E26 -> 341332.47 | K26: =SUM(K22:K25) -> -9917.1199
F27: =D27*E27 -> 0
A28: 11-b | B28: 3 mm thick Cement Punning | C28: m2 | D28: =[60]QTY.Reservoir_400m3!G59 -> 381.99128 | E28: =Rates!F67 -> 346.26 | F28: =D28*E28 -> 132268.3 | I28: 3879.2092 | J28: -1.0806611 | K28: =I28*J28 -> -4192.1106
F29: =D29*E29 -> 0 | I29: 3983.3981 | J29: -1.2291 | K29: =I29*J29 -> -4895.9946
A30: 12 | B30: Earthwork in backfilling | C30: m3 | D30: =[60]QTY.Reservoir_400m3!G64 -> 11.353716 | E30: =Rates!F16 -> 710.7 | F30: =D30*E30 -> 8069.0859 | I30: 4087.587 | J30: -1.3775389 | K30: =I30*J30 -> -5630.81
F31: =D31*E31 -> 0 | I31: 4191.7758 | J31: -1.5259778 | K31: =I31*J31 -> -6396.5567
A32: 13 | B32: 25 mm thick Plain G.l. Sheet of 16 SWG as a water-stop supplying and fixing | C32: m | D32: =[60]QTY.Reservoir_400m3!G65 -> 39.269908 | E32: =Rates!F49 -> 1070.18 | F32: =D32*E32 -> 42025.87 | I32: 4295.9647 | J32: -1.6744167 | K32: =SUM(K28:K31) -> -21115.472
F33: =D33*E33 -> 0 | I33: 4400.1535 | J33: -1.8228556
A34: 14 | B34: 32mm día. Gl pipe railings and staircase | C34: m | D34: =[60]QTY.Reservoir_400m3!G66 -> 48 | E34: 755.97406 | F34: =D34*E34 -> 36286.755 | I34: 4504.3424 | J34: -1.9712944 | K34: =0.1*K32 -> -2111.5472
F35: =D35*E35 -> 0
A36: 15 | B36: 2 coat enamel paint in railing & inspection ladders on top of primer | C36: m2 | D36: =[60]QTY.Reservoir_400m3!G67 -> 48 | E36: =Rates!F70 -> 400.29 | F36: =D36*E36 -> 19213.92
A37: 16 | B37: Ventilations of Wooden Frame With Chicken Wire Mesh & Mosquito Mesh | C37: Set | D37: 4 | E37: 8000 | F37: =D37*E37 -> 32000
A38: 16 | B38: Ventilations of Wooden Frame With Chicken Wire Mesh & Mosquito Mesh | C38: Set | D38: =[60]QTY.Reservoir_400m3!G68 -> 4 | E38: 6.45 | F38: =D38*E38 -> 25.8
F39: =D39*E39 -> 0
A40: 17 | B40: Manhole Cover | C40: Set | D40: =[60]QTY.Reservoir_400m3!G69 -> 2 | E40: =Rates!$F$93 -> 2479.6125 | F40: =D40*E40 -> 4959.225
F41: =D41*E41 -> 0
B42: Total | F42: =SUM(F6:F41) -> 7691591.2 | I42: 5040469.3
...

Sheet Sump well
A1: QUANTITY ESTIMATES
A2: SUMP WELL FOR PUMPS IN GROUND RESERVOIR
A3: S.No. | B3: Description of Works | C3: No. | D3: Length (m) | E3: Breadth (m) | F3: Height (m) | G3: Quantity | H3: Rate | I3: Amount
A4: a | B4: E/W in Excavation | C4: 1 | D4: 6.1 | E4: 4.9 | F4: 4.75 | G4: 141.98 | H4: =Rates!F10 -> 1883.36 | I4: =H4*G4 -> 267399.45
A6: b | B6: Back Filling | C6: 1 | D6: 35% of Total Earth Work | G6: 49.69 | H6: =Rates!F16 -> 710.7 | I6: =H6*G6 -> 35314.683
A8: c | B8: Stone Soling | C8: 1 | D8: 4.1 | E8: 2.9 | F8: 0.15 | G8: 1.78 | H8: =Rates!F19 -> 5523.35 | I8: =H8*G8 -> 9831.563
A10: d | B10: M10 Cement Concrete Work for PCC | C10: 1 | D10: 4.1 | E10: 2.9 | F10: 0.1 | G10: 1.19 | H10: =Rates!F31 -> 14810.58 | I10: =H10*G10 -> 17624.59
A12: e | B12: M20 Cement Concrete Work for PCC
B13: Bottom Slab | C13: 1 | D13: 4.1 | E13: 2.9 | F13: 0.4 | G13: 4.76
B14: Long Wall | C14: 2 | D14: 3.4 | E14: 0.35 | F14: 5.1 | G14: 12.14
B15: Short Wall | C15: 2 | D15: 1.5 | E15: 0.35 | F15: 5.1 | G15: 5.36
B16: Roof Slab | C16: 1 | D16: 3.4 | E16: 2.2 | F16: 0.1 | G16: 0.75
F17: Total | G17: 23.01 | H17: =Rates!F33 -> 17163.13 | I17: =H17*G17 -> 394923.62
A19: f | B19: Formwork
B20: Foundation | C20: 1 | D20: 14 | F20: 0.5 | G20: 7
B21: Outer Side of Wall | C21: 1 | D21: 11.2 | F21: 5.2 | G21: 58.24
B22: Inner Side of Wall | C22: 1 | D22: 8.4 | F22: 5.1 | G22: 42.84
B23: Bottom Face of Slab | C23: 1 | D23: 2.7 | F23: 1.5 | G23: 4.05
F24: Total | G24: 112.13 | H24: =Rates!F40 -> 1322.68 | I24: =H24*G24 -> 148312.11
A26: g | B26: Reinforcement
B27: 12 Dia. Bar in Base Slab in Longer Dir. | C27: 38 | D27: 5.3 | E27: Unit Wt. | F27: 0.899 | G27: 181.06
B28: 12 Dia. Bar in Base Slab in Short Dir. | C28: 52 | D28: 4.1 | E28: Unit Wt. | F28: 0.899 | G28: 191.67
B29: 16 Dia. Vertical Wall (Long) | C29: 116 | D29: 6.78 | E29: Unit Wt. | F29: 1.598 | G29: 1256.8
B30: 16 Dia. Vertical Wall (Short) | C30: 44 | D30: 6.78 | E30: Unit Wt. | F30: 1.598 | G30: 476.72
B31: 12 Dia. Horizontal Bar | C31: 31 | D31: 22.4 | E31: Unit Wt. | F31: 0.899 | G31: 624.27
B32: 17 Dia. Bar in Base Slab in Longer Dir. | C32: 20 | D32: 3.7 | E32: Unit Wt. | F32: 0.4 | G32: 29.6
B33: 8 Dia. Main Bar in Roof Slab | C33: 14 | D33: 2.5 | E33: Unit Wt. | F33: 0.4 | G33: 14
B34: 8 Dia. Mainor Bar in Roof Slab | C34: 34 | D34: 1.9 | E34: Unit Wt. | F34: 0.4 | G34: 25.84
B35: 8 Extra Bar in Roof Slab | C35: 70 | D35: 1.7 | E35: Unit Wt. | F35: 0.899 | G35: 106.98
B36: 21 Dia. Chair Bar | C36: 0.15 | G36: 436.04
B37: Extra for Lapping, Chiar, etc. | F37: Total | G37: 3343 | H37: =Rates!F39 -> 125.35 | I37: =H37*G37 -> 419045.05
A39: h | B39: Plaster (1:4) 12.5 and Punning
B40: Wall of Tank | D40: Same as Inner form Work | G40: 42.84
B41: Base of Tank | C41: 1 | D41: 2.7 | E41: 1.5 | G41: 4.05
F42: Total | G42: 46.89 | H42: =Rates!F67 -> 346.26 | I42: =H42*G42 -> 16236.131
A44: i | B44: Plaster (1:4) 12.5 in Ceiling | C44: 1 | D44: 2.7 | E44: 1.5 | G44: 4.05 | H44: =Rates!F60 -> 503.61 | I44: =H44*G44 -> 2039.6205
A46: j | B46: Providing Crystalline Cater Proof Treatment | G46: 48.89 | H46: 5000 | I46: =H46*G46 -> 244450
A48: k | B48: Mild Steel Iron Step | C48: 54 | G48: 54 | H48: 225 | I48: =H48*G48 -> 12150
A50: l | B50: 600 X 600 Manhole Cover (Cash Iron) | C50: 3 | G50: 3 | H50: =Rates!$F$93 -> 2479.6125 | I50: =H50*G50 -> 7438.8375
A52: m | B52: 18 SWG Water Stopper (with 15% for Lapping) | C52: 3 | D52: 11.2 | G52: 39 | H52: 526 | I52: =H52*G52 -> 20514
...

Sheet Abstract_TRUSS
B1: Abstract of Cost of Truss and Roofing
A2: S.No. | B2: Items Of works | C2: Unit | D2: Quantity | E2: Unit rate | F2: Amount | G2: Remarks
A3: 1 | B3: Clearing the site from trees, logs, bushes, weeds, grass, debris & rubbish of any nature to make the site suitable for construction work and clearing the site from construction materials and equipment after completion of the work as per instruction of the engineer. | C3: Job | D3: 1 | E3: 20000 | F3: =E3*D3 -> 20000
A4: 2 | B4: Earthwork in excavation in foundation in hard with a lead of 10 m. i> Upto depth 4M | C4: cum | D4: ='Qty Truss'!G9 -> 90 | E4: =Rates!$F$9 -> 1480.63 | F4: =E4*D4 -> 133256.7
A5: 3 | B5: Providing and backfilling the earth in the trenches in layers not exceeding more than 225 mm with watering and ramming for the proper compaction as per the instruction and specification all complete. | C5: cum | D5: ='Qty Truss'!G11 -> 27 | E5: =Rates!$F$14 -> 592.25 | F5: =E5*D5 -> 15990.75
A6: 4 | B6: Providing and laying first class chimney made brick soling on flat as per the instruction of the Engineer | C6: sqm | D6: ='Qty Truss'!G14 -> 36 | E6: =Rates!$F$28 -> 19440.44 | F6: =E6*D6 -> 699855.84
A7: 5 | B7: Providing and laying of 75mm thick PCC (1:3:6) in foundation with a size of aggregate not exceeding 38 mm all complete as per the specification and instruction of the engineer | C7: sqm | D7: ='Qty Truss'!G18*0.075 -> 2.7 | E7: =Rates!$F$31 -> 14810.58 | F7: =E7*D7 -> 39988.566
A8: 6 | B8: Supplying, mixing, placing, compacting and cure concrete PCC (1:1.5:3) for lintel as per drawing, specification and instruction of Engineer | C8: cum | D8: ='Qty Truss'!G21 -> 4.5 | E8: =Rates!$F$33 -> 17163.13 | F8: =E8*D8 -> 77234.085
A9: 7 | B9: Brickwork in walls and foundation in cement sand mortar (1:4) with 1st class chimney bricks in perfect lines and levels with necessary scaffolding including wetting the brick, properly packing the joint with cement mortar and curing the works all complete | C9: cum | D9: ='Qty Truss'!G26 -> 58.5 | E9: =Rates!F28 -> 19440.44 | F9: =E9*D9 -> 1137265.7
A10: 8 | B10: Providing and fitting of roof truss with black iron pipe including all necessary joints and accessories as per drawing and instruction, all complete. | C10: Kgs | D10: ='Qty Truss'!G33 -> 546.31326 | E10: =Rates!F39 -> 125.35 | F10: =E10*D10 -> 68480.367
A11: 9 | B11: Roofing with 0.5 mm thick corrugated coloured GI Sheet with necessary 8mm nut bolts, J-hooks, bitumin washers as per drawing and instruction, all complete. | C11: Sft | D11: ='Qty Truss'!G36 -> 485.76 | E11: =Rates!$F$49 -> 1070.18 | F11: =E11*D11 -> 519850.64
A12: 10 | B12: Providing and fixing gutter of 0.5mm coloured plain sheet 150 mm width and 450 mm depth with 40*3 mm iron braket, nutbolt, washer, all complete | C12: Rft | D12: ='Qty Truss'!G42 -> 36.8 | E12: =Rates!F49 -> 1070.18 | F12: =E12*D12 -> 39382.624
A13: 11 | B13: Providing and fixing ridge of 0.5mm coloured plain sheet , nutbolt, washer, all complete | C13: Rft | D13: ='Qty Truss'!G39 -> 18.4 | E13: =Rates!F50 -> 1010.11 | F13: =E13*D13 -> 18586.024
A14: 17 | B14: providing 10 SWG 3"X3" Chain mesh Fecing on all faces of the truss structure with metal door and proper locking system along with required support system | C14: job | D14: 1 | E14: 50000 | F14: =E14*D14 -> 50000
E15: Total | F15: =SUM(F3:F14) -> 2819891.3

Sheet Pipe Support
A1: Detailed Quantity Estimate
A2: ='sum cost_All'!$B$2 -> Name of Scheme: Sankhu Drinking Water Supply Project
A3: Component: Pipe Suppor Pillars
A4: 2 | B4: 2m
B5: Earthwork Excavation | C5: cu.m | D5: 1 | E5: 0.6 | F5: 0.6 | G5: 0.5 | H5: 0.18 | I5: =Rates!F10 -> 1883.36 | J5: =H5*I5 -> 339.0048
B6: Filling of trenches, | C6: cu.m | D6: 2 | E6: 0.6 | F6: 0.1 | G6: 0.15 | H6: 0.018 | I6: =Rates!F16 -> 710.7 | J6: =H6*I6 -> 12.7926
D7: 2 | E7: 0.4 | F7: 0.1 | G7: 0.15 | H7: 0.012 | I7: =I6 -> 710.7 | J7: =H7*I7 -> 8.5284
B8: Stone soling | C8: cu.m | D8: 1 | E8: 0.6 | F8: 0.6 | G8: 0.2 | H8: 0.072 | I8: =Rates!F19 -> 5523.35 | J8: =H8*I8 -> 397.6812
B9: PCC 1:3:6 | C9: cu.m | D9: 1 | E9: 0.6 | F9: 0.6 | G9: 0.15 | H9: 0.054 | I9: =Rates!F31 -> 14810.58 | J9: =H9*I9 -> 799.77132
B10: RRM in CM 1:4 | C10: cu.m | D10: 1 | E10: 0.4 | F10: 0.4 | G10: 1 | H10: 0.16 | I10: =Rates!F24 -> 15619.64 | J10: =H10*I10 -> 2499.1424
B11: PCC 1:2:4 | C11: cu.m | D11: 1 | E11: 0.4 | F11: 0.4 | G11: 0.1 | H11: 0.016 | I11: =Rates!F32 -> 16022.87 | J11: =H11*I11 -> 256.36592
J12: =SUM(J5:J11) -> 4313.2866
A13: 2 | B13: 2m
B14: Earthwork Excavation | C14: cu.m | D14: 1 | E14: 1 | F14: 1 | G14: 0.8 | H14: 0.8 | I14: =I5 -> 1883.36 | J14: =H14*I14 -> 1506.688
B15: Filling of trenches, | C15: cu.m | D15: 2 | E15: 1 | F15: 0.1 | G15: 0.45 | H15: 0.09 | I15: =I6 -> 710.7 | J15: =H15*I15 -> 63.963
C16: cu.m | D16: 2 | E16: 0.8 | F16: 0.1 | G16: 0.45 | H16: 0.072 | I16: =I7 -> 710.7 | J16: =H16*I16 -> 51.1704
B17: Stone soling | C17: cu.m | D17: 1 | E17: 1 | F17: 1 | G17: 0.2 | H17: 0.2 | I17: =I8 -> 5523.35 | J17: =H17*I17 -> 1104.67
B18: PCC 1:3:6 | C18: cu.m | D18: 1 | E18: 1 | F18: 1 | G18: 0.15 | H18: 0.15 | I18: =I9 -> 14810.58 | J18: =H18*I18 -> 2221.587
B19: RRM in CM 1:4 | C19: cu.m | D19: 1 | E19: 0.8 | F19: 0.8 | G19: 1 | H19: 0.64 | I19: =I10 -> 15619.64 | J19: =H19*I19 -> 9996.5696
C20: cu.m | D20: 1 | E20: 0.4 | F20: 0.4 | G20: 1 | H20: 0.16 | I20: =I10 -> 15619.64 | J20: =H20*I20 -> 2499.1424
B21: PCC 1:2:4 | C21: cu.m | D21: 1 | E21: 0.4 | F21: 0.4 | G21: 0.1 | H21: 0.016 | I21: =I11 -> 16022.87 | J21: =H21*I21 -> 256.36592
J22: =SUM(J14:J21) -> 17700.156
A23: 3 | B23: 3m
B24: Earthwork Excavation | C24: cu.m | D24: 1 | E24: 1 | F24: 1 | G24: 0.8 | H24: 0.8 | I24: =I14 -> 1883.36 | J24: =H24*I24 -> 1506.688
B25: Filling of trenches, | C25: cu.m | D25: 2 | E25: 1 | F25: 0.1 | G25: 0.45 | H25: 0.09 | I25: =I15 -> 710.7 | J25: =H25*I25 -> 63.963
C26: cu.m | D26: 2 | E26: 0.8 | F26: 0.1 | G26: 0.45 | H26: 0.072 | I26: =I16 -> 710.7 | J26: =H26*I26 -> 51.1704
B27: Stone soling | C27: cu.m | D27: 1 | E27: 1 | F27: 1 | G27: 0.2 | H27: 0.2 | I27: =I17 -> 5523.35 | J27: =H27*I27 -> 1104.67
B28: PCC 1:3:6 | C28: cu.m | D28: 1 | E28: 1 | F28: 1 | G28: 0.15 | H28: 0.15 | I28: =I18 -> 14810.58 | J28: =H28*I28 -> 2221.587
B29: RRM in CM 1:4 | C29: cu.m | D29: 1 | E29: 0.8 | F29: 0.8 | G29: 1 | H29: 0.64 | I29: =I19 -> 15619.64 | J29: =H29*I29 -> 9996.5696
C30: cu.m | D30: 1 | E30: 0.6 | F30: 0.6 | G30: 1 | H30: 0.36 | I30: =I19 -> 15619.64 | J30: =H30*I30 -> 5623.0704
C31: cu.m | D31: 1 | E31: 0.4 | F31: 0.4 | G31: 1 | H31: 0.16 | I31: =I19 -> 15619.64 | J31: =H31*I31 -> 2499.1424
B32: PCC 1:2:4 | C32: cu.m | D32: 1 | E32: 0.4 | F32: 0.4 | G32: 0.1 | H32: 0.016 | I32: =I21 -> 16022.87 | J32: =H32*I32 -> 256.36592
J33: =SUM(J24:J32) -> 23323.227
A34: SN | B34: >3m
A35: 1 | B35: Earthwork Excavation | C35: cu.m | D35: 1 | E35: 1.2 | F35: 1.2 | G35: 0.9 | H35: 1.296 | I35: =I24 -> 1883.36 | J35: =H35*I35 -> 2440.8346
A36: 2 | B36: Filling of trenches, | C36: cu.m | D36: 2 | E36: 1.2 | F36: 0.4 | G36: 0.4 | H36: 0.384 | I36: =I25 -> 710.7 | J36: =H36*I36 -> 272.9088
A37: 3 | C37: cu.m | D37: 2 | E37: 0.4 | F37: 0.4 | G37: 0.4 | H37: 0.128 | I37: =I25 -> 710.7 | J37: =H37*I37 -> 90.9696
A38: 4 | B38: Stone soling | C38: cu.m | D38: 1 | E38: 1.2 | F38: 1.2 | G38: 0.2 | H38: 0.288 | I38: =I27 -> 5523.35 | J38: =H38*I38 -> 1590.7248
A39: 5 | B39: RCC 1:2:4 | C39: cu.m | D39: 1 | E39: 1.2 | F39: 1.2 | G39: 0.3 | H39: 0.432 | I39: =I11 -> 16022.87 | J39: =H39*I39 -> 6921.8798
C40: cu.m | D40: 1 | E40: 0.4 | F40: 0.4 | G40: 4 | H40: 0.64 | I40: =I39 -> 16022.87 | J40: =H40*I40 -> 10254.637
...

Sheet Cost_In_1
A1: ABSTRACT OF COST
A3: TYPE OF WORK : Intake Construction-Fedi
A5: S.no. | B5: Description of works | C5: Unit | D5: Quantity | E5: Rate | F5: Amount | G5: Remarks
A6: 1 | B6: Site Clearance | C6: sqm | D6: =Qty_in_1!H4 -> 170.4 | E6: =Rates!$F$7 -> 149.5 | F6: =+ROUND(D6*E6,2) -> 25474.8 | I6: =F7+F35 -> 170082.36
A7: 2 | B7: Earthwork Excavation in River Bed | C7: Cum | D7: =Qty_in_1!H11 -> 32.23 | E7: =Rates!$F$11 -> 3553.5 | F7: =+ROUND(D7*E7,2) -> 114529.31
A8: 3 | B8: =Qty_in_1!B12 -> Stone Soling | C8: =Qty_in_1!C16 -> Cum | D8: =Qty_in_1!H16 -> 6.93 | E8: =Rates!$F$19 -> 5523.35 | F8: =+ROUND(D8*E8,2) -> 38276.82 | H8: =+F8 -> 38276.82 | I8: =F8+F38+#REF! -> #REF!
A9: 4 | B9: P.C.C Works
A10: 4.1 | B10: =Qty_in_1!B18 -> PCC M10 | C10: =Qty_in_1!C22 -> Cum | D10: =Qty_in_1!H22 -> 3.46 | E10: =Rates!$F$31 -> 14810.58 | F10: =+ROUND(D10*E10,2) -> 51244.61 | H10: =+F10 -> 51244.61 | I10: =F10+F42 -> 51244.61
A11: 4.2 | B11: RCC works M20 | C11: cum | D11: =Qty_in_1!H35 -> 24.95 | E11: =Rates!$F$33 -> 17163.13 | F11: =+ROUND(D11*E11,2) -> 428220.09
A12: 5 | B12: Form Works | C12: sqm | D12: =Qty_in_1!H53 -> 125.78 | E12: =Rates!$F$40 -> 1322.68 | F12: =+ROUND(D12*E12,2) -> 166366.69 | H12: =+F12+#REF!+F50 -> #REF! | I12: =F12+F43 -> 166366.69
A13: 6 | B13: Reinforcement | C13: kg | D13: =Qty_in_1!H54 -> 3965.553 | E13: =Rates!$F$39 -> 125.35 | F13: =+ROUND(D13*E13,2) -> 497082.07 | H13: =+F13+#REF!+#REF! -> #REF!
A14: 7 | B14: 20 to 25mm thick screeding (1:4) on floors | C14: sqm | D14: =Qty_in_1!H59 -> 5.25 | E14: =+'[61]Analysis of rates'!E793 -> 439.26889 | F14: =+ROUND(D14*E14,2) -> 2306.16
A15: 8 | B15: Cement punning | C15: sqm | D15: =Qty_in_1!H65 -> 61.15 | E15: =+'[61]Analysis of rates'!E807 -> 220.97709 | F15: =+ROUND(D15*E15,2) -> 13512.75
A16: 9 | B16: 12.5 mm thick cement plaster on concrete surface with 1:3 cement sand mortar | C16: sqm | D16: =Qty_in_1!H74 -> 79.09 | E16: ='[61]Analysis of rates'!E859 -> 351.50553 | F16: =+ROUND(D16*E16,2) -> 27800.57 | I16: =F16+F44 -> 27800.57 | K16: 2016 | L16: 2073
A17: 10 | B17: Gabion Works | K17: =+K16-#REF! -> #REF! | L17: 2060
B18: Launching Apron | H18: =+#REF!/12 -> #REF!
B19: 2mx1mx0.3m | C19: Cum | D19: =Qty_in_1!H77 -> 44.52 | E19: ='[61]Analysis of rates'!E2318 -> 6073.622 | F19: =+ROUND(D19*E19,2) -> 270397.65
A20: 12 | B20: 600dia. Manhole Cover | C20: No. | D20: =Qty_in_1!H78 -> 2 | E20: 15000 | F20: =+ROUND(D20*E20,2) -> 30000
A21: 13 | B21: Supplying and laying Pipes Fittings
B22: 75∅ Tee | C22: No. | E22: =320*1.1 -> 352 | F22: =+ROUND(D22*E22,2) -> 0
B23: 75∅ Elbow | C23: No. | E23: =285*1.1 -> 313.5 | F23: =+ROUND(D23*E23,2) -> 0
B24: 75∅ Pipe Piece | C24: No. | E24: ='[61]rate73-74'!O46 -> 452.18 | F24: =+ROUND(D24*E24,2) -> 0
B25: 65∅ Gate Valve | C25: No. | E25: =11087+'[61]GI fittings'!K17 -> 11221.096 | F25: =+ROUND(D25*E25,2) -> 0
B26: 65∅ Union | C26: No. | E26: =976+'[61]GI fittings'!K35 -> 1046.2785 | F26: =+ROUND(D26*E26,2) -> 0
B27: 65∅ Nipple | C27: No. | E27: =373+'[61]GI fittings'!K35 -> 443.27849 | F27: =+ROUND(D27*E27,2) -> 0
B28: 65/75 GI/PE Flanged set | C28: No. | E28: =1586+'[61]GI fittings'!K35 -> 1656.2785 | F28: =+ROUND(D28*E28,2) -> 0
B29: 75∅ PE Stainer | C29: No. | E29: ='[61]rate73-74'!O46*1.15 -> 520.007 | F29: =+ROUND(D29*E29,2) -> 0
F30: =SUM(F6:F29) -> 1665211.5
A33: TYPE OF WORK : Pitching works in river
A34: S.no. | B34: Description of works | C34: Unit | D34: Quantity | E34: Rate | F34: Amount | G34: Remarks
A35: 1 | B35: Earthwork Excavation in River Bed | C35: Cum | D35: =Qty_in_1!H93 -> 134 | E35: ='[61]Analysis of rates'!E67 -> 414.575 | F35: =+ROUND(D35*E35,2) -> 55553.05
A36: 2 | B36: Back filling | C36: Cum | D36: =Qty_in_1!H96 -> 30 | E36: ='[61]Analysis of rates'!E78 -> 296.125 | F36: =+ROUND(D36*E36,2) -> 8883.75
A37: 3 | B37: Masonary Works
A38: 3.1 | B38: Stone Soling | C38: Cum | D38: =Qty_in_1!H100 -> 16.8 | E38: ='[61]Analysis of rates'!E1593 -> 4565 | F38: =+ROUND(D38*E38,2) -> 76692
A39: 3.2 | B39: Stone Masonary(1:6) | C39: Cum | D39: 0 | E39: ='[61]Analysis of rates'!E1534 -> 8027 | F39: =+ROUND(D39*E39,2) -> 0
A40: 4 | B40: P.C.C Works
A41: 4.1 | B41: M10 | C41: Cum | D41: =Qty_in_1!H110 -> 8.45 | E41: ='[61]Analysis of rates'!E166 -> 10715.088 | F41: =+ROUND(D41*E41,2) -> 90542.49
A42: 4.2 | B42: M15 | C42: Cum | D42: 0 | E42: ='[61]Analysis of rates'!E181 -> 12897.013 | F42: =+ROUND(D42*E42,2) -> 0
A43: 5 | B43: Form Works | C43: sqm | D43: 0 | E43: ='[61]Analysis of rates'!E343 -> 764.33148 | F43: =+ROUND(D43*E43,2) -> 0 | L43: =2.4*3*1.5 -> 10.8
A44: 6 | B44: 12.5mm thick c/s plaster (1:3) in wall (both sides) and 100mm below GL | C44: sqm | D44: 0 | E44: =E16 -> 351.50553 | F44: =+ROUND(D44*E44,2) -> 0 | K44: =3.6/3.281 -> 1.0972265
...

Sheet Qnty_ALL
A1: Detailed Quantity Estimate
A3: Component: Plain Sedimentation Tank
A5: S.N. | B5: Description of Works | C5: No | D5: Length (m) | E5: Breadth (m) | F5: Height (m) | G5: Quantity | H5: Units
A6: 1 | B6: Site Clearence | C6: 1 | D6: 14 | E6: 6 | G6: =ROUND((C6*D6*E6),2) -> 84 | H6: m2
A7: 2 | B7: Earth Work in Excavation in Boulder Mixed Soil
B8: Levelling work | C8: 1 | D8: 13.52 | E8: 5.52 | F8: 0.3 | G8: =ROUND((C8*D8*E8*F8),2) -> 22.39
B9: Foundation in Boulder Mixed Soil
B10: PS | C10: 1 | D10: 13.52 | E10: 5.52 | F10: 1.48 | G10: =ROUND((C10*D10*E10*F10),2) -> 110.45
B11: Inlet VC | C11: 1 | D11: 1.83 | E11: 1.86 | F11: 1.48 | G11: =ROUND((C11*D11*E11*F11),2) -> 5.04
B12: Outlet VC | C12: 1 | D12: 1.83 | E12: 1.86 | F12: 1.48 | G12: =ROUND((C12*D12*E12*F12),2) -> 5.04
E13: Total | G13: =ROUND(SUM(G8:G12),2) -> 142.92 | H13: m3
A14: 3 | B14: Earth Filling in Foundation
B15: Long wall | C15: 2 | D15: 13.52 | E15: 0.6 | F15: 1.48 | G15: =ROUND((C15*D15*E15*F15),2) -> 24.01
B16: short wall | C16: 2 | D16: 4.32 | E16: 0.6 | F16: 1.48 | G16: =ROUND((C16*D16*E16*F16),2) -> 7.67
B17: Inlet VC | C17: 1 | D17: 1.83 | E17: 0.2 | F17: 1.48 | G17: =ROUND((C17*D17*E17*F17),2) -> 0.54
B18: Outlet VC | C18: 1 | D18: 1.83 | E18: 0.2 | F18: 1.48 | G18: =ROUND((C18*D18*E18*F18),2) -> 0.54
E19: Sub Total | G19: =ROUND(SUM(G15:G18),2) -> 32.76 | H19: m3
B20: Deduct
B21: Long wall | C21: 2 | D21: 13.52 | E21: 0.15 | F21: 0.48 | G21: =ROUND((C21*D21*E21*F21),2) -> 1.95
B22: short wall | C22: 2 | D22: 4.32 | E22: 0.15 | F22: 0.48 | G22: =ROUND((C22*D22*E22*F22),2) -> 0.62
B23: Inlet VC | C23: 1 | D23: 1.83 | E23: 0.05 | F23: 0.35 | G23: =ROUND((C23*D23*E23*F23),2) -> 0.03
B24: Outlet VC | C24: 1 | D24: 1.83 | E24: 0.05 | F24: 0.35 | G24: =ROUND((C24*D24*E24*F24),2) -> 0.03
E25: Total | G25: =ROUND((G19-G21-G22-G23-G24),2) -> 30.13 | H25: m3
A26: 4 | B26: Stone Soling with sand packing on
B27: Base of Foundation, PS | C27: 1 | D27: 13.22 | E27: 5.22 | F27: 0.2 | G27: =ROUND((C27*D27*E27*F27),2) -> 13.8
B28: Inlet VC | C28: 1 | D28: 1.73 | E28: 1.76 | F28: 0.2 | G28: =ROUND((C28*D28*E28*F28),2) -> 0.61
B29: Outlet VC | C29: 1 | D29: 1.73 | E29: 1.76 | F29: 0.2 | G29: =ROUND((C29*D29*E29*F29),2) -> 0.61
E30: Total | G30: =ROUND(SUM(G27:G29),2) -> 15.02 | H30: m3
A31: 5 | B31: Laying of P.C.C. 1:3:6 on Base of
B32: Foundation PS | C32: 1 | D32: 13.8 | E32: 5.22 | F32: 0.1 | G32: =ROUND((C32*D32*E32*F32),2) -> 7.2
B33: Inlet VC | C33: 1 | D33: 1.73 | E33: 1.76 | F33: 0.1 | G33: =ROUND((C33*D33*E33*F33),2) -> 0.3
B34: Outlet VC | C34: 1 | D34: 1.73 | E34: 1.76 | F34: 0.1 | G34: =ROUND((C34*D34*E34*F34),2) -> 0.3
E35: Total | G35: =ROUND(SUM(G32:G34),2) -> 7.8 | H35: m3
A36: 6 | B36: Laying of One Layer Tarfelt Over
B37: Lean Concrete PS | C37: 1 | D37: 13.8 | E37: 5.22 | G37: =ROUND((C37*D37*E37),2) -> 72.04
E38: Total | G38: =ROUND(SUM(G37:G37),2) -> 72.04 | H38: m3
A39: 7 | B39: P.C.C (1: 1.5:3) Works for R.C.C
B40: SSF
B41: Base Slab | C41: 1 | D41: 13.22 | E41: 5.22 | F41: 0.18 | G41: =ROUND((C41*D41*E41*F41),2) -> 12.42
B42: Long Wall | C42: 2 | D42: 12.32 | E42: 0.16 | F42: 1 | G42: =ROUND((C42*D42*E42*F42),2) -> 3.94
...

Sheet QTY.Reservoir_400m3
A1: DETAIL QUANTITY ESTIMATES OF CIRCULAR RCC RESERVOIR 400 m3
A3: Description of Work :- Circular RCC Ground Reservoir (400 cu m)
A4: S.No. | B4: Description of Works | C4: No. | D4: Length | E4: Breadth | F4: Height | G4: Quantity | H4: Remarks
A5: I. | K5: =11.4+2*0.65+2*0.6 -> 13.9
A6: 1 | B6: Site Clearance | C6: 1 | D6: =PI()*(14^2)/4 -> 153.93804 | E6: Area | G6: =C6*D6 -> 153.93804
F7: Total | G7: =G6 -> 153.93804 | H7: m2
A8: 2 | B8: Earthwork in excavation in foundation | C8: 1 | D8: =PI()*(14^2)/4 -> 153.93804 | E8: Area | F8: 1.35 | G8: =C8*D8*F8 -> 207.81635
F9: Total | G9: =G8 -> 207.81635 | H9: m3
A10: 3 | B10: Stone soling | C10: 1 | D10: =PI()*(13.9^2)/4 -> 151.74678 | E10: Area | F10: 0.2 | G10: =C10*D10*F10 -> 30.349356
F11: Total | G11: =G10 -> 30.349356 | H11: m3
A12: 4 | B12: Plain Cement Concrete P.C.C. (M10) in 1:3:6
B13: Base | C13: 1 | D13: =D10 -> 151.74678 | E13: Area | F13: 0.15 | G13: =C13*D13*F13 -> 22.762017
F14: Total | G14: =G13 -> 22.762017 | H14: m3
A15: 5 | B15: Cement Concrete work for R.C.C (1:1.5:3) (M20) for
B16: Base | C16: 1 | D16: =PI()*(13.9^2)/4 -> 151.74678 | E16: Area | F16: 0.72 | G16: =F16*D16*C16 -> 109.25768
B17: Wall L = pi * 11.825m | C17: 1 | D17: =PI()*(11.4+2*0.425) -> 38.48451 | E17: =(0.2+0.65)/2 -> 0.425 | F17: 4.35 | G17: =+F17*E17*D17*C17 -> 71.148238
B18: Ring Beam | C18: 1 | D18: =PI()*(11.4+2*0.45+2*0.175) -> 39.741147 | E18: 0.35 | F18: 0.35 | G18: =+F18*E18*D18*C18 -> 4.8682905
B19: Top slab | C19: 1 | D19: 17.3025 | E19: Cu m | G19: =D19*C19 -> 17.3025
B20: Deduction for ventilation | C20: -1 | D20: =PI()*(1^2)/4 -> 0.78539816 | E20: Area | F20: 0.15 | G20: =C20*D20*F20 -> -0.11780972
B21: Wall of ventilation | C21: 1 | D21: =PI()*1.15 -> 3.6128316 | E21: 0.15 | F21: 0.42 | G21: =C21*D21*E21*F21 -> 0.22760839
C22: 1 | D22: =PI()*1.25 -> 3.9269908 | E22: 0.05 | F22: 0.08 | G22: =C22*D22*E22*F22 -> 0.015707963
B23: Ventilation slab cover on top | C23: 1 | D23: =PI()*1.18^2/4 -> 1.0935884 | E23: Area | F23: 0.075 | G23: =C23*D23*F23 -> 0.08201913
B24: Deduction for ventilating holes on slab tob | C24: -4 | D24: =PI()*(0.23^2)/4 -> 0.041547563 | E24: Area | F24: 0.15 | G24: =C24*D24*F24 -> -0.024928538
F25: Total | G25: =SUM(G16:G24) -> 202.75931 | H25: m3
A26: 6 | B26: Reinforcement Bar for RCC | G26: 12562 | H26: Kg
A27: 7 | B27: Erecting, centering and shuttering of formwork for RCC
B28: Base edge | C28: 1 | D28: =PI()*13.9 -> 43.668138 | F28: 0.15 | G28: =F28*D28*C28 -> 6.5502207
B29: Tank Base edge | C29: 1 | D29: =PI()*13.9 -> 43.668138 | F29: 0.6 | G29: =F29*D29*C29 -> 26.200883
B30: Inner Wall | C30: 1 | D30: =PI()*11.4 -> 35.814156 | F30: 4.7 | G30: =F30*D30*C30 -> 168.32653
B31: Outer Wall | C31: 1 | D31: =PI()*(11.4+2*0.65) -> 39.898227 | F31: 4.35 | G31: =F31*D31*C31 -> 173.55729
B32: Ring Beam | C32: 1 | D32: =PI()*(11.4+2*0.45+0.35) -> 39.741147 | F32: =3*0.35-0.2 -> 0.85 | G32: =F32*D32*C32 -> 33.779975
B33: Top Slab Bottom | C33: 1 | D33: =PI()*11.92^2/4 -> 111.5944 | E33: Area | G33: =D33*C33 -> 111.5944
B34: Ventilation Wall (Inner) | C34: 1 | D34: =PI()*1 -> 3.1415927 | F34: 0.56 | G34: =C34*D34*F34 -> 1.7592919
C35: 1 | D35: =PI()*1.2 -> 3.7699112 | F35: 0.08 | G35: =C35*D35*F35 -> 0.30159289
B36: Ventilation Wall (Outer) | C36: 1 | D36: =PI()*1.3 -> 4.0840704 | F36: 0.5 | G36: =C36*D36*F36 -> 2.0420352
B37: Deduction for ventilation | C37: -1 | D37: =PI()*1^2/4 -> 0.78539816 | E37: Area | G37: =C37*D37 -> -0.78539816
B38: Deduction for ventilating holes on slab tob | C38: -4 | D38: =D24 -> 0.041547563 | E38: Area | G38: =C38*D38 -> -0.16619025
B39: Top Ventilating Slab | C39: 1 | D39: =PI()*(1^2)/4 -> 0.78539816 | E39: Area | G39: =C39*D39 -> 0.78539816
B40: Edge of top ventilating slab | C40: 1 | D40: =PI()*1.18 -> 3.7070793 | F40: 0.075 | G40: =C40*D40*F40 -> 0.27803095
F41: Total | G41: =SUM(G28:G40) -> 524.22406 | H41: m2
...

Sheet Source
A1: Description of Sources
E4: Discharge | F4: Date | G4: Yield | I4: Quality | J4: Dispute | K4: Remarks
A5: S.No. | B5: Name of Source | C5: Location of source | D5: Type of Source | E5: measured | F5: of | G5: Safe | H5: Tapped | I5: (by eye observation) | K5: (Specify if land slide upstream settlement, pollution, etc)
C6: Place, VDC-wards | E6: Lps | F6: Measurement | G6: Lps | H6: Lps
A8: 1 | B8: Kakune Khola | C8: Bame | D8: Stream | E8: 0.88 | G8: =E8*0.9 -> 0.792 | H8: 0.88 | I8: Good | J8: No | K8: Not any
A9: 2 | B9: Bara Khola | C9: Bame | D9: Stream | E9: 0.29 | G9: =E9*0.9 -> 0.261 | H9: 0.29 | I9: Good | J9: No | K9: Not any
A10: 3 | C10: Bame | D10: Spring | E10: 0.5 | G10: =E10*0.9 -> 0.45 | H10: 0.5 | I10: Good | J10: No | K10: Not any

Sheet Pipe-existing
A1: Procurement of Pipes
I2: Rate of HDPE Pipe = | J2: 250
A3: S.No. | B3: Pipe size and series | D3: Unit | E3: Quantity | F3: Rate | G3: Amount
F4: Rs./unit | G4: Rs.
A5: 1 | B5: HDPE pipes
K6: Scheme 1
B7: 32 | C7: 6 | D7: m | E7: =N19 -> 0 | F7: Existing | G7: Existing | K7: Tr | L7: Dr | M7: Total | N7: DL
B8: 40 | C8: 6 | D8: m | E8: =N20 -> 0 | F8: Existing | G8: Existing | J8: GPM-15 | K8: 0 | L8: 0 | M8: =K8+L8 -> 0 | N8: =ROUNDUP(M8*1.1,0) -> 0
B9: 50 | C9: 6 | D9: m | E9: =N21 -> 0 | F9: Existing | G9: Existing | J9: GPM-20 | K9: 0 | L9: 0 | M9: =K9+L9 -> 0 | N9: =ROUNDUP(M9*1.1,0) -> 0
B10: 63 | C10: 6 | D10: m | E10: =N22 -> 0 | F10: Existing | G10: Existing | J10: GPM-25 | K10: 0 | L10: 0 | M10: =K10+L10 -> 0 | N10: =ROUNDUP(M10*1.1,0) -> 0
B11: 75 | C11: 6 | D11: m | E11: =N23 -> 0 | F11: Existing | G11: Existing | J11: GPM-32 | K11: 0 | L11: 0 | M11: =K11+L11 -> 0 | N11: =ROUNDUP(M11*1.1,0) -> 0
B12: 90 | C12: 6 | D12: m | E12: =N24 -> 0 | F12: Existing | G12: Existing | J12: GPM-40 | K12: 0 | L12: 0 | M12: =K12+L12 -> 0 | N12: =ROUNDUP(M12*1.1,0) -> 0
B13: 110 | C13: 6 | D13: m | E13: =N25 -> 0 | F13: Existing | G13: Existing | J13: GPM-50 | K13: 0 | L13: 0 | M13: =K13+L13 -> 0 | N13: =ROUNDUP(M13*1.1,0) -> 0
B14: 125 | C14: 6 | D14: m | E14: =N26 -> 0 | F14: Existing | G14: Existing | J14: GPM-65 | M14: =K14+L14 -> 0 | N14: =ROUNDUP(M14*1.1,0) -> 0
B15: 16 | C15: 10 | D15: m | E15: =N27 -> 0 | F15: Existing | G15: Existing | J15: GPM-80 | M15: =K15+L15 -> 0 | N15: =ROUNDUP(M15*1.1,0) -> 0
B16: 20 | C16: 10 | D16: m | E16: =N28 -> 0 | F16: Existing | G16: Existing | J16: GPM-100 | M16: =K16+L16 -> 0 | N16: =ROUNDUP(M16*1.1,0) -> 0 | O16: scheme 2
B17: 25 | C17: 10 | D17: m | E17: =N29 -> 0 | F17: Existing | G17: Existing | J17: GPM-125 | M17: =K17+L17 -> 0 | N17: =ROUNDUP(M17*1.1,0) -> 0 | O17: scheme 1
B18: 32 | C18: 10 | D18: m | E18: =N30 -> 0 | F18: Existing | G18: Existing | J18: GPM-150 | M18: =K18+L18 -> 0 | N18: =ROUNDUP(M18*1.1,0) -> 0
B19: 40 | C19: 10 | D19: m | E19: =N31 -> 0 | F19: Existing | G19: Existing | J19: HP6-32 | M19: =K19+L19 -> 0 | N19: =ROUNDUP(M19*1.1,0) -> 0
B20: 50 | C20: 10 | D20: m | E20: =N32 -> 1565 | F20: Existing | G20: Existing | J20: HP6-40 | M20: =K20+L20 -> 0 | N20: =ROUNDUP(M20*1.1,0) -> 0
B21: 63 | C21: 10 | D21: m | E21: =N33 -> 1138 | F21: Existing | G21: Existing | J21: HP6-50 | M21: =K21+L21 -> 0 | N21: =ROUNDUP(M21*1.1,0) -> 0
B22: 75 | C22: 10 | D22: m | E22: =N34 -> 2657 | F22: Existing | G22: Existing | J22: HP6-63 | M22: =K22+L22 -> 0 | N22: =ROUNDUP(M22*1.1,0) -> 0
B23: 90 | C23: 10 | D23: m | E23: =N35 -> 1362 | F23: Existing | G23: Existing | J23: HP6-75 | M23: =K23+L23 -> 0 | N23: =ROUNDUP(M23*1.1,0) -> 0 | Q23: 1379.6
B24: 110 | C24: 10 | D24: m | E24: =N36 -> 772 | F24: Existing | G24: Existing | J24: HP6-90 | M24: =K24+L24 -> 0 | N24: =ROUNDUP(M24*1.1,0) -> 0
B25: 125 | C25: 10 | D25: m | E25: =N37 -> 0 | F25: Existing | G25: Existing | J25: HP6-110 | M25: =K25+L25 -> 0 | N25: =ROUNDUP(M25*1.1,0) -> 0
B26: 110 | C26: 4 | D26: m | F26: Existing | G26: Existing | J26: HP6-125 | M26: =K26+L26 -> 0 | N26: =ROUNDUP(M26*1.1,0) -> 0
B27: 63 | C27: 4 | D27: m | F27: Existing | G27: Existing | J27: HP10-16 | M27: =K27+L27 -> 0 | N27: =ROUNDUP(M27*1.1,0) -> 0
B28: 250 | C28: 10 | D28: m | E28: =N43 -> 27 | F28: Existing | G28: Existing | J28: HP10-20 | M28: =K28+L28 -> 0 | N28: =ROUNDUP(M28*1.1,0) -> 0
J29: HP10-25 | M29: =K29+L29 -> 0 | N29: =ROUNDUP(M29*1.1,0) -> 0
C30: Subtotal | E30: =SUM(E7:E29) -> 7521 | F30: Rs. | G30: =SUM(G7:G29) -> 0 | J30: HP10-32 | M30: =K30+L30 -> 0 | N30: =ROUNDUP(M30*1.1,0) -> 0
B31: Add transportation cost | F31: 5 | G31: =F31*G30/100 -> 0 | J31: HP10-40 | M31: =K31+L31 -> 0 | N31: =ROUNDUP(M31*1.1,0) -> 0
C32: Total | G32: =SUM(G30:G31) -> 0 | J32: HP10-50 | L32: 1422 | M32: =K32+L32 -> 1422 | N32: =ROUNDUP(M32*1.1,0) -> 1565
B33: Value added Tax | F33: ='Entry for Rates'!$F$114 -> 13 | G33: =F33*G32/100 -> 0 | J33: HP10-63 | L33: 1034 | M33: =K33+L33 -> 1034 | N33: =ROUNDUP(M33*1.1,0) -> 1138
B34: Total cost of HDPE pipes | F34: Rs. | G34: =+G33+G32 -> 0 | J34: HP10-75 | K34: 0 | L34: 2415 | M34: =K34+L34 -> 2415 | N34: =ROUNDUP(M34*1.1,0) -> 2657
A35: 2 | B35: GI pipes | J35: HP10-90 | K35: 0 | L35: 1238 | M35: =K35+L35 -> 1238 | N35: =ROUNDUP(M35*1.1,0) -> 1362
B36: 15 | C36: GI (Heavy) | D36: m | E36: =N8 -> 0 | F36: =IF(C36="GI (Medium)",VLOOKUP(B36,data!$A$4:$D$14,4,FALSE),IF(C36="GI (Heavy)",VLOOKUP(B36,data!$A$17:$D$27,4,FALSE),0)) -> 203 | G36: =+ROUND(E36*F36,2) -> 0 | J36: HP10-110 | K36: 0 | L36: 701 | M36: =K36+L36 -> 701 | N36: =ROUNDUP(M36*1.1,0) -> 772
B37: 25 | C37: GI (Heavy) | D37: m | E37: =N10 -> 0 | F37: =IF(C37="GI (Medium)",VLOOKUP(B37,data!$A$4:$D$14,4,FALSE),IF(C37="GI (Heavy)",VLOOKUP(B37,data!$A$17:$D$27,4,FALSE),0)) -> 383 | G37: =+ROUND(E37*F37,2) -> 0 | J37: HP10-125 | K37: 0 | L37: 0 | M37: =K37+L37 -> 0 | N37: =ROUNDUP(M37*1.1,0) -> 0
B38: 32 | C38: GI (Heavy) | D38: m | E38: =N11 -> 0 | F38: =IF(C38="GI (Medium)",VLOOKUP(B38,data!$A$4:$D$14,4,FALSE),IF(C38="GI (Heavy)",VLOOKUP(B38,data!$A$17:$D$27,4,FALSE),0)) -> 490 | G38: =+ROUND(E38*F38,2) -> 0 | J38: HP10-140 | L38: 0 | M38: =K38+L38 -> 0 | N38: =ROUNDUP(M38*1.1,0) -> 0
B39: 40 | C39: GI (Heavy) | D39: m | E39: =N12 -> 0 | F39: =IF(C39="GI (Medium)",VLOOKUP(B39,data!$A$4:$D$14,4,FALSE),IF(C39="GI (Heavy)",VLOOKUP(B39,data!$A$17:$D$27,4,FALSE),0)) -> 565 | G39: =+ROUND(E39*F39,2) -> 0 | J39: HP10-160 | L39: 726 | M39: =K39+L39 -> 726 | N39: =ROUNDUP(M39*1.1,0) -> 799
B40: 50 | C40: GI (Heavy) | D40: m | E40: =N13 -> 0 | F40: =IF(C40="GI (Medium)",VLOOKUP(B40,data!$A$4:$D$14,4,FALSE),IF(C40="GI (Heavy)",VLOOKUP(B40,data!$A$17:$D$27,4,FALSE),0)) -> 823 | G40: =+ROUND(E40*F40,2) -> 0 | J40: HP10-180 | L40: 0 | M40: =K40+L40 -> 0 | N40: =ROUNDUP(M40*1.1,0) -> 0
...

Sheet Pipe
A1: Procurement of Pipes
I2: Rate of HDPE Pipe = | J2: 250
A3: S.No. | B3: Pipe size and series | D3: Unit | E3: Quantity | F3: Rate | G3: Amount
F4: Rs./unit | G4: Rs.
A5: 1 | B5: HDPE pipes
K6: Scheme 1
B7: 32 | C7: 6 | D7: m | E7: =N19 -> 0 | F7: =ROUND(VLOOKUP(B7+C7,data!$A$31:$E$89,4,FALSE)*J$2,2) -> 56.5 | G7: =+ROUND(E7*F7,2) -> 0 | K7: Tr | L7: Dr | M7: Total | N7: DL
B8: 40 | C8: 6 | D8: m | E8: =N20 -> 0 | F8: =ROUND(VLOOKUP(B8+C8,data!$A$31:$E$89,4,FALSE)*J$2,2) -> 87.5 | G8: =+ROUND(E8*F8,2) -> 0 | J8: GPM-15 | K8: 0 | L8: 0 | M8: =K8+L8 -> 0 | N8: =ROUNDUP(M8*1.1,0) -> 0
B9: 50 | C9: 6 | D9: m | E9: =N21 -> 0 | F9: =ROUND(VLOOKUP(B9+C9,data!$A$31:$E$89,4,FALSE)*J$2,2) -> 135.5 | G9: =+ROUND(E9*F9,2) -> 0 | J9: GPM-20 | K9: 0 | L9: 0 | M9: =K9+L9 -> 0 | N9: =ROUNDUP(M9*1.1,0) -> 0
B10: 63 | C10: 6 | D10: m | E10: =N22 -> 0 | F10: =ROUND(VLOOKUP(B10+C10,data!$A$31:$E$89,4,FALSE)*J$2,2) -> 212.5 | G10: =+ROUND(E10*F10,2) -> 0 | J10: GPM-25 | K10: 0 | L10: 0 | M10: =K10+L10 -> 0 | N10: =ROUNDUP(M10*1.1,0) -> 0
B11: 75 | C11: 6 | D11: m | E11: =N23 -> 0 | F11: =ROUND(VLOOKUP(B11+C11,data!$A$31:$E$89,4,FALSE)*J$2,2) -> 297.75 | G11: =+ROUND(E11*F11,2) -> 0 | J11: GPM-32 | K11: 0 | L11: 0 | M11: =K11+L11 -> 0 | N11: =ROUNDUP(M11*1.1,0) -> 0
B12: 90 | C12: 6 | D12: m | E12: =N24 -> 0 | F12: =ROUND(VLOOKUP(B12+C12,data!$A$31:$E$89,4,FALSE)*J$2,2) -> 428.75 | G12: =+ROUND(E12*F12,2) -> 0 | J12: GPM-40 | K12: 0 | L12: 0 | M12: =K12+L12 -> 0 | N12: =ROUNDUP(M12*1.1,0) -> 0
B13: 110 | C13: 6 | D13: m | E13: =N25 -> 0 | F13: =ROUND(VLOOKUP(B13+C13,data!$A$31:$E$89,4,FALSE)*J$2,2) -> 636.25 | G13: =+ROUND(E13*F13,2) -> 0 | J13: GPM-50 | K13: 0 | L13: 0 | M13: =K13+L13 -> 0 | N13: =ROUNDUP(M13*1.1,0) -> 0
B14: 125 | C14: 6 | D14: m | E14: =N26 -> 0 | F14: =ROUND(VLOOKUP(B14+C14,data!$A$31:$E$89,4,FALSE)*J$2,2) -> 823.25 | G14: =+ROUND(E14*F14,2) -> 0 | J14: GPM-65 | K14: 0 | L14: 0 | M14: =K14+L14 -> 0 | N14: =ROUNDUP(M14*1.1,0) -> 0
B15: 16 | C15: 10 | D15: m | E15: =N27 -> 0 | F15: =ROUND(VLOOKUP(B15+C15,data!$A$31:$E$89,4,FALSE)*J$2,2) -> 23 | G15: =+ROUND(E15*F15,2) -> 0 | J15: GPM-80 | K15: 0 | L15: 0 | M15: =K15+L15 -> 0 | N15: =ROUNDUP(M15*1.1,0) -> 0
B16: 20 | C16: 10 | D16: m | E16: =N28 -> 0 | F16: =ROUND(VLOOKUP(B16+C16,data!$A$31:$E$89,4,FALSE)*J$2,2) -> 33.5 | G16: =+ROUND(E16*F16,2) -> 0 | J16: GPM-100 | K16: 100 | L16: =1334.8+641.68 -> 1976.48 | M16: =K16+L16 -> 2076.48 | N16: =ROUNDUP(M16*1.1,0) -> 2285 | O16: scheme 2
B17: 25 | C17: 10 | D17: m | E17: =N29 -> 0 | F17: =ROUND(VLOOKUP(B17+C17,data!$A$31:$E$89,4,FALSE)*J$2,2) -> 50.5 | G17: =+ROUND(E17*F17,2) -> 0 | J17: GPM-125 | M17: =K17+L17 -> 0 | N17: =ROUNDUP(M17*1.1,0) -> 0 | O17: scheme 1
B18: 32 | C18: 10 | D18: m | E18: =N30 -> 0 | F18: =ROUND(VLOOKUP(B18+C18,data!$A$31:$E$89,4,FALSE)*J$2,2) -> 83.5 | G18: =+ROUND(E18*F18,2) -> 0 | J18: GPM-150 | K18: 158.63 | L18: 1231 | M18: =K18+L18 -> 1389.63 | N18: =ROUNDUP(M18*1.1,0) -> 1529
B19: 40 | C19: 10 | D19: m | E19: =N31 -> 0 | F19: =ROUND(VLOOKUP(B19+C19,data!$A$31:$E$89,4,FALSE)*J$2,2) -> 128.5 | G19: =+ROUND(E19*F19,2) -> 0 | J19: HP6-32 | M19: =K19+L19 -> 0 | N19: =ROUNDUP(M19*1.1,0) -> 0
B20: 50 | C20: 10 | D20: m | E20: =N32 -> 0 | F20: =ROUND(VLOOKUP(B20+C20,data!$A$31:$E$89,4,FALSE)*J$2,2) -> 199 | G20: =+ROUND(E20*F20,2) -> 0 | J20: HP6-40 | M20: =K20+L20 -> 0 | N20: =ROUNDUP(M20*1.1,0) -> 0
B21: 63 | C21: 10 | D21: m | E21: =N33 -> 0 | F21: =ROUND(VLOOKUP(B21+C21,data!$A$31:$E$89,4,FALSE)*J$2,2) -> 317.25 | G21: =+ROUND(E21*F21,2) -> 0 | J21: HP6-50 | M21: =K21+L21 -> 0 | N21: =ROUNDUP(M21*1.1,0) -> 0
B22: 75 | C22: 10 | D22: m | E22: =N34 -> 0 | F22: =ROUND(VLOOKUP(B22+C22,data!$A$31:$E$89,4,FALSE)*J$2,2) -> 445.5 | G22: =+ROUND(E22*F22,2) -> 0 | J22: HP6-63 | M22: =K22+L22 -> 0 | N22: =ROUNDUP(M22*1.1,0) -> 0
B23: 90 | C23: 10 | D23: m | E23: =N35 -> 0 | F23: =ROUND(VLOOKUP(B23+C23,data!$A$31:$E$89,4,FALSE)*J$2,2) -> 642 | G23: =+ROUND(E23*F23,2) -> 0 | J23: HP6-75 | M23: =K23+L23 -> 0 | N23: =ROUNDUP(M23*1.1,0) -> 0 | Q23: 1379.6
B24: 110 | C24: 10 | D24: m | E24: =N36 -> 0 | F24: =ROUND(VLOOKUP(B24+C24,data!$A$31:$E$89,4,FALSE)*J$2,2) -> 950.25 | G24: =+ROUND(E24*F24,2) -> 0 | J24: HP6-90 | M24: =K24+L24 -> 0 | N24: =ROUNDUP(M24*1.1,0) -> 0
B25: 125 | C25: 10 | D25: m | E25: =N37 -> 0 | F25: =ROUND(VLOOKUP(B25+C25,data!$A$31:$E$89,4,FALSE)*J$2,2) -> 1240.5 | G25: =+ROUND(E25*F25,2) -> 0 | J25: HP6-110 | M25: =K25+L25 -> 0 | N25: =ROUNDUP(M25*1.1,0) -> 0
B26: 110 | C26: 4 | D26: m | F26: =ROUND(VLOOKUP(B26+C26,data!$A$31:$E$89,4,FALSE)*J$2,2) -> 425.75 | G26: =+ROUND(E26*F26,2) -> 0 | J26: HP6-125 | M26: =K26+L26 -> 0 | N26: =ROUNDUP(M26*1.1,0) -> 0
B27: 63 | C27: 4 | D27: m | F27: =ROUND(VLOOKUP(B27+C27,data!$A$31:$E$89,4,FALSE)*J$2,2) -> 146.25 | G27: =+ROUND(E27*F27,2) -> 0 | J27: HP10-16 | M27: =K27+L27 -> 0 | N27: =ROUNDUP(M27*1.1,0) -> 0
B28: 250 | C28: 10 | D28: m | E28: =N43 -> 1518 | F28: =ROUND(VLOOKUP(B28+C28,data!$A$31:$E$89,4,FALSE)*J$2,2) -> 4939.25 | G28: =+ROUND(E28*F28,2) -> 7497781.5 | J28: HP10-20 | M28: =K28+L28 -> 0 | N28: =ROUNDUP(M28*1.1,0) -> 0
J29: HP10-25 | M29: =K29+L29 -> 0 | N29: =ROUNDUP(M29*1.1,0) -> 0
C30: Subtotal | E30: =SUM(E7:E29) -> 1518 | F30: Rs. | G30: =SUM(G7:G29) -> 7497781.5 | J30: HP10-32 | M30: =K30+L30 -> 0 | N30: =ROUNDUP(M30*1.1,0) -> 0
B31: Add transportation cost | F31: 5 | G31: =F31*G30/100 -> 374889.08 | J31: HP10-40 | M31: =K31+L31 -> 0 | N31: =ROUNDUP(M31*1.1,0) -> 0
C32: Total | G32: =SUM(G30:G31) -> 7872670.6 | J32: HP10-50 | M32: =K32+L32 -> 0 | N32: =ROUNDUP(M32*1.1,0) -> 0
B33: Value added Tax | F33: ='Entry for Rates'!$F$114 -> 13 | G33: =F33*G32/100 -> 1023447.2 | J33: HP10-63 | M33: =K33+L33 -> 0 | N33: =ROUNDUP(M33*1.1,0) -> 0
B34: Total cost of HDPE pipes | F34: Rs. | G34: =+G33+G32 -> 8896117.7 | J34: HP10-75 | K34: 0 | L34: 0 | M34: =K34+L34 -> 0 | N34: =ROUNDUP(M34*1.1,0) -> 0
A35: 2 | B35: GI pipes | J35: HP10-90 | K35: 0 | L35: 0 | M35: =K35+L35 -> 0 | N35: =ROUNDUP(M35*1.1,0) -> 0
B36: 15 | C36: GI (Heavy) | D36: m | E36: =N8 -> 0 | F36: =IF(C36="GI (Medium)",VLOOKUP(B36,data!$A$4:$D$14,4,FALSE),IF(C36="GI (Heavy)",VLOOKUP(B36,data!$A$17:$D$27,4,FALSE),0)) -> 203 | G36: =+ROUND(E36*F36,2) -> 0 | J36: HP10-110 | K36: 0 | L36: 0 | M36: =K36+L36 -> 0 | N36: =ROUNDUP(M36*1.1,0) -> 0
B37: 25 | C37: GI (Heavy) | D37: m | E37: =N10 -> 0 | F37: =IF(C37="GI (Medium)",VLOOKUP(B37,data!$A$4:$D$14,4,FALSE),IF(C37="GI (Heavy)",VLOOKUP(B37,data!$A$17:$D$27,4,FALSE),0)) -> 383 | G37: =+ROUND(E37*F37,2) -> 0 | J37: HP10-125 | K37: 0 | L37: 0 | M37: =K37+L37 -> 0 | N37: =ROUNDUP(M37*1.1,0) -> 0
B38: 32 | C38: GI (Heavy) | D38: m | E38: =N11 -> 0 | F38: =IF(C38="GI (Medium)",VLOOKUP(B38,data!$A$4:$D$14,4,FALSE),IF(C38="GI (Heavy)",VLOOKUP(B38,data!$A$17:$D$27,4,FALSE),0)) -> 490 | G38: =+ROUND(E38*F38,2) -> 0 | J38: HP10-140 | M38: =K38+L38 -> 0 | N38: =ROUNDUP(M38*1.1,0) -> 0
B39: 40 | C39: GI (Heavy) | D39: m | E39: =N12 -> 0 | F39: =IF(C39="GI (Medium)",VLOOKUP(B39,data!$A$4:$D$14,4,FALSE),IF(C39="GI (Heavy)",VLOOKUP(B39,data!$A$17:$D$27,4,FALSE),0)) -> 565 | G39: =+ROUND(E39*F39,2) -> 0 | J39: HP10-160 | M39: =K39+L39 -> 0 | N39: =ROUNDUP(M39*1.1,0) -> 0
B40: 50 | C40: GI (Heavy) | D40: m | E40: =N13 -> 0 | F40: =IF(C40="GI (Medium)",VLOOKUP(B40,data!$A$4:$D$14,4,FALSE),IF(C40="GI (Heavy)",VLOOKUP(B40,data!$A$17:$D$27,4,FALSE),0)) -> 823 | G40: =+ROUND(E40*F40,2) -> 0 | J40: HP10-180 | M40: =K40+L40 -> 0 | N40: =ROUNDUP(M40*1.1,0) -> 0
...

Sheet Qty Truss
A1: Details Quantity Estimate Truss
A2: S.N. | B2: Description of Works | C2: Nos. | D2: Length (ft) | E2: Breadth (ft) | F2: Height (ft) | G2: Quantity | H2: Unit | I2: Remark
A3: 1 | B3: Site Clearance Work:
C4: 1 | G4: =F4*E4*D4*C4 -> 0 | H4: Job
A6: 2 | B6: Earthwork in Excavation:
C7: 9 | D7: 2 | E7: 2 | F7: 2.5 | G7: =PRODUCT(C7:F7) -> 90
G8: =PRODUCT(C8:F8) -> 0
E9: Total (Cft) | G9: =SUM(G7:G8) -> 90 | H9: Cft
A10: 3 | B10: Earthwork in Backfilling:
C11: 1 | D11: @ 30% of Excavation: | G11: =0.3*G9 -> 27 | H11: Cft
A12: 4 | B12: Brick Soling Works
B13: At Foundation | C13: 9 | D13: 2 | E13: 2 | G13: =PRODUCT(C13:F13) -> 36
E14: Total (Sft) | G14: =SUM(G13:G13) -> 36 | H14: Sft
A15: 5 | B15: 3" PCC Work:
B16: At Foundation | C16: 9 | D16: 2 | E16: 2 | G16: =PRODUCT(C16:F16) -> 36
G17: =PRODUCT(C17:F17) -> 0
E18: Total (Sft) | G18: =SUM(G16:G17) -> 36 | H18: Sft
A19: 6 | B19: PCC for lintel ( 1:1.5:3)
B20: For Foundation of 4" Pipe | C20: 9 | D20: 1 | E20: 1 | F20: 0.5 | G20: =PRODUCT(C20:F20) -> 4.5
B21: Total | G21: =SUM(G20:G20) -> 4.5 | H21: Cft
A23: 7 | B23: Brick Work:
B24: Below DPC: 1st step | C24: 9 | D24: 4 | E24: CSA | F24: 1 | G24: =PRODUCT(C24:F24) -> 36
