Workbook
Name description_262: [1]Abstract!$B$34
Name description_6: [1]Abstract!$B$172

Sheet Sheet1
A1: 152 | B1: ;'Vvf O{6f RofK6f] 5fKg] sfd .
A2: H 15 | B2: b/ ljZn]if0fsf] nflu !) j=dL= lnOPsf]
B3: ;|f]t ;fwg | C3: tx÷lsl;d | D3: kl/df0f | E3: PsfO{ | F3: b/ k|lt PsfO{ | G3: /sd | H3: k|To]s ;|f]t ;fwgsf] hDdf
B4: >lds | C4: s_ l;kfn' | D4: 0.5 | E4: hjfg | F4: 1330 | G4: =FLOOR(D4*F4,0.01) -> 665
C5: v_ HofdL | D5: 1 | E5: hjfg | F5: 1000 | G5: =FLOOR(D5*F5,0.01) -> 1000 | H5: =SUM(G4+G5) -> 1665
B6: lgdf{0f ;fdu|L | C6: O{6f | D6: =420*0 -> 0 | E6: uf]6f | F6: 15.145 | G6: =FLOOR(D6*F6,0.01) -> 0
C7: jfn'jf vf]nfsf] | D7: =0.71*0 -> 0 | E7: 3=dL= | F7: 3389.76 | G7: =FLOOR(D7*F7,0.01) -> 0 | H7: =SUM(G6:G7) -> 0
F8: jf:tljs b//]6 | H8: =SUM(H7,H5) -> 1665
B9: b/ k|lt j=dL=sf] | F9: !%Ü 7]s]bf/ cf]e/x]8 | H9: =FLOOR(H8*0.15,0.01) -> 249.75
B10: =+H10 -> 1914.75 | C10: Ö ?= | D10: =INT(B10/B11*100)/100 -> 191.47 | E10: k}= | F10: hDdf b/ /]6 | H10: =SUM(H8:H9) -> 1914.75
B11: 10

Sheet Size of water tank
A1: Length | B1: Breadth | C1: Height | D1: Slab thickness | E1: Cover for slab | F1: Shear wall thickness | G1: Cover for shear wall | H1: Soiling thickness | I1: PCC | J1: Vertical rebar | K1: Opening | M1: Fillet
K2: Length | L2: Breadth | M2: Length | N2: Height
A3: =14.5/3.281 -> 4.4193843 | B3: =14/3.281 -> 4.2669918 | C3: =5.5/3.281 -> 1.6763182 | D3: 0.125 | E3: 0.025 | F3: =8/12/3.281 -> 0.20319008 | G3: =1.5/12/3.281 -> 0.038098141 | H3: 0.05 | I3: 0.075 | J3: 8 | K3: =2/3.281 -> 0.60957025 | L3: =2/3.281 -> 0.60957025 | M3: =1/3.281 -> 0.30478513 | N3: =1/3.281 -> 0.30478513
J4: =57*J3/1000 -> 0.456 | M4: =SQRT(('Size of water tank'!M3)^2+('Size of water tank'!N3)^2) -> 0.43103126

Sheet estimated
A1: Government of Nepal
A2: Shankharapur Municipality
A3: Shankhu, Kathmandu
A4: Detail Estimate Sheet
A5: Project:-gfªn]ef/] :jf:yo rf}sL kfgL 6\ofÍL dd{t tyf j8f sfof{no sDkfp08 /+u/f]ug | J5: F.Y.:-2083/084
A6: Location:- Shankharapur Municipality- 1 | H6: Date: 2082/04/01
A8: S.N. | B8: Description of work | C8: No. | D8: Length | E8: Breadth | F8: Height | G8: Quantity | H8: Unit | I8: Rate | J8: Amount | K8: Remark
A9: A. | B9: kfgL 6\ofÍL dd{t
A10: 1 | B10: Kn]g l;d]G6 sqmL6 jf jh| s+qmL6 eTsfO{ !) dL= k/ x6fpg] sfd
B11: -water tank | C11: 1 | D11: 5 | E11: =11/3.281 -> 3.3526364 | F11: 0.075 | G11: =PRODUCT(C11:F11) -> 1.2572386
G12: =SUM(G11:G11) -> 1.2572386 | H12: cum | I12: =3740 -> 3740 | J12: =G12*I12 -> 4702.0725
A14: 2 | B14: l;d]G6 jf jh|df hf]8]sf] uf/f] eTsfO{ To;af6 cfPsf] ;fdfu+|L !) dL
B15: =B11 -> -water tank | C15: 2 | D15: =D11 -> 5 | E15: 0.23 | F15: 1.4 | G15: =PRODUCT(C15:F15) -> 3.22
C16: 2 | D16: =E11-0.23*2 -> 2.8926364 | E16: 0.23 | F16: 1.4 | G16: =PRODUCT(C16:F16) -> 1.8628578
C17: 1 | D17: =D11 -> 5 | E17: 0.23 | F17: 0.45 | G17: =PRODUCT(C17:F17) -> 0.5175
G18: =SUM(G15:G17) -> 5.6003578 | H18: cum | I18: =1982.2 -> 1982.2 | J18: =G18*I18 -> 11101.029
A20: 3 | B20: ;fx|f] k|sf/sf] Sn], g/d d'/d 9'+uf -#) ;]=dL=;Dd_ ld;]sf] df6f]df ;j} lsl;dsf] vGg] sfd
C21: 1 | D21: ='Size of water tank'!A3+0.15 -> 4.5693843 | E21: ='Size of water tank'!B3+0.15 -> 4.4169918 | F21: 0.125 | G21: =PRODUCT(C21:F21) -> 2.5228666
G22: =SUM(G21) -> 2.5228666 | H22: cum | I22: =770.43 -> 770.43 | J22: =G22*I22 -> 1943.6921
A24: 4 | B24: ;'Vvf O{6f RofK6f] 5fKg] sfd
B25: -for flooring | C25: =C21 -> 1 | D25: =D21 -> 4.5693843 | E25: =E21 -> 4.4169918 | G25: =PRODUCT(C25:F25) -> 20.182933
G26: =SUM(G25) -> 20.182933 | H26: sqm | I26: =Sheet1!H8/10 -> 166.5 | J26: =G26*I26 -> 3360.4583
A28: 5 | B28: hu leQf kvf{ndf l;d]G6 s+lqm6 ug]{ sfd -lk=;L=;L= !M@M$_
B29: =B25 -> -for flooring | C29: =C21 -> 1 | D29: =D21 -> 4.5693843 | E29: =E21 -> 4.4169918 | F29: ='Size of water tank'!I3 -> 0.075 | G29: =PRODUCT(C29:F29) -> 1.51372
G30: =SUM(G29) -> 1.51372 | H30: cum | I30: =13351.1 -> 13351.1 | J30: =G30*I30 -> 20209.827
A32: 6 | B32: cf/=;L=;L= nflu !) ld=ld= kmnfd] 808L sf6\g], df]8\g] #) dL6/ ;Dd
B33: -Along long length | C33: =TRUNC(('Size of water tank'!A3-'Size of water tank'!G3*2)/0.15,0)+1 -> 29 | D33: =('Size of water tank'!B3-'Size of water tank'!G3*2)+(('Size of water tank'!C3+'Size of water tank'!D3*2-'Size of water tank'!E3*4)*2)+((57*'Size of water tank'!J3/1000)*2) -> 8.7554319 | F33: =10*10/162 -> 0.61728395 | G33: =PRODUCT(C33:F33) -> 156.73304
C34: =TRUNC(('Size of water tank'!A3-'Size of water tank'!F3*2+'Size of water tank'!G3*2)/0.15,0)+1 -> 28 | D34: =('Size of water tank'!B3-'Size of water tank'!F3*2+'Size of water tank'!G3*2)+(('Size of water tank'!C3+'Size of water tank'!D3*2-'Size of water tank'!E3*4)*2)+((57*'Size of water tank'!J3/1000)*2) -> 8.5014443 | F34: =10*10/162 -> 0.61728395 | G34: =PRODUCT(C34:F34) -> 146.93854
B35: -Along short length | C35: =TRUNC(('Size of water tank'!B3-'Size of water tank'!G3*2)/0.15,0)+1 -> 28 | D35: =('Size of water tank'!A3-'Size of water tank'!G3*2)+(('Size of water tank'!C3+'Size of water tank'!D3*2-'Size of water tank'!E3*4)*2)+((57*'Size of water tank'!J3/1000)*2) -> 8.9078244 | F35: =10*10/162 -> 0.61728395 | G35: =PRODUCT(C35:F35) -> 153.9624
C36: =TRUNC(('Size of water tank'!B3-'Size of water tank'!F3*2+'Size of water tank'!G3*2)/0.15,0)+1 -> 27 | D36: =('Size of water tank'!A3-'Size of water tank'!F3*2+'Size of water tank'!G3*2)+(('Size of water tank'!C3+'Size of water tank'!D3*2-'Size of water tank'!E3*4)*2)+((57*'Size of water tank'!J3/1000)*2) -> 8.6538368 | F36: =10*10/162 -> 0.61728395 | G36: =PRODUCT(C36:F36) -> 144.23061
B37: -binder | C37: =TRUNC(('Size of water tank'!C3+'Size of water tank'!D3-'Size of water tank'!E3)/0.15,0)+1 -> 12 | D37: =('Size of water tank'!A3-'Size of water tank'!G3*2)*2+('Size of water tank'!B3-'Size of water tank'!G3*2)*2 -> 17.067967 | F37: =8*8/162 -> 0.39506173 | G37: =PRODUCT(C37:F37) -> 80.914807
C38: =TRUNC(('Size of water tank'!C3+'Size of water tank'!E3)/0.15,0)+1 -> 12 | D38: =('Size of water tank'!A3-'Size of water tank'!F3*2+'Size of water tank'!G3*2)*2+('Size of water tank'!B3-'Size of water tank'!F3*2+'Size of water tank'!G3*2)*2 -> 16.052017 | F38: =8*8/162 -> 0.39506173 | G38: =PRODUCT(C38:F38) -> 76.098449
B39: -Slab | C39: =2*(TRUNC(('Size of water tank'!B3-'Size of water tank'!G3*2)/0.15,0)+1) -> 56 | D39: ='Size of water tank'!A3 -> 4.4193843 | F39: =8*8/162 -> 0.39506173 | G39: =PRODUCT(C39:F39) -> 97.772058
C40: =2*(TRUNC(('Size of water tank'!A3-'Size of water tank'!G3*2)/0.15,0)+1) -> 58 | D40: ='Size of water tank'!B3 -> 4.2669918 | F40: =8*8/162 -> 0.39506173 | G40: =PRODUCT(C40:F40) -> 97.772058
B41: -deduction for opening | C41: =-2*(TRUNC('Size of water tank'!L3/0.15,0)+1) -> -10 | D41: ='Size of water tank'!K3 -> 0.60957025 | F41: =8*8/162 -> 0.39506173 | G41: =PRODUCT(C41:F41) -> -2.4081788
C42: =-2*(TRUNC('Size of water tank'!K3/0.15,0)+1) -> -10 | D42: ='Size of water tank'!L3 -> 0.60957025 | F42: =8*8/162 -> 0.39506173 | G42: =PRODUCT(C42:F42) -> -2.4081788
B43: -for fillet | C43: =2*(TRUNC(((('Size of water tank'!A3-'Size of water tank'!F3*2)+('Size of water tank'!A3-'Size of water tank'!F3*2-'Size of water tank'!M3*2))/2)/0.15,0)+1) -> 50 | D43: =(2*57*('Size of water tank'!J3/1000))+SQRT(('Size of water tank'!M3)^2+('Size of water tank'!N3)^2) -> 1.3430313 | F43: =8*8/162 -> 0.39506173 | G43: =PRODUCT(C43:F43) -> 26.529013
C44: =2*(TRUNC(((('Size of water tank'!B3-'Size of water tank'!F3*2)+('Size of water tank'!B3-'Size of water tank'!F3*2-'Size of water tank'!M3*2))/2)/0.15,0)+1) -> 48 | D44: =(2*57*('Size of water tank'!J3/1000))+SQRT(('Size of water tank'!M3)^2+('Size of water tank'!N3)^2) -> 1.3430313 | F44: =8*8/162 -> 0.39506173 | G44: =PRODUCT(C44:F44) -> 25.467852
B45: -binder | C45: =TRUNC(((SQRT(('Size of water tank'!M3)^2+('Size of water tank'!N3)^2))/0.15)+1)-2 -> 1 | D45: =(((('Size of water tank'!A3-'Size of water tank'!F3*2)+('Size of water tank'!A3-'Size of water tank'!F3*2-'Size of water tank'!M3*2))/2)+((('Size of water tank'!B3-'Size of water tank'!F3*2)+('Size of water tank'!B3-'Size of water tank'!F3*2-'Size of water tank'!M3*2))/2))*2 -> 14.528091 | F45: =8*8/162 -> 0.39506173 | G45: =PRODUCT(C45:F45) -> 5.7394928
B46: -for kitchen setup at ward office | C46: =TRUNC((D47-0.1)/0.15,0)+1 -> 5 | D46: 1.5 | F46: =12*12/162 -> 0.88888889 | G46: =PRODUCT(C46:F46) -> 6.6666667
...
