Workbook

Sheet ESTIMATE
A1: Government of Nepal
A2: Shankharapur Municipality
A3: Shankhu, Kathmandu
A4: Detail Estimate Sheet
B5: Project:- | C5: gfªn]ef/] :jf:yo rf}sL 5fgf tyf kfgL 6\ofÍL dd{t | K5: F.Y.:-2080/081
B6: Location:- Shankharapur Municipality- 1 | I6: Date: 2081/02/21 | O6: Date: 2080/05/21
B8: S.N. | C8: Description of work | D8: No. | E8: Length | F8: Breadth | G8: Height | H8: Quantity | I8: Unit | J8: Rate | K8: Amount | L8: Remarks
B9: A. | C9: kfgL 6\ofÍL dd{t
B10: 1 | C10: cf/=l;=l;= jf cf/=lj=l;= sfd eTsfO{ !) dL= k/ x6fpg] sfd | D10: 1 | E10: 4.5 | F10: 3 | G10: 0.1 | H10: =D10*E10*F10*G10 -> 1.35 | I10: cu.m. | J10: ='[1]Table of Content 2'!$H$312 -> 9900 | K10: =H10*J10 -> 13365
B12: 2 | C12: l;d]G6 jf jh| Knfi6/ eTsfO{ !) dL= k/ x6fpg] sfd | D12: 2 | E12: =E10 -> 4.5 | G12: 1.4 | H12: =D12*E12*G12 -> 12.6
D13: 2 | E13: =F10 -> 3 | G13: 1.4 | H13: =D13*E13*G13 -> 8.4
H14: =SUM(H12:H13) -> 21 | I14: sq.m. | J14: ='[1]Table of Content 2'!$H$314 -> 97.2 | K14: =H14*J14 -> 2041.2
B16: 3 | C16: e'O{+tNnfdf lrDgL e§fsf] O{+6fsf] uf/f] l;d]G6 d;nf -!M$_ df | D16: 2 | E16: =E12 -> 4.5 | F16: 0.1 | G16: 0.9 | H16: =D16*E16*F16*G16 -> 0.81
D17: 2 | E17: =E13 -> 3 | F17: 0.1 | G17: 0.9 | H17: =D17*E17*F17*G17 -> 0.54
D18: 1 | E18: =2*(5+4)/3.28 -> 5.4878049 | F18: 0.23 | G18: 0.45 | H18: =D18*E18*F18*G18 -> 0.5679878
H19: =SUM(H16:H18) -> 1.9179878 | I19: cu.m. | J19: ='[1]Table of Content 2'!$H$43 -> 14911.97 | K19: =H19*J19 -> 28600.977
C20: vat on cement | K20: ='[1]Update Descrip'!$G$397*H19*0.13 -> 359.82027
C21: vat on sand | K21: ='[1]Update Descrip'!$G$398*H19*0.13 -> 175.02559
C22: vat on brick | K22: ='[1]Update Descrip'!$G$396*H19*0.13 -> 2185.4811
B24: 4 | C24: cf/=;L=;L= nflu !) ld=ld= kmnfd] 808L sf6\g], df]8\g] #) dL6/ ;Dd | D24: =E25/0.15 -> 20 | E24: =E16 -> 4.5 | G24: =10*10/162 -> 0.61728395 | H24: =D24*E24*G24 -> 55.555556
D25: =E24/0.15 -> 30 | E25: =E17 -> 3 | G25: =10*10/162 -> 0.61728395 | H25: =D25*E25*G25 -> 55.555556
C26: vat on material | H26: =SUM(H24:H25) -> 111.11111 | I26: kg | J26: ='[1]Table of Content 2'!$H$77/1000 -> 130.21 | K26: =H26*J26 -> 14467.778
K27: =0.13*K26 -> 1880.8111
B28: 5 | C28: ;'k/ :6«Sr/, 8]s :n]a ljdx?df l;d]G6 s+lqm6 ug]{ sfd -!M!.%M#_ | D28: 1 | E28: =E16 -> 4.5 | F28: =E17 -> 3 | G28: 0.075 | H28: =D28*E28*F28*G28 -> 1.0125
D29: 2 | E29: =E16 -> 4.5 | F29: 0.15 | G29: =G16 -> 0.9 | H29: =D29*E29*F29*G29 -> 1.215
D30: 2 | E30: =E17 -> 3 | F30: 0.15 | G30: =G17 -> 0.9 | H30: =D30*E30*F30*G30 -> 0.81
H31: =SUM(H28:H30) -> 3.0375 | I31: cum | J31: ='[1]Table of Content 2'!$H$67 -> 17107.9 | K31: =H31*J31 -> 51965.246
C32: vat on cement | K32: ='[1]Update Descrip'!$G$676*H31*0.13 -> 2279.3765
C33: vat on sand | K33: ='[1]Update Descrip'!$G$679*H31*0.13 -> 420.72747
C34: vat on aggregate | K34: =('[1]Update Descrip'!$G$677+'[1]Update Descrip'!$G$678)*H31*0.13 -> 1166.4726
B36: 6 | C36: l;d]G6 s+qmL6 ˆnf]l/Ë -!M@M$_ -#* dL=dL=_ | D36: 1 | E36: =E28 -> 4.5 | F36: =F28 -> 3 | H36: =F36*E36*D36 -> 13.5 | I36: sqm | J36: ='[1]Table of Content 2'!$H$155 -> 692.38 | K36: =H36*J36 -> 9347.13
C37: vat on cement | K37: ='[1]Update Descrip'!$G$1804/10*H36*0.13 -> 329.24327
C38: vat on sand | K38: ='[1]Update Descrip'!$G$1805/10*H36*0.13 -> 79.19613
C39: vat on aggregate | K39: ='[1]Update Descrip'!$G$1806/10*H36*0.13 -> 227.54979
B41: 7 | C41: !@=% dL=dL= l;d]G6 afn'jf -!M$_ Knfi6/ | D41: =D16 -> 2 | E41: =E16 -> 4.5 | G41: =G48 -> 1.5 | H41: =D41*E41*G41 -> 13.5
D42: =D17 -> 2 | E42: =E17 -> 3 | G42: =G49 -> 1.5 | H42: =D42*E42*G42 -> 9
H43: =SUM(H41:H42) -> 22.5 | I43: sq.m. | J43: ='[1]Table of Content 2'!$H$215 -> 402.23 | K43: =H43*J43 -> 9050.175
C44: vat on cement | K44: ='[1]Update Descrip'!$G$2611/100*H43*0.13 -> 227.0932
C45: vat on sand | K45: ='[1]Update Descrip'!$G$2612/100*H43*0.13 -> 107.06173
B47: 8 | C47: # dL=dL= df]6fO{ d;Lgf] l;d]G6 3f]6\g] sfd | D47: =D28 -> 1 | E47: =E28 -> 4.5 | G47: =F28 -> 3 | H47: =D47*E47*G47 -> 13.5
...

Sheet WCR
A1: Government of Nepal
A2: Shankharapur Municipality Office
A3: Sankhu, Kathmandu
A4: Work Completion Report
A6: Total Estimated Amount: | C6: =E51 -> #REF! | G6: Total Valuated Amount : | I6: =H51 -> #REF!
A8: Project: | B8: =#REF! -> #REF! | J8: Fiscal Year:079/80
A9: Location:Shankharapur-1 | J9: Date:2079/12/21
A10: S.No. | B10: Description | C10: Estimated | F10: Valuated | I10: Difference | J10: Remarks
C11: Quantity | D11: Rate | E11: Amount (Rs) | F11: Quantity | G11: Rate | H11: Amount(Rs)
A12: 1 | B12: Earthwork in excavaiton | C12: =ESTIMATE!#REF! -> #REF! | D12: =ESTIMATE!#REF! -> #REF! | E12: =ESTIMATE!#REF! -> #REF! | F12: =#REF! -> #REF! | G12: =#REF! -> #REF! | H12: =#REF! -> #REF! | I12: =F12-C12 -> #REF!
A14: 2 | B14: Dismantle the rcc work on the base of water tank | C14: =ESTIMATE!H10 -> 1.35 | D14: =ESTIMATE!J10 -> 9900 | E14: =ESTIMATE!K10 -> 13365 | F14: =#REF! -> #REF! | G14: =#REF! -> #REF! | H14: =#REF! -> #REF! | I14: =F14-C14 -> #REF!
A16: 3 | B16: stone soling | C16: =ESTIMATE!H14 -> 21 | D16: =ESTIMATE!J14 -> 97.2 | E16: =ESTIMATE!K14 -> 2041.2 | F16: =#REF! -> #REF! | G16: =#REF! -> #REF! | H16: =#REF! -> #REF! | I16: =F16-C16 -> #REF!
B17: vat on stone | E17: =ESTIMATE!K15 -> 0 | H17: =#REF! -> #REF!
A19: 4 | B19: Dry Stone Masonry work | C19: =ESTIMATE!#REF! -> #REF! | D19: =ESTIMATE!#REF! -> #REF! | E19: =ESTIMATE!#REF! -> #REF! | F19: =#REF! -> #REF! | G19: =#REF! -> #REF! | H19: =#REF! -> #REF! | I19: =F19-C19 -> #REF!
B20: vat on stone | E20: =ESTIMATE!#REF! -> #REF! | H20: =#REF! -> #REF!
A22: 5 | B22: Brick Masonry work in 1:6 | C22: =ESTIMATE!H19 -> 1.9179878 | D22: =ESTIMATE!J19 -> 14911.97 | E22: =ESTIMATE!K19 -> 28600.977 | F22: =#REF! -> #REF! | G22: =#REF! -> #REF! | H22: =#REF! -> #REF! | I22: =F22-C22 -> #REF!
B23: vat on cement | E23: =ESTIMATE!K20 -> 359.82027 | H23: =#REF! -> #REF!
B24: vat on brick | E24: =ESTIMATE!K21 -> 175.02559 | H24: =#REF! -> #REF!
B25: vat on sand | E25: =ESTIMATE!K22 -> 2185.4811 | H25: =#REF! -> #REF!
A27: 6 | B27: RCC works 1:1.5:3 ratio in water collection chamber with all work complete | C27: =ESTIMATE!H31 -> 3.0375 | D27: =ESTIMATE!J31 -> 17107.9 | E27: =ESTIMATE!K31 -> 51965.246 | F27: =#REF! -> #REF! | G27: =#REF! -> #REF! | H27: =#REF! -> #REF! | I27: =F27-C27 -> #REF!
B28: vat on cement | E28: =ESTIMATE!K32 -> 2279.3765 | H28: =#REF! -> #REF!
B29: vat on aggregate | E29: =ESTIMATE!K33 -> 420.72747 | H29: =#REF! -> #REF!
B30: vat on sand | E30: =ESTIMATE!K34 -> 1166.4726 | H30: =#REF! -> #REF!
A32: 7 | B32: 3mm punning all complete work | C32: =ESTIMATE!#REF! -> #REF! | D32: =ESTIMATE!#REF! -> #REF! | E32: =ESTIMATE!#REF! -> #REF! | F32: =#REF! -> #REF! | G32: =#REF! -> #REF! | H32: =#REF! -> #REF! | I32: =F32-C32 -> #REF!
B33: vat on cement | E33: =ESTIMATE!K37 -> 329.24327 | H33: =#REF! -> #REF!
A35: 8 | B35: plastering work | C35: =ESTIMATE!H43 -> 22.5 | D35: =ESTIMATE!J43 -> 402.23 | E35: =ESTIMATE!K43 -> 9050.175 | F35: =#REF! -> #REF! | G35: =#REF! -> #REF! | H35: =#REF! -> #REF! | I35: =F35-C35 -> #REF!
B36: vat on cement | E36: =ESTIMATE!K44 -> 227.0932 | H36: =#REF! -> #REF!
B37: vat on sand | E37: =ESTIMATE!K45 -> 107.06173 | H37: =#REF! -> #REF!
A39: 9 | B39: tap and fittings | C39: =ESTIMATE!H54 -> 1 | D39: =ESTIMATE!J54 -> 4659 | E39: =ESTIMATE!K54 -> 4659 | F39: =#REF! -> #REF! | G39: =#REF! -> #REF! | H39: =#REF! -> #REF! | I39: =F39-C39 -> #REF!
A41: 10 | B41: Iron frame for barbed wire | C41: =ESTIMATE!#REF! -> #REF! | D41: =ESTIMATE!#REF! -> #REF! | E41: =ESTIMATE!#REF! -> #REF! | F41: =#REF! -> #REF! | G41: =#REF! -> #REF! | H41: =#REF! -> #REF! | I41: =F41-C41 -> #REF!
B42: Vat on iron frame | E42: =ESTIMATE!#REF! -> #REF! | H42: =#REF! -> #REF!
A44: 11 | B44: Barbed wire | C44: =ESTIMATE!#REF! -> #REF! | D44: =ESTIMATE!#REF! -> #REF! | E44: =ESTIMATE!#REF! -> #REF! | F44: =#REF! -> #REF! | G44: =#REF! -> #REF! | H44: =#REF! -> #REF! | I44: =F44-C44 -> #REF!
B45: vat on barbed wire | E45: =ESTIMATE!#REF! -> #REF! | H45: =#REF! -> #REF!
A47: 12 | B47: Roof top PVC Water Tank | C47: =ESTIMATE!#REF! -> #REF! | D47: =ESTIMATE!#REF! -> #REF! | E47: =ESTIMATE!#REF! -> #REF! | F47: =#REF! -> #REF! | G47: =#REF! -> #REF! | H47: =#REF! -> #REF! | I47: =F47-C47 -> #REF!
B48: vat on pvc water tank | E48: =ESTIMATE!#REF! -> #REF! | H48: =#REF! -> #REF!
A50: 12 | B50: Information Board | C50: 1 | D50: 500 | E50: 500 | F50: =#REF! -> #REF! | G50: =#REF! -> #REF! | H50: =#REF! -> #REF! | I50: =F50-C50 -> #REF!
B51: Total | E51: =SUM(E12:E50) -> #REF! | H51: =SUM(H12:H50) -> #REF!

Sheet me
A1: Government of Nepal
A2: Shankharapur Municipality
A3: Shankhu, Kathmandu
A4: Detail Estimate Sheet
A5: Project:-gfªn]ef/] :jf:yo rf}sL kfgL 6\ofÍL dd{t tyf j8f sfof{no sDkfp08 /+u/f]ug | J5: F.Y.:-2082/083
A6: Location:- Shankharapur Municipality- 1 | H6: Date: 2082/04/01
A8: S.N. | B8: Description of work | C8: No. | D8: Length | E8: Breadth | F8: Height | G8: Quantity | H8: Unit | I8: Rate | J8: Amount | K8: Remark
A9: A. | B9: kfgL 6\ofÍL dd{t
A10: 1 | B10: Kn]g l;d]G6 sqmL6 jf jh| s+qmL6 eTsfO{ !) dL= k/ x6fpg] sfd
B11: -water tank | C11: 1 | D11: 5 | E11: =11/3.281 -> 3.3526364 | F11: 0.075 | G11: =C11*D11*E11*F11 -> 1.2572386
G12: =SUM(G11:G11) -> 1.2572386 | H12: cum | I12: 4000 | J12: =G12*I12 -> 5028.9546
A14: 2 | B14: l;d]G6 jf jh|df hf]8]sf] uf/f] eTsfO{ To;af6 cfPsf] ;fdfu+|L !) dL
B15: =B11 -> -water tank | C15: 2 | D15: =D11 -> 5 | E15: 0.23 | F15: 1.4 | G15: =C15*D15*F15 -> 14
C16: 2 | D16: =E11-0.23*2 -> 2.8926364 | E16: 0.23 | F16: 1.4 | G16: =C16*D16*F16 -> 8.0993819
C17: 1 | D17: =D11 -> 5 | E17: 0.23 | F17: 0.45 | G17: =C17*D17*F17 -> 2.25
G18: =SUM(G15:G17) -> 24.349382 | H18: cum | I18: 2120 | J18: =G18*I18 -> 51620.69
A20: 3 | B20: ;fx|f] k|sf/sf] Sn], g/d d'/d 9'+uf -#) ;]=dL=;Dd_ ld;]sf] df6f]df ;j} lsl;dsf] vGg] sfd
C21: =C11 -> 1 | D21: =D11 -> 5 | E21: =E11 -> 3.3526364 | F21: 0.3 | G21: =C21*D21*E21*F21 -> 5.0289546
G22: =SUM(G21) -> 5.0289546 | H22: cum | I22: 824 | J22: =G22*I22 -> 4143.8586
A24: 4 | B24: ;'Vvf O{6f RofK6f] 5fKg] sfd
B25: -for flooring | C25: =C17 -> 1 | D25: =D17 -> 5 | E25: =E21 -> 3.3526364 | G25: =PRODUCT(C25:F25) -> 16.763182
G26: =SUM(G25) -> 16.763182 | H26: sqm | I26: =Sheet1!H8/10 -> 166.5 | J26: =G26*I26 -> 2791.0698
A28: 5 | B28: hu leQf kvf{ndf l;d]G6 s+lqm6 ug]{ sfd -lk=;L=;L= !M@M$_
B29: =B25 -> -for flooring | C29: =C25 -> 1 | D29: =D25 -> 5 | E29: =E25 -> 3.3526364 | F29: 0.075 | G29: =C29*D29*E29*F29 -> 1.2572386
G30: =SUM(G29) -> 1.2572386 | H30: cum | I30: 13944.36 | J30: =G30*I30 -> 17531.388
B31: 13% VAT on cement | J31: =0.13*G30*4169.92 -> 681.536
B32: 13% VAT on sand | J32: =0.13*G30*1508.44 -> 246.54098
B33: 13% VAT on aggregate | J33: =0.13*G30*(1744.31+776.82+372.87) -> 472.99832
B34: 13% VAT on water | J34: =0.13*G30*(42) -> 6.864523
A36: 6 | B36: cf/=;L=;L= nflu !) ld=ld= kmnfd] 808L sf6\g], df]8\g] #) dL6/ ;Dd
B37: -Along long length | C37: 33 | D37: =(2+5.917+16.17+5.917+2)/3.281 -> 9.7543432 | F37: =10*10/162 -> 0.61728395 | G37: =C37*D37*F37 -> 198.69958
C38: 32 | D38: =(2+5.5+15.667+5.5+2)/3.281 -> 9.3468455 | F38: =10*10/162 -> 0.61728395 | G38: =C38*D38*F38 -> 184.62905
B39: -Along short length | C39: 23 | D39: =(2+5.917+10.75+5.917+2)/3.281 -> 8.1024078 | F39: =10*10/162 -> 0.61728395 | G39: =C39*D39*F39 -> 115.03418
C40: 22 | D40: =(2+5.5+10.25+5.5+2)/3.281 -> 7.6958244 | F40: =10*10/162 -> 0.61728395 | G40: =C40*D40*F40 -> 104.5112
B41: -binder | C41: 12 | D41: =(16.17+10.75+16.17+10.75)/3.281 -> 16.409631 | F41: =8*8/162 -> 0.39506173 | G41: =C41*D41*F41 -> 77.793807
C42: 11 | D42: =(15.667+10.25+15.667+10.25)/3.281 -> 15.798232 | F42: =8*8/162 -> 0.39506173 | G42: =C42*D42*F42 -> 68.654046
B43: -Slab | C43: =2*TRUNC((D44/0.15),0) -> 42 | D43: =(16.17/3.281) -> 4.9283755 | F43: =8*8/162 -> 0.39506173 | G43: =C43*D43*F43 -> 81.774527
C44: =2*TRUNC((D43/0.15),0) -> 64 | D44: =10.75/3.281 -> 3.2764401 | F44: =8*8/162 -> 0.39506173 | G44: =C44*D44*F44 -> 82.84135
B45: -deduction for opening | C45: =-2*5 -> -10 | D45: 0.6 | F45: =8*8/162 -> 0.39506173 | G45: =PRODUCT(C45:F45) -> -2.3703704
C46: =-2*5 -> -10 | D46: 0.6 | F46: =8*8/162 -> 0.39506173 | G46: =PRODUCT(C46:F46) -> -2.3703704
...

Sheet Sheet1
A1: 152 | B1: ;'Vvf O{6f RofK6f] 5fKg] sfd .
A2: H 15 | B2: b/ ljZn]if0fsf] nflu !) j=dL= lnOPsf]
B3: ;|f]t ;fwg | C3: tx÷lsl;d | D3: kl/df0f | E3: PsfO{ | F3: b/ k|lt PsfO{ | G3: /sd | H3: k|To]s ;|f]t ;fwgsf] hDdf
B4: >lds | C4: s_ l;kfn' | D4: 0.5 | E4: hjfg | F4: 1330 | G4: =FLOOR(D4*F4,0.01) -> 665
C5: v_ HofdL | D5: 1 | E5: hjfg | F5: 1000 | G5: =FLOOR(D5*F5,0.01) -> 1000 | H5: =SUM(G4+G5) -> 1665
B6: lgdf{0f ;fdu|L | C6: O{6f | D6: =420*0 -> 0 | E6: uf]6f | F6: 15.145 | G6: =FLOOR(D6*F6,0.01) -> 0
C7: jfn'jf vf]nfsf] | D7: =0.71*0 -> 0 | E7: 3=dL= | F7: 3389.76 | G7: =FLOOR(D7*F7,0.01) -> 0 | H7: =SUM(G6:G7) -> 0
F8: jf:tljs b//]6 | H8: =SUM(H7,H5) -> 1665
B9: b/ k|lt j=dL=sf] | F9: !%Ü 7]s]bf/ cf]e/x]8 | H9: =FLOOR(H8*0.15,0.01) -> 249.75
B10: =+H10 -> 1914.75 | C10: Ö ?= | D10: =INT(B10/B11*100)/100 -> 191.47 | E10: k}= | F10: hDdf b/ /]6 | H10: =SUM(H8:H9) -> 1914.75
B11: 10

Sheet include dhara marmat
A1: Government of Nepal
A2: Shankharapur Municipality
A3: Shankhu, Kathmandu
A4: Detail Estimate Sheet
A5: Project:-gfªn]ef/] :jf:yo rf}sL kfgL 6\ofÍL dd{t tyf j8f sfof{no sDkfp08 /+u/f]ug | J5: F.Y.:-2082/083
A6: Location:- Shankharapur Municipality- 1 | H6: Date: 2082/04/01
A8: S.N. | B8: Description of work | C8: No. | D8: Length | E8: Breadth | F8: Height | G8: Quantity | H8: Unit | I8: Rate | J8: Amount | K8: Remark
A9: A. | B9: kfgL 6\ofÍL dd{t
A10: 1 | B10: Kn]g l;d]G6 sqmL6 jf jh| s+qmL6 eTsfO{ !) dL= k/ x6fpg] sfd
B11: -water tank | C11: 1 | D11: 5 | E11: =11/3.281 -> 3.3526364 | F11: 0.075 | G11: =C11*D11*E11*F11 -> 1.2572386
G12: =SUM(G11:G11) -> 1.2572386 | H12: cum | I12: 3740 | J12: =G12*I12 -> 4702.0725
A14: 2 | B14: l;d]G6 jf jh|df hf]8]sf] uf/f] eTsfO{ To;af6 cfPsf] ;fdfu+|L !) dL
B15: =B11 -> -water tank | C15: 2 | D15: =D11 -> 5 | E15: 0.23 | F15: 1.4 | G15: =C15*D15*F15 -> 14
C16: 2 | D16: =E11-0.23*2 -> 2.8926364 | E16: 0.23 | F16: 1.4 | G16: =C16*D16*F16 -> 8.0993819
C17: 1 | D17: =D11 -> 5 | E17: 0.23 | F17: 0.45 | G17: =C17*D17*F17 -> 2.25
G18: =SUM(G15:G17) -> 24.349382 | H18: cum | I18: 1982.2 | J18: =G18*I18 -> 48265.345
A20: 3 | B20: ;fx|f] k|sf/sf] Sn], g/d d'/d 9'+uf -#) ;]=dL=;Dd_ ld;]sf] df6f]df ;j} lsl;dsf] vGg] sfd
C21: =C11 -> 1 | D21: =D11 -> 5 | E21: =E11 -> 3.3526364 | F21: 0.075 | G21: =C21*D21*E21*F21 -> 1.2572386
G22: =SUM(G21) -> 1.2572386 | H22: cum | I22: 770.43 | J22: =G22*I22 -> 968.61437
A24: 4 | B24: ;'Vvf O{6f RofK6f] 5fKg] sfd
B25: -for flooring | C25: =C17 -> 1 | D25: =D17 -> 5 | E25: =E21 -> 3.3526364 | G25: =PRODUCT(C25:F25) -> 16.763182
G26: =SUM(G25) -> 16.763182 | H26: sqm | I26: =Sheet1!H8/10 -> 166.5 | J26: =G26*I26 -> 2791.0698
A28: 5 | B28: hu leQf kvf{ndf l;d]G6 s+lqm6 ug]{ sfd -lk=;L=;L= !M@M$_
B29: =B25 -> -for flooring | C29: =C25 -> 1 | D29: =D25 -> 5 | E29: =E25 -> 3.3526364 | F29: 0.075 | G29: =C29*D29*E29*F29 -> 1.2572386
G30: =SUM(G29) -> 1.2572386 | H30: cum | I30: 13351.1 | J30: =G30*I30 -> 16785.519
B31: vat on cement | J31: =0.13*G30*4169.92 -> 681.536
B32: vat on sand | J32: =0.13*G30*1414.16 -> 231.13176
B33: vat on aggregate | J33: =0.13*G30*(1652.5+737.97+349.56) -> 447.83331
A35: 6 | B35: cf/=;L=;L= nflu !) ld=ld= kmnfd] 808L sf6\g], df]8\g] #) dL6/ ;Dd
B36: -Along long length | C36: 33 | D36: =(2+5.917+16.17+5.917+2)/3.281 -> 9.7543432 | F36: =10*10/162 -> 0.61728395 | G36: =C36*D36*F36 -> 198.69958
C37: 32 | D37: =(2+5.5+15.667+5.5+2)/3.281 -> 9.3468455 | F37: =10*10/162 -> 0.61728395 | G37: =C37*D37*F37 -> 184.62905
B38: -Along short length | C38: 23 | D38: =(2+5.917+10.75+5.917+2)/3.281 -> 8.1024078 | F38: =10*10/162 -> 0.61728395 | G38: =C38*D38*F38 -> 115.03418
C39: 22 | D39: =(2+5.5+10.25+5.5+2)/3.281 -> 7.6958244 | F39: =10*10/162 -> 0.61728395 | G39: =C39*D39*F39 -> 104.5112
B40: -binder | C40: 12 | D40: =(16.17+10.75+16.17+10.75)/3.281 -> 16.409631 | F40: =8*8/162 -> 0.39506173 | G40: =C40*D40*F40 -> 77.793807
C41: 11 | D41: =(15.667+10.25+15.667+10.25)/3.281 -> 15.798232 | F41: =8*8/162 -> 0.39506173 | G41: =C41*D41*F41 -> 68.654046
B42: -Slab | C42: =2*TRUNC((D43/0.15),0) -> 42 | D42: =(16.17/3.281) -> 4.9283755 | F42: =8*8/162 -> 0.39506173 | G42: =C42*D42*F42 -> 81.774527
C43: =2*TRUNC((D42/0.15),0) -> 64 | D43: =10.75/3.281 -> 3.2764401 | F43: =8*8/162 -> 0.39506173 | G43: =C43*D43*F43 -> 82.84135
B44: -deduction for opening | C44: =-2*5 -> -10 | D44: 0.6 | F44: =8*8/162 -> 0.39506173 | G44: =PRODUCT(C44:F44) -> -2.3703704
C45: =-2*5 -> -10 | D45: 0.6 | F45: =8*8/162 -> 0.39506173 | G45: =PRODUCT(C45:F45) -> -2.3703704
B46: -for fillet | C46: =28*2+17*2 -> 90 | D46: =(1+1.42+1)/3.281 -> 1.0423651 | F46: =8*8/162 -> 0.39506173 | G46: =C46*D46*F46 -> 37.061871
...

Sheet measurement
B1: No. | C1: L | D1: B | E1: H | F1: Quantity | G1: Unit | H1: Area
B2: 1 | C2: 3.4 | D2: 0.23 | E2: 1.3 | F2: =PRODUCT(B2:E2) -> 1.0166 | G2: m3 | H2: =B2*C2*E2 -> 4.42 | I2: m2
B3: 1 | C3: 4 | D3: 0.35 | E3: 1.3 | F3: =PRODUCT(B3:E3) -> 1.82 | G3: m3 | H3: =B3*C3*E3 -> 5.2 | I3: m2
B4: 1 | C4: 3.9 | D4: 0.23 | E4: 1.2 | F4: =PRODUCT(B4:E4) -> 1.0764 | G4: m3 | H4: =B4*C4*E4 -> 4.68 | I4: m2
B5: 1 | C5: 3.97 | D5: 0.23 | E5: 1.35 | F5: =PRODUCT(B5:E5) -> 1.232685 | G5: m3 | H5: =B5*C5*E5 -> 5.3595 | I5: m2
B6: 1 | C6: 3.89 | D6: 0.23 | E6: 1.2 | F6: =PRODUCT(B6:E6) -> 1.07364 | G6: m3 | H6: =B6*C6*E6 -> 4.668 | I6: m2
B7: 1 | C7: 3.7 | D7: 0.23 | E7: 1.2 | F7: =PRODUCT(B7:E7) -> 1.0212 | G7: m3 | H7: =B7*C7*E7 -> 4.44 | I7: m2
B8: 1 | C8: 3.95 | D8: 0.23 | E8: 1.04 | F8: =PRODUCT(B8:E8) -> 0.94484 | G8: m3 | H8: =B8*C8*E8 -> 4.108 | I8: m2
B9: 6 | C9: 0.45 | D9: 0.45 | E9: 2.25 | F9: =PRODUCT(B9:E9) -> 2.73375 | G9: m3 | H9: =B9*C9*E9 -> 6.075 | I9: m2
B10: 1 | C10: 29.51 | D10: 0.35 | E10: 0.45 | F10: =PRODUCT(B10:E10) -> 4.647825 | G10: m3 | H10: =B10*C10*E10 -> 13.2795 | I10: m2
B12: 1 | C12: 2.45 | D12: 0.23 | E12: 1.1 | F12: =PRODUCT(B12:E12) -> 0.61985 | G12: m3 | H12: =B12*C12*E12 -> 2.695 | I12: m2
B13: 1 | C13: 3.92 | D13: 0.23 | E13: 1.13 | F13: =PRODUCT(B13:E13) -> 1.018808 | G13: m3 | H13: =B13*C13*E13 -> 4.4296 | I13: m2
B14: 1 | C14: 3.95 | D14: 0.23 | E14: 1.25 | F14: =PRODUCT(B14:E14) -> 1.135625 | G14: m3 | H14: =B14*C14*E14 -> 4.9375 | I14: m2
... B21: 1 | C21: 33.49 | D21: 0.35 | E21: 0.45 | F21: =PRODUCT(B21:E21) -> 5.274675 | G21: m3 | H21: =B21*C21*E21 -> 15.0705 | I21: m2
F22: =SUM(F2:F21) -> 32.373298 | G22: m3 | H22: =SUM(H2:H21) -> 109.8626 | I22: m2 | J22: =CONVERT(H22,"m^2","ft^2") -> 1182.5512 | K22: 1234.66 | L22: =K22-J22 -> 52.108815
G24: plaster | H24: 187.39 | J24: =CONVERT(H24,"m^2","ft^2") -> 2017.0492 | K24: 2129 | L24: =K24-J24 -> 111.95083
H26: 5.55
