Workbook

Sheet ESTIMATE
A1: Government of Nepal
A2: Shankharapur Municipality
A3: Shankhu, Kathmandu
A4: Detail Estimate Sheet
B5: Project:- | C5: gfªn]ef/] :jf:yo rf}sL 5fgf tyf kfgL 6\ofÍL dd{t | K5: F.Y.:-2080/081
B6: Location:- Shankharapur Municipality- 1 | I6: Date: 2081/02/21 | O6: Date: 2080/05/21
B8: S.N. | C8: Description of work | D8: No. | E8: Length | F8: Breadth | G8: Height | H8: Quantity | I8: Unit | J8: Rate | K8: Amount | L8: Remarks
B9: A. | C9: kfgL 6\ofÍL dd{t
B10: 1 | C10: cf/=l;=l;= jf cf/=lj=l;= sfd eTsfO{ !) dL= k/ x6fpg] sfd | D10: 1 | E10: 4.5 | F10: 3 | G10: 0.1 | H10: =D10*E10*F10*G10 -> 1.35 | I10: cu.m. | J10: ='[1]Table of Content 2'!$H$312 -> 9900 | K10: =H10*J10 -> 13365
B12: 2 | C12: l;d]G6 jf jh| Knfi6/ eTsfO{ !) dL= k/ x6fpg] sfd | D12: 2 | E12: =E10 -> 4.5 | G12: 1.4 | H12: =D12*E12*G12 -> 12.6
D13: 2 | E13: =F10 -> 3 | G13: 1.4 | H13: =D13*E13*G13 -> 8.4
H14: =SUM(H12:H13) -> 21 | I14: sq.m. | J14: ='[1]Table of Content 2'!$H$314 -> 97.2 | K14: =H14*J14 -> 2041.2
B16: 3 | C16: e'O{+tNnfdf lrDgL e§fsf] O{+6fsf] uf/f] l;d]G6 d;nf -!M$_ df | D16: 2 | E16: =E12 -> 4.5 | F16: 0.1 | G16: 0.9 | H16: =D16*E16*F16*G16 -> 0.81
D17: 2 | E17: =E13 -> 3 | F17: 0.1 | G17: 0.9 | H17: =D17*E17*F17*G17 -> 0.54
D18: 1 | E18: =2*(5+4)/3.28 -> 5.4878049 | F18: 0.23 | G18: 0.45 | H18: =D18*E18*F18*G18 -> 0.5679878
H19: =SUM(H16:H18) -> 1.9179878 | I19: cu.m. | J19: ='[1]Table of Content 2'!$H$43 -> 14911.97 | K19: =H19*J19 -> 28600.977
C20: vat on cement | K20: ='[1]Update Descrip'!$G$397*H19*0.13 -> 359.82027
C21: vat on sand | K21: ='[1]Update Descrip'!$G$398*H19*0.13 -> 175.02559
C22: vat on brick | K22: ='[1]Update Descrip'!$G$396*H19*0.13 -> 2185.4811
B24: 4 | C24: cf/=;L=;L= nflu !) ld=ld= kmnfd] 808L sf6\g], df]8\g] #) dL6/ ;Dd | D24: =E25/0.15 -> 20 | E24: =E16 -> 4.5 | G24: =10*10/162 -> 0.61728395 | H24: =D24*E24*G24 -> 55.555556
D25: =E24/0.15 -> 30 | E25: =E17 -> 3 | G25: =10*10/162 -> 0.61728395 | H25: =D25*E25*G25 -> 55.555556
C26: vat on material | H26: =SUM(H24:H25) -> 111.11111 | I26: kg | J26: ='[1]Table of Content 2'!$H$77/1000 -> 130.21 | K26: =H26*J26 -> 14467.778
K27: =0.13*K26 -> 1880.8111
B28: 5 | C28: ;'k/ :6«Sr/, 8]s :n]a ljdx?df l;d]G6 s+lqm6 ug]{ sfd -!M!.%M#_ | D28: 1 | E28: =E16 -> 4.5 | F28: =E17 -> 3 | G28: 0.075 | H28: =D28*E28*F28*G28 -> 1.0125
D29: 2 | E29: =E16 -> 4.5 | F29: 0.15 | G29: =G16 -> 0.9 | H29: =D29*E29*F29*G29 -> 1.215
D30: 2 | E30: =E17 -> 3 | F30: 0.15 | G30: =G17 -> 0.9 | H30: =D30*E30*F30*G30 -> 0.81
H31: =SUM(H28:H30) -> 3.0375 | I31: cum | J31: ='[1]Table of Content 2'!$H$67 -> 17107.9 | K31: =H31*J31 -> 51965.246
C32: vat on cement | K32: ='[1]Update Descrip'!$G$676*H31*0.13 -> 2279.3765
C33: vat on sand | K33: ='[1]Update Descrip'!$G$679*H31*0.13 -> 420.72747
C34: vat on aggregate | K34: =('[1]Update Descrip'!$G$677+'[1]Update Descrip'!$G$678)*H31*0.13 -> 1166.4726
B36: 6 | C36: l;d]G6 s+qmL6 ˆnf]l/Ë -!M@M$_ -#* dL=dL=_ | D36: 1 | E36: =E28 -> 4.5 | F36: =F28 -> 3 | H36: =F36*E36*D36 -> 13.5 | I36: sqm | J36: ='[1]Table of Content 2'!$H$155 -> 692.38 | K36: =H36*J36 -> 9347.13
C37: vat on cement | K37: ='[1]Update Descrip'!$G$1804/10*H36*0.13 -> 329.24327
C38: vat on sand | K38: ='[1]Update Descrip'!$G$1805/10*H36*0.13 -> 79.19613
C39: vat on aggregate | K39: ='[1]Update Descrip'!$G$1806/10*H36*0.13 -> 227.54979
B41: 7 | C41: !@=% dL=dL= l;d]G6 afn'jf -!M$_ Knfi6/ | D41: =D16 -> 2 | E41: =E16 -> 4.5 | G41: =G48 -> 1.5 | H41: =D41*E41*G41 -> 13.5
D42: =D17 -> 2 | E42: =E17 -> 3 | G42: =G49 -> 1.5 | H42: =D42*E42*G42 -> 9
H43: =SUM(H41:H42) -> 22.5 | I43: sq.m. | J43: ='[1]Table of Content 2'!$H$215 -> 402.23 | K43: =H43*J43 -> 9050.175
C44: vat on cement | K44: ='[1]Update Descrip'!$G$2611/100*H43*0.13 -> 227.0932
C45: vat on sand | K45: ='[1]Update Descrip'!$G$2612/100*H43*0.13 -> 107.06173
B47: 8 | C47: # dL=dL= df]6fO{ d;Lgf] l;d]G6 3f]6\g] sfd | D47: =D28 -> 1 | E47: =E28 -> 4.5 | G47: =F28 -> 3 | H47: =D47*E47*G47 -> 13.5
...

Sheet mb
C1: Description | D1: length | E1: breadth | F1: height | G1: Quantity | H1: capacity
C2: water tank | D2: 2.25 | E2: 2.25 | F2: 1.5 | G2: =(D2*E2*(F2-0.3)) -> 6.075 | H2: =G2*1000&"litres" -> 6075litres
A4: Government of Nepal
A5: Shankharapur Municipality
A6: Shankhu, Kathmandu
A7: Measurement Sheet
B8: Project:- | C8: hut] vfg]kfgL | I8: F.Y.:-2079/080
B9: Location:- Shankharapur Municipality- 1 | I9: Date: 2079/12/21
B11: S.N. | C11: Description of work | D11: No. | E11: Length | F11: Breadth | G11: Height | H11: Quantity | I11: Unit | J11: Remarks
B12: 1 | C12: Earthwork in excavaiton | D12: 1 | E12: =+E16 -> 8.5 | F12: 0.5 | G12: 1 | H12: =D12*E12*F12*G12 -> 4.25 | I12: cu.m.
B14: 2 | C14: Dismantle the rcc work on the base of water tank | D14: 1 | E14: =3-0.15*2 -> 2.7 | F14: =3-0.15*2 -> 2.7 | G14: 0.1 | H14: =D14*E14*F14*G14 -> 0.729 | I14: cu.m.
B16: 3 | C16: stone soling | D16: 2 | E16: =E18+E19 -> 8.5 | F16: 0.6 | G16: 0.15 | H16: =D16*E16*F16*G16 -> 1.53 | I16: cu.m.
B18: 4 | C18: Dry Stone Masonry work | D18: 1 | E18: 5 | F18: 0.6 | G18: 1.5 | H18: =D18*E18*F18*G18 -> 4.5
D19: 1 | E19: 3.5 | F19: 0.6 | G19: 0.6 | H19: =D19*E19*F19*G19 -> 1.26
H20: =SUM(H18:H19) -> 5.76 | I20: cu.m.
B22: 5 | C22: Brick Masonry work in 1:6 | D22: 2 | E22: =3-0.15*2 -> 2.7 | F22: 0.23 | G22: 0.8 | H22: =D22*E22*F22*G22 -> 0.9936
H23: =SUM(H22:H22) -> 0.9936 | I23: cu.m.
B25: 6 | C25: RCC works 1:1.5:3 ratio in water collection chamber with all work complete | D25: 1 | E25: =2.7+0.9 -> 3.6 | F25: 0.15 | G25: 0.8 | H25: =D25*E25*F25*G25 -> 0.432
D26: 1 | E26: 2.7 | F26: 2.7 | G26: 0.1 | H26: =D26*E26*F26*G26 -> 0.729
H27: =SUM(H25:H26) -> 1.161 | I27: cum
B29: 7 | C29: 3mm punning all complete work | D29: 1 | E29: 2.7 | F29: 2.7 | H29: =F29*E29*D29 -> 7.29
D30: 2 | E30: =+E25 -> 3.6 | G30: =+G25 -> 0.8 | H30: =G30*E30*D30 -> 5.76
H31: =SUM(H29:H30) -> 13.05 | I31: sqm
B33: 8 | C33: plastering work
D34: 2 | E34: =+E22 -> 2.7 | G34: =+G22 -> 0.8 | H34: =D34*E34*G34 -> 4.32
H35: =SUM(H34:H34) -> 4.32 | I35: sq.m.
B37: 9 | C37: tap and fittings | D37: 1 | H37: =+D37 -> 1 | I37: job
B39: 10 | C39: Iron frame for barbed wire | D39: 7 | E39: 1 | G39: 1.5 | H39: =D39*E39*G39 -> 10.5 | I39: kg
B41: 11 | C41: Barbed wire | D41: 1 | E41: 10 | H41: =D41*E41 -> 10 | I41: r.m.
B43: 12 | C43: Roof top PVC Water Tank | D43: 1 | H43: 10000 | I43: ltr
B45: 13 | C45: Information Board | D45: 1 | H45: 0 | I45: no.

Sheet valuation
C1: Description | D1: length | E1: breadth | F1: height | G1: Quantity | H1: capacity
C2: water tank | D2: 2.25 | E2: 2.25 | F2: 1.5 | G2: =(D2*E2*(F2-0.3)) -> 6.075 | H2: =G2*1000&"litres" -> 6075litres
A4: Government of Nepal
A5: Shankharapur Municipality
A6: Shankhu, Kathmandu
A7: Valuation Sheet
B8: Project:- | C8: hut] vfg]kfgL | K8: F.Y.:-2079/080
B9: Location:- Shankharapur Municipality- 1 | I9: Date: 2079/12/21
B11: S.N. | C11: Description of work | D11: No. | E11: Length | F11: Breadth | G11: Height | H11: Quantity | I11: Unit | J11: Rate | K11: Amount | L11: Remarks
B12: 1 | C12: Earthwork in excavaiton | D12: 1 | E12: =+E17 -> 8.5 | F12: 0.5 | G12: 1 | H12: =D12*E12*F12*G12 -> 4.25 | I12: cu.m. | J12: 627.27 | K12: =H12*J12 -> 2665.8975
B14: 2 | C14: Dismantle the rcc work on the base of water tank | D14: 1 | E14: =3-0.15*2 -> 2.7 | F14: =3-0.15*2 -> 2.7 | G14: 0.1 | H14: =D14*E14*F14*G14 -> 0.729 | I14: cu.m. | J14: 9570 | K14: =H14*J14 -> 6976.53
B17: 3 | C17: stone soling | D17: 2 | E17: =E20+E21 -> 8.5 | F17: 0.6 | G17: 0.15 | H17: =D17*E17*F17*G17 -> 1.53 | I17: cu.m. | J17: 4567.63 | K17: =H17*J17 -> 6988.4739
C18: vat on stone | K18: =3262.64*H17*0.13 -> 648.9391
B20: 4 | C20: Dry Stone Masonry work | D20: 1 | E20: 5 | F20: 0.6 | G20: 1.5 | H20: =D20*E20*F20*G20 -> 4.5
D21: 1 | E21: 3.5 | F21: 0.6 | G21: 0.6 | H21: =D21*E21*F21*G21 -> 1.26
H22: =SUM(H20:H21) -> 5.76 | I22: cu.m. | J22: 5915.75 | K22: =H22*J22 -> 34074.72
C23: vat on stone | K23: =2990.75*H22*0.13 -> 2239.4736
B25: 5 | C25: Brick Masonry work in 1:6 | D25: 2 | E25: =3-0.15*2 -> 2.7 | F25: 0.23 | G25: 0.8 | H25: =D25*E25*F25*G25 -> 0.9936
H26: =SUM(H25:H25) -> 0.9936 | I26: cu.m. | J26: 14627.37 | K26: =H26*J26 -> 14533.755
C27: vat on cement | K27: =8765.12*H26*0.13 -> 1132.173
C28: vat on brick | K28: =1010.17*H26*0.13 -> 130.48164
C29: vat on sand | K29: =953.37*H26*0.13 -> 123.1449
B31: 6 | C31: RCC works 1:1.5:3 ratio in water collection chamber with all work complete | D31: 1 | E31: =2.7+0.9 -> 3.6 | F31: 0.15 | G31: 0.8 | H31: =D31*E31*F31*G31 -> 0.432
D32: 1 | E32: 2.7 | F32: 2.7 | G32: 0.1 | H32: =D32*E32*F32*G32 -> 0.729
H33: =SUM(H31:H32) -> 1.161 | I33: cum | J33: 17171.03 | K33: =H33*J33 -> 19935.566
C34: vat on cement | K34: =5772.4*H33*0.13 -> 871.22833
C35: vat on aggregate | K35: =2954.03*H33*0.13 -> 445.85175
C36: vat on sand | K36: =1350.6*H33*0.13 -> 203.84606
B38: 7 | C38: 3mm punning all complete work | D38: 1 | E38: 2.7 | F38: 2.7 | H38: =F38*E38*D38 -> 7.29
D39: 2 | E39: =+E31 -> 3.6 | G39: =+G31 -> 0.8 | H39: =G39*E39*D39 -> 5.76
H40: =SUM(H38:H39) -> 13.05 | I40: sqm | J40: 282.27 | K40: =J40*H40 -> 3683.6235
C41: vat on cement | K41: =7448*H40*0.13/100 -> 126.35532
B43: 8 | C43: plastering work
D44: 2 | E44: =+E25 -> 2.7 | G44: =+G25 -> 0.8 | H44: =D44*E44*G44 -> 4.32
H45: =SUM(H44:H44) -> 4.32 | I45: sq.m. | J45: 386.42 | K45: =H45*J45 -> 1669.3344
C46: vat on cement | K46: =5512.64*H45*0.13/100 -> 30.958986
C47: vat on sand | K47: =4989.3*H45*0.13/100 -> 28.019909
B49: 9 | C49: tap and fittings | D49: 1 | H49: =+D49 -> 1 | I49: job | J49: 2000 | K49: =H49*J49 -> 2000
B51: 10 | C51: Iron frame for barbed wire | D51: 7 | E51: 1 | G51: 1.5 | H51: =D51*E51*G51 -> 10.5 | I51: kg | J51: 177.66 | K51: =H51*J51 -> 1865.43
C52: Vat on iron frame | K52: =1871.42*H51*0.13/18.94 -> 134.87267
...

Sheet WCR
A1: Government of Nepal
A2: Shankharapur Municipality Office
A3: Sankhu, Kathmandu
A4: Work Completion Report
A6: Total Estimated Amount: | C6: =E51 -> #REF! | G6: Total Valuated Amount : | I6: =H51 -> 226129.27
A8: Project: | B8: =valuation!C8 -> hut] vfg]kfgL | J8: Fiscal Year:079/80
A9: Location:Shankharapur-1 | J9: Date:2079/12/21
A10: S.No. | B10: Description | C10: Estimated | F10: Valuated | I10: Difference | J10: Remarks
C11: Quantity | D11: Rate | E11: Amount (Rs) | F11: Quantity | G11: Rate | H11: Amount(Rs)
A12: 1 | B12: Earthwork in excavaiton | C12: =ESTIMATE!#REF! -> #REF! | D12: =ESTIMATE!#REF! -> #REF! | E12: =ESTIMATE!#REF! -> #REF! | F12: =valuation!H12 -> 4.25 | G12: =valuation!J12 -> 627.27 | H12: =valuation!K12 -> 2665.8975 | I12: =F12-C12 -> #REF!
A14: 2 | B14: Dismantle the rcc work on the base of water tank | C14: =ESTIMATE!H10 -> 1.35 | D14: =ESTIMATE!J10 -> 9900 | E14: =ESTIMATE!K10 -> 13365 | F14: =valuation!H14 -> 0.729 | G14: =valuation!J14 -> 9570 | H14: =valuation!K14 -> 6976.53 | I14: =F14-C14 -> -0.621
A16: 3 | B16: stone soling | C16: =ESTIMATE!H14 -> 21 | D16: =ESTIMATE!J14 -> 97.2 | E16: =ESTIMATE!K14 -> 2041.2 | F16: =valuation!H17 -> 1.53 | G16: =valuation!J17 -> 4567.63 | H16: =valuation!K17 -> 6988.4739 | I16: =F16-C16 -> -19.47
B17: vat on stone | E17: =ESTIMATE!K15 -> 0 | H17: =valuation!K18 -> 648.9391
A19: 4 | B19: Dry Stone Masonry work | C19: =ESTIMATE!#REF! -> #REF! | D19: =ESTIMATE!#REF! -> #REF! | E19: =ESTIMATE!#REF! -> #REF! | F19: =valuation!H22 -> 5.76 | G19: =valuation!J22 -> 5915.75 | H19: =valuation!K22 -> 34074.72 | I19: =F19-C19 -> #REF!
B20: vat on stone | E20: =ESTIMATE!#REF! -> #REF! | H20: =valuation!K23 -> 2239.4736
A22: 5 | B22: Brick Masonry work in 1:6 | C22: =ESTIMATE!H19 -> 1.9179878 | D22: =ESTIMATE!J19 -> 14911.97 | E22: =ESTIMATE!K19 -> 28600.977 | F22: =valuation!H26 -> 0.9936 | G22: =valuation!J26 -> 14627.37 | H22: =valuation!K26 -> 14533.755 | I22: =F22-C22 -> -0.9243878
B23: vat on cement | E23: =ESTIMATE!K20 -> 359.82027 | H23: =valuation!K27 -> 1132.173
B24: vat on brick | E24: =ESTIMATE!K21 -> 175.02559 | H24: =valuation!K28 -> 130.48164
B25: vat on sand | E25: =ESTIMATE!K22 -> 2185.4811 | H25: =valuation!K29 -> 123.1449
A27: 6 | B27: RCC works 1:1.5:3 ratio in water collection chamber with all work complete | C27: =ESTIMATE!H31 -> 3.0375 | D27: =ESTIMATE!J31 -> 17107.9 | E27: =ESTIMATE!K31 -> 51965.246 | F27: =valuation!H33 -> 1.161 | G27: =valuation!J33 -> 17171.03 | H27: =valuation!K33 -> 19935.566 | I27: =F27-C27 -> -1.8765
B28: vat on cement | E28: =ESTIMATE!K32 -> 2279.3765 | H28: =valuation!K34 -> 871.22833
B29: vat on aggregate | E29: =ESTIMATE!K33 -> 420.72747 | H29: =valuation!K35 -> 445.85175
B30: vat on sand | E30: =ESTIMATE!K34 -> 1166.4726 | H30: =valuation!K36 -> 203.84606
A32: 7 | B32: 3mm punning all complete work | C32: =ESTIMATE!#REF! -> #REF! | D32: =ESTIMATE!#REF! -> #REF! | E32: =ESTIMATE!#REF! -> #REF! | F32: =valuation!H40 -> 13.05 | G32: =valuation!J40 -> 282.27 | H32: =valuation!K40 -> 3683.6235 | I32: =F32-C32 -> #REF!
B33: vat on cement | E33: =ESTIMATE!K37 -> 329.24327 | H33: =valuation!K41 -> 126.35532
A35: 8 | B35: plastering work | C35: =ESTIMATE!H43 -> 22.5 | D35: =ESTIMATE!J43 -> 402.23 | E35: =ESTIMATE!K43 -> 9050.175 | F35: =valuation!H45 -> 4.32 | G35: =valuation!J45 -> 386.42 | H35: =valuation!K45 -> 1669.3344 | I35: =F35-C35 -> -18.18
B36: vat on cement | E36: =ESTIMATE!K44 -> 227.0932 | H36: =valuation!K46 -> 30.958986
B37: vat on sand | E37: =ESTIMATE!K45 -> 107.06173 | H37: =valuation!K47 -> 28.019909
A39: 9 | B39: tap and fittings | C39: =ESTIMATE!H54 -> 1 | D39: =ESTIMATE!J54 -> 4659 | E39: =ESTIMATE!K54 -> 4659 | F39: =valuation!H49 -> 1 | G39: =valuation!J49 -> 2000 | H39: =valuation!K49 -> 2000 | I39: =F39-C39 -> 0
A41: 10 | B41: Iron frame for barbed wire | C41: =ESTIMATE!#REF! -> #REF! | D41: =ESTIMATE!#REF! -> #REF! | E41: =ESTIMATE!#REF! -> #REF! | F41: =valuation!H51 -> 10.5 | G41: =valuation!J51 -> 177.66 | H41: =valuation!K51 -> 1865.43 | I41: =F41-C41 -> #REF!
B42: Vat on iron frame | E42: =ESTIMATE!#REF! -> #REF! | H42: =valuation!K52 -> 134.87267
A44: 11 | B44: Barbed wire | C44: =ESTIMATE!#REF! -> #REF! | D44: =ESTIMATE!#REF! -> #REF! | E44: =ESTIMATE!#REF! -> #REF! | F44: =valuation!H54 -> 10 | G44: =valuation!J54 -> 79.47 | H44: =valuation!K54 -> 794.7 | I44: =F44-C44 -> #REF!
B45: vat on barbed wire | E45: =ESTIMATE!#REF! -> #REF! | H45: =valuation!K55 -> 25.89782
A47: 12 | B47: Roof top PVC Water Tank | C47: =ESTIMATE!#REF! -> #REF! | D47: =ESTIMATE!#REF! -> #REF! | E47: =ESTIMATE!#REF! -> #REF! | F47: =valuation!H57 -> 10000 | G47: =valuation!J57 -> 11 | H47: =valuation!K57 -> 110000 | I47: =F47-C47 -> #REF!
B48: vat on pvc water tank | E48: =ESTIMATE!#REF! -> #REF! | H48: =valuation!K58 -> 14300
A50: 12 | B50: Information Board | C50: 1 | D50: 500 | E50: 500 | F50: =valuation!H60 -> 1 | G50: =valuation!J60 -> 500 | H50: =valuation!K60 -> 500 | I50: =F50-C50 -> 0
B51: Total | E51: =SUM(E12:E50) -> #REF! | H51: =SUM(H12:H50) -> 226129.27
