Workbook
Name description_103: [1]Abstract!$B$16
Name description_124: #REF!
Name description_124: #REF!
Name description_124: #REF!
Name description_124: #REF!
Name description_247: [1]Abstract!$B$22
Name description_248: [1]Abstract!$B$23
Name description_261: [2]Abstract!$B$33
Name description_262: [1]Abstract!$B$34
Name description_276: [3]Abstract!$B$40
Name description_3: [1]Abstract!$B$169
Name description_310: #REF!
Name description_310: #REF!
Name description_310: [4]Abstract!$B$60
Name description_310: #REF!
Name description_312: #REF!
Name description_312: #REF!
Name description_312: [5]Abstract!$B$61
Name description_312: #REF!
Name description_4: [6]Abstract!$B$170
Name description_5: [1]Abstract!$B$171
Name description_6: #REF!
Name description_6: #REF!
Name description_6: [4]Abstract!$B$172
Name description_6: #REF!
Name description_759: [1]Abstract!$B$278
Name description_781: #REF!
Name description_781: #REF!
Name description_781: [7]Abstract!$B$299
Name description_781: #REF!
Name description_783: [1]Abstract!$B$301
Name description_784: [3]Abstract!$B$300

Sheet estimate
A1: Government of Nepal
A2: Shankharapur Municipality Office
A3: Bagmati Province
A4: Sankhu, Kathmandu
A5: Detail Estimated Sheet
A6: Project:- nfFs'/Ljf]6 b]jL ;'df/f ;8s | H6: F.Y.: 2082/2083
A7: Location:- Shankharapur Municipality 1 | H7: Date:2082
A8: S.N. | B8: Description of work | C8: No. | D8: Length | E8: Breadth | F8: Height | G8: Quantity | H8: Unit | I8: Rate | J8: Amount | K8: Remark
A9: 1 | B9: Earthwork Excavation in Cutting, Roadway Excavation in all types of Soil by Mechanical Means ., Road way Excavation in all types of soil as per Drawing and technical specifications including removal of stumps and other deleterious matter, all lifts and lead as per Drawing and instruction of the Engineer.
B10: -for road | C10: 1 | D10: 56 | E10: =10/3.281 -> 3.0478513 | F10: 0.15 | G10: =PRODUCT(C10:F10) -> 25.601951
B11: sub-total | G11: =SUM(G10:G10) -> 25.601951 | H11: cum | I11: 62.95 | J11: =G11*I11 -> 1611.6428
B12: -13% VAT for excavator | J12: =0.13*G11*18612/360 -> 172.07071
A14: 2 | B14: Providing and laying of hand pack locally available Stone soling with 150 to 200 mm thick stones and packing with smaller stone on prepared surface as per Drawing and Technical Specifications.
B15: =B10 -> -for road | C15: 1 | D15: =D10 -> 56 | E15: =E10 -> 3.0478513 | F15: 0.15 | G15: =PRODUCT(C15:F15) -> 25.601951
B16: sub-total | G16: =SUM(G15:G15) -> 25.601951 | H16: cum | I16: 4458.52 | J16: =G16*I16 -> 114146.81
B17: -13% VAT for block stone | J17: =0.13*G16*14817.6/5 -> 9863.3461
A19: 3 | B19: Providing and laying of Plain/Reinforced Cement Concrete in Foundation complete as per Drawing and Technical Specifications., RCC Grade M 20
B20: =B15 -> -for road | C20: 1 | D20: =D15 -> 56 | E20: =E15 -> 3.0478513 | F20: 0.15 | G20: =PRODUCT(C20:F20) -> 25.601951
B21: sub-total | G21: =SUM(G20:G20) -> 25.601951 | H21: cum | I21: 12000.5 | J21: =G21*I21 -> 307236.21
B22: -13% VAT for cement | J22: =0.13*G21*67891.51/15 -> 15064.011
B23: -13% VAT for sand | J23: =0.13*G21*21432.6/15 -> 4755.5418
B24: -13% VAT for aggregate | J24: =0.13*G21*(27147.96+17146.08)/15 -> 9828.1198
B25: -13% VAT for water | J25: =0.13*G21*775/15 -> 171.95977
B26: -13% VAT for formwork | J26: =0.13*G21*6923.4/15 -> 1536.1887
A28: 4 | B28: Providing and laying , fitting and placing HYSD bar reinforcement in sub-structure complete as per Drawing and Technical Specifications and instruction of site engineer | C28: No. | D28: Length (m) | E28: Unit weight (Kg/m) | F28: Total Weight (Kg)
B29: =B10 -> -for road | C29: =TRUNC(D30/0.15,0)+1 -> 20 | D29: =D15-0.1 -> 55.9 | E29: =10*10/162 -> 0.61728395 | F29: =PRODUCT(C29:E29) -> 690.12346 | G29: =F29/1000 -> 0.69012346
C30: =TRUNC(D29/0.15,0)+1 -> 373 | D30: =E20-0.1 -> 2.9478513 | E30: =10*10/162 -> 0.61728395 | F30: =PRODUCT(C30:E30) -> 678.73366 | G30: =F30/1000 -> 0.67873366
B31: sub-total | G31: =SUM(G29:G29) -> 0.69012346 | H31: tonne | I31: 124355 | J31: =G31*I31 -> 85820.302
B32: -13% VAT for HYSD bar | J32: =0.13*G31*110000 -> 9868.7654
B33: -13% VAT for binding wire | J33: =0.13*G31*960 -> 86.127407
A35: 5 | B35: Provisional sum for lab tests | C35: 1 | G35: =PRODUCT(C35:F35) -> 1 | H35: PS | I35: 5000 | J35: =G35*I35 -> 5000
A37: 6 | B37: Information board (सुचना पाटि) | C37: 1 | G37: =PRODUCT(C37:F37) -> 1 | H37: no. | I37: 500 | J37: =G37*I37 -> 500
B39: Total | J39: =SUM(J9:J37) -> 565661.09
B41: Total Estimated | C41: =J39 -> 565661.09 | E41: 100
B42: Budget allocated | C42: 500000
B43: Municipal payment | C43: =C42-C45-C46 -> 475000 | E43: =C43/C41*100 -> 83.972542
B44: User contribution | C44: =C41-C43 -> 90661.093 | E44: =100-E43 -> 16.027458
B45: Contingencies | C45: =C42*0.03 -> 15000 | E45: 3
B46: Maintanince | C46: =C42*0.02 -> 10000 | E46: 2

Sheet WCR
A1: Government of Nepal
A2: Shankharapur Municipality Office
A3: Bagmati Province
A4: Sankhu, Kathmandu
A5: Work Completion Report
A6: Total Estimated Amount: | C6: =F34 -> 565661.09 | H6: Total Valuated Amount : | J6: =I34 -> 563256.5
A7: Work Started : | I7: Work Finished:
A8: Project:- nfFs'/Ljf]6 b]jL ;'df/f ;8s | I8: F.Y:2082/2083
A9: =[8]estimate!A7 -> Location:- Shankharapur Municipality 1 | I9: Date:2083/02/18
A11: S.No. | B11: Description | C11: Unit | D11: Estimated | G11: Valuated | J11: Difference | K11: Remarks
D12: Quantity | E12: Rate | F12: Amount | G12: Quantity | H12: Rate | I12: Amount
A13: =estimate!A9 -> 1 | B13: =estimate!B9 -> Earthwork Excavation in Cutting, Roadway Excavation in all types of Soil by Mechanical Means ., Road way Excavation in all types of soil as per Drawing and technical specifications including removal of stumps and other deleterious matter, all lifts and lead as per Drawing and instruction of the Engineer. | C13: =estimate!H11 -> cum | D13: =estimate!G11 -> 25.601951 | E13: =estimate!I11 -> 62.95 | F13: =D13*E13 -> 1611.6428 | G13: =V!G26 -> 27.265642 | H13: =V!I26 -> 62.95 | I13: =G13*H13 -> 1716.3722 | J13: =I13-F13 -> 104.72938 | M13: =1.25*F13 -> 2014.5535
B14: =estimate!B12 -> -13% VAT for excavator | F14: =estimate!J12 -> 172.07071 | I14: =V!J27 -> 183.25238 | J14: =I14-F14 -> 11.181671 | M14: =1.25*F14 -> 215.08839
A16: =estimate!A14 -> 2 | B16: =estimate!B14 -> Providing and laying of hand pack locally available Stone soling with 150 to 200 mm thick stones and packing with smaller stone on prepared surface as per Drawing and Technical Specifications. | C16: =estimate!H16 -> cum | D16: =estimate!G16 -> 25.601951 | E16: =estimate!I16 -> 4458.52 | F16: =D16*E16 -> 114146.81 | G16: =V!G46 -> 19.640222 | H16: =V!I46 -> 4458.52 | I16: =G16*H16 -> 87566.325 | J16: =I16-F16 -> -26580.484 | M16: =1.25*F16 -> 142683.51
B17: =estimate!B17 -> -13% VAT for block stone | F17: =estimate!J17 -> 9863.3461 | I17: =V!J47 -> 7566.545 | J17: =I17-F17 -> -2296.8011 | M17: =1.25*F17 -> 12329.183
A19: =estimate!A19 -> 3 | B19: =estimate!B19 -> Providing and laying of Plain/Reinforced Cement Concrete in Foundation complete as per Drawing and Technical Specifications., RCC Grade M 20 | C19: =estimate!H21 -> cum | D19: =estimate!G21 -> 25.601951 | E19: =estimate!I21 -> 12000.5 | F19: =D19*E19 -> 307236.21 | G19: =V!G66 -> 27.265642 | H19: =V!I66 -> 12000.5 | I19: =G19*H19 -> 327201.34 | J19: =I19-F19 -> 19965.13 | M19: =1.25*F19 -> 384045.26
B20: =estimate!B22 -> -13% VAT for cement | F20: =estimate!J22 -> 15064.011 | I20: =V!J67 -> 16042.915 | J20: =I20-F20 -> 978.9046 | M20: =1.25*F20 -> 18830.013
B21: =estimate!B23 -> -13% VAT for sand | F21: =estimate!J23 -> 4755.5418 | I21: =V!J68 -> 5064.5712 | J21: =I21-F21 -> 309.02937
B22: =estimate!B24 -> -13% VAT for aggregate | F22: =estimate!J24 -> 9828.1198 | I22: =V!J69 -> 10466.781 | J22: =I22-F22 -> 638.6607
B23: =estimate!B25 -> -13% VAT for water | F23: =estimate!J25 -> 171.95977 | I23: =V!J70 -> 183.13423 | J23: =I23-F23 -> 11.174461
B24: =estimate!B26 -> -13% VAT for formwork | F24: =estimate!J26 -> 1536.1887 | I24: =V!J71 -> 1636.0149 | J24: =I24-F24 -> 99.82615
A26: =estimate!A28 -> 4 | B26: =estimate!B28 -> Providing and laying , fitting and placing HYSD bar reinforcement in sub-structure complete as per Drawing and Technical Specifications and instruction of site engineer | C26: =estimate!H31 -> tonne | D26: =estimate!G31 -> 0.69012346 | E26: =estimate!I31 -> 124355 | F26: =D26*E26 -> 85820.302 | G26: =V!G102 -> 0.72149728 | H26: =V!I102 -> 124355 | I26: =G26*H26 -> 89721.795 | J26: =I26-F26 -> 3901.4923 | M26: =1.25*F26 -> 107275.38
B27: =estimate!B32 -> -13% VAT for HYSD bar | F27: =estimate!J32 -> 9868.7654 | I27: =V!J103 -> 10317.411 | J27: =I27-F27 -> 448.64573 | M27: =1.25*F27 -> 12335.957
B28: =estimate!B33 -> -13% VAT for binding wire | F28: =estimate!J33 -> 86.127407 | I28: =V!J104 -> 90.042861 | J28: =I28-F28 -> 3.9154536
A30: =estimate!A35 -> 5 | B30: =estimate!B35 -> Provisional sum for lab tests | C30: =estimate!H35 -> PS | D30: =estimate!G35 -> 1 | E30: =estimate!I35 -> 5000 | F30: =D30*E30 -> 5000 | G30: =V!G106 -> 1 | H30: =V!I106 -> 5000 | I30: =G30*H30 -> 5000 | J30: =I30-F30 -> 0 | M30: =1.25*F30 -> 6250
A32: =estimate!A37 -> 6 | B32: =estimate!B37 -> Information board (सुचना पाटि) | C32: =estimate!H37 -> no. | D32: =estimate!G37 -> 1 | E32: =estimate!I37 -> 500 | F32: =D32*E32 -> 500 | G32: =V!G108 -> 1 | H32: =V!I108 -> 500 | I32: =G32*H32 -> 500 | J32: =I32-F32 -> 0
B34: Total | F34: =SUM(F13:F32) -> 565661.09 | I34: =SUM(I13:I32) -> 563256.5 | J34: =I34-F34 -> -2404.5952

Sheet V
A1: Government of Nepal
A2: Shankharapur Municipality Office
A3: Bagmati Province
A4: Sankhu, Kathmandu
A5: Detail Estimated Sheet
A6: Project:- nfFs'/Ljf]6 b]jL ;'df/f ;8s | H6: F.Y.: 2082/2083
A7: Location:- Shankharapur Municipality 1 | H7: Date:2083/02/18
A8: S.N. | B8: Description of work | C8: No. | D8: Length | E8: Breadth | F8: Height | G8: Quantity | H8: Unit | I8: Rate | J8: Amount | K8: Remark
A9: 1 | B9: Earthwork Excavation in Cutting, Roadway Excavation in all types of Soil by Mechanical Means ., Road way Excavation in all types of soil as per Drawing and technical specifications including removal of stumps and other deleterious matter, all lifts and lead as per Drawing and instruction of the Engineer.
B10: -for road | C10: 1 | D10: ='chainage measurement'!C3 -> 5 | E10: ='chainage measurement'!E3 -> 3.3907345 | F10: ='chainage measurement'!G3-0.15 -> 0.1269938 | G10: =PRODUCT(C10:F10) -> 2.1530114
C11: 1 | D11: ='chainage measurement'!C4 -> 5 | E11: ='chainage measurement'!E4 -> 3.3145383 | F11: ='chainage measurement'!G4-0.15 -> 0.1269938 | G11: =PRODUCT(C11:F11) -> 2.1046291
C12: 1 | D12: ='chainage measurement'!C5 -> 5 | E12: ='chainage measurement'!E5 -> 3.0219445 | F12: ='chainage measurement'!G5-0.15 -> 0.10398761 | G12: =PRODUCT(C12:F12) -> 1.5712239
C13: 1 | D13: ='chainage measurement'!C6 -> 5 | E13: ='chainage measurement'!E6 -> 2.9838464 | F13: ='chainage measurement'!G6-0.15 -> 0.1103373 | G13: =PRODUCT(C13:F13) -> 1.6461477
C14: 1 | D14: ='chainage measurement'!C7 -> 5 | E14: ='chainage measurement'!E7 -> 3.1621457 | F14: ='chainage measurement'!G7-0.15 -> 0.11668699 | G14: =PRODUCT(C14:F14) -> 1.8449062
C15: 1 | D15: ='chainage measurement'!C8 -> 5 | E15: ='chainage measurement'!E8 -> 3.0859494 | F15: ='chainage measurement'!G8-0.15 -> 0.11668699 | G15: =PRODUCT(C15:F15) -> 1.8004507
C16: 1 | D16: ='chainage measurement'!C9 -> 5 | E16: ='chainage measurement'!E9 -> 3.1366961 | F16: ='chainage measurement'!G9-0.15 -> 0.1103373 | G16: =PRODUCT(C16:F16) -> 1.7304728
C17: 1 | D17: ='chainage measurement'!C10 -> 5 | E17: ='chainage measurement'!E10 -> 3.1366961 | F17: ='chainage measurement'!G10-0.15 -> 0.10398761 | G17: =PRODUCT(C17:F17) -> 1.6308876
C18: 1 | D18: ='chainage measurement'!C11 -> 5 | E18: ='chainage measurement'!E11 -> 3.1240475 | F18: ='chainage measurement'!G11-0.15 -> 0.10398761 | G18: =PRODUCT(C18:F18) -> 1.6243111
C19: 1 | D19: ='chainage measurement'!C12 -> 5 | E19: ='chainage measurement'!E12 -> 3.2002438 | F19: ='chainage measurement'!G12-0.15 -> 0.10398761 | G19: =PRODUCT(C19:F19) -> 1.6639285
C20: 1 | D20: ='chainage measurement'!C13 -> 5 | E20: ='chainage measurement'!E13 -> 3.1240475 | F20: ='chainage measurement'!G13-0.15 -> 0.078588845 | G20: =PRODUCT(C20:F20) -> 1.2275764
C21: 1 | D21: ='chainage measurement'!C14 -> 3.0478513 | E21: ='chainage measurement'!E14 -> 3.2002438 | F21: ='chainage measurement'!G14-0.15 -> 0.065889465 | G21: =PRODUCT(C21:F21) -> 0.64267709
C22: 1 | D22: ='chainage measurement'!C15 -> 6 | E22: ='chainage measurement'!E15 -> 3.5557757 | F22: 0.15 | G22: =PRODUCT(C22:F22) -> 3.2001981
C23: 1 | D23: ='chainage measurement'!C16 -> 0.35558265 | E23: ='chainage measurement'!E16 -> 3.8351112 | F23: 0.15 | G23: =PRODUCT(C23:F23) -> 0.20455485
C24: 1 | D24: ='chainage measurement'!C17 -> 5 | E24: ='chainage measurement'!E17 -> 4.4925556 | F24: 0.15 | G24: =PRODUCT(C24:F24) -> 3.3694167
C25: 1 | D25: ='chainage measurement'!C18 -> 1 | E25: ='chainage measurement'!E18 -> 5.675 | F25: 0.15 | G25: =PRODUCT(C25:F25) -> 0.85125
B26: sub-total | G26: =SUM(G10:G25) -> 27.265642 | H26: cum | I26: 62.95 | J26: =G26*I26 -> 1716.3722
B27: -13% VAT for excavator | J27: =0.13*G26*18612/360 -> 183.25238
A29: 2 | B29: Providing and laying of hand pack locally available Stone soling with 150 to 200 mm thick stones and packing with smaller stone on prepared surface as per Drawing and Technical Specifications.
B30: =B10 -> -for road | C30: =C10 -> 1 | D30: =D10 -> 5 | E30: =E10 -> 3.3907345 | F30: =F10 -> 0.1269938 | G30: =PRODUCT(C30:F30) -> 2.1530114
C31: =C11 -> 1 | D31: =D11 -> 5 | E31: =E11 -> 3.3145383 | F31: =F11 -> 0.1269938 | G31: =PRODUCT(C31:F31) -> 2.1046291
C32: =C12 -> 1 | D32: =D12 -> 5 | E32: =E12 -> 3.0219445 | F32: =F12 -> 0.10398761 | G32: =PRODUCT(C32:F32) -> 1.5712239
C33: =C13 -> 1 | D33: =D13 -> 5 | E33: =E13 -> 2.9838464 | F33: =F13 -> 0.1103373 | G33: =PRODUCT(C33:F33) -> 1.6461477
C34: =C14 -> 1 | D34: =D14 -> 5 | E34: =E14 -> 3.1621457 | F34: =F14 -> 0.11668699 | G34: =PRODUCT(C34:F34) -> 1.8449062
C35: =C15 -> 1 | D35: =D15 -> 5 | E35: =E15 -> 3.0859494 | F35: =F15 -> 0.11668699 | G35: =PRODUCT(C35:F35) -> 1.8004507
C36: =C16 -> 1 | D36: =D16 -> 5 | E36: =E16 -> 3.1366961 | F36: =F16 -> 0.1103373 | G36: =PRODUCT(C36:F36) -> 1.7304728
C37: =C17 -> 1 | D37: =D17 -> 5 | E37: =E17 -> 3.1366961 | F37: =F17 -> 0.10398761 | G37: =PRODUCT(C37:F37) -> 1.6308876
C38: =C18 -> 1 | D38: =D18 -> 5 | E38: =E18 -> 3.1240475 | F38: =F18 -> 0.10398761 | G38: =PRODUCT(C38:F38) -> 1.6243111
C39: =C19 -> 1 | D39: =D19 -> 5 | E39: =E19 -> 3.2002438 | F39: =F19 -> 0.10398761 | G39: =PRODUCT(C39:F39) -> 1.6639285
C40: =C20 -> 1 | D40: =D20 -> 5 | E40: =E20 -> 3.1240475 | F40: =F20 -> 0.078588845 | G40: =PRODUCT(C40:F40) -> 1.2275764
C41: =C21 -> 1 | D41: =D21 -> 3.0478513 | E41: =E21 -> 3.2002438 | F41: =F21 -> 0.065889465 | G41: =PRODUCT(C41:F41) -> 0.64267709
...

Sheet chainage measurement
A1: Description | B1: Chainage | C1: Length | E1: Breadth | G1: Height | H1: Remarks
B2: 0 | D2: =11/3.281 -> 3.3526364 | F2: =10/12/3.281 -> 0.25398761 | H2: include stone soling
B3: 5 | C3: 5 | D3: =11.25/3.281 -> 3.4288327 | E3: =(D2+D3)/2 -> 3.3907345 | F3: =0.3 -> 0.3 | G3: =(F2+F3)/2 -> 0.2769938 | H3: include stone soling
B4: 5 | C4: 5 | D4: =10.5/3.281 -> 3.2002438 | E4: =(D3+D4)/2 -> 3.3145383 | F4: =10/12/3.281 -> 0.25398761 | G4: =(F3+F4)/2 -> 0.2769938 | H4: include stone soling
B5: 5 | C5: 5 | D5: =9.33/3.281 -> 2.8436452 | E5: =(D4+D5)/2 -> 3.0219445 | F5: =10/12/3.281 -> 0.25398761 | G5: =(F4+F5)/2 -> 0.25398761 | H5: include stone soling
B6: 5 | C6: 5 | D6: =10.25/3.281 -> 3.1240475 | E6: =(D5+D6)/2 -> 2.9838464 | F6: =10.5/12/3.281 -> 0.26668699 | G6: =(F5+F6)/2 -> 0.2603373 | H6: include stone soling
B7: 5 | C7: 5 | D7: =10.5/3.281 -> 3.2002438 | E7: =(D6+D7)/2 -> 3.1621457 | F7: =10.5/12/3.281 -> 0.26668699 | G7: =(F6+F7)/2 -> 0.26668699 | H7: include stone soling
B8: 5 | C8: 5 | D8: =9.75/3.281 -> 2.971655 | E8: =(D7+D8)/2 -> 3.0859494 | F8: =10.5/12/3.281 -> 0.26668699 | G8: =(F7+F8)/2 -> 0.26668699 | H8: include stone soling
B9: 5 | C9: 5 | D9: =10.833/3.281 -> 3.3017373 | E9: =(D8+D9)/2 -> 3.1366961 | F9: =10/12/3.281 -> 0.25398761 | G9: =(F8+F9)/2 -> 0.2603373 | H9: include stone soling
B10: 5 | C10: 5 | D10: =9.75/3.281 -> 2.971655 | E10: =(D9+D10)/2 -> 3.1366961 | F10: =10/12/3.281 -> 0.25398761 | G10: =(F9+F10)/2 -> 0.25398761 | H10: include stone soling
B11: 5 | C11: 5 | D11: =10.75/3.281 -> 3.2764401 | E11: =(D10+D11)/2 -> 3.1240475 | F11: =10/12/3.281 -> 0.25398761 | G11: =(F10+F11)/2 -> 0.25398761 | H11: include stone soling
B12: 5 | C12: 5 | D12: =10.25/3.281 -> 3.1240475 | E12: =(D11+D12)/2 -> 3.2002438 | F12: =10/12/3.281 -> 0.25398761 | G12: =(F11+F12)/2 -> 0.25398761 | H12: include stone soling
B13: 5 | C13: 5 | D13: =10.25/3.281 -> 3.1240475 | E13: =(D12+D13)/2 -> 3.1240475 | F13: =8/12/3.281 -> 0.20319008 | G13: =(F12+F13)/2 -> 0.22858884 | H13: include stone soling
B14: =10/3.281 -> 3.0478513 | C14: =10/3.281 -> 3.0478513 | D14: =10.75/3.281 -> 3.2764401 | E14: =(D13+D14)/2 -> 3.2002438 | F14: =9/12/3.281 -> 0.22858884 | G14: =(F13+F14)/2 -> 0.21588946 | H14: include stone soling
B15: 5 | C15: 6 | D15: =12.583/3.281 -> 3.8351112 | E15: =(D14+D15)/2 -> 3.5557757 | F15: =7/12/3.281 -> 0.17779132 | G15: =(F14+F15)/2 -> 0.20319008 | H15: only RCC
B16: =14/12/3.281 -> 0.35558265 | C16: =14/12/3.281 -> 0.35558265 | D16: =12.583/3.281 -> 3.8351112 | E16: =(D15+D16)/2 -> 3.8351112 | F16: =7/12/3.281 -> 0.17779132 | G16: =(F15+F16)/2 -> 0.17779132 | H16: only RCC
B17: 5 | C17: 5 | D17: =5.15 -> 5.15 | E17: =(D16+D17)/2 -> 4.4925556 | F17: =8/12/3.281 -> 0.20319008 | G17: =(F16+F17)/2 -> 0.1904907 | H17: only RCC
B18: 1 | C18: 1 | D18: 6.2 | E18: =(D17+D18)/2 -> 5.675 | F18: =6/12/3.281 -> 0.15239256 | G18: =(F17+F18)/2 -> 0.17779132 | H18: only RCC
