Workbook
Name description_103: [1]Abstract!$B$16
Name description_124: #REF!
Name description_124: #REF!
Name description_124: #REF!
Name description_124: #REF!
Name description_124: #REF!
Name description_247: [1]Abstract!$B$22
Name description_248: [1]Abstract!$B$23
Name description_261: [2]Abstract!$B$33
Name description_262: [1]Abstract!$B$34
Name description_276: [3]Abstract!$B$40
Name description_3: [1]Abstract!$B$169
Name description_310: #REF!
Name description_310: #REF!
Name description_310: #REF!
Name description_310: [4]Abstract!$B$60
Name description_310: #REF!
Name description_312: #REF!
Name description_312: #REF!
Name description_312: #REF!
Name description_312: [5]Abstract!$B$61
Name description_312: #REF!
Name description_5: [1]Abstract!$B$171
Name description_6: #REF!
Name description_6: #REF!
Name description_6: #REF!
Name description_6: [4]Abstract!$B$172
Name description_6: #REF!
Name description_759: [1]Abstract!$B$278
Name description_781: #REF!
Name description_781: #REF!
Name description_781: #REF!
Name description_781: [6]Abstract!$B$299
Name description_781: #REF!
Name description_783: [1]Abstract!$B$301
Name description_784: [3]Abstract!$B$300

Sheet estimate
A1: Government of Nepal
A2: Shankharapur Municipality Office
A3: Bagmati Province
A4: Sankhu, Kathmandu
A5: Detail Estimated Sheet
A6: Project:- v'bf] ksfpg] el6 r'nf] | H6: F.Y.: 2082/2083
A7: Location:- Shankharapur Municipality 1 | H7: Date:2082/09/13
A8: S.N. | B8: Description of work | C8: No. | D8: Length | E8: Breadth | F8: Height | G8: Quantity | H8: Unit | I8: Rate | J8: Amount | K8: Remark
A9: 1 | B9: sfnf] kmnfd] kfO{ksf] 6«; agfO{ h8fg ug]{ sfd | C9: No. | D9: Length (m) | E9: Unit length (Kg/m) | F9: Total Weight (kg)
B10: -MS square pipe of 3" * 3" of 2mm thickness for vertical post | C10: =2*3 -> 6 | D10: =(11+1+2)/3.281 -> 4.2669918 | E10: 4.4 | F10: =PRODUCT(C10:E10) -> 112.64858 | G10: =F10 -> 112.64858
C11: =2*3 -> 6 | D11: =(11+1+1+2)/3.281 -> 4.5717769 | E11: 4.4 | F11: =PRODUCT(C11:E11) -> 120.69491 | G11: =F11 -> 120.69491
C12: =2 -> 2 | D12: =(11+1+2)/3.281 -> 4.2669918 | E12: 4.4 | F12: =PRODUCT(C12:E12) -> 37.549528 | G12: =F12 -> 37.549528
C13: =2 -> 2 | D13: =(11+1+1+2)/3.281 -> 4.5717769 | E13: 4.4 | F13: =PRODUCT(C13:E13) -> 40.231637 | G13: =F13 -> 40.231637
B14: -MS square pipe horizontal of 2" * 2" of 2mm thickness for binding post | C14: =2*(2+1) -> 6 | D14: =(12+3)/3.281 -> 4.5717769 | E14: 3.01 | F14: =PRODUCT(C14:E14) -> 82.566291 | G14: =F14 -> 82.566291 | Q14: =PRODUCT(C14:D14) -> 27.430661 | R14: =CONVERT(Q14,"m","ft") -> 89.995608
C15: =2*(2+1) -> 6 | D15: =(10+3)/3.281 -> 3.9622066 | E15: 3.01 | F15: =PRODUCT(C15:E15) -> 71.557452 | G15: =F15 -> 71.557452
B16: -MS square pipe horizontal of 1.5" * 1.5" of 2mm thickness as purlin at mid portion of upper part | C16: =2*2 -> 4 | D16: =(12+3)/3.281 -> 4.5717769 | E16: 2.26 | F16: =PRODUCT(C16:E16) -> 41.328863 | G16: =F16 -> 41.328863
B17: sub-total | G17: =SUM(G10:G16) -> 506.57726 | H17: Kg | I17: 182.51 | J17: =G17*I17 -> 92455.416
B18: -VAT 13% for materials | J18: =0.13*G17*(1871.42/18.94) -> 6506.993
A20: 2 | B20: ).#^ lblv ).$ dL.dL.afSnf] sf]?u]6]8 /+lug ss{6 kftfsf] 5fgf 5fpg] sfd
B21: -upper portion | C21: =2*1 -> 2 | D21: =(10+3)/3.281 -> 3.9622066 | E21: =(12+3)/3.281 -> 4.5717769 | G21: =PRODUCT(C21:F21) -> 36.22865
C22: 1 | D22: =(10+3)/3.281 -> 3.9622066 | E22: =(10+3)/3.281 -> 3.9622066 | G22: =PRODUCT(C22:F22) -> 15.699081
B23: sub-total | G23: =SUM(G21:G22) -> 51.927731 | H23: sqm | I23: 1074.98 | J23: =G23*I23 -> 55821.272
B24: -13% VAT for sheet | J24: =0.13*G23*6674.66/10 -> 4505.7993
B25: -13% VAT for nut bolt | J25: =0.13*G23*1023.75/10 -> 691.09319
B26: -13% VAT for j-hook | J26: =0.13*G23*348.21/10 -> 235.06282
B27: -13% VAT for bitumen washer | J27: =0.13*G23*165/10 -> 111.38498
A29: 3 | B29: g/d k|sf/sf] Sn] / l;N6L df6f]df ;j} lsl;dsf] vGg] sfd
B30: -Masonary wall | C30: =2*2 -> 4 | D30: =8/3.281 -> 2.438281 | E30: 0.45 | F30: 0.9 | G30: =PRODUCT(C30:F30) -> 3.9500152
B31: -for footing of vertical post | C31: =2*4 -> 8 | D31: 0.6 | E31: 0.6 | F31: 0.6 | G31: =PRODUCT(C31:F31) -> 1.728
B32: sub-total | G32: =SUM(G30:G31) -> 5.6780152 | H32: cum | I32: 674.12 | J32: =G32*I32 -> 3827.6636
A34: 4 | B34: husf] vf8ndf 9'+uf eg]{ / n]en ug]{ sfddf
B35: =B31 -> -for footing of vertical post | C35: =C31 -> 8 | D35: =D31 -> 0.6 | E35: =E31 -> 0.6 | F35: 0.15 | G35: =PRODUCT(C35:F35) -> 0.432
B36: -for flooring | C36: =2*1 -> 2 | D36: =10/3.281 -> 3.0478513 | E36: =12/3.281 -> 3.6574215 | F36: 0.15 | G36: =PRODUCT(C36:F36) -> 3.344183
B37: -deduction for tunnel | C37: =2*-1 -> -2 | D37: =8/3.281 -> 2.438281 | E37: =0.6+0.45+0.45 -> 1.5 | F37: 0.15 | G37: =PRODUCT(C37:F37) -> -1.0972265
B38: sub-total | G38: =SUM(G35:G37) -> 2.6789566 | H38: cum | I38: 4495.64 | J38: =G38*I38 -> 12043.624
B39: -13% VAT for block stone | J39: =0.13*G38*2577.63 -> 897.69665
B40: -13% VAT for bond stone | J40: =0.13*G38*515.52 -> 179.53724
A42: 5 | B42: hu leQf kvf{ndf l;d]G6 s+lqm6 ug]{ sfd -lk=;L=;L= !M@M$_
B43: =B35 -> -for footing of vertical post | C43: =2*4 -> 8 | D43: 0.6 | E43: 0.6 | F43: 0.075 | G43: =PRODUCT(C43:F43) -> 0.216
C44: =2*4 -> 8 | D44: 0.45 | E44: 0.45 | F44: 0.45 | G44: =PRODUCT(C44:F44) -> 0.729
...

Sheet V
A1: Government of Nepal
A2: Shankharapur Municipality Office
A3: Bagmati Province
A4: Sankhu, Kathmandu
A5: Detail Valuated Sheet
A6: Project:- v'bf] ksfpg] el6 r'nf] | H6: F.Y.: 2082/2083
A7: Location:- Shankharapur Municipality 1 | H7: Date:2082/11/10
A8: S.N. | B8: Description of work | C8: No. | D8: Length | E8: Breadth | F8: Height | G8: Quantity | H8: Unit | I8: Rate | J8: Amount | K8: Remark
A9: 1 | B9: sfnf] kmnfd] kfO{ksf] 6«; agfO{ h8fg ug]{ sfd | C9: No. | D9: Length (m) | E9: Unit length (Kg/m) | F9: Total Weight (kg)
B10: -MS square pipe of 3" * 3" of 1.6mm thickness for vertical post | C10: 2 | D10: =(15.5+1)/3.281 -> 5.0289546 | E10: 3.54 | F10: =PRODUCT(C10:E10) -> 35.604998 | G10: =F10 -> 35.604998
C11: 2 | D11: =(15.5-1.5+2)/3.281 -> 4.876562 | E11: 3.54 | F11: =PRODUCT(C11:E11) -> 34.526059 | G11: =F11 -> 34.526059
B12: -MS square pipe of 2" * 2" of 1.4mm thickness for vertical post | C12: 2 | D12: 3.9 | E12: 2.14 | F12: =PRODUCT(C12:E12) -> 16.692 | G12: =F12 -> 16.692
B13: -MS square pipe of 2" * 2" of 1.4mm thickness for purlins | C13: 9 | D13: 3.09 | E13: 2.14 | F13: =PRODUCT(C13:E13) -> 59.5134 | G13: =F13 -> 59.5134
B14: -MS square pipe of 66mm*33mm of 1.4mm thickness for vertical post | C14: 1 | D14: 3.9 | E14: 2.35 | F14: =PRODUCT(C14:E14) -> 9.165 | G14: =F14 -> 9.165
B15: -MS square pipe of 3" * 3" of 1.6mm thickness for vertical post for cooking area | C15: 3 | D15: =(7+1)/3.281 -> 2.438281 | E15: 3.54 | F15: =PRODUCT(C15:E15) -> 25.894544 | G15: =F15 -> 25.894544
C16: 3 | D16: 2.6 | E16: 3.54 | F16: =PRODUCT(C16:E16) -> 27.612 | G16: =F16 -> 27.612
B17: -MS square pipe of 1.5" * 1.5" of 1.2mm thickness for purlins | C17: 5 | D17: 3.09 | E17: 1.39 | F17: =PRODUCT(C17:E17) -> 21.4755 | G17: =F17 -> 21.4755
B18: -MS square pipe of 1.5" * 1.5" of 1.2mm thickness for horizontal support in mid-height section | C18: 5 | D18: =1.8+1.9 -> 3.7 | E18: 1.39 | F18: =PRODUCT(C18:E18) -> 25.715 | G18: =F18 -> 25.715
B19: -MS square pipe of 2" * 2" of 1.4mm thickness for horizontal support of roof | C19: 3 | D19: =13/3.281 -> 3.9622066 | E19: 1.39 | F19: =PRODUCT(C19:E19) -> 16.522402 | G19: =F19 -> 16.522402
B20: -MS square pipe of 3" * 3" of 1.6mm thickness for vertical post | C20: 3 | D20: =(13)/3.281 -> 3.9622066 | E20: 3.54 | F20: =PRODUCT(C20:E20) -> 42.078635 | G20: =F20 -> 42.078635
C21: 3 | D21: =(9)/3.281 -> 2.7430661 | E21: 3.54 | F21: =PRODUCT(C21:E21) -> 29.131362 | G21: =F21 -> 29.131362
B22: -MS square pipe of 1.5" * 1.5" of 1.2mm thickness for purlins | C22: 5 | D22: =3.8+7-11.33/3.281+0.6 -> 7.9467845 | E22: 1.39 | F22: =PRODUCT(C22:E22) -> 55.230152 | G22: =F22 -> 55.230152
B23: -MS square pipe of 66mm*33mm of 1.4mm thickness for horizontal member | C23: 3 | D23: =11.25/3.281 -> 3.4288327 | E23: 2.35 | F23: =PRODUCT(C23:E23) -> 24.17327 | G23: =F23 -> 24.17327
B24: -MS square pipe of 1.5" * 1.5" of 1.2mm thickness for horizontal support at walls | C24: 3 | D24: =(11.667*2)/3.281 -> 7.1118561 | E24: 1.39 | F24: =PRODUCT(C24:E24) -> 29.65644 | G24: =F24 -> 29.65644
C25: 3 | D25: =11.25/3.281 -> 3.4288327 | E25: 1.39 | F25: =PRODUCT(C25:E25) -> 14.298232 | G25: =F25 -> 14.298232
C26: 6 | D26: =11.25/3.281 -> 3.4288327 | E26: 1.39 | F26: =PRODUCT(C26:E26) -> 28.596464 | G26: =F26 -> 28.596464
B27: sub-total | G27: =SUM(G10:G26) -> 495.88546 | H27: Kg | I27: 182.51 | J27: =G27*I27 -> 90504.055
B28: -VAT 13% for materials | J28: =0.13*G27*(1871.42/18.94) -> 6369.6566
A30: 2 | B30: ).#^ lblv ).$ dL.dL.afSnf] sf]?u]6]8 /+lug ss{6 kftfsf] 5fgf 5fpg] sfd
B31: -upper portion | C31: 1 | D31: =(10+3)/3.281 -> 3.9622066 | E31: =(7)/3.281 -> 2.1334959 | G31: =PRODUCT(C31:F31) -> 8.4533516
B32: -cooking area | C32: 1 | D32: =(13)/3.281 -> 3.9622066 | E32: =1.75+1.75 -> 3.5 | G32: =PRODUCT(C32:F32) -> 13.867723
C33: 1 | D33: =3.75+7-11.33/3.281 -> 7.2967845 | E33: =14/3.281 -> 4.2669918 | G33: =PRODUCT(C33:F33) -> 31.135319
B34: sub-total | G34: =SUM(G31:G33) -> 53.456394 | H34: sqm | I34: 1074.98 | J34: =G34*I34 -> 57464.555
B35: -13% VAT for sheet | J35: =0.13*G34*6674.66/10 -> 4638.4423
B36: -13% VAT for nut bolt | J36: =0.13*G34*1023.75/10 -> 711.43779
B37: -13% VAT for j-hook | J37: =0.13*G34*348.21/10 -> 241.98266
B38: -13% VAT for bitumen washer | J38: =0.13*G34*165/10 -> 114.66397
A40: 3 | B40: g/d k|sf/sf] Sn] / l;N6L df6f]df ;j} lsl;dsf] vGg] sfd
B41: -Masonary wall | C41: 2 | D41: =8/3.281 -> 2.438281 | E41: 0.45 | F41: 0.9 | G41: =PRODUCT(C41:F41) -> 1.9750076
B42: -for footing of vertical post | C42: =2*6 -> 12 | D42: 0.45 | E42: 0.45 | F42: 0.45 | G42: =PRODUCT(C42:F42) -> 1.0935
...

Sheet WCR
A1: Government of Nepal
A2: Shankharapur Municipality Office
A3: Bagmati Province
A4: Sankhu, Kathmandu
A5: Work Completion Report
A6: Total Estimated Amount: | C6: =F42 -> 234835.07 | H6: Total Valuated Amount : | J6: =I42 -> 240974.86
A7: Work Started : | I7: Work Finished:
A8: Project:- v'bf] ksfpg] el6 r'nf] | I8: F.Y:2082/2083
A9: =[7]estimate!A7 -> Location:- Shankharapur Municipality 1 | I9: Date:2082/11/10
A11: S.No. | B11: Description | C11: Unit | D11: Estimated | G11: Valuated | J11: Difference | K11: Remarks
D12: Quantity | E12: Rate | F12: Amount | G12: Quantity | H12: Rate | I12: Amount
A13: =estimate!A9 -> 1 | B13: =estimate!B9 -> sfnf] kmnfd] kfO{ksf] 6«; agfO{ h8fg ug]{ sfd | C13: =estimate!H17 -> Kg | D13: =estimate!G17 -> 506.57726 | E13: =estimate!I17 -> 182.51 | F13: =D13*E13 -> 92455.416 | G13: =V!G27 -> 495.88546 | H13: =V!I27 -> 182.51 | I13: =G13*H13 -> 90504.055 | J13: =I13-F13 -> -1951.3609 | M13: =1.25*F13 -> 115569.27
B14: =estimate!B18 -> -VAT 13% for materials | F14: =estimate!J18 -> 6506.993 | I14: =V!J28 -> 6369.6566 | J14: =I14-F14 -> -137.33638 | M14: =1.25*F14 -> 8133.7412
A16: =estimate!A20 -> 2 | B16: =estimate!B20 -> ).#^ lblv ).$ dL.dL.afSnf] sf]?u]6]8 /+lug ss{6 kftfsf] 5fgf 5fpg] sfd | C16: =estimate!H23 -> sqm | D16: =estimate!G23 -> 51.927731 | E16: =estimate!I23 -> 1074.98 | F16: =D16*E16 -> 55821.272 | G16: =V!G34 -> 53.456394 | H16: =V!I34 -> 1074.98 | I16: =G16*H16 -> 57464.555 | J16: =I16-F16 -> 1643.2824 | M16: =1.25*F16 -> 69776.59
B17: =estimate!B24 -> -13% VAT for sheet | F17: =estimate!J24 -> 4505.7993 | I17: =V!J35 -> 4638.4423 | J17: =I17-F17 -> 132.64299 | M17: =1.25*F17 -> 5632.2492
B18: =estimate!B25 -> -13% VAT for nut bolt | F18: =estimate!J25 -> 691.09319 | I18: =V!J36 -> 711.43779 | J18: =I18-F18 -> 20.344597 | M18: =1.25*F18 -> 863.86649
B19: =estimate!B26 -> -13% VAT for j-hook | F19: =estimate!J26 -> 235.06282 | I19: =V!J37 -> 241.98266 | J19: =I19-F19 -> 6.9198457 | M19: =1.25*F19 -> 293.82852
B20: =estimate!B27 -> -13% VAT for bitumen washer | F20: =estimate!J27 -> 111.38498 | I20: =V!J38 -> 114.66397 | J20: =I20-F20 -> 3.2789826 | M20: =1.25*F20 -> 139.23123
A22: =estimate!A29 -> 3 | B22: =estimate!B29 -> g/d k|sf/sf] Sn] / l;N6L df6f]df ;j} lsl;dsf] vGg] sfd | C22: =estimate!H32 -> cum | D22: =estimate!G32 -> 5.6780152 | E22: =estimate!I32 -> 674.12 | F22: =D22*E22 -> 3827.6636 | G22: =V!G46 -> 5.919385 | H22: =V!I46 -> 674.12 | I22: =G22*H22 -> 3990.3758 | J22: =I22-F22 -> 162.71217 | M22: =1.25*F22 -> 4784.5795
A24: =estimate!A34 -> 4 | B24: =estimate!B34 -> husf] vf8ndf 9'+uf eg]{ / n]en ug]{ sfddf | C24: =estimate!H38 -> cum | D24: =estimate!G38 -> 2.6789566 | E24: =estimate!I38 -> 4495.64 | F24: =D24*E24 -> 12043.624 | G24: =V!G55 -> 2.90025 | H24: =V!I55 -> 4495.64 | I24: =G24*H24 -> 13038.48 | J24: =I24-F24 -> 994.85553 | M24: =1.25*F24 -> 15054.53
B25: =estimate!B39 -> -13% VAT for block stone | F25: =estimate!J39 -> 897.69665 | I25: =V!J56 -> 971.85028 | J25: =I25-F25 -> 74.153631 | M25: =1.25*F25 -> 1122.1208
B26: =estimate!B40 -> -13% VAT for bond stone | F26: =estimate!J40 -> 179.53724 | I26: =V!J57 -> 194.36779 | J26: =I26-F26 -> 14.830554 | M26: =1.25*F26 -> 224.42155
A28: =estimate!A42 -> 5 | B28: =estimate!B42 -> hu leQf kvf{ndf l;d]G6 s+lqm6 ug]{ sfd -lk=;L=;L= !M@M$_ | C28: =estimate!H47 -> cum | D28: =estimate!G47 -> 2.0772289 | E28: =estimate!I47 -> 13351.1 | F28: =D28*E28 -> 27733.291 | G28: =V!G65 -> 2.3495 | H28: =V!I65 -> 13351.1 | I28: =G28*H28 -> 31368.409 | J28: =I28-F28 -> 3635.1186 | M28: =1.25*F28 -> 34666.614
B29: =estimate!B48 -> -13% VAT for cement | F29: =estimate!J48 -> 1126.0442 | I29: =V!J66 -> 1273.6395 | J29: =I29-F29 -> 147.59533 | M29: =1.25*F29 -> 1407.5552
B30: =estimate!B49 -> -13% VAT for sand | F30: =estimate!J49 -> 381.87942 | I30: =V!J67 -> 431.93396 | J30: =I30-F30 -> 50.054536 | M30: =1.25*F30 -> 477.34928
B31: =estimate!B50 -> -13% VAT for aggregate | F31: =estimate!J50 -> 739.91704 | I31: =V!J68 -> 836.90106 | J31: =I31-F31 -> 96.984026 | M31: =1.25*F31 -> 924.8963
B32: =estimate!B51 -> -13% VAT for water | F32: =estimate!J51 -> 11.34167 | I32: =V!J69 -> 12.82827 | J32: =I32-F32 -> 1.4866002 | M32: =1.25*F32 -> 14.177087
A34: =estimate!A53 -> 6 | B34: =estimate!B53 -> 9'Ëfsf] uf/f] df6f] nufpg] sfd | C34: =estimate!H55 -> cum | D34: =estimate!G55 -> 3.9500152 | E34: =estimate!I55 -> 6337.3 | F34: =D34*E34 -> 25032.432 | G34: =V!G74 -> 4.1350076 | H34: =V!I74 -> 6337.3 | I34: =G34*H34 -> 26204.784 | J34: =I34-F34 -> 1172.3522 | M34: =1.25*F34 -> 31290.539
B35: =estimate!B56 -> -13% VAT for block stone | F35: =estimate!J56 -> 1323.6181 | I35: =V!J75 -> 1385.6076 | J35: =I35-F35 -> 61.989448 | M35: =1.25*F35 -> 1654.5226
B36: =estimate!B57 -> -13% VAT for bond stone | F36: =estimate!J57 -> 132.36027 | I36: =V!J76 -> 138.55914 | J36: =I36-F36 -> 6.1988727 | M36: =1.25*F36 -> 165.45034
B37: =estimate!B58 -> -13% VAT for stone | F37: =estimate!J58 -> 68.583325 | I37: =V!J77 -> 71.79531 | J37: =I37-F37 -> 3.2119857 | M37: =1.25*F37 -> 85.729156
B38: =estimate!B59 -> -13% VAT for water | F38: =estimate!J59 -> 10.064639 | I38: =V!J78 -> 10.535999 | J38: =I38-F38 -> 0.47136059 | M38: =1.25*F38 -> 12.580799
A40: =estimate!A61 -> 7 | B40: =estimate!B61 -> Information board (सुचना पाटि) | C40: =estimate!H61 -> no. | D40: =estimate!G61 -> 1 | E40: =estimate!I61 -> 1000 | F40: =D40*E40 -> 1000 | G40: =V!G80 -> 1 | H40: =V!I80 -> 1000 | I40: =G40*H40 -> 1000 | J40: =I40-F40 -> 0
B42: Total | F42: =SUM(F13:F40) -> 234835.07 | I42: =SUM(I13:I40) -> 240974.86 | J42: =I42-F42 -> 6139.7864

Sheet M
A1: Government of Nepal
A2: Shankharapur Municipality Office
A3: Bagmati Province
A4: Sankhu, Kathmandu
A5: Detail Quantity Measurement Sheet
A6: Project:- v'bf] ksfpg] el6 r'nf] | K6: F.Y.: 2082/2083
A7: Location:- Shankharapur Municipality 1 | K7: Date:2082/11/10
A8: S.N. | B8: Description of work | C8: No. | D8: Length | E8: Breadth | F8: Height | G8: Quantity | H8: Unit | I8: Rate | J8: Amount | K8: Remark
A9: 1 | B9: sfnf] kmnfd] kfO{ksf] 6«; agfO{ h8fg ug]{ sfd | C9: No. | D9: Length (m) | E9: Unit length (Kg/m) | F9: Total Weight (kg)
B10: -MS square pipe of 3" * 3" of 1.6mm thickness for vertical post | C10: 2 | D10: =(15.5+1)/3.281 -> 5.0289546 | E10: 3.54 | F10: =PRODUCT(C10:E10) -> 35.604998 | G10: =F10 -> 35.604998
C11: 2 | D11: =(15.5-1.5+2)/3.281 -> 4.876562 | E11: 3.54 | F11: =PRODUCT(C11:E11) -> 34.526059 | G11: =F11 -> 34.526059
B12: -MS square pipe of 2" * 2" of 1.4mm thickness for vertical post | C12: 2 | D12: 3.9 | E12: 2.14 | F12: =PRODUCT(C12:E12) -> 16.692 | G12: =F12 -> 16.692
B13: -MS square pipe of 2" * 2" of 1.4mm thickness for purlins | C13: 9 | D13: 3.09 | E13: 2.14 | F13: =PRODUCT(C13:E13) -> 59.5134 | G13: =F13 -> 59.5134
B14: -MS square pipe of 66mm*33mm of 1.4mm thickness for vertical post | C14: 1 | D14: 3.9 | E14: 2.35 | F14: =PRODUCT(C14:E14) -> 9.165 | G14: =F14 -> 9.165
B15: -MS square pipe of 3" * 3" of 1.6mm thickness for vertical post for cooking area | C15: 3 | D15: =(7+1)/3.281 -> 2.438281 | E15: 3.54 | F15: =PRODUCT(C15:E15) -> 25.894544 | G15: =F15 -> 25.894544
C16: 3 | D16: 2.6 | E16: 3.54 | F16: =PRODUCT(C16:E16) -> 27.612 | G16: =F16 -> 27.612
B17: -MS square pipe of 1.5" * 1.5" of 1.2mm thickness for purlins | C17: 5 | D17: 3.09 | E17: 1.39 | F17: =PRODUCT(C17:E17) -> 21.4755 | G17: =F17 -> 21.4755
B18: -MS square pipe of 1.5" * 1.5" of 1.2mm thickness for horizontal support in mid-height section | C18: 5 | D18: =1.8+1.9 -> 3.7 | E18: 1.39 | F18: =PRODUCT(C18:E18) -> 25.715 | G18: =F18 -> 25.715
B19: -MS square pipe of 2" * 2" of 1.4mm thickness for horizontal support of roof | C19: 3 | D19: =13/3.281 -> 3.9622066 | E19: 1.39 | F19: =PRODUCT(C19:E19) -> 16.522402 | G19: =F19 -> 16.522402
B20: -MS square pipe of 3" * 3" of 1.6mm thickness for vertical post | C20: 3 | D20: =(13)/3.281 -> 3.9622066 | E20: 3.54 | F20: =PRODUCT(C20:E20) -> 42.078635 | G20: =F20 -> 42.078635
C21: 3 | D21: =(9)/3.281 -> 2.7430661 | E21: 3.54 | F21: =PRODUCT(C21:E21) -> 29.131362 | G21: =F21 -> 29.131362
B22: -MS square pipe of 1.5" * 1.5" of 1.2mm thickness for purlins | C22: 5 | D22: =3.8+7-11.33/3.281+0.6 -> 7.9467845 | E22: 1.39 | F22: =PRODUCT(C22:E22) -> 55.230152 | G22: =F22 -> 55.230152
B23: -MS square pipe of 66mm*33mm of 1.4mm thickness for horizontal member | C23: 3 | D23: =11.25/3.281 -> 3.4288327 | E23: 2.35 | F23: =PRODUCT(C23:E23) -> 24.17327 | G23: =F23 -> 24.17327
B24: -MS square pipe of 1.5" * 1.5" of 1.2mm thickness for horizontal support at walls | C24: 3 | D24: =(11.667*2)/3.281 -> 7.1118561 | E24: 1.39 | F24: =PRODUCT(C24:E24) -> 29.65644 | G24: =F24 -> 29.65644
C25: 3 | D25: =11.25/3.281 -> 3.4288327 | E25: 1.39 | F25: =PRODUCT(C25:E25) -> 14.298232 | G25: =F25 -> 14.298232
C26: 6 | D26: =11.25/3.281 -> 3.4288327 | E26: 1.39 | F26: =PRODUCT(C26:E26) -> 28.596464 | G26: =F26 -> 28.596464
B27: sub-total | G27: =SUM(G10:G26) -> 495.88546 | H27: Kg | I27: 182.51 | J27: =G27*I27 -> 90504.055
B28: -VAT 13% for materials | J28: =0.13*G27*(1871.42/18.94) -> 6369.6566
A30: 2 | B30: ).#^ lblv ).$ dL.dL.afSnf] sf]?u]6]8 /+lug ss{6 kftfsf] 5fgf 5fpg] sfd
B31: -upper portion | C31: 1 | D31: =(10+3)/3.281 -> 3.9622066 | E31: =(7)/3.281 -> 2.1334959 | G31: =PRODUCT(C31:F31) -> 8.4533516
B32: -cooking area | C32: 1 | D32: =(13)/3.281 -> 3.9622066 | E32: =1.75+1.75 -> 3.5 | G32: =PRODUCT(C32:F32) -> 13.867723
C33: 1 | D33: =3.75+7-11.33/3.281 -> 7.2967845 | E33: =14/3.281 -> 4.2669918 | G33: =PRODUCT(C33:F33) -> 31.135319
B34: sub-total | G34: =SUM(G31:G33) -> 53.456394 | H34: sqm | I34: 1074.98 | J34: =G34*I34 -> 57464.555
B35: -13% VAT for sheet | J35: =0.13*G34*6674.66/10 -> 4638.4423
B36: -13% VAT for nut bolt | J36: =0.13*G34*1023.75/10 -> 711.43779
B37: -13% VAT for j-hook | J37: =0.13*G34*348.21/10 -> 241.98266
B38: -13% VAT for bitumen washer | J38: =0.13*G34*165/10 -> 114.66397
A40: 3 | B40: g/d k|sf/sf] Sn] / l;N6L df6f]df ;j} lsl;dsf] vGg] sfd
B41: -Masonary wall | C41: 2 | D41: =8/3.281 -> 2.438281 | E41: 0.45 | F41: 0.9 | G41: =PRODUCT(C41:F41) -> 1.9750076
B42: -for footing of vertical post | C42: =2*6 -> 12 | D42: 0.45 | E42: 0.45 | F42: 0.45 | G42: =PRODUCT(C42:F42) -> 1.0935
...
