Workbook

Sheet TIME PERIOD
A1: FUNDAMENTAL TIME PERIOD AS PER NBC 105: 2025
A2: NBC 105: 2025 CL: 5.1.2 (Page 28)
J5: value | K5: type of frame
J6: 0.075 | K6: moment resisting concrete frame
J7: 0.085 | K7: moment resisting steel frame
J8: 0.075 | K8: eccentrically braced structural steel frame
J9: 0.05 | K9: for all other structures
A13: kt | B13: = | C13: 0.075 | D13: =VLOOKUP(C13,J6:K9,2,0) -> moment resisting concrete frame
A14: H | B14: = | C14: 15.0876 | D14: m
A15: T1 | B15: = | C15: =+C13*C14^0.75 -> 0.57415134 | D15: seconds
A16: The approximate fundamental time period as per
A17: NBC 105: 2025 CL: 5.1.3 (Page 29)
A18: T1 | B18: = | C18: =+C15*1.25 -> 0.71768918 | D18: seconds
A19: Tr | C19: 0.52
A20: Ta | B20: = | C20: =COEFFICIENT!$D$8 -> 0.5 | F20: K | G20: = | H20: =0.5*(C18-0.5)+1 -> 1.1088446
F23: 0.00625 | G23: 0.006
F24: =F23*C14*1000 -> 94.2975 | G24: =C14*G23*1000 -> 90.5256

Sheet COEFFICIENT
A1: BASE SHEAR COEFFICIENT AS PER NBC 105: 2020
B2: Z | C2: = | D2: 0.35 | E2: Kathmandu | F2: Table 4-5
B3: I | C3: = | D3: 1 | E3: Residential | F3: Table 4-6
B4: Ch(T) | C4: = | D4: 2.25 | F4: Clause: 4.1.2
B5: T | C5: = | D5: ='TIME PERIOD'!C18 -> 0.71768918 | E5: Sec | F5: (Ta<T<Tc)
B6: Soil Type | C6: = | D6: D | F6: Table 4-4
B7: a | C7: = | D7: 2.25 | E7: check table 4.1 | F7: Table 4-1 | G7: soil type D
B8: Ta | C8: = | D8: 0.5 | F8: Table 4-1
B9: Tc | C9: = | D9: 2 | F9: Table 4-1
B10: K | C10: = | D10: 0.8 | F10: Table 4-1
A11: For Ultimate Limit State | B11: C(T) = Ch(T) Z I | C11: = | D11: =+D4*D2*D3 -> 0.7875 | F11: Clause: 4.1.1
A12: For Serviceability Limit State | B12: Cs(T) = 0.2 C(T) | C12: = | D12: =0.2*D11 -> 0.1575 | F12: Clause: 4.2
A14: Horizontal Base Shear Coefficient for Ultimate Limit State (Clause: 6.1.1)
B17: Rm | C17: = | D17: 4
B18: Wu | C18: = | D18: 1.5
B19: Cd(T1) | C19: = | D19: =+D11/(D17*D18) -> 0.13125
A21: Horizontal Base Shear Coefficient for Serviceability Limit State (Clause: 6.1.2)
B24: Ws | C24: = | D24: 1.25
B25: Cd(T1) | C25: = | D25: =+D12/D24 -> 0.126

Sheet WALL LOAD AND STAIR
B4: Wall Load | C4: (Assuming 30 % opening) | K4: Staircase Load Calculation:
B5: Wall load calculation | C5: B` | D5: Density | E5: H | F5: Without opening | G5: With opening | H5: Unit | K5: Total staircase area (A) | L5: =72.19/10.76/2 -> 3.3545539 | M5: m2
B6: 9" wall(on grid) | C6: 0.23 | D6: 19.2 | E6: =3.048-0.35 -> 2.698 | F6: =PRODUCT(C6:E6) -> 11.914368 | G6: =0.7*F6 -> 8.3400576 | H6: KN/m | K6: Increase 20% for sloped area.
B7: Plaster 12.5mm | C7: =0.0125 -> 0.0125 | D7: 20.4 | E7: =E6 -> 2.698 | F7: =PRODUCT(C7:E7) -> 0.68799 | G7: =0.7*F7 -> 0.481593 | H7: KN/m | K7: Hence, A’ | L7: =1.2*L5 -> 4.0254647 | M7: m2
B8: Total | F8: =SUM(F6:F7) -> 12.602358 | G8: =SUM(G6:G7) -> 8.8216506 | H8: KN/m | K8: Overall Depth of waist slab (D) = | L8: 125
B9: Adopted value | F9: 13 | G9: 9 | H9: KN/m | K9: Dead Load:
K10: ="•Self-weight = 25 kN/m3*0.125m*"&L7&" " -> •Self-weight = 25 kN/m3*0.125m*4.02546468401487 | L10: =25*L8/1000*L7 -> 12.579577
B11: 4" wall (on grid) | C11: 0.115 | D11: 19.2 | E11: =E6 -> 2.698 | F11: =PRODUCT(C11:E11) -> 5.957184 | G11: =0.75*F11 -> 4.467888 | H11: KN/m | K11: ="•Floor-finish = 1.5 kN/m2*"&L7&" m2" -> •Floor-finish = 1.5 kN/m2*4.02546468401487 m2 | L11: =1.5*L7 -> 6.038197 | S11: =0.5*0.28*0.15*1*25*14 -> 7.35
B12: Plaster 12.5mm | C12: =0.0125 -> 0.0125 | D12: 20.4 | E12: =E11 -> 2.698 | F12: =PRODUCT(C12:E12) -> 0.68799 | G12: =0.7*F12 -> 0.481593 | H12: KN/m | K12: Riser | L12: 0.18 | M12: m
B13: Total | F13: =SUM(F11:F12) -> 6.645174 | G13: =SUM(G11:G12) -> 4.949481 | H13: KN/m | K13: Tread | L13: 0.25 | M13: m
B14: Adopted value | F14: 7 | G14: 5.5 | H14: KN/m | K14: Stair Width | L14: 1 | M14: m
K15: No. of Steps in a flight | L15: 8 | M15: no
B16: Parapet wall | K16: ="•Step Dead =25* .5*"&L12&"*"&L13&"*"&L14&"*"&L15&" " -> •Step Dead =25* .5*0.18*0.25*1*8 | L16: =25*0.5*L12*L13*L14*L15 -> 4.5 | S16: 4.5
B17: 4" wall (on grid) | C17: 0.115 | D17: 19.2 | E17: =3/3.28 -> 0.91463415 | F17: =PRODUCT(C17:E17) -> 2.0195122 | H17: KN/m | K17: •Total Dead Load | L17: =L10+L16+L11 -> 23.117774
B18: Plaster 12.5mm | C18: =0.0125 -> 0.0125 | D18: 20.4 | E18: =E17 -> 0.91463415 | F18: =PRODUCT(C18:E18) -> 0.23323171 | H18: KN/m | K18: •Taking half load for staircase | L18: =L17/2 -> 11.558887
B19: Total | F19: =SUM(F17:F18) -> 2.2527439 | H19: KN/m | K19: •Beam Length | L19: 3.81 | M19: m
B20: Adopted value | F20: 2.5 | H20: KN/m | K20: •UDL = | L20: =L18/L19 -> 3.0338286
K21: Adopted value | L21: 3.5 | M21: taken
K23: Live Load: | S23: 3
K24: ="•Live load for staircase=3 kN/m2*"&L7&" " -> •Live load for staircase=3 kN/m2*4.02546468401487 | L24: =3*L7 -> 12.076394
K25: •Taking half load for staircase | L25: =L24/2 -> 6.038197
K26: •Beam Length | L26: =L19 -> 3.81
K27: •UDL = | L27: =L25/L26 -> 1.5848286
K28: Adopted value | L28: 2 | M28: taken

Sheet SCALE FACTOR
B2: SCALE FACTOR | C2: 9806.65 | D2: mm/s2
B4: BASE SHEAR STATIC | C4: X | D4: Y
B5: ULS EQX | C5: -193.7311 | D5: 0
B6: ULS EQY | C6: 0 | D6: -193.7311
B7: SLS EQY | C7: 0 | D7: -744.3119
B8: SLS EQX | C8: -744.3119 | D8: 0
B9: BASE SHEAR DYNAMIC
B10: uls rsx | C10: 3319.1066 | D10: 0.424
B11: uls rsy | C11: 0.424 | D11: 3312.2879
B12: sls rsx | C12: 4752.3364 | D12: 161.0035
B13: sls rsy | C13: 161.0035 | D13: 5905.4538
B15: SCALE FACTOR
B16: for RSx ULS= | C16: =ABS(C5/C10*C2) -> 572.39894 | D16: =ABS(C5/C10) -> 0.058368448
B17: for RSy ULS= | C17: =ABS(D6/D11*C2) -> 573.57728 | D17: =ABS(D6/D11) -> 0.058488605
B18: for RSy SLS= | C18: =ABS(D7/D13*C2) -> 1236.0111 | D18: =ABS(D7/D13) -> 0.12603805
B19: for RSx SLS= | C19: =ABS(C8/C12*C2) -> 1535.9195 | D19: =ABS(C8/C12) -> 0.1566202
B21: SCALED BASE SHEAR | C21: X | D21: Y
B22: RSx ULS | C22: 504.0586 | D22: 3.4786
B23: RSy ULS | C23: 3.3567 | D23: 504.0557
B24: RSx SLS | C24: 483.7132 | D24: 3.3382
B25: RSy SLS | C25: 3.2212 | D25: 483.7123

Sheet ECCENTRICITY
A1: eccentricity check
A3: Story | B3: Diaphragm | C3: Mass X | D3: Mass Y | E3: XCM | F3: YCM | G3: Cum Mass X | H3: Cum Mass Y | I3: XCCM | J3: YCCM | K3: XCR | L3: YCR | M3: ex | N3: ey | O3: %x | P3: %y
C4: kg | D4: kg | E4: m | F4: m | G4: kg | H4: kg | I4: m | J4: m | K4: m | L4: m
A5: Story1 | B5: D1 | C5: 70595.83 | D5: 70595.83 | E5: 4.5321 | F5: 3.7952 | G5: 70595.83 | H5: 70595.83 | I5: 4.5321 | J5: 3.7952 | K5: 4.3623 | L5: 3.6958 | M5: =ABS(I5-K5) -> 0.1698 | N5: =ABS(J5-L5) -> 0.0994 | O5: =M5/8.89*100 -> 1.9100112 | P5: =N5/8.05*100 -> 1.2347826 | Q5: =ABS(G5-G6)/G5*100 -> 0
A6: Story2 | B6: D2 | C6: 70595.83 | D6: 70595.83 | E6: 4.5321 | F6: 3.7952 | G6: 70595.83 | H6: 70595.83 | I6: 4.5321 | J6: 3.7952 | K6: 4.3682 | L6: 3.6138 | M6: =ABS(I6-K6) -> 0.1639 | N6: =ABS(J6-L6) -> 0.1814 | O6: =M6/8.89*100 -> 1.8436445 | P6: =N6/8.05*100 -> 2.2534161 | Q6: =ABS(G6-G7)/G6*100 -> 8.6285691
A7: Story3 | B7: D3 | C7: 64504.42 | D7: 64504.42 | E7: 4.2287 | F7: 4.086 | G7: 64504.42 | H7: 64504.42 | I7: 4.2287 | J7: 4.086 | K7: 4.3702 | L7: 3.5861 | M7: =ABS(I7-K7) -> 0.1415 | N7: =ABS(J7-L7) -> 0.4999 | O7: =M7/8.89*100 -> 1.591676 | P7: =N7/8.05*100 -> 6.2099379 | Q7: =ABS(G7-G8)/G7*100 -> 63.651158
A8: Story4 | B8: D4 | C8: 23446.61 | D8: 23446.61 | E8: 3.9122 | F8: 4.1537 | G8: 23446.61 | H8: 23446.61 | I8: 3.9122 | J8: 4.1537 | K8: 4.2853 | L8: 3.6528 | M8: =ABS(I8-K8) -> 0.3731 | N8: =ABS(J8-L8) -> 0.5009 | O8: =M8/8.89*100 -> 4.1968504 | P8: =N8/8.05*100 -> 6.2223602

Sheet ISOLATED
B1: Isolated Footing Design
B2: Foundation Type : | D2: F1
B3: Required Data
B4: size of colunm=
C5: l = | E5: 0.35 | F5: m
C6: b = | E6: 0.35 | F6: m
B7: Bearing Capacity of Soil= | E7: 120 | F7: KN/m²
B8: Strength of Steel (fy)= | E8: 500 | F8: N/mm²
B9: Strength of Concrete (fck)= | E9: 20 | F9: N/mm² | G9: =+IF(E9=20,"( M 20 )",IF(E9=25,"( M 25 )"," ")) -> ( M 20 )
B10: Factor Load= | E10: ='joint reaction'!F12 -> 963.8899
B11: Axial Load = | E11: =E10/1.5 -> 642.59327 | F11: KN
B13: Approximate area of footing= | E13: =E11/E7 -> 5.3549439 | F13: m²
B14: Weight of footing including earth= | E14: =20*1.5*E13 -> 160.64832
B15: Axial Load = | E15: =E11 -> 642.59327 | F15: KN
B16: Total weight on soil= | E16: =SUM(E14:E15) -> 803.24158 | F16: KN
B17: Actual Area= | E17: =E16/E7 -> 6.6936799 | F17: m²
B18: Size of Square Footing = | E18: =SQRT(E17) -> 2.5872147 | G18: =E18*3.28 -> 8.4860642
B20: Adopted size=
C21: L = | E21: 2.59 | F21: m | G21: =E21*3.28 -> 8.4952
C22: B = | E22: =E21 -> 2.59 | F22: m
B23: Actual area of footing = | E23: =E21*E21 -> 6.7081 | F23: m² | I23: =IF(E23<E17,"Increase Area","OK") -> OK
B24: Net Pressure acting upwads = | E24: =E10/E23 -> 143.69045 | F24: KN/m²
B25: B. M. at the face of column about an axis = | F25: =E24*E21*((E21-E5)/2)*(E21-E5)/2*0.5 -> 233.41766 | G25: KN-m
B28: The effective depth required is given by
E29: BM= 0.138 fck*bd^2
D31: d= | E31: =SQRT((F25*10^6)/(0.138*E9*E21*1000)) -> 180.70178 | F31: mm
B33: Adopt d = 2 to 3 Times of calculated value of d for Shear considerations.
D35: Adop. d= | E35: 375 | F35: mm
D36: D= | E36: =E35+50 -> 425 | F36: mm
B37: Check for one-way Shear action
B38: The critical section is taken at distance d away from the face of column
B40: Shear force Vu= | D40: =E24*(E21*((E21/2-E5/2)-E35/1000)) -> 277.25791 | E40: KN
B41: Nominal shear stress (Tv) = | E41: Vu/b*d = | F41: =D40*1000/(E22*1000*E35) -> 0.28546503 | G41: N/mm²
B43: Allowable Shear Stress of Concrete for pt% of Steel < = 0.15 & | G43: =+G9 -> ( M 20 ) | H43: 0.28
B44: For 0.165% | C44: Tc = | D44: 0.292 | E44: N/sq.mm | F44: (From IS 456: 2000, table 19)
D45: Hence, | E45: =IF(D44>=F41,"OK"," Revised the Depth") -> OK
C46: Tc should be equal to or greater than Tv
B48: Check for two-way Shear action
B49: The critical section is taken at a distance of 0.5d away from the face of column ,
C50: Shear force Vu= | E50: =E24*(E23-(E5+E35/1000)*(E6+E35/1000)) -> 888.36261 | F50: KN
...

Sheet rectangular isolated
B1: Isolated Footing Design
B2: Foundation Type : | D2: F1
B3: Required Data
B4: size of colunm=
C5: l = | E5: 0.5 | F5: m
C6: b = | E6: 0.35 | F6: m
B7: Bearing Capacity of Soil= | E7: 120 | F7: KN/m²
B8: Strength of Steel (fy)= | E8: 500 | F8: N/mm²
B9: Strength of Concrete (fck)= | E9: 25 | F9: N/mm² | G9: =+IF(E9=20,"( M 20 )",IF(E9=25,"( M 25 )"," ")) -> ( M 25 )
B10: Factor Load= | E10: ='[1]joint reaction'!F7 -> 919.0531
B11: Axial Load = | E11: =E10/1.5 -> 612.70207 | F11: KN
B13: Approximate area of footing= | E13: =E11/E7 -> 5.1058506 | F13: m²
B14: Weight of footing including earth= | E14: =20*1.5*E13 -> 153.17552
B15: Axial Load = | E15: =E11 -> 612.70207 | F15: KN
B16: Total weight on soil= | E16: =SUM(E14:E15) -> 765.87758 | F16: KN
B17: Actual Area= | E17: =E16/E7 -> 6.3823132 | F17: m²
B18: Size of Square Footing = | E18: =SQRT(E17) -> 2.526324 | G18: =E18*3.28 -> 8.2863429
B20: Adopted size=
C21: L = | E21: 2.59 | F21: m | G21: =E21*3.28 -> 8.4952
C22: B = | E22: 2.59 | F22: m | G22: =E22*3.28 -> 8.4952
B23: Actual area of footing = | E23: =E21*E22 -> 6.7081 | F23: m² | I23: =IF(E23<E17,"Increase Area","OK") -> OK
B24: Net Pressure acting upwads = | E24: =E10/E23 -> 137.00647 | F24: KN/m²
A25: M1 | B25: B. M. at the face of column about an axis X-X = | F25: =E24*E22*((E21-E5)/2)*(E21-E5)/2*0.5 -> 193.75076 | G25: KN-m
A26: M2 | B26: B. M. at the face of column about an axis Y-Y= | F26: =E24*E21*((E22-E6)/2)*(E22-E6)/2*0.5 -> 222.55989 | G26: KN-m
B27: M1>M2
B29: The effective depth required is given by
E30: BM= 0.138 fck*bd^2
D32: d= | E32: =SQRT((F25*10^6)/(0.138*E9*E22*1000)) -> 147.25237 | F32: mm
B34: Adopt d = 2 to 3 Times of calculated value of d for Shear considerations.
D36: Adop. d= | E36: 350 | F36: mm
D37: D= | E37: =E36+50 -> 400 | F37: mm
B38: Check for one-way Shear action
B39: The critical section is taken at distance d away from the face of column
B41: Shear force VuX= | D41: =E24*E22*((E21/2-E5/2)-E36/1000) -> 246.6185 | E41: KN
B42: Shear force VuY= | D42: =E24*E21*((E22/2-E6/2)-E36/1000) -> 273.232 | E42: KN
B43: Nominal shear stress (Tv) = | E43: Vu/b*d = | F43: =D41*1000/(E22*1000*E36) -> 0.2720557 | G43: N/mm²
M44: M20 | N44: M25
B45: Allowable Shear Stress of Concrete for pt% of Steel < = 0.15 & | G45: =+G9 -> ( M 25 ) | H45: 0.31 | L45: 0.15 | M45: 0.28 | N45: 0.29
B46: ="For "&E73&"%" -> For 0.144563975855198% | C46: Tc = | D46: 0.29 | E46: N/sq.mm | F46: (From IS 456: 2000, table 19) | L46: 0.25 | M46: 0.36 | N46: 0.36
D47: Hence, | E47: =IF(D46>=F43,"OK"," Revised the Depth") -> OK
...

Sheet joint reaction
B4: TABLE: Joint Design Reactions
B5: Story | C5: Label | D5: Unique Name | E5: Output Case | F5: FZ
F6: kN | J6: Joint level | K6: Unfactored load | L6: Footing size(ft) | M6: Depth of footing pad | N6: Reinforecement bar | O6: Provided | P6: footing size in feet
B7: Base | C7: 1 | D7: 2 | E7: 1.5dl+1.5ll | F7: 390.1285 | G7: A1 | J7: =G7 -> A1 | K7: =F7/1.5 -> 260.08567 | L7: 5.5X5.5 | M7: 450mm | N7: 12 mm 5" c/c Both ways | O7: =ROUNDUP(P7,1) -> 5.5 | P7: =SQRT((K7+0.1*F7+2*18)/120)*3.28 -> 5.4811221 | Q7: =O7*O7 -> 30.25
B8: Base | C8: 2 | D8: 4 | E8: 1.5dl+1.5ll | F8: 920.3668 | G8: A2 | H8: =F9+F7 -> 1032.1557 | J8: =G8 -> A2 | K8: =F8/1.5 -> 613.57787 | L8: 8.8X8.5 | O8: =ROUNDUP(P8,1) -> 8.2 | P8: =SQRT((K8+0.1*F8+2*18)/120)*3.28 -> 8.1540307 | Q8: =O8*O8 -> 67.24
B9: Base | C9: 3 | D9: 6 | E9: 1.5dl+1.5ll | F9: 642.0272 | G9: A3 | J9: =G9 -> A3 | K9: =F9/1.5 -> 428.01813 | L9: 7X7 | O9: =ROUNDUP(P9,1) -> 6.9 | P9: =SQRT((K9+0.1*F9+2*18)/120)*3.28 -> 6.8816248 | Q9: =O9*O9 -> 47.61
B10: Base | C10: 4 | D10: 8 | E10: 1.5dl+1.5ll | F10: 481.7931 | G10: B3 | J10: =G10 -> B3 | K10: =F10/1.5 -> 321.1954 | L10: 6X6 | O10: =ROUNDUP(P10,1) -> 6.1 | P10: =SQRT((K10+0.1*F10+2*18)/120)*3.28 -> 6.0285317 | Q10: =O10*O10 -> 37.21
B11: Base | C11: 5 | D11: 10 | E11: 1.5dl+1.5ll | F11: 468.4279 | G11: B3' | H11: =F11+F12 -> 1432.3178 | J11: =G11 -> B3' | K11: =F11/1.5 -> 312.28527 | L11: 6X6 | O11: =ROUNDUP(P11,1) -> 6 | P11: =SQRT((K11+0.1*F11+2*18)/120)*3.28 -> 5.9518524 | Q11: =O11*O11 -> 36
B12: Base | C12: 6 | D12: 12 | E12: 1.5dl+1.5ll | F12: 963.8899 | G12: B2 | J12: =G12 -> B2 | K12: =F12/1.5 -> 642.59327 | L12: 8.5X8.5 | O12: =ROUNDUP(P12,1) -> 8.4 | P12: =SQRT((K12+0.1*F12+2*18)/120)*3.28 -> 8.335451 | Q12: =O12*O12 -> 70.56
B13: Base | C13: 7 | D13: 14 | E13: 1.5dl+1.5ll | F13: 637.809 | G13: B1 | J13: =G13 -> B1 | K13: =F13/1.5 -> 425.206 | L13: 7X7 | O13: =ROUNDUP(P13,1) -> 6.9 | P13: =SQRT((K13+0.1*F13+2*18)/120)*3.28 -> 6.8605266 | Q13: =O13*O13 -> 47.61
B14: Base | C14: 8 | D14: 16 | E14: 1.5dl+1.5ll | F14: 406.9743 | G14: C1 | H14: =F14+F23 -> 406.9743 | J14: =G14 -> C1 | K14: =F14/1.5 -> 271.3162 | L14: 5.5X5.5 | O14: =ROUNDUP(P14,1) -> 5.6 | P14: =SQRT((K14+0.1*F14+2*18)/120)*3.28 -> 5.5857481 | Q14: =O14*O14 -> 31.36
B15: Base | C15: 9 | D15: 18 | E15: 1.5dl+1.5ll | F15: 511.09 | G15: C2 | J15: =G15 -> C2 | K15: =F15/1.5 -> 340.72667 | L15: 6X6 | O15: =ROUNDUP(P15,1) -> 6.2 | P15: =SQRT((K15+0.1*F15+2*18)/120)*3.28 -> 6.1932942 | Q15: =O15*O15 -> 38.44
B16: Base | C16: 10 | D16: 20 | E16: 1.5dl+1.5ll | F16: 409.0103 | G16: C3 | J16: =G16 -> C3 | K16: =F16/1.5 -> 272.67353 | L16: 5.5X5.5 | O16: =ROUNDUP(P16,1) -> 5.6 | P16: =SQRT((K16+0.1*F16+2*18)/120)*3.28 -> 5.5982609 | Q16: =O16*O16 -> 31.36
H18: =MAX(F7:F16) -> 963.8899

Sheet strapc2-B2
E2: L1 = | F2: =+K37 -> 1.83 | G2: m | I2: =+I3+E14/2-F2*1000-L2*1000/2 -> 1469 | K2: L2 = | L2: =+K38 -> 1.83 | M2: m
H3: c/c distance = | I3: 4039
C5: =(A8-C8)/2 -> 740
A8: =+J24*1000 -> 1830 | C8: =+E14 -> 350 | E8: A | L8: B
A10: B = | C10: =+C5 -> 740
P11: =4191/900 -> 4.6566667
E14: 350 | I14: =+I3-E14/2-L14/2 -> 3689 | L14: 350 | M14: =(L2*1000-L14)/2 -> 740
H16: =F2*1000+I2+L2*1000 -> 5129
H18: PA | I18: = | J18: ='joint reaction'!K15 -> 340.72667 | K18: KN
H19: PB | I19: = | J19: ='joint reaction'!K12 -> 642.59327 | K19: KN
H20: SAFE BEARING CAPACITY, SBC | I20: = | J20: 120 | K20: KN/m2 | O20: =1.5/1.2 -> 1.25 | P20: =(1.2+1.5)/2 -> 1.35 | Q20: =1.2/1.35 -> 0.88888889 | R20: =1.5/1.35 -> 1.1111111 | S20: =Q20+R20 -> 2
H21: Areqd, A | I21: = | J21: =1.1*(J18+J19)/J20 -> 9.0137661 | K21: m2
E22: i.e, | H22: BL1+BL2 | I22: = | J22: =+J21 -> 9.0137661
H23: cg of Forces from B, X | I23: = | J23: =J18*I3/(J18+J19)/1000 -> 1.3995394 | K23: m
H24: Let, B | I24: = | J24: 1.83 | K24: m | L24: =J24*3.28 -> 6.0024
E26: ="A1("&I3/1000&"+"&E14/2/1000&"-L1/2) = (A1+A2)X" -> A1(4.039+0.175-L1/2) = (A1+A2)X
E27: ="BL1("&I3/1000+E14/2/1000&"-L1/2) = (BL1+BL2)X" -> BL1(4.214-L1/2) = (BL1+BL2)X
E28: ="X="&"BL1("&I3/1000+E14/2/1000&"-L1/2) / (BL1+BL2)" -> X=BL1(4.214-L1/2) / (BL1+BL2)
E29: ="X="&"BL1("&I3/1000+E14/2/1000&"-L1/2) / A" -> X=BL1(4.214-L1/2) / A
E30: ="2*A*X/B="&2*(I3/1000+E14/2/1000)&"*L1-L1^2" -> 2*A*X/B=8.428*L1-L1^2
E31: ="L1^2"&"-"&2*(I3/1000+E14/2/1000)&"*L1+2*A*X/B = 0" -> L1^2-8.428*L1+2*A*X/B = 0
G33: a | H33: = | I33: 1
G34: b | H34: = | I34: =-2*(I3/1000+E14/2/1000) -> -8.428
G35: c | H35: = | I35: =2*J22*J23/J24 -> 13.787017
G37: L1 | H37: = | I37: =MIN((-I34-SQRT(I34^2-4*I33*I35))/(2*I33),(-I34+SQRT(I34^2-4*I33*I35))/(2*I33)) -> 2.2213187 | J37: say, L1 = | K37: 1.83 | L37: m | M37: =K37*3.28 -> 6.0024
G38: L2 | H38: = | I38: =(J22-J24*I37)/J24 -> 2.7042365 | J38: say, L2 = | K38: 1.83 | L38: m | M38: =K38*3.28 -> 6.0024
G40: NET SOIL PRESSURE UNDER THE FOOTING | H40: = | I40: =1.5*(J18+J19)/(K37*J24+K38*J24) -> 220.21856 | J40: KN/m2
G41: ASSUMED DEPTH OF PAD | H41: = | I41: 350 | J41: mm
G42: ASSUMED DEPTH OF STRAP BEAM | H42: = | I42: 600 | J42: mm
G43: ASSUMED WIDTH OF STRAP BEAM | H43: = | I43: 400 | J43: mm
G44: CLEAR COVER TO MAIN REINF | H44: = | I44: 50 | J44: mm
G45: GRADE OF CONCRETE | H45: = | I45: 20 | J45: N/mm2
G46: GRADE OF REINF | H46: = | I46: 500 | J46: N/mm2
G47: DIA OF STRAP BEAM MAIN REINF | H47: = | I47: 16 | J47: mm
G48: DIA OF STRAP BEAM SHEAR REINF | H48: = | I48: 8 | J48: mm
G49: DIA OF PAD REINF | H49: = | I49: 12 | J49: mm
G50: EFFECTIVE DEPTH OF PAD | H50: = | I50: =+I41-I44-I49/2 -> 294 | J50: mm
G51: EFFECTIVE DEPTH OF STRAP BEAM | H51: = | I51: =+I42-I44-I47/2 -> 542 | J51: mm
G53: BENDING MOMENT AT BASE PAD
G54: AT EXTERIOR FOOTING A, Mu | H54: = | I54: =I40*F2*(C5/1000)^2/2 -> 110.34139 | J54: KN-m
...

Sheet strap b3c3
E2: L1 = | F2: =+K37 -> 1.83 | G2: m | I2: =+I3+E14/2-F2*1000-L2*1000/2 -> 1469 | K2: L2 = | L2: =+K38 -> 1.83 | M2: m
H3: c/c distance = | I3: 4039
C5: =(A8-C8)/2 -> 740
A8: =+J24*1000 -> 1830 | C8: =+E14 -> 350 | E8: A | L8: B
A10: B = | C10: =+C5 -> 740
P11: =4191/900 -> 4.6566667
E14: 350 | I14: =+I3-E14/2-L14/2 -> 3689 | L14: 350 | M14: =(L2*1000-L14)/2 -> 740
H16: =F2*1000+I2+L2*1000 -> 5129
H18: PA | I18: = | J18: ='joint reaction'!K16 -> 272.67353 | K18: KN
H19: PB | I19: = | J19: ='joint reaction'!K11 -> 312.28527 | K19: KN
H20: SAFE BEARING CAPACITY, SBC | I20: = | J20: 120 | K20: KN/m2 | O20: =1.5/1.2 -> 1.25 | P20: =(1.2+1.5)/2 -> 1.35 | Q20: =1.2/1.35 -> 0.88888889 | R20: =1.5/1.35 -> 1.1111111 | S20: =Q20+R20 -> 2
H21: Areqd, A | I21: = | J21: =1.1*(J18+J19)/J20 -> 5.3621223 | K21: m2
E22: i.e, | H22: BL1+BL2 | I22: = | J22: =+J21 -> 5.3621223
H23: cg of Forces from B, X | I23: = | J23: =J18*I3/(J18+J19)/1000 -> 1.8827452 | K23: m
H24: Let, B | I24: = | J24: 1.83 | K24: m | L24: =J24*3.28 -> 6.0024
E26: ="A1("&I3/1000&"+"&E14/2/1000&"-L1/2) = (A1+A2)X" -> A1(4.039+0.175-L1/2) = (A1+A2)X
E27: ="BL1("&I3/1000+E14/2/1000&"-L1/2) = (BL1+BL2)X" -> BL1(4.214-L1/2) = (BL1+BL2)X
E28: ="X="&"BL1("&I3/1000+E14/2/1000&"-L1/2) / (BL1+BL2)" -> X=BL1(4.214-L1/2) / (BL1+BL2)
E29: ="X="&"BL1("&I3/1000+E14/2/1000&"-L1/2) / A" -> X=BL1(4.214-L1/2) / A
E30: ="2*A*X/B="&2*(I3/1000+E14/2/1000)&"*L1-L1^2" -> 2*A*X/B=8.428*L1-L1^2
E31: ="L1^2"&"-"&2*(I3/1000+E14/2/1000)&"*L1+2*A*X/B = 0" -> L1^2-8.428*L1+2*A*X/B = 0
G33: a | H33: = | I33: 1
G34: b | H34: = | I34: =-2*(I3/1000+E14/2/1000) -> -8.428
G35: c | H35: = | I35: =2*J22*J23/J24 -> 11.033345
G37: L1 | H37: = | I37: =MIN((-I34-SQRT(I34^2-4*I33*I35))/(2*I33),(-I34+SQRT(I34^2-4*I33*I35))/(2*I33)) -> 1.6208453 | J37: say, L1 = | K37: 1.83 | L37: m | M37: =K37*3.28 -> 6.0024
G38: L2 | H38: = | I38: =(J22-J24*I37)/J24 -> 1.3092762 | J38: say, L2 = | K38: 1.83 | L38: m | M38: =K38*3.28 -> 6.0024
G40: NET SOIL PRESSURE UNDER THE FOOTING | H40: = | I40: =1.5*(J18+J19)/(K37*J24+K38*J24) -> 131.00394 | J40: KN/m2
G41: ASSUMED DEPTH OF PAD | H41: = | I41: 350 | J41: mm
G42: ASSUMED DEPTH OF STRAP BEAM | H42: = | I42: 600 | J42: mm
G43: ASSUMED WIDTH OF STRAP BEAM | H43: = | I43: 400 | J43: mm
G44: CLEAR COVER TO MAIN REINF | H44: = | I44: 50 | J44: mm
G45: GRADE OF CONCRETE | H45: = | I45: 20 | J45: N/mm2
G46: GRADE OF REINF | H46: = | I46: 500 | J46: N/mm2
G47: DIA OF STRAP BEAM MAIN REINF | H47: = | I47: 20 | J47: mm
G48: DIA OF STRAP BEAM SHEAR REINF | H48: = | I48: 8 | J48: mm
G49: DIA OF PAD REINF | H49: = | I49: 12 | J49: mm
G50: EFFECTIVE DEPTH OF PAD | H50: = | I50: =+I41-I44-I49/2 -> 294 | J50: mm
G51: EFFECTIVE DEPTH OF STRAP BEAM | H51: = | I51: =+I42-I44-I47/2 -> 540 | J51: mm
G53: BENDING MOMENT AT BASE PAD
G54: AT EXTERIOR FOOTING A, Mu | H54: = | I54: =I40*F2*(C5/1000)^2/2 -> 65.640049 | J54: KN-m
...

Sheet strrap a2a4
E2: L1 = | F2: =+K37 -> 2.13 | G2: m | I2: =+I3+E14/2-F2*1000-L2*1000/2 -> 1654 | K2: L2 = | L2: =+K38 -> 2.13 | M2: m
H3: c/c distance = | I3: 4674
C5: =(A8-C8)/2 -> 890
A8: =+J24*1000 -> 2130 | C8: =+E14 -> 350 | E8: A | L8: B
A10: B = | C10: =+C5 -> 890
P11: =4191/900 -> 4.6566667
E14: 350 | I14: =+I3-E14/2-L14/2 -> 4324 | L14: 350 | M14: =(L2*1000-L14)/2 -> 890
H16: =F2*1000+I2+L2*1000 -> 5914
H18: PA | I18: = | J18: ='joint reaction'!K14 -> 271.3162 | K18: KN
H19: PB | I19: = | J19: ='joint reaction'!K8 -> 613.57787 | K19: KN
H20: SAFE BEARING CAPACITY, SBC | I20: = | J20: 120 | K20: KN/m2 | O20: =1.5/1.2 -> 1.25 | P20: =(1.2+1.5)/2 -> 1.35 | Q20: =1.2/1.35 -> 0.88888889 | R20: =1.5/1.35 -> 1.1111111 | S20: =Q20+R20 -> 2
H21: Areqd, A | I21: = | J21: =1.1*(J18+J19)/J20 -> 8.1115289 | K21: m2
E22: i.e, | H22: BL1+BL2 | I22: = | J22: =+J21 -> 8.1115289
H23: cg of Forces from B, X | I23: = | J23: =J18*I3/(J18+J19)/1000 -> 1.433089 | K23: m
H24: Let, B | I24: = | J24: 2.13 | K24: m | L24: =J24*3.28 -> 6.9864
E26: ="A1("&I3/1000&"+"&E14/2/1000&"-L1/2) = (A1+A2)X" -> A1(4.674+0.175-L1/2) = (A1+A2)X
E27: ="BL1("&I3/1000+E14/2/1000&"-L1/2) = (BL1+BL2)X" -> BL1(4.849-L1/2) = (BL1+BL2)X
E28: ="X="&"BL1("&I3/1000+E14/2/1000&"-L1/2) / (BL1+BL2)" -> X=BL1(4.849-L1/2) / (BL1+BL2)
E29: ="X="&"BL1("&I3/1000+E14/2/1000&"-L1/2) / A" -> X=BL1(4.849-L1/2) / A
E30: ="2*A*X/B="&2*(I3/1000+E14/2/1000)&"*L1-L1^2" -> 2*A*X/B=9.698*L1-L1^2
E31: ="L1^2"&"-"&2*(I3/1000+E14/2/1000)&"*L1+2*A*X/B = 0" -> L1^2-9.698*L1+2*A*X/B = 0
G33: a | H33: = | I33: 1
G34: b | H34: = | I34: =-2*(I3/1000+E14/2/1000) -> -9.698
G35: c | H35: = | I35: =2*J22*J23/J24 -> 10.915063
G37: L1 | H37: = | I37: =MIN((-I34-SQRT(I34^2-4*I33*I35))/(2*I33),(-I34+SQRT(I34^2-4*I33*I35))/(2*I33)) -> 1.2996708 | J37: say, L1 = | K37: 2.13 | L37: m | M37: =K37*3.28 -> 6.9864
G38: L2 | H38: = | I38: =(J22-J24*I37)/J24 -> 2.5085587 | J38: say, L2 = | K38: 2.13 | L38: m | M38: =K38*3.28 -> 6.9864
G40: NET SOIL PRESSURE UNDER THE FOOTING | H40: = | I40: =1.5*(J18+J19)/(K37*J24+K38*J24) -> 146.28283 | J40: KN/m2
G41: ASSUMED DEPTH OF PAD | H41: = | I41: 350 | J41: mm
G42: ASSUMED DEPTH OF STRAP BEAM | H42: = | I42: 700 | J42: mm
G43: ASSUMED WIDTH OF STRAP BEAM | H43: = | I43: 400 | J43: mm
G44: CLEAR COVER TO MAIN REINF | H44: = | I44: 50 | J44: mm
G45: GRADE OF CONCRETE | H45: = | I45: 20 | J45: N/mm2
G46: GRADE OF REINF | H46: = | I46: 500 | J46: N/mm2
G47: DIA OF STRAP BEAM MAIN REINF | H47: = | I47: 20 | J47: mm
G48: DIA OF STRAP BEAM SHEAR REINF | H48: = | I48: 8 | J48: mm
G49: DIA OF PAD REINF | H49: = | I49: 12 | J49: mm
G50: EFFECTIVE DEPTH OF PAD | H50: = | I50: =+I41-I44-I49/2 -> 294 | J50: mm
G51: EFFECTIVE DEPTH OF STRAP BEAM | H51: = | I51: =+I42-I44-I47/2 -> 640 | J51: mm
G53: BENDING MOMENT AT BASE PAD
G54: AT EXTERIOR FOOTING A, Mu | H54: = | I54: =I40*F2*(C5/1000)^2/2 -> 123.40222 | J54: KN-m
...

Sheet torsion
A1: Torsional Irregularity Check
B3: ULSEQX
B4: Displacement at upper end(A) | C4: = | D4: 37.379
B5: Displacement at upper end(B) | C5: = | D5: 29.485
B6: A/B | C6: = | D6: =D4/D5 -> 1.2677294 | E6: <1.5(OK)
B8: SLSEQX
B9: Displacement at upper end(A) | C9: = | D9: 35.87
B10: Displacement at upper end(B) | C10: = | D10: 28.295
B11: A/B | C11: = | D11: =D9/D10 -> 1.2677151 | E11: <1.5(OK)
B13: ULSEQY
B14: Displacement at upper end(A) | C14: = | D14: 35.142
B15: Displacement at upper end(B) | C15: = | D15: 26.471
B16: A/B | C16: = | D16: =D14/D15 -> 1.327566 | E16: <1.5(OK)
B18: SLSEQY
B19: Displacement at upper end(A) | C19: = | D19: 33.724
B20: Displacement at upper end(B) | C20: = | D20: 25.402
B21: A/B | C21: = | D21: =D19/D20 -> 1.327612 | E21: <1.5(OK)
B23: The structure pass in torsion

Sheet rayleigh
A1: Rayleigh method | L1: W | P1: TABLE: Diaphragm Center Of Mass Displacements | AD1: TABLE: Story Response
A2: Story | B2: Weight of floor(KN) | C2: Lateral load | D2: Deflection | E2: Wi*d^2 | F2: L*d | I2: UY | J2: UZ | L2: KN | M2: D | P2: Story | Q2: Diaphragm | R2: Output Case | S2: Case Type | T2: Step Type | U2: Step Number | V2: UX | W2: UY | X2: RZ | Y2: Point | Z2: X | AA2: Y | AB2: Z | AD2: Story | AE2: Elevation | AF2: Location | AG2: X-Dir | AH2: Y-Dir
I3: kg | J3: kg | V3: mm | W3: mm | X3: rad | Z3: m | AA3: m | AB3: m | AE3: m | AG3: kN | AH3: kN
A4: Story3 | B4: =AK14 -> 260.50171 | C4: =AG4 -> 116.9635 | D4: =MAX(V4:V60)/1000 -> 0.017937 | E4: =B4*D4^2 -> 0.083812769 | F4: =C4*D4 -> 2.0979743 | I4: 16198.8 | J4: 0 | L4: =#REF!*9.81/1000 -> #REF! | M4: =MAX(V4:V15) -> 0.09 | P4: Story3 | Q4: D3 | R4: Modal | S4: LinModEigen | T4: Mode | U4: 1 | V4: 0.001 | W4: 0.088 | X4: -3e-06 | Y4: 25 | Z4: 4.739 | AA4: 4.5828 | AB4: 9.144 | AD4: Story3 | AE4: 9.144 | AF4: Top | AG4: 116.9635 | AH4: 0
A5: Story2 | B5: =AK15 -> 715.25897 | C5: =AG5 -> 166.9869 | D5: =MAX(V61:V117)/1000 -> 0.012909 | E5: =B5*D5^2 -> 0.11919239 | F5: =C5*D5 -> 2.1556339 | I5: 68346.07 | J5: 0 | L5: =#REF!*9.81/1000 -> #REF! | M5: =MAX(V16:V27) -> 17.658 | P5: Story3 | Q5: D3 | R5: Modal | S5: LinModEigen | T5: Mode | U5: 2 | V5: -0.091 | W5: 0.001 | X5: -4.067e-07 | Y5: 25 | Z5: 4.739 | AA5: 4.5828 | AB5: 9.144 | AD5: Story2 | AE5: 6.096 | AF5: Top | AG5: 166.9869 | AH5: 0
A6: Story1 | B6: =AK16 -> 942.59787 | C6: =AG6 -> 110.2847 | D6: =MAX(V118:V174)/1000 -> 0.005847 | E6: =B6*D6^2 -> 0.032224979 | F6: =C6*D6 -> 0.64483464 | I6: 115625.39 | J6: 0 | L6: =#REF!*9.81/1000 -> #REF! | M6: =MAX(V28:V39) -> 17.937 | P6: Story3 | Q6: D3 | R6: Modal | S6: LinModEigen | T6: Mode | U6: 3 | V6: 0.002 | W6: 0.013 | X6: 2e-05 | Y6: 25 | Z6: 4.739 | AA6: 4.5828 | AB6: 9.144 | AD6: Story1 | AE6: 3.048 | AF6: Top | AG6: 110.2847 | AH6: 0
I7: 120468.19 | J7: 0 | L7: =#REF!*9.81/1000 -> #REF! | M7: =MAX(V40:V50) -> 17.911 | P7: Story3 | Q7: D3 | R7: Modal | S7: LinModEigen | T7: Mode | U7: 4 | V7: -0.004 | W7: -0.089 | X7: 2e-06 | Y7: 25 | Z7: 4.739 | AA7: 4.5828 | AB7: 9.144 | AD7: Base | AE7: 0 | AF7: Top | AG7: 0 | AH7: 0
I8: 120651.27 | J8: 0 | L8: =#REF!*9.81/1000 -> #REF! | M8: =MAX(V52:V63) -> 17.632 | P8: Story3 | Q8: D3 | R8: Modal | S8: LinModEigen | T8: Mode | U8: 5 | V8: 0.09 | W8: -0.005 | X8: -6e-06 | Y8: 25 | Z8: 4.739 | AA8: 4.5828 | AB8: 9.144
A9: Base | E9: =SUM(E4:E8) -> 0.23523013 | F9: =SUM(F4:F8) -> 4.8984428 | I9: 6647.78 | J9: 0 | L9: =#REF!*9.81/1000 -> #REF! | P9: Story3 | Q9: D3 | R9: Modal | S9: LinModEigen | T9: Mode | U9: 6 | V9: -0.014 | W9: -0.005 | X9: -2.3e-05 | Y9: 25 | Z9: 4.739 | AA9: 4.5828 | AB9: 9.144
P10: Story3 | Q10: D3 | R10: Modal | S10: LinModEigen | T10: Mode | U10: 7 | V10: 0.005 | W10: -0.058 | X10: -3.635e-07 | Y10: 25 | Z10: 4.739 | AA10: 4.5828 | AB10: 9.144
P11: Story3 | Q11: D3 | R11: Modal | S11: LinModEigen | T11: Mode | U11: 8 | V11: 0.046 | W11: 0.007 | X11: -4e-06 | Y11: 25 | Z11: 4.739 | AA11: 4.5828 | AB11: 9.144 | AD11: TABLE: Mass Summary by Diaphragm
P12: Story3 | Q12: D3 | R12: Modal | S12: LinModEigen | T12: Mode | U12: 9 | V12: 0.022 | W12: -0.003 | X12: 1.6e-05 | Y12: 25 | Z12: 4.739 | AA12: 4.5828 | AB12: 9.144 | AD12: Story | AE12: Diaphragm | AF12: Mass X | AG12: Mass Y | AH12: Mass Moment of Inertia | AI12: X Mass Center | AJ12: Y Mass Center
I13: 9.81 | P13: Story3 | Q13: D3 | R13: Modal | S13: LinModEigen | T13: Mode | U13: 10 | V13: 0.001 | W13: -0.0004554 | X13: -6.483e-08 | Y13: 25 | Z13: 4.739 | AA13: 4.5828 | AB13: 9.144 | AF13: kg | AG13: kg | AH13: ton-m² | AI13: m | AJ13: m
B14: T= | C14: =2*3.14*SQRT(E9/(9.81*F9)) -> 0.43938234 | I14: 5 | P14: Story3 | Q14: D3 | R14: Modal | S14: LinModEigen | T14: Mode | U14: 11 | V14: 0.001 | W14: -0.0001489 | X14: -4.425e-08 | Y14: 25 | Z14: 4.739 | AA14: 4.5828 | AB14: 9.144 | AD14: Story3 | AE14: D3 | AF14: 26554.71 | AG14: 26554.71 | AH14: 520.7019 | AI14: 4.739 | AJ14: 4.5828 | AK14: =AF14*9.81/1000 -> 260.50171
P15: Story3 | Q15: D3 | R15: Modal | S15: LinModEigen | T15: Mode | U15: 12 | V15: 0.001 | W15: 6.477e-05 | X15: 7.862e-09 | Y15: 25 | Z15: 4.739 | AA15: 4.5828 | AB15: 9.144 | AD15: Story2 | AE15: D2 | AF15: 72911.21 | AG15: 72911.21 | AH15: 1661.4339 | AI15: 4.9369 | AJ15: 5.2102 | AK15: =AF15*9.81/1000 -> 715.25897
I16: =2*3.14*SQRT((L7*M7^2+L6*M6^2+L5*M5^2+L4*M4^2+L8*M8^2)/(9.81*(AG7*M7+AG6*M6+AG5*M5+AG4*M4+AG8*M8))) -> #REF! | P16: Story3 | Q16: D3 | R16: Dead | S16: LinStatic | V16: 0.143 | W16: 0.151 | X16: -1.1e-05 | Y16: 25 | Z16: 4.739 | AA16: 4.5828 | AB16: 9.144 | AD16: Story1 | AE16: D1 | AF16: 96085.41 | AG16: 96085.41 | AH16: 2640.2229 | AI16: 5.2347 | AJ16: 4.735 | AK16: =AF16*9.81/1000 -> 942.59787
P17: Story3 | Q17: D3 | R17: Live | S17: LinStatic | V17: 0.016 | W17: 0.522 | X17: 1.2e-05 | Y17: 25 | Z17: 4.739 | AA17: 4.5828 | AB17: 9.144
P18: Story3 | Q18: D3 | R18: WALL | S18: LinStatic | V18: -0.234 | W18: -0.777 | X18: -5.8e-05 | Y18: 25 | Z18: 4.739 | AA18: 4.5828 | AB18: 9.144
P19: Story3 | Q19: D3 | R19: ROOF LIVE | S19: LinStatic | V19: 0.046 | W19: -0.073 | X19: -6e-06 | Y19: 25 | Z19: 4.739 | AA19: 4.5828 | AB19: 9.144
P20: Story3 | Q20: D3 | R20: FF | S20: LinStatic | V20: 0.033 | W20: 0.102 | X20: -4.969e-07 | Y20: 25 | Z20: 4.739 | AA20: 4.5828 | AB20: 9.144
P21: Story3 | Q21: D3 | R21: ULS EQX | S21: LinStatic | T21: Step By Step | U21: 1 | V21: 17.523 | W21: 0.555 | X21: -0.000422 | Y21: 25 | Z21: 4.739 | AA21: 4.5828 | AB21: 9.144
P22: Story3 | Q22: D3 | R22: ULS EQX | S22: LinStatic | T22: Step By Step | U22: 2 | V22: 17.658 | W22: 0.047 | X22: 0.0004 | Y22: 25 | Z22: 4.739 | AA22: 4.5828 | AB22: 9.144
P23: Story3 | Q23: D3 | R23: ULS EQY | S23: LinStatic | T23: Step By Step | U23: 1 | V23: 0.157 | W23: 24.913 | X23: 0.000152 | Y23: 25 | Z23: 4.739 | AA23: 4.5828 | AB23: 9.144
P24: Story3 | Q24: D3 | R24: ULS EQY | S24: LinStatic | T24: Step By Step | U24: 2 | V24: -0.031 | W24: 25.565 | X24: -0.000856 | Y24: 25 | Z24: 4.739 | AA24: 4.5828 | AB24: 9.144
P25: Story3 | Q25: D3 | R25: SLS EQY | S25: LinStatic | T25: Step By Step | U25: 1 | V25: 0.151 | W25: 23.907 | X25: 0.000146 | Y25: 25 | Z25: 4.739 | AA25: 4.5828 | AB25: 9.144
P26: Story3 | Q26: D3 | R26: SLS EQY | S26: LinStatic | T26: Step By Step | U26: 2 | V26: -0.03 | W26: 24.533 | X26: -0.000821 | Y26: 25 | Z26: 4.739 | AA26: 4.5828 | AB26: 9.144
P27: Story3 | Q27: D3 | R27: SLS EQX | S27: LinStatic | T27: Step By Step | U27: 1 | V27: 16.816 | W27: 0.533 | X27: -0.000405 | Y27: 25 | Z27: 4.739 | AA27: 4.5828 | AB27: 9.144
P28: Story3 | Q28: D3 | R28: SLS EQX | S28: LinStatic | T28: Step By Step | U28: 2 | V28: 16.945 | W28: 0.045 | X28: 0.000384 | Y28: 25 | Z28: 4.739 | AA28: 4.5828 | AB28: 9.144
P29: Story3 | Q29: D3 | R29: uls rsx | S29: LinRespSpec | T29: Max | V29: 17.937 | W29: 1.005 | X29: 0.00055 | Y29: 25 | Z29: 4.739 | AA29: 4.5828 | AB29: 9.144
P30: Story3 | Q30: D3 | R30: uls rsy | S30: LinRespSpec | T30: Max | V30: 0.724 | W30: 26.181 | X30: 0.001612 | Y30: 25 | Z30: 4.739 | AA30: 4.5828 | AB30: 9.144
P31: Story3 | Q31: D3 | R31: sls rsx | S31: LinRespSpec | T31: Max | V31: 17.213 | W31: 0.965 | X31: 0.000527 | Y31: 25 | Z31: 4.739 | AA31: 4.5828 | AB31: 9.144
P32: Story3 | Q32: D3 | R32: sls rsy | S32: LinRespSpec | T32: Max | V32: 0.695 | W32: 25.124 | X32: 0.001547 | Y32: 25 | Z32: 4.739 | AA32: 4.5828 | AB32: 9.144
P33: Story3 | Q33: D3 | R33: step Dead | S33: LinStatic | V33: 0.014 | W33: 0.185 | X33: 4e-06 | Y33: 25 | Z33: 4.739 | AA33: 4.5828 | AB33: 9.144
P34: Story3 | Q34: D3 | R34: DL | S34: Combination | V34: -0.044 | W34: -0.34 | X34: -6.6e-05 | Y34: 25 | Z34: 4.739 | AA34: 4.5828 | AB34: 9.144
P35: Story3 | Q35: D3 | R35: LL | S35: Combination | V35: 0.062 | W35: 0.449 | X35: 6e-06 | Y35: 25 | Z35: 4.739 | AA35: 4.5828 | AB35: 9.144
P36: Story3 | Q36: D3 | R36: 1.2DL+1.5LL | S36: Combination | V36: 0.04 | W36: 0.266 | X36: -7.1e-05 | Y36: 25 | Z36: 4.739 | AA36: 4.5828 | AB36: 9.144
P37: Story3 | Q37: D3 | R37: DL+.3LL-ULSEQX | S37: Combination | T37: Max | V37: -17.549 | W37: -0.252 | X37: 0.000357 | Y37: 25 | Z37: 4.739 | AA37: 4.5828 | AB37: 9.144
P38: Story3 | Q38: D3 | R38: DL+.3LL-ULSEQX | S38: Combination | T38: Min | V38: -17.684 | W38: -0.76 | X38: -0.000464 | Y38: 25 | Z38: 4.739 | AA38: 4.5828 | AB38: 9.144
P39: Story3 | Q39: D3 | R39: DL+.3LL+SLSEQX | S39: Combination | T39: Max | V39: 16.92 | W39: 0.328 | X39: 0.000319 | Y39: 25 | Z39: 4.739 | AA39: 4.5828 | AB39: 9.144
P40: Story3 | Q40: D3 | R40: DL+.3LL+SLSEQX | S40: Combination | T40: Min | V40: 16.79 | W40: -0.16 | X40: -0.000469 | Y40: 25 | Z40: 4.739 | AA40: 4.5828 | AB40: 9.144
...

Sheet COMBINEDB3B33
A1: DIMENISON OF COMBINED FLAT FOOTING | I1: EQ checking | M1: FAC. | N1: SBC | P1: SBC
A2: B1 | B2: ='joint reaction'!K10 -> 321.1954 | C2: kN | D2: Area Required | E2: =(B3+B2)*1.1/B4 -> 5.8069061 | F2: LEFT PROJ. | G2: 0.85 | I2: B | J2: 2.7 | K2: e | L2: =(J3/2-Q2-(B5*0.5))-J4 -> 1.3315384 | M2: PMAX | N2: =(B2+B3)/(J2*J3)+(B2+B3)*L2*6/(J2*J3^2) -> 109.67109 | O2: =IF((P2*1.25)>N2,"OK","NO") -> OK | P2: 100 | Q2: 0.6 | R2: PROJECT LEFT
A3: B2 | B3: ='joint reaction'!K11 -> 312.28527 | C3: kN | D3: Width Provied | E3: 1.83 | F3: RIGHT PROJ. | G3: 0.85 | I3: L | J3: 5.34 | M3: PMIN | N3: =(B2+B3)/(J2*J3)-(B2+B3)*L2*6/(J2*J3^2) -> -21.797504 | O3: =IF((P3*1.25)>N3,"OK","NO") -> OK | P3: 100
A4: SBC | B4: 120 | C4: kN/m2 | D4: Total Length | E4: =E2/E3 -> 3.1731727 | F4: =CONCATENATE("CF FROM ",A2) -> CF FROM B1 | G4: =B3*B7/(B3+B2) -> 0.56346165 | H4: =G4*3.281 -> 1.8487177 | I4: CG FROM END | J4: =G4 -> 0.56346165
A5: =CONCATENATE("Dimension of ", A3) -> Dimension of B2 | B5: 0.35 | C5: m | D5: Fck | E5: 20 | F5: TOTAL LENGTH | G5: =G2+B5/2+B7+B6/2+G3 -> 3.193 | H5: =H4-9 -> -7.1512823 | I5: =E4*3.281 -> 10.41118
A6: =CONCATENATE("Dimension of ", A2) -> Dimension of B1 | B6: 0.35 | C6: m | D6: Fy | E6: 500 | F6: FAC. PRESSURE | G6: =1.5*(B2+B3)/(E3*E4) -> 163.63636 | H6: =H5*12 -> -85.815388 | I6: =I5-21 -> -10.58882 | O6: =G4*3.281 -> 1.8487177
A7: c/c Distance | B7: 1.143 | C7: m | D7: Transverse Projection | E7: =(E3-B6)*0.5 -> 0.74 | G7: kN/m2 | I7: =I6*12 -> -127.06584 | P7: 7.9977338
A8: DEPTH CACULATION
A9: ONE WAY SHEAR | C9: SHEAR FORCE | D9: BM | E9: TWO WAY SHEAR | I9: =(I10-1)*12 -> 21.4662 | J9: =B2 -> 321.1954 | K9: =A2 -> B1 | M9: =B3 -> 312.28527
A10: =CONCATENATE("SF AT ",A2," LEFT") -> SF AT B1 LEFT | C10: =-G6*E3*(G2+B5/2) -> -306.94091 | D10: =G6*E3*(G2+B5/2)^2/2 -> 157.30722 | E10: Design Punching shear | G10: =1.5*MAX(B2:B3)-G6*(B5+D16/1000)^2 -> 413.92721 | I10: =I11*3.281 -> 2.78885 | N10: =N11*3.281 -> 2.78885 | O10: =A3 -> B2
A11: =CONCATENATE("SF AT ",A2," RIGHT") -> SF AT B1 RIGHT | C11: =B2*1.5+C10 -> 174.85219 | E11: Critical col size_l | G11: =B5 -> 0.35 | I11: =G2 -> 0.85 | N11: =G3 -> 0.85
A12: =CONCATENATE("SF AT ",A3," LEFT") -> SF AT B2 LEFT | C12: =-(B3*1.5-C13) -> -161.48699 | D12: =G6*E3*(G3+B6/2)^2/2 -> 157.30722 | E12: Critical col size_b | G12: =B6 -> 0.35 | P12: =E4*3.281 -> 10.41118
A13: =CONCATENATE("SF AT",A3, " RIGHT") -> SF ATB2 RIGHT | C13: =G6*E3*(G3+B6/2) -> 306.94091 | E13: Perimetre | G13: =(G11*1000+D16)*2+(G12*1000+D16)*2 -> 2576 | P13: =P12-17 -> -6.5888202
A14: Point of zero distance | C14: =B7*C11/(C11-C12) -> 0.59420985 | D14: =G6*E3*(C14+G2+B5/2)^2/2-1.5*B2*C14 -> 106.27483 | E14: bc | G14: =MIN(G11:G12)/MAX(G11:G12) -> 1 | O14: =D16+50 -> 344 | P14: =P13*12 -> -79.065843
A15: d eff required ( from BM) | D15: =SQRT(MAX(ABS(D10),ABS(D12),ABS(D14))*10^6/(0.133*E5*E3*1000)) -> 179.76617 | E15: Ks | G15: =IF(0.5+G14<1,(0.5+G14),1) -> 1
A16: D provided | B16: 350 | C16: d eff provided | D16: =B16-B19/2-50 -> 294 | E16: τc | G16: =0.25*SQRT(E5) -> 1.118034
C17: Area Req. from Max BM | D17: =D33 -> 1309.728 | E17: τc'=ksTc (Strength of Concrete) | G17: =G15*G16 -> 1.118034 | L17: =E4 -> 3.1731727
D18: =IF(B20>=D17,"OK","NOT OK") -> OK | E18: Tv(Due to Load) | G18: =G10*1000/(G13*D16) -> 0.54655112 | L18: =I11+B5+B7+G3 -> 3.193
A19: Rebar | B19: 12 | C19: C/C spacing mm | D19: 125 | E19: =IF(G17>G18,"SAFE IN TWO WAY","Not SAFE") -> SAFE IN TWO WAY | I19: =B20/2 -> 827.8725 | O19: =SQRT(D12*10^6/(0.133*20*2000)) -> 171.95646
A20: Ast prov | B20: =PI()*B19^2/4*1000/D19*E3 -> 1655.745 | C20: Pt | D20: =B20/(E3*1000*D16)*100 -> 0.30774785
A21: Critical shear | D21: =MAX(ABS(C10),ABS(C11),ABS(C12),ABS(C13))-(B6/2+D16/1000)*G6*E3 -> 166.49673
A22: B Value | B22: =0.8*E5/(6.89*D20) -> 7.5458077 | C22: Actual B | D22: =IF(B22>1,B22,1) -> 7.5458077 | E22: =IF(D23>B23,"SAFE IN ONE WAY","NOT OK") -> SAFE IN ONE WAY
A23: Tv (Due to Load) | B23: =D21*1000/(E3*1000*D16) -> 0.30946197 | C23: τc' | D23: =(0.85*SQRT(0.8*E5)*(SQRT(1+5*D22)-1))/(6*D22) -> 0.39225101
A24: REBARS CALCULATION AS PER BENDING MOMENT | O24: =E3 -> 1.83
C25: a | D25: =0.87*E6^2/(E5*E3*1000) -> 5.942623
C26: b | D26: =-0.87*E6*D16 -> -127890
A27: =CONCATENATE("BM ",A2, " Per Width") -> BM B1 Per Width | B27: =G6*E3*(G2+B5/2)^2/2 -> 157.30722 | C27: Ast Required (per Width) | D27: =(-$D$26-SQRT($D$26^2-(4*$D$25*B27*10^6)))/(2*$D$25) -> 1309.728 | E27: Ast Min | F27: =0.0012*E3*1000*(D16+50) -> 755.424 | G27: mm2
A28: Re-bar To be Provided | B28: 12 | C28: C/C | D28: =D19 -> 125 | E28: =CONCATENATE("Bottom Bars To Be Provided at ",A2, " ",B28," Dia @ ",D28," C/C") -> Bottom Bars To Be Provided at B1 12 Dia @ 125 C/C
A29: Ast Provided (per Width) | B29: =PI()*B28^2/4*1000/D28*$E$3 -> 1655.745 | C29: =IF(B29>=D27,"OK", "NOT OK") -> OK
A30: =CONCATENATE("BM AT "," 0 SHEAR FORCE kN.m") -> BM AT 0 SHEAR FORCE kN.m | B30: =ABS(D14) -> 106.27483 | C30: Ast Required (per Width) | D30: =(-$D$26-SQRT($D$26^2-(4*$D$25*B30*10^6)))/(2*$D$25) -> 865.81967 | E30: =CONCATENATE("Top Bars To Be Provided at 0 SF", " ",B31," Dia @ ",D31," C/C") -> Top Bars To Be Provided at 0 SF 12 Dia @ 125 C/C
A31: Re-bar To be Provided | B31: 12 | C31: C/C | D31: =D28 -> 125
A32: Ast Provided (per Width) | B32: =PI()*B31^2/4*1000/D31*$E$3 -> 1655.745 | C32: =IF(B32>=D30,"OK", "NOT OK") -> OK
A33: =CONCATENATE("BM ",A3, " ") -> BM B2 | B33: =G6*E3*(G3+B6/2)^2/2 -> 157.30722 | C33: Ast Required (per Width) | D33: =(-$D$26-SQRT($D$26^2-(4*$D$25*B33*10^6)))/(2*$D$25) -> 1309.728 | E33: =CONCATENATE("Bottom Bars To Be Provided at ",A3, " ",B34," Dia @ ",D34," C/C") -> Bottom Bars To Be Provided at B2 12 Dia @ 125 C/C
A34: Re-bar To be Provided | B34: 12 | C34: C/C | D34: =D31 -> 125
A35: Ast Provided (per Width) | B35: =PI()*B34^2/4*1000/D34*$E$3 -> 1655.745 | C35: =IF(B35>=D33,"OK", "NOT OK") -> OK
A36: BENDING MOMENT IN TRANSVERSE DIRECTION
A37: =CONCATENATE("Under Column ",A2) -> Under Column B1 | D37: =CONCATENATE("Under Column ",A3) -> Under Column B2
A38: =CONCATENATE("Factored Pressure under ",A2," kN/m") -> Factored Pressure under B1 kN/m | B38: =(1.5*B2)/(E3*1) -> 263.27492 | C38: kN | D38: =CONCATENATE("Factored Pressure under ",A3," kN/m") -> Factored Pressure under B2 kN/m | E38: =(1.5*B3)/E3 -> 255.97153 | F38: kN
A39: Design BM (per 1000) | B39: =B38*((E3-B5)/2)^2/2 -> 72.084673 | C39: kN.m | D39: Design BM (per 1000) | E39: =E38*((E3-B6)/2)^2/2 -> 70.085005 | F39: kN.m
A40: =CONCATENATE(A2," Effective Width") -> B1 Effective Width | B40: =B5*1000+(D16-20)+MIN((D16-20),G2*1000) -> 898 | C40: m | D40: =CONCATENATE(A3," Effective Width") -> B2 Effective Width | E40: =B6*1000+(D16-20)+MIN((D16-20),G3*1000) -> 898 | F40: m
...
