Workbook
Name description_103: #REF!
Name description_103: [1]Abstract!$B$16
Name description_124: #REF!
Name description_124: #REF!
Name description_124: #REF!
Name description_124: #REF!
Name description_124: #REF!
Name description_124: #REF!
Name description_247: #REF!
Name description_247: [1]Abstract!$B$22
Name description_248: #REF!
Name description_248: [1]Abstract!$B$23
Name description_261: #REF!
Name description_261: [2]Abstract!$B$33
Name description_262: #REF!
Name description_262: [1]Abstract!$B$34
Name description_276: #REF!
Name description_276: [3]Abstract!$B$40
Name description_3: #REF!
Name description_3: [1]Abstract!$B$169
Name description_310: #REF!
Name description_310: #REF!
Name description_310: #REF!
Name description_310: #REF!
Name description_310: #REF!
Name description_310: #REF!
Name description_312: #REF!
Name description_312: #REF!
Name description_312: #REF!
Name description_312: #REF!
Name description_312: #REF!
Name description_312: #REF!
Name description_4: #REF!
Name description_5: #REF!
Name description_5: [1]Abstract!$B$171
Name description_6: #REF!
Name description_6: #REF!
Name description_6: #REF!
Name description_6: #REF!
Name description_6: #REF!
Name description_6: #REF!
Name description_759: #REF!
Name description_759: [1]Abstract!$B$278
Name description_781: #REF!
Name description_781: #REF!
Name description_781: #REF!
Name description_781: #REF!
Name description_781: #REF!
Name description_781: #REF!
Name description_783: #REF!
Name description_783: [1]Abstract!$B$301
Name description_784: #REF!
Name description_784: [3]Abstract!$B$300

Sheet estimate
A1: Government of Nepal
A2: Shankharapur Municipality Office
A3: Bagmati Province
A4: Sankhu, Kathmandu
A5: Detail Estimated Sheet
A6: Project:- तल्लो नाङ्गलेद्वारे चिहानपाटी | H6: F.Y.: 2082/2083
A7: Location:- Shankharapur Municipality 1 | H7: Date:2082/09/07
A8: S.N. | B8: Description of work | C8: No. | D8: Length | E8: Breadth | F8: Height | G8: Quantity | H8: Unit | I8: Rate | J8: Amount | K8: Remark
A9: 1 | B9: sfnf] kmnfd] kfO{ksf] 6«; agfO{ h8fg ug]{ sfd | C9: No. | D9: Length (m) | E9: Unit length (Kg/m) | F9: Total Weight (kg)
B10: -MS square pipe of 3" * 3" of 3mm thickness for vertical post | C10: =4 -> 4 | D10: =(12+1+2)/3.281 -> 4.5717769 | E10: 6.5 | F10: =PRODUCT(C10:E10) -> 118.8662 | G10: =F10 -> 118.8662
B11: -MS square pipe horizontal of 3" * 3" of 3mm thickness for binding post | C11: 4 | D11: =12/3.281 -> 3.6574215 | E11: 6.5 | F11: =PRODUCT(C11:E11) -> 95.092959 | G11: =F11 -> 95.092959 | Q11: =PRODUCT(C11:D11) -> 14.629686 | R11: =CONVERT(Q11,"m","ft") -> 47.997658
B12: -MS square pipe horizontal of 3" * 3" of 3mm thickness for base of upper portion | C12: 2 | D12: =12/3.281 -> 3.6574215 | E12: 6.5 | F12: =PRODUCT(C12:E12) -> 47.54648 | G12: =F12 -> 47.54648
B13: -MS square pipe vertical section of 3" * 3" of 3mm thickness for upper portion | C13: 4 | D13: =5.33/3.281 -> 1.6245047 | E13: 6.5 | F13: =PRODUCT(C13:E13) -> 42.237123 | G13: =F13 -> 42.237123
B14: -MS square pipe horizontal of 2" * 2" of 3mm thickness for diagnol of uppermost portion | C14: 2 | D14: =8.25/3.281 -> 2.5144773 | E14: 4.43 | F14: =PRODUCT(C14:E14) -> 22.278269 | G14: =F14 -> 22.278269
B15: -MS square pipe horizontal of 2" * 2" of 3mm thickness for binding at mid portion of upper part | C15: =2*4 -> 8 | D15: =6/3.281 -> 1.8287108 | E15: 4.43 | F15: =PRODUCT(C15:E15) -> 64.809509 | G15: =F15 -> 64.809509
B16: -MS square pipe horizontal of 2" * 2" of 3mm thickness as purlin at mid portion of upper part | C16: =4 -> 4 | D16: =9.5/3.281 -> 2.8954587 | E16: 4.43 | F16: =PRODUCT(C16:E16) -> 51.307528 | G16: =F16 -> 51.307528
C17: =4 -> 4 | D17: =14.083/3.281 -> 4.2922889 | E17: 4.43 | F17: =PRODUCT(C17:E17) -> 76.05936 | G17: =F17 -> 76.05936
B18: -MS square pipe horizontal of 2" * 2" of 3mm thickness at corner of upper part | C18: =4*2 -> 8 | D18: =6.42/3.281 -> 1.9567205 | E18: 4.43 | F18: =PRODUCT(C18:E18) -> 69.346175 | G18: =F18 -> 69.346175
B19: -MS square pipe horizontal of 2" * 2" of 3mm thickness as purlin at mid portion of uppermost part | C19: 4 | D19: =8/3.281 -> 2.438281 | E19: 4.43 | F19: =PRODUCT(C19:E19) -> 43.20634 | G19: =F19 -> 43.20634
C20: 4 | D20: =2.5/3.281 -> 0.76196282 | E20: 5.43 | F20: =PRODUCT(C20:E20) -> 16.549832 | G20: =F20 -> 16.549832
B21: -MS square pipe horizontal of 2" * 2" of 3mm thickness at corner of uppermost part | C21: =4*2 -> 8 | D21: =4.17/3.281 -> 1.270954 | E21: 4.43 | F21: =PRODUCT(C21:E21) -> 45.042609 | G21: =F21 -> 45.042609
B22: -MS square pipe horizontal of 2" * 2" of 2mm thickness for vertical post of railing | C22: 6 | D22: 1.5 | E22: 3.01 | F22: =PRODUCT(C22:E22) -> 27.09 | G22: =F22 -> 27.09
B23: -MS square pipe horizontal of 2" * 2" of 2mm thickness for vertical post of railing | C23: 1 | D23: =36/3.281 -> 10.972265 | E23: 3.01 | F23: =PRODUCT(C23:E23) -> 33.026516 | G23: =F23 -> 33.026516
B24: -MS square pipe horizontal of 1.5" * 1.5" of 2mm thickness for vertical post of railing | C24: 2 | D24: =(36-0.17*7)/3.281 -> 10.60957 | E24: 2.26 | F24: =PRODUCT(C24:E24) -> 47.955258 | G24: =F24 -> 47.955258
B25: sub-total | G25: =SUM(G10:G24) -> 800.41416 | H25: Kg | I25: 182.51 | J25: =G25*I25 -> 146083.59
B26: -VAT 13% for materials | J26: =0.13*G25*(1871.42/18.94) -> 10281.333
A28: 2 | B28: )=$! dL=dL=afSnf] sf]?u]6]8 /+lug ss{6 kftfsf] 5fgf 5fpg] sfd
B29: -upper portion | C29: 4 | D29: =((15.833+6.5)/2)/3.281 -> 3.4033831 | E29: =5.33/3.281 -> 1.6245047 | G29: =PRODUCT(C29:F29) -> 22.115248
B30: -uppermost portion | C30: 4 | D30: =((0+9.583)/2)/3.281 -> 1.4603779 | E30: =5.5/3.281 -> 1.6763182 | G30: =PRODUCT(C30:F30) -> 9.7922324
B31: sub-total | G31: =SUM(G29:G30) -> 31.90748 | H31: sqm | I31: 1112.58 | J31: =G31*I31 -> 35499.624
B32: -13% VAT for sheet | J32: =0.13*G31*7050.67/10 -> 2924.5985
B33: -13% VAT for nut bolt | J33: =0.13*G31*1023.75/10 -> 424.64868
B34: -13% VAT for j-hook | J34: =0.13*G31*348.21/10 -> 144.43655
B35: -13% VAT for bitumen washer | J35: =0.13*G31*165/10 -> 68.441545
A37: 3 | B37: Earthwork Excavation in Cutting., Roadway Excavation in all types of Soil by Mechanical Means ., Road way Excavation in all types of soil as per Drawing and technical specifications including removal of stumps and other deleterious matter, all lifts and lead as per Drawing and instruction of the Engineer.
B38: -Masonary wall | C38: 1 | D38: =D47 -> 8.5 | E38: =E47 -> 2 | F38: 0.9 | G38: =PRODUCT(C38:F38) -> 15.3
C39: 1 | D39: =D48 -> 5 | E39: =E48 -> 1 | F39: 0.75 | G39: =PRODUCT(C39:F39) -> 3.75
B40: -for footing of vertical post | C40: 4 | D40: 0.6 | E40: 0.6 | F40: 0.6 | G40: =PRODUCT(C40:F40) -> 0.864
B41: -for plinth level | C41: 4 | D41: =10.25/3.281 -> 3.1240475 | E41: 0.45 | F41: =0.45+0.075 -> 0.525 | G41: =PRODUCT(C41:F41) -> 2.9522249
B42: -for railing | C42: 6 | D42: 0.3 | E42: 0.3 | F42: 0.6 | G42: =PRODUCT(C42:F42) -> 0.324
...

Sheet WCR
A1: Government of Nepal
A2: Shankharapur Municipality Office
A3: Bagmati Province
A4: Sankhu, Kathmandu
A5: Work Completion Report
A6: Total Estimated Amount: | C6: =F49 -> 786973.55 | H6: Total Valuated Amount : | J6: =I49 -> 789632.09
A7: Work Started : | I7: Work Finished:
A8: =estimate!A6 -> Project:- तल्लो नाङ्गलेद्वारे चिहानपाटी | I8: F.Y:2082/2083
A9: Location:- Shankharapur Municipality 1 | I9: Date:2083/03/15
A11: S.No. | B11: Description | C11: Unit | D11: Estimated | G11: Valuated | J11: Difference | K11: Remarks
D12: Quantity | E12: Rate | F12: Amount | G12: Quantity | H12: Rate | I12: Amount
A13: =estimate!A9 -> 1 | B13: =estimate!B9 -> sfnf] kmnfd] kfO{ksf] 6«; agfO{ h8fg ug]{ sfd | C13: =estimate!H25 -> Kg | D13: =estimate!G25 -> 800.41416 | E13: =estimate!I25 -> 182.51 | F13: =D13*E13 -> 146083.59 | G13: =V!G32 -> 880.06057 | H13: =V!I32 -> 182.51 | I13: =G13*H13 -> 160619.85 | J13: =I13-F13 -> 14536.266 | M13: =1.25*F13 -> 182604.48
B14: =[4]estimate!B12 -> -13% VAT for excavator | F14: =estimate!J26 -> 10281.333 | I14: =V!J33 -> 11304.392 | J14: =I14-F14 -> 1023.0594 | M14: =1.25*F14 -> 12851.666
A16: =estimate!A28 -> 2 | B16: =estimate!B28 -> )=$! dL=dL=afSnf] sf]?u]6]8 /+lug ss{6 kftfsf] 5fgf 5fpg] sfd | C16: =estimate!H31 -> sqm | D16: =estimate!G31 -> 31.90748 | E16: =estimate!I31 -> 1112.58 | F16: =D16*E16 -> 35499.624 | G16: =V!G38 -> 32.154877 | H16: =V!I38 -> 1112.58 | I16: =G16*H16 -> 35774.873 | J16: =I16-F16 -> 275.24905 | M16: =1.25*F16 -> 44374.53
B17: =estimate!B32 -> -13% VAT for sheet | F17: =estimate!J32 -> 2924.5985 | I17: =V!J39 -> 2947.2746 | J17: =I17-F17 -> 22.676098 | M17: =1.25*F17 -> 3655.7481
B18: =estimate!B33 -> -13% VAT for nut bolt | F18: =estimate!J33 -> 424.64868 | I18: =V!J40 -> 427.94122 | J18: =I18-F18 -> 3.292546
B19: =estimate!B34 -> -13% VAT for j-hook | F19: =estimate!J34 -> 144.43655 | I19: =V!J41 -> 145.55645 | J19: =I19-F19 -> 1.1198998
B20: =estimate!B35 -> -13% VAT for bitumen washer | F20: =estimate!J35 -> 68.441545 | I20: =V!J42 -> 68.972212 | J20: =I20-F20 -> 0.53066675
A22: =estimate!A37 -> 3 | B22: =estimate!B37 -> Earthwork Excavation in Cutting., Roadway Excavation in all types of Soil by Mechanical Means ., Road way Excavation in all types of soil as per Drawing and technical specifications including removal of stumps and other deleterious matter, all lifts and lead as per Drawing and instruction of the Engineer. | C22: =estimate!H43 -> cum | D22: =estimate!G43 -> 23.190225 | E22: =estimate!I43 -> 62.95 | F22: =D22*E22 -> 1459.8247 | G22: =V!G50 -> 22.882158 | H22: =V!I50 -> 62.95 | I22: =G22*H22 -> 1440.4318 | J22: =I22-F22 -> -19.392814 | M22: =1.25*F22 -> 1824.7808
B23: =estimate!B44 -> -13% VAT for excavator | F23: =estimate!J44 -> 155.8615 | I23: =V!J51 -> 153.79098 | J23: =I23-F23 -> -2.0705179 | M23: =1.25*F23 -> 194.82688
A25: =estimate!A46 -> 4 | B25: =estimate!B46 -> Providing and laying of hand pack locally available Stone soling with 150 to 200 mm thick stones and packing with smaller stone on prepared surface as per Drawing and Technical Specifications. | C25: =estimate!H54 -> cum | D25: =estimate!G54 -> 5.6868978 | E25: =estimate!I54 -> 4458.52 | F25: =D25*E25 -> 25355.148 | G25: =V!G61 -> 6.0110164 | H25: =V!I61 -> 4458.52 | I25: =G25*H25 -> 26800.237 | J25: =I25-F25 -> 1445.0891 | M25: =1.25*F25 -> 31693.934
B26: =estimate!B55 -> -13% VAT for stone | F26: =estimate!J55 -> 2284.8172 | I26: =V!J62 -> 2415.0379 | J26: =I26-F26 -> 130.22067 | M26: =1.25*F26 -> 2856.0215
A28: =estimate!A57 -> 5 | B28: =estimate!B57 -> Providing and laying of Plain/Reinforced Cement Concrete in Foundation complete as per Drawing and Technical Specifications, PCC Grade M 15 | C28: =estimate!H67 -> cum | D28: =estimate!G67 -> 3.4883371 | E28: =estimate!I67 -> 10964.46 | F28: =D28*E28 -> 38247.733 | G28: =V!G74 -> 3.3959918 | H28: =V!I74 -> 10964.46 | I28: =G28*H28 -> 37235.216 | J28: =I28-F28 -> -1012.5164 | M28: =1.25*F28 -> 47809.666
B29: =estimate!B68 -> -13% VAT for cement | F29: =estimate!J68 -> 1627.0404 | I29: =V!J75 -> 1583.9684 | J29: =I29-F29 -> -43.071967 | M29: =1.25*F29 -> 2033.8005
B30: =estimate!B69 -> -13% VAT for sand | F30: =estimate!J69 -> 647.95583 | I30: =V!J76 -> 630.80276 | J30: =I30-F30 -> -17.153066
B31: =estimate!B70 -> -13% VAT for aggregate | F31: =estimate!J70 -> 1317.5102 | I31: =V!J77 -> 1282.6323 | J31: =I31-F31 -> -34.877902
B32: =estimate!B71 -> -13% VAT for formwork | F32: =estimate!J71 -> 191.24018 | I32: =V!J78 -> 186.17755 | J32: =I32-F32 -> -5.062622
B33: =estimate!B72 -> -13% VAT for water | F33: =estimate!J72 -> 28.115997 | I33: =V!J79 -> 27.371694 | J33: =I33-F33 -> -0.74430315
A35: =estimate!A74 -> 6 | B35: =estimate!B74 -> Random Rubble Masonry, Providing and laying of Stone Masonry Work in Cement Mortar 1:6 in Foundation complete as per Drawing and Technical Specifications., Using Concrete Mixer | C35: =estimate!H78 -> cum | D35: =estimate!G78 -> 52.438555 | E35: =estimate!I78 -> 8987.83 | F35: =D35*E35 -> 471308.82 | G35: =V!G86 -> 51.032688 | H35: =V!I86 -> 8987.83 | I35: =G35*H35 -> 458673.13 | J35: =I35-F35 -> -12635.694 | M35: =1.25*F35 -> 589136.03
B36: =estimate!B79 -> -13% VAT for cement | F36: =estimate!J79 -> 7994.9237 | I36: =V!J87 -> 7780.5814 | J36: =I36-F36 -> -214.34229 | M36: =1.25*F36 -> 9993.6547
B37: =estimate!B80 -> -13% VAT for sand | F37: =estimate!J80 -> 9004.4769 | I37: =V!J88 -> 8763.0687 | J37: =I37-F37 -> -241.40821
B38: =estimate!B81 -> -13% VAT for stone | F38: =estimate!J81 -> 20190.327 | I38: =V!J89 -> 19649.028 | J38: =I38-F38 -> -541.29859
B39: =estimate!B82 -> -13% VAT for water | F39: =estimate!J82 -> 422.65476 | I39: =V!J90 -> 411.32347 | J39: =I39-F39 -> -11.331289
A41: =estimate!A84 -> 7 | B41: =estimate!B84 -> ;'Vvf O{6f RofK6f] 5fKg] sfd | C41: =estimate!H86 -> sqm | D41: =estimate!G86 -> 2.4 | E41: =estimate!I86 -> 1017.47 | F41: =D41*E41 -> 2441.928 | G41: =V!G94 -> 2.4 | H41: =V!I94 -> 1017.47 | I41: =G41*H41 -> 2441.928 | J41: =I41-F41 -> 0 | M41: =1.25*F41 -> 3052.41
B42: =estimate!B87 -> -13% VAT for brick | F42: =estimate!J87 -> 268.85664 | I42: =V!J95 -> 268.85664 | J42: =I42-F42 -> 0 | M42: =1.25*F42 -> 336.0708
A44: =estimate!A89 -> 8 | B44: =estimate!B89 -> -High Density Polythene Pipe NS 40 pipe material PE 100, PN 16 | C44: =estimate!H91 -> kg | D44: =estimate!G91 -> 24.975 | E44: =estimate!I91 -> 287 | F44: =D44*E44 -> 7167.825 | G44: =V!G99 -> 24.975 | H44: =V!I99 -> 287 | I44: =G44*H44 -> 7167.825 | J44: =I44-F44 -> 0 | M44: =1.25*F44 -> 8959.7812
B45: =estimate!B92 -> -13% VAT for material | F45: =estimate!J92 -> 931.81725 | I45: =V!J100 -> 931.81725
A47: =estimate!A94 -> 9 | B47: =estimate!B94 -> Information board (सुचना पाटि) | C47: =estimate!H94 -> no. | D47: =estimate!G94 -> 1 | E47: =estimate!I94 -> 500 | F47: =D47*E47 -> 500 | G47: =V!G102 -> 1 | H47: =V!I102 -> 500 | I47: =G47*H47 -> 500 | J47: =I47-F47 -> 0
B49: Total | F49: =SUM(F13:F47) -> 786973.55 | I49: =SUM(I13:I47) -> 789632.09 | J49: =I49-F49 -> 2658.5392

Sheet V
A1: Government of Nepal
A2: Shankharapur Municipality Office
A3: Bagmati Province
A4: Sankhu, Kathmandu
A5: Detail Valuated Sheet
A6: Project:- तल्लो नाङ्गलेद्वारे चिहानपाटी | H6: F.Y.: 2082/2083
A7: Location:- Shankharapur Municipality 1 | H7: Date:2083/03/15
A8: S.N. | B8: Description of work | C8: No. | D8: Length | E8: Breadth | F8: Height | G8: Quantity | H8: Unit | I8: Rate | J8: Amount | K8: Remark
A9: 1 | B9: sfnf] kmnfd] kfO{ksf] 6«; agfO{ h8fg ug]{ sfd | C9: No. | D9: Length (m) | E9: Unit length (Kg/m) | F9: Total Weight (kg)
B10: -MS square pipe of 3" * 3" of 3mm thickness for vertical post | C10: =4 -> 4 | D10: =(12+1)/3.281 -> 3.9622066 | E10: 6.5 | F10: =PRODUCT(C10:E10) -> 103.01737 | G10: =F10 -> 103.01737
B11: -MS square pipe horizontal of 3" * 3" of 3mm thickness for binding post | C11: 4 | D11: =11.5/3.281 -> 3.505029 | E11: 6.5 | F11: =PRODUCT(C11:E11) -> 91.130753 | G11: =F11 -> 91.130753 | Q11: =PRODUCT(C11:D11) -> 14.020116 | R11: =CONVERT(Q11,"m","ft") -> 45.997755
B12: -MS square pipe horizontal of 3" * 3" of 3mm thickness for base of upper portion | C12: 2 | D12: =11.5/3.281 -> 3.505029 | E12: 6.5 | F12: =PRODUCT(C12:E12) -> 45.565376 | G12: =F12 -> 45.565376
B13: -MS square pipe vertical section of 3" * 3" of 3mm thickness for upper portion | C13: 4 | D13: 1.5 | E13: 6.5 | F13: =PRODUCT(C13:E13) -> 39 | G13: =F13 -> 39
C14: 1 | D14: =0.45 -> 0.45 | E14: 6.5 | F14: =PRODUCT(C14:E14) -> 2.925 | G14: =F14 -> 2.925
B15: -MS square pipe horizontal of 2" * 2" of 3mm thickness for diagnol of uppermost portion | C15: 2 | D15: =9/3.281 -> 2.7430661 | E15: 4.43 | F15: =PRODUCT(C15:E15) -> 24.303566 | G15: =F15 -> 24.303566
B16: -MS square pipe horizontal of 2" * 2" of 3mm thickness for binding at mid portion of upper part | C16: 4 | D16: =5.75/3.281 -> 1.7525145 | E16: 4.43 | F16: =PRODUCT(C16:E16) -> 31.054557 | G16: =F16 -> 31.054557
C17: 4 | D17: =77/12/3.281 -> 1.9557046 | E17: 4.43 | F17: =PRODUCT(C17:E17) -> 34.655085 | G17: =F17 -> 34.655085
B18: -MS square pipe horizontal of 2" * 2" of 3mm thickness as purlin at mid portion of upper part | C18: =4 -> 4 | D18: =10.67/3.281 -> 3.2520573 | E18: 4.43 | F18: =PRODUCT(C18:E18) -> 57.626455 | G18: =F18 -> 57.626455
C19: =4 -> 4 | D19: =15/3.281 -> 4.5717769 | E19: 4.43 | F19: =PRODUCT(C19:E19) -> 81.011887 | G19: =F19 -> 81.011887
B20: -MS square pipe horizontal of 2" * 2" of 3mm thickness at corner of upper part | C20: =4*1 -> 4 | D20: =6.42/3.281 -> 1.9567205 | E20: 4.43 | F20: =PRODUCT(C20:E20) -> 34.673087 | G20: =F20 -> 34.673087
C21: =4*2 -> 8 | D21: =6.42/3.281 -> 1.9567205 | E21: 4.43 | F21: =PRODUCT(C21:E21) -> 69.346175 | G21: =F21 -> 69.346175
B22: -MS square pipe horizontal of 2" * 2" of 3mm thickness as purlin at mid portion of uppermost part | C22: 4 | D22: =8/12/3.281 -> 0.20319008 | E22: 4.43 | F22: =PRODUCT(C22:E22) -> 3.6005283 | G22: =F22 -> 3.6005283
C23: 4 | D23: =54/12/3.281 -> 1.3715331 | E23: 4.43 | F23: =PRODUCT(C23:E23) -> 24.303566 | G23: =F23 -> 24.303566
C24: 4 | D24: =105/12/3.281 -> 2.6668699 | E24: 4.43 | F24: =PRODUCT(C24:E24) -> 47.256934 | G24: =F24 -> 47.256934
B25: -MS square pipe horizontal of 2" * 2" of 3mm thickness at corner of uppermost part | C25: 4 | D25: =75/12/3.281 -> 1.904907 | E25: 4.43 | F25: =PRODUCT(C25:E25) -> 33.754953 | G25: =F25 -> 33.754953
C26: =4*2 -> 8 | D26: =(36+37)/12/3.281 -> 1.8541095 | E26: 4.43 | F26: =PRODUCT(C26:E26) -> 65.709641 | G26: =F26 -> 65.709641
B27: -MS square pipe horizontal of 2" * 2" of 2mm thickness for vertical post of railing | C27: 1 | D27: =6/3.281 -> 1.8287108 | E27: 3.01 | F27: =PRODUCT(C27:E27) -> 5.5044194 | G27: =F27 -> 5.5044194
C28: 4 | D28: 1.5 | E28: 3.01 | F28: =PRODUCT(C28:E28) -> 18.06 | G28: =F28 -> 18.06
B29: -MS square pipe horizontal of 1.5" * 1.5" of 2mm thickness for railing | C29: 1 | D29: =(7+65/12+76/12+74/12+6)/3.281 -> 9.4229402 | E29: 2.26 | F29: =PRODUCT(C29:E29) -> 21.295845 | G29: =F29 -> 21.295845
C30: 2 | D30: =(69+72+75+64+82)/12/3.281 -> 9.1943513 | E30: 2.26 | F30: =PRODUCT(C30:E30) -> 41.558468 | G30: =F30 -> 41.558468
C31: 1 | D31: =82/12/3.281 -> 2.0826984 | E31: 2.26 | F31: =PRODUCT(C31:E31) -> 4.7068983 | G31: =F31 -> 4.7068983
B32: sub-total | G32: =SUM(G10:G31) -> 880.06057 | H32: Kg | I32: 182.51 | J32: =G32*I32 -> 160619.85
B33: -VAT 13% for materials | J33: =0.13*G32*(1871.42/18.94) -> 11304.392
A35: 2 | B35: )=$! dL=dL=afSnf] sf]?u]6]8 /+lug ss{6 kftfsf] 5fgf 5fpg] sfd
B36: -upper portion | C36: 4 | D36: =(15+6)/2/3.281 -> 3.2002438 | E36: =5.583/3.281 -> 1.7016154 | G36: =PRODUCT(C36:F36) -> 21.782336
B37: -uppermost portion | C37: 4 | D37: =5/3.281 -> 1.5239256 | E37: =5.583/3.281 -> 1.7016154 | G37: =PRODUCT(C37:F37) -> 10.372541
B38: sub-total | G38: =SUM(G36:G37) -> 32.154877 | H38: sqm | I38: 1112.58 | J38: =G38*I38 -> 35774.873
B39: -13% VAT for sheet | J39: =0.13*G38*7050.67/10 -> 2947.2746
B40: -13% VAT for nut bolt | J40: =0.13*G38*1023.75/10 -> 427.94122
B41: -13% VAT for j-hook | J41: =0.13*G38*348.21/10 -> 145.55645
...

Sheet M
A1: Government of Nepal
A2: Shankharapur Municipality Office
A3: Bagmati Province
A4: Sankhu, Kathmandu
A5: Detail Quantity Mesurement Sheet
A6: Project:- तल्लो नाङ्गलेद्वारे चिहानपाटी | K6: F.Y.: 2082/2083
A7: Location:- Shankharapur Municipality 1 | K7: Date:2083/03/15
A8: S.N. | B8: Description of work | C8: No. | D8: Length | E8: Breadth | F8: Height | G8: Quantity | H8: Unit | I8: Rate | J8: Amount | K8: Remark
A9: 1 | B9: sfnf] kmnfd] kfO{ksf] 6«; agfO{ h8fg ug]{ sfd | C9: No. | D9: Length (m) | E9: Unit length (Kg/m) | F9: Total Weight (kg)
B10: -MS square pipe of 3" * 3" of 3mm thickness for vertical post | C10: =4 -> 4 | D10: =(12+1)/3.281 -> 3.9622066 | E10: 6.5 | F10: =PRODUCT(C10:E10) -> 103.01737 | G10: =F10 -> 103.01737
B11: -MS square pipe horizontal of 3" * 3" of 3mm thickness for binding post | C11: 4 | D11: =11.5/3.281 -> 3.505029 | E11: 6.5 | F11: =PRODUCT(C11:E11) -> 91.130753 | G11: =F11 -> 91.130753 | Q11: =PRODUCT(C11:D11) -> 14.020116 | R11: =CONVERT(Q11,"m","ft") -> 45.997755
B12: -MS square pipe horizontal of 3" * 3" of 3mm thickness for base of upper portion | C12: 2 | D12: =11.5/3.281 -> 3.505029 | E12: 6.5 | F12: =PRODUCT(C12:E12) -> 45.565376 | G12: =F12 -> 45.565376
B13: -MS square pipe vertical section of 3" * 3" of 3mm thickness for upper portion | C13: 4 | D13: 1.5 | E13: 6.5 | F13: =PRODUCT(C13:E13) -> 39 | G13: =F13 -> 39
C14: 1 | D14: =0.45 -> 0.45 | E14: 6.5 | F14: =PRODUCT(C14:E14) -> 2.925 | G14: =F14 -> 2.925
B15: -MS square pipe horizontal of 2" * 2" of 3mm thickness for diagnol of uppermost portion | C15: 2 | D15: =9/3.281 -> 2.7430661 | E15: 4.43 | F15: =PRODUCT(C15:E15) -> 24.303566 | G15: =F15 -> 24.303566
B16: -MS square pipe horizontal of 2" * 2" of 3mm thickness for binding at mid portion of upper part | C16: 4 | D16: =5.75/3.281 -> 1.7525145 | E16: 4.43 | F16: =PRODUCT(C16:E16) -> 31.054557 | G16: =F16 -> 31.054557
C17: 4 | D17: =77/12/3.281 -> 1.9557046 | E17: 4.43 | F17: =PRODUCT(C17:E17) -> 34.655085 | G17: =F17 -> 34.655085
B18: -MS square pipe horizontal of 2" * 2" of 3mm thickness as purlin at mid portion of upper part | C18: =4 -> 4 | D18: =10.67/3.281 -> 3.2520573 | E18: 4.43 | F18: =PRODUCT(C18:E18) -> 57.626455 | G18: =F18 -> 57.626455
C19: =4 -> 4 | D19: =15/3.281 -> 4.5717769 | E19: 4.43 | F19: =PRODUCT(C19:E19) -> 81.011887 | G19: =F19 -> 81.011887
B20: -MS square pipe horizontal of 2" * 2" of 3mm thickness at corner of upper part | C20: =4*1 -> 4 | D20: =6.42/3.281 -> 1.9567205 | E20: 4.43 | F20: =PRODUCT(C20:E20) -> 34.673087 | G20: =F20 -> 34.673087
C21: =4*2 -> 8 | D21: =6.42/3.281 -> 1.9567205 | E21: 4.43 | F21: =PRODUCT(C21:E21) -> 69.346175 | G21: =F21 -> 69.346175
B22: -MS square pipe horizontal of 2" * 2" of 3mm thickness as purlin at mid portion of uppermost part | C22: 4 | D22: =8/12/3.281 -> 0.20319008 | E22: 4.43 | F22: =PRODUCT(C22:E22) -> 3.6005283 | G22: =F22 -> 3.6005283
C23: 4 | D23: =54/12/3.281 -> 1.3715331 | E23: 4.43 | F23: =PRODUCT(C23:E23) -> 24.303566 | G23: =F23 -> 24.303566
C24: 4 | D24: =105/12/3.281 -> 2.6668699 | E24: 4.43 | F24: =PRODUCT(C24:E24) -> 47.256934 | G24: =F24 -> 47.256934
B25: -MS square pipe horizontal of 2" * 2" of 3mm thickness at corner of uppermost part | C25: 4 | D25: =75/12/3.281 -> 1.904907 | E25: 4.43 | F25: =PRODUCT(C25:E25) -> 33.754953 | G25: =F25 -> 33.754953
C26: =4*2 -> 8 | D26: =(36+37)/12/3.281 -> 1.8541095 | E26: 4.43 | F26: =PRODUCT(C26:E26) -> 65.709641 | G26: =F26 -> 65.709641
B27: -MS square pipe horizontal of 2" * 2" of 2mm thickness for vertical post of railing | C27: 1 | D27: =6/3.281 -> 1.8287108 | E27: 3.01 | F27: =PRODUCT(C27:E27) -> 5.5044194 | G27: =F27 -> 5.5044194
C28: 4 | D28: 1.5 | E28: 3.01 | F28: =PRODUCT(C28:E28) -> 18.06 | G28: =F28 -> 18.06
B29: -MS square pipe horizontal of 1.5" * 1.5" of 2mm thickness for railing | C29: 1 | D29: =(7+65/12+76/12+74/12+6)/3.281 -> 9.4229402 | E29: 2.26 | F29: =PRODUCT(C29:E29) -> 21.295845 | G29: =F29 -> 21.295845
C30: 2 | D30: =(69+72+75+64+82)/12/3.281 -> 9.1943513 | E30: 2.26 | F30: =PRODUCT(C30:E30) -> 41.558468 | G30: =F30 -> 41.558468
C31: 1 | D31: =82/12/3.281 -> 2.0826984 | E31: 2.26 | F31: =PRODUCT(C31:E31) -> 4.7068983 | G31: =F31 -> 4.7068983
B32: sub-total | G32: =SUM(G10:G31) -> 880.06057 | H32: Kg | I32: 182.51 | J32: =G32*I32 -> 160619.85
B33: -VAT 13% for materials | J33: =0.13*G32*(1871.42/18.94) -> 11304.392
A35: 2 | B35: )=$! dL=dL=afSnf] sf]?u]6]8 /+lug ss{6 kftfsf] 5fgf 5fpg] sfd
B36: -upper portion | C36: 4 | D36: =(15+6)/2/3.281 -> 3.2002438 | E36: =5.583/3.281 -> 1.7016154 | G36: =PRODUCT(C36:F36) -> 21.782336
B37: -uppermost portion | C37: 4 | D37: =5/3.281 -> 1.5239256 | E37: =5.583/3.281 -> 1.7016154 | G37: =PRODUCT(C37:F37) -> 10.372541
B38: sub-total | G38: =SUM(G36:G37) -> 32.154877 | H38: sqm | I38: 1112.58 | J38: =G38*I38 -> 35774.873
B39: -13% VAT for sheet | J39: =0.13*G38*7050.67/10 -> 2947.2746
B40: -13% VAT for nut bolt | J40: =0.13*G38*1023.75/10 -> 427.94122
B41: -13% VAT for j-hook | J41: =0.13*G38*348.21/10 -> 145.55645
...

Sheet With measurement
A1: Government of Nepal
A2: Shankharapur Municipality Office
A3: Bagmati Province
A4: Sankhu, Kathmandu
A5: Detail Estimated Sheet
A6: Project:- तल्लो नाङ्गलेद्वारे चिहानपाटी | H6: F.Y.: 2082/2083
A7: Location:- Shankharapur Municipality 1 | H7: Date:2082/09/07
A8: S.N. | B8: Description of work | C8: No. | D8: Length | E8: Breadth | F8: Height | G8: Quantity | H8: Unit | I8: Rate | J8: Amount | K8: Remark
A9: 1 | B9: sfnf] kmnfd] kfO{ksf] 6«; agfO{ h8fg ug]{ sfd | C9: No. | D9: Length (m) | E9: Unit length (Kg/m) | F9: Total Weight (kg)
B10: -MS square pipe of 3" * 3" of 3mm thickness for vertical post | C10: =4 -> 4 | D10: =(12+1)/3.281 -> 3.9622066 | E10: 6.5 | F10: =PRODUCT(C10:E10) -> 103.01737 | G10: =F10 -> 103.01737 | J10: 39kg per pipe
B11: -MS square pipe horizontal of 3" * 3" of 3mm thickness for binding post | C11: 4 | D11: =11.5/3.281 -> 3.505029 | E11: 6.5 | F11: =PRODUCT(C11:E11) -> 91.130753 | G11: =F11 -> 91.130753 | J11: =20/3.281 -> 6.0957025 | Q11: =PRODUCT(C11:D11) -> 14.020116 | R11: =CONVERT(Q11,"m","ft") -> 45.997755
B12: -MS square pipe horizontal of 3" * 3" of 3mm thickness for base of upper portion | C12: 2 | D12: =11.5/3.281 -> 3.505029 | E12: 6.5 | F12: =PRODUCT(C12:E12) -> 45.565376 | G12: =F12 -> 45.565376
B13: -MS square pipe vertical section of 3" * 3" of 3mm thickness for upper portion | C13: 4 | D13: 1.5 | E13: 6.5 | F13: =PRODUCT(C13:E13) -> 39 | G13: =F13 -> 39
C14: 1 | D14: =0.45 -> 0.45 | E14: 6.5 | F14: =PRODUCT(C14:E14) -> 2.925 | G14: =F14 -> 2.925 | I14: =22/12 -> 1.8333333
B15: -MS square pipe horizontal of 2" * 2" of 3mm thickness for diagnol of uppermost portion | C15: 2 | D15: =9/3.281 -> 2.7430661 | E15: 4.43 | F15: =PRODUCT(C15:E15) -> 24.303566 | G15: =F15 -> 24.303566 | I15: =110/12 -> 9.1666667
B16: -MS square pipe horizontal of 2" * 2" of 3mm thickness for binding at mid portion of upper part | C16: 4 | D16: =5.75/3.281 -> 1.7525145 | E16: 4.43 | F16: =PRODUCT(C16:E16) -> 31.054557 | G16: =F16 -> 31.054557 | I16: =71/12 -> 5.9166667
C17: 4 | D17: =77/12/3.281 -> 1.9557046 | E17: 4.43 | F17: =PRODUCT(C17:E17) -> 34.655085 | G17: =F17 -> 34.655085 | I17: =77/12 -> 6.4166667
B18: -MS square pipe horizontal of 2" * 2" of 3mm thickness as purlin at mid portion of upper part | C18: =4 -> 4 | D18: =10.67/3.281 -> 3.2520573 | E18: 4.43 | F18: =PRODUCT(C18:E18) -> 57.626455 | G18: =F18 -> 57.626455 | I18: =128/12 -> 10.666667
C19: =4 -> 4 | D19: =15/3.281 -> 4.5717769 | E19: 4.43 | F19: =PRODUCT(C19:E19) -> 81.011887 | G19: =F19 -> 81.011887 | I19: =183/12 -> 15.25
B20: -MS square pipe horizontal of 2" * 2" of 3mm thickness at corner of upper part | C20: =4*1 -> 4 | D20: =6.42/3.281 -> 1.9567205 | E20: 4.43 | F20: =PRODUCT(C20:E20) -> 34.673087 | G20: =F20 -> 34.673087 | I20: =82/12 -> 6.8333333
C21: =4*2 -> 8 | D21: =6.42/3.281 -> 1.9567205 | E21: 4.43 | F21: =PRODUCT(C21:E21) -> 69.346175 | G21: =F21 -> 69.346175 | I21: =(38+41)/12 -> 6.5833333
B22: -MS square pipe horizontal of 2" * 2" of 3mm thickness as purlin at mid portion of uppermost part | C22: 4 | D22: =8/12/3.281 -> 0.20319008 | E22: 4.43 | F22: =PRODUCT(C22:E22) -> 3.6005283 | G22: =F22 -> 3.6005283 | I22: =8/12 -> 0.66666667
C23: 4 | D23: =54/12/3.281 -> 1.3715331 | E23: 4.43 | F23: =PRODUCT(C23:E23) -> 24.303566 | G23: =F23 -> 24.303566 | I23: =54/12 -> 4.5
C24: 4 | D24: =105/12/3.281 -> 2.6668699 | E24: 4.43 | F24: =PRODUCT(C24:E24) -> 47.256934 | G24: =F24 -> 47.256934 | I24: =105/12 -> 8.75
B25: -MS square pipe horizontal of 2" * 2" of 3mm thickness at corner of uppermost part | C25: 4 | D25: =75/12/3.281 -> 1.904907 | E25: 4.43 | F25: =PRODUCT(C25:E25) -> 33.754953 | G25: =F25 -> 33.754953 | I25: =75/12 -> 6.25
C26: =4*2 -> 8 | D26: =(36+37)/12/3.281 -> 1.8541095 | E26: 4.43 | F26: =PRODUCT(C26:E26) -> 65.709641 | G26: =F26 -> 65.709641 | I26: =(36+37)/12 -> 6.0833333
B27: -MS square pipe horizontal of 2" * 2" of 2mm thickness for vertical post of railing | C27: 1 | D27: =6/3.281 -> 1.8287108 | E27: 3.01 | F27: =PRODUCT(C27:E27) -> 5.5044194 | G27: =F27 -> 5.5044194 | I27: 6ft
C28: 4 | D28: 1.5 | E28: 3.01 | F28: =PRODUCT(C28:E28) -> 18.06 | G28: =F28 -> 18.06
B29: -MS square pipe horizontal of 1.5" * 1.5" of 2mm thickness for railing | C29: 1 | D29: =(7+65/12+76/12+74/12+6)/3.281 -> 9.4229402 | E29: 2.26 | F29: =PRODUCT(C29:E29) -> 21.295845 | G29: =F29 -> 21.295845
C30: 2 | D30: =(69+72+75+64+82)/12/3.281 -> 9.1943513 | E30: 2.26 | F30: =PRODUCT(C30:E30) -> 41.558468 | G30: =F30 -> 41.558468
C31: 1 | D31: =82/12/3.281 -> 2.0826984 | E31: 2.26 | F31: =PRODUCT(C31:E31) -> 4.7068983 | G31: =F31 -> 4.7068983
B32: sub-total | G32: =SUM(G10:G31) -> 880.06057 | H32: Kg | I32: 182.51 | J32: =G32*I32 -> 160619.85
B33: -VAT 13% for materials | J33: =0.13*G32*(1871.42/18.94) -> 11304.392
A35: 2 | B35: )=$! dL=dL=afSnf] sf]?u]6]8 /+lug ss{6 kftfsf] 5fgf 5fpg] sfd
B36: -upper portion | C36: 4 | D36: =(15+6)/2/3.281 -> 3.2002438 | E36: =5.583/3.281 -> 1.7016154 | G36: =PRODUCT(C36:F36) -> 21.782336 | I36: =183/12 -> 15.25
B37: -uppermost portion | C37: 4 | D37: =5/3.281 -> 1.5239256 | E37: =5.583/3.281 -> 1.7016154 | G37: =PRODUCT(C37:F37) -> 10.372541
B38: sub-total | G38: =SUM(G36:G37) -> 32.154877 | H38: sqm | I38: 1112.58 | J38: =G38*I38 -> 35774.873
B39: -13% VAT for sheet | J39: =0.13*G38*7050.67/10 -> 2947.2746
B40: -13% VAT for nut bolt | J40: =0.13*G38*1023.75/10 -> 427.94122
B41: -13% VAT for j-hook | J41: =0.13*G38*348.21/10 -> 145.55645
...
