Workbook
Name description_103: #REF!
Name description_103: [1]Abstract!$B$16
Name description_124: #REF!
Name description_124: #REF!
Name description_124: #REF!
Name description_124: #REF!
Name description_124: #REF!
Name description_247: #REF!
Name description_247: [1]Abstract!$B$22
Name description_248: #REF!
Name description_248: [1]Abstract!$B$23
Name description_261: #REF!
Name description_261: [2]Abstract!$B$33
Name description_262: #REF!
Name description_262: [1]Abstract!$B$34
Name description_276: #REF!
Name description_276: [3]Abstract!$B$40
Name description_3: #REF!
Name description_3: [1]Abstract!$B$169
Name description_310: #REF!
Name description_310: #REF!
Name description_310: #REF!
Name description_310: #REF!
Name description_310: #REF!
Name description_312: #REF!
Name description_312: #REF!
Name description_312: #REF!
Name description_312: #REF!
Name description_312: #REF!
Name description_4: #REF!
Name description_5: #REF!
Name description_5: [1]Abstract!$B$171
Name description_6: #REF!
Name description_6: #REF!
Name description_6: #REF!
Name description_6: #REF!
Name description_6: #REF!
Name description_759: #REF!
Name description_759: [1]Abstract!$B$278
Name description_781: #REF!
Name description_781: #REF!
Name description_781: #REF!
Name description_781: #REF!
Name description_781: #REF!
Name description_783: #REF!
Name description_783: [1]Abstract!$B$301
Name description_784: #REF!
Name description_784: [3]Abstract!$B$300

Sheet Estimate
A1: Government of Nepal
A2: Shankharapur Municipality Office
A3: Bagmati Province
A4: Sankhu, Kathmandu
A5: Detail Estimated Sheet
A6: Project:- पटाप बिबिध कार्य | H6: F.Y.: 2082/2083
A7: Location:- Shankharapur Municipality 1 | H7: Date:2083/03/12
A8: S.N. | B8: Description of work | C8: No. | D8: Length | E8: Breadth | F8: Height | G8: Quantity | H8: Unit | I8: Rate | J8: Amount | K8: Remark
A9: 1 | B9: Earthwork Excavation in Cutting., Roadway Excavation in all types of Soil by Manual Means ., Roadway Excavation in all types of soil as per drawing and technical specification, including removal of stumps and other deleterious matter, with all lifts and lead as per Drawing and instruction of the Engineer.
B10: -Masonary wall | C10: 1 | D10: =D20 -> 4.75 | E10: =E20 -> 0.81276034 | F10: 0.9 | G10: =PRODUCT(C10:F10) -> 3.4745504
C11: 1 | D11: =D21 -> 4.7888601 | E11: =E21 -> 0.5 | F11: 0.6 | G11: =PRODUCT(C11:F11) -> 1.436658
B12: -for pathway level | C12: 1 | D12: 4 | E12: =((83+66)/2)/12/3.281 -> 1.8922077 | F12: 0.15 | G12: =PRODUCT(C12:F12) -> 1.1353246
C13: 1 | D13: 7.4 | E13: =((55+45)/2)/12/3.281 -> 1.269938 | F13: 0.15 | G13: =PRODUCT(C13:F13) -> 1.4096312
B14: -at compound | C14: 1 | D14: =(83/12) -> 6.9166667 | E14: =(66/12) -> 5.5 | F14: =1/12/3.281 -> 0.025398761 | G14: =PRODUCT(C14:F14) -> 0.96621118
C15: 1 | D15: 1.2 | E15: 1.2 | F15: 0.025 | G15: =PRODUCT(C15:F15) -> 0.036
B16: -for dhara | C16: 1 | D16: =(43/12)/3.281 -> 1.0921467 | E16: 1.2 | F16: 0.15 | G16: =PRODUCT(C16:F16) -> 0.19658641
B17: sub-total | G17: =SUM(G10:G16) -> 8.6549619 | H17: cum | I17: 748.9 | J17: =G17*I17 -> 6481.7009
A19: 2 | B19: Providing and laying of hand pack locally available Stone soling with 150 to 200 mm thick stones and packing with smaller stone on prepared surface as per Drawing and Technical Specifications.
B20: -Masonary wall | C20: 1 | D20: =D31 -> 4.75 | E20: =E31 -> 0.81276034 | F20: 0.15 | G20: =PRODUCT(C20:F20) -> 0.57909174
C21: 1 | D21: =D33 -> 4.7888601 | E21: =E33 -> 0.5 | F21: 0.15 | G21: =PRODUCT(C21:F21) -> 0.35916451
B22: =B12 -> -for pathway level | C22: =C12 -> 1 | D22: =D12 -> 4 | E22: =E12 -> 1.8922077 | F22: 0.15 | G22: =PRODUCT(C22:F22) -> 1.1353246
C23: 1 | D23: =D13 -> 7.4 | E23: =E13 -> 1.269938 | F23: 0.15 | G23: =PRODUCT(C23:F23) -> 1.4096312
B24: =B14 -> -at compound | C24: =C14 -> 1 | D24: =D14 -> 6.9166667 | E24: =E14 -> 5.5 | F24: 0.15 | G24: =PRODUCT(C24:F24) -> 5.70625
C25: =C15 -> 1 | D25: =D15 -> 1.2 | E25: =E15 -> 1.2 | F25: 0.15 | G25: =PRODUCT(C25:F25) -> 0.216
B26: =B16 -> -for dhara | C26: =C16 -> 1 | D26: =D16 -> 1.0921467 | E26: =E16 -> 1.2 | F26: 0.15 | G26: =PRODUCT(C26:F26) -> 0.19658641
B27: sub-total | G27: =SUM(G20:G26) -> 9.6020485 | H27: cum | I27: 4458.52 | J27: =G27*I27 -> 42810.925
B28: -13% VAT for stone | J28: =0.13*G27*15452.64/5 -> 3857.802
A30: 3 | B30: Providing and laying of Plain/Reinforced Cement Concrete in Foundation complete as per Drawing and Technical Specifications, PCC Grade M 15
B31: -Masonary wall | C31: 1 | D31: =D47 -> 4.75 | E31: =F47/2 -> 0.81276034 | F31: 0.05 | G31: =PRODUCT(C31:F31) -> 0.19303058
C32: 1 | D32: =D31 -> 4.75 | E32: 0.45 | F32: 0.05 | G32: =PRODUCT(C32:F32) -> 0.106875
C33: 1 | D33: =D48 -> 4.7888601 | E33: =E48 -> 0.5 | F33: 0.05 | G33: =PRODUCT(C33:F33) -> 0.1197215
C34: 1 | D34: =D48 -> 4.7888601 | E34: =E33 -> 0.5 | F34: 0.05 | G34: =PRODUCT(C34:F34) -> 0.1197215
B35: =B22 -> -for pathway level | C35: =C22 -> 1 | D35: =D22 -> 4 | E35: =E22 -> 1.8922077 | F35: 0.05 | G35: =PRODUCT(C35:F35) -> 0.37844153
C36: 1 | D36: =D23 -> 7.4 | E36: =E23 -> 1.269938 | F36: 0.075 | G36: =PRODUCT(C36:F36) -> 0.7048156
B37: =B26 -> -for dhara | C37: =C26 -> 1 | D37: =D26 -> 1.0921467 | E37: =E26 -> 1.2 | F37: 0.05 | G37: =PRODUCT(C37:F37) -> 0.065528802
C38: 1 | D38: =((43/12)+4+4)/3.281 -> 3.5304277 | E38: 0.15 | F38: 0.15 | G38: =PRODUCT(C38:F38) -> 0.079434624
B39: sub-total | G39: =SUM(G31:G38) -> 1.7675691 | H39: cum | I39: 10964.46 | J39: =G39*I39 -> 19380.441
B40: -13% VAT for cement | J40: =0.13*G39*53818.03/15 -> 824.43478
B41: -13% VAT for sand | J41: =0.13*G39*21432.6/15 -> 328.32456
B42: -13% VAT for aggregate | J42: =0.13*G39*(25719.12+13573.98+4286.52)/15 -> 667.59326
...

Sheet WCR
A1: Government of Nepal
A2: Shankharapur Municipality Office
A3: Bagmati Province
A4: Sankhu, Kathmandu
A5: Work Completion Report
A6: Total Estimated Amount: | C6: =F48 -> 144620.53 | H6: Total Valuated Amount : | J6: =I48 -> 144620.53
A7: Work Started : | I7: Work Finished:
A8: =#REF! -> #REF! | I8: F.Y:2082/2083
A9: Location:- Shankharapur Municipality 1 | I9: Date:2083/02/18
A11: S.No. | B11: Description | C11: Unit | D11: Estimated | G11: Valuated | J11: Difference | K11: Remarks
D12: Quantity | E12: Rate | F12: Amount | G12: Quantity | H12: Rate | I12: Amount
A13: =Estimate!A9 -> 1 | B13: =Estimate!B9 -> Earthwork Excavation in Cutting., Roadway Excavation in all types of Soil by Manual Means ., Roadway Excavation in all types of soil as per drawing and technical specification, including removal of stumps and other deleterious matter, with all lifts and lead as per Drawing and instruction of the Engineer. | C13: =Estimate!H17 -> cum | D13: =Estimate!G17 -> 8.6549619 | E13: =Estimate!I17 -> 748.9 | F13: =D13*E13 -> 6481.7009 | G13: =V!G17 -> 8.6549619 | H13: =V!I17 -> 748.9 | I13: =G13*H13 -> 6481.7009 | J13: =I13-F13 -> 0 | M13: =1.25*F13 -> 8102.1262
A15: =Estimate!A19 -> 2 | B15: =Estimate!B19 -> Providing and laying of hand pack locally available Stone soling with 150 to 200 mm thick stones and packing with smaller stone on prepared surface as per Drawing and Technical Specifications. | C15: =Estimate!H27 -> cum | D15: =Estimate!G27 -> 9.6020485 | E15: =Estimate!I27 -> 4458.52 | F15: =D15*E15 -> 42810.925 | G15: =V!G27 -> 9.6020485 | H15: =V!I27 -> 4458.52 | I15: =G15*H15 -> 42810.925 | J15: =I15-F15 -> 0 | M15: =1.25*F15 -> 53513.656
B16: =Estimate!B28 -> -13% VAT for stone | F16: =Estimate!J28 -> 3857.802 | I16: =V!J28 -> 3857.802 | J16: =I16-F16 -> 0 | M16: =1.25*F16 -> 4822.2524
A18: =Estimate!A30 -> 3 | B18: =Estimate!B30 -> Providing and laying of Plain/Reinforced Cement Concrete in Foundation complete as per Drawing and Technical Specifications, PCC Grade M 15 | C18: =Estimate!H39 -> cum | D18: =Estimate!G39 -> 1.7675691 | E18: =Estimate!I39 -> 10964.46 | F18: =D18*E18 -> 19380.441 | G18: =V!G39 -> 1.7675691 | H18: =V!I39 -> 10964.46 | I18: =G18*H18 -> 19380.441 | J18: =I18-F18 -> 0 | M18: =1.25*F18 -> 24225.552
B19: =Estimate!B40 -> -13% VAT for cement | F19: =Estimate!J40 -> 824.43478 | I19: =V!J40 -> 824.43478 | J19: =I19-F19 -> 0 | M19: =1.25*F19 -> 1030.5435
B20: =Estimate!B41 -> -13% VAT for sand | F20: =Estimate!J41 -> 328.32456 | I20: =V!J41 -> 328.32456 | J20: =I20-F20 -> 0
B21: =Estimate!B42 -> -13% VAT for aggregate | F21: =Estimate!J42 -> 667.59326 | I21: =V!J42 -> 667.59326 | J21: =I21-F21 -> 0
B22: =Estimate!B43 -> -13% VAT for formwork | F22: =Estimate!J43 -> 96.902972 | I22: =V!J43 -> 96.902972 | J22: =I22-F22 -> 0
B23: =Estimate!B44 -> -13% VAT for water | F23: =Estimate!J44 -> 14.246607 | I23: =V!J44 -> 14.246607 | J23: =I23-F23 -> 0
A25: =Estimate!A46 -> 4 | B25: =Estimate!B46 -> Random Rubble Masonry, Providing and laying of Stone Masonry Work in Cement Mortar 1:6 in Foundation complete as per Drawing and Technical Specifications., Using Concrete Mixer | C25: =Estimate!H49 -> cum | D25: =Estimate!G49 -> 6.5778628 | E25: =Estimate!I49 -> 8987.83 | F25: =D25*E25 -> 59120.712 | G25: =V!G49 -> 6.5778628 | H25: =V!I49 -> 8987.83 | I25: =G25*H25 -> 59120.712 | J25: =I25-F25 -> 0 | M25: =1.25*F25 -> 73900.89
B26: =Estimate!B50 -> -13% VAT for cement | F26: =Estimate!J50 -> 1002.8787 | I26: =V!J50 -> 1002.8787 | J26: =I26-F26 -> 0 | M26: =1.25*F26 -> 1253.5984
B27: =Estimate!B51 -> -13% VAT for sand | F27: =Estimate!J51 -> 1129.5165 | I27: =V!J51 -> 1129.5165 | J27: =I27-F27 -> 0
B28: =Estimate!B52 -> -13% VAT for stone | F28: =Estimate!J52 -> 2532.6632 | I28: =V!J52 -> 2532.6632 | J28: =I28-F28 -> 0
B29: =Estimate!B53 -> -13% VAT for water | F29: =Estimate!J53 -> 53.017574 | I29: =V!J53 -> 53.017574 | J29: =I29-F29 -> 0
A31: =Estimate!A55 -> 5 | B31: =Estimate!B55 -> e'O{+tNnfdf lrDgL e§fsf] O{+6fsf] uf/f] l;d]G6 d;nf -!M^_ df | C31: =Estimate!H58 -> cum | D31: =Estimate!G58 -> 0.17233771 | E31: =Estimate!I58 -> 14491.84 | F31: =D31*E31 -> 2497.4906 | G31: =V!G58 -> 0.17233771 | H31: =V!I58 -> 14491.84 | I31: =G31*H31 -> 2497.4906 | J31: =I31-F31 -> 0 | M31: =1.25*F31 -> 3121.8632
B32: =Estimate!B59 -> -13% VAT for cement | F32: =Estimate!J59 -> 20.436168 | I32: =V!J59 -> 20.436168 | J32: =I32-F32 -> 0 | M32: =1.25*F32 -> 25.54521
B33: =Estimate!B60 -> -13% VAT for sand | F33: =Estimate!J60 -> 21.359209 | I33: =V!J60 -> 21.359209 | J33: =I33-F33 -> 0
B34: =Estimate!B61 -> -13% VAT for brick | F34: =Estimate!J61 -> 190.01198 | I34: =V!J61 -> 190.01198 | J34: =I34-F34 -> 0
B35: =Estimate!B62 -> -13% VAT for water | F35: =Estimate!J62 -> 0.62730927 | I35: =V!J62 -> 0.62730927 | J35: =I35-F35 -> 0
A37: =Estimate!A64 -> 6 | B37: =Estimate!B64 -> !@=% dL=dL= l;d]G6 afn'jf -!M$_ Knfi6/ | C37: =Estimate!H67 -> sqm | D37: =Estimate!G67 -> 1.4985888 | E37: =Estimate!I67 -> 415.5 | F37: =D37*E37 -> 622.66365 | G37: =V!G67 -> 1.4985888 | H37: =V!I67 -> 415.5 | I37: =G37*H37 -> 622.66365 | J37: =I37-F37 -> 0 | M37: =1.25*F37 -> 778.32956
B38: =Estimate!B68 -> -13% VAT for cement | F38: =Estimate!J68 -> 13.657945 | I38: =V!J68 -> 13.657945 | J38: =I38-F38 -> 0 | M38: =1.25*F38 -> 17.072431
B39: =Estimate!B69 -> -13% VAT for sand | F39: =Estimate!J69 -> 9.0389616 | I39: =V!J69 -> 9.0389616 | J39: =I39-F39 -> 0
A41: =Estimate!A71 -> 7 | B41: =Estimate!B71 -> # dL=dL= df]6fO{ d;Lgf] l;d]G6 3f]6\g] sfd | C41: =Estimate!H74 -> sqm | D41: =Estimate!G74 -> 1.4985888 | E41: =Estimate!I74 -> 287.32 | F41: =D41*E41 -> 430.57453 | G41: =V!G74 -> 1.4985888 | H41: =V!I74 -> 287.32 | I41: =G41*H41 -> 430.57453 | J41: =I41-F41 -> 0 | M41: =1.25*F41 -> 538.21817
B42: =Estimate!B75 -> -13% VAT for cement | F42: =Estimate!J75 -> 13.505462 | I42: =V!J75 -> 13.505462 | J42: =I42-F42 -> 0 | M42: =1.25*F42 -> 16.881828
A44: =Estimate!A77 -> 8 | B44: =Estimate!B77 -> Prtovisional sum for unforseen works | C44: =Estimate!H77 -> PS | D44: =Estimate!G77 -> 1 | E44: =Estimate!I77 -> 2000 | F44: =D44*E44 -> 2000 | G44: =V!G77 -> 1 | H44: =V!I77 -> 2000 | I44: =G44*H44 -> 2000 | J44: =I44-F44 -> 0 | M44: =1.25*F44 -> 2500
A46: =Estimate!A79 -> 9 | B46: =Estimate!B79 -> Information board (सुचना पाटि) | C46: =Estimate!H79 -> no. | D46: =Estimate!G79 -> 1 | E46: =Estimate!I79 -> 500 | F46: =D46*E46 -> 500 | G46: =V!G79 -> 1 | H46: =V!I79 -> 500 | I46: =G46*H46 -> 500 | J46: =I46-F46 -> 0
B48: Total | F48: =SUM(F13:F46) -> 144620.53 | I48: =SUM(I13:I46) -> 144620.53 | J48: =I48-F48 -> 0

Sheet V
A1: Government of Nepal
A2: Shankharapur Municipality Office
A3: Bagmati Province
A4: Sankhu, Kathmandu
A5: Detail Valuated Sheet
A6: Project:- पटाप बिबिध कार्य | H6: F.Y.: 2082/2083
A7: Location:- Shankharapur Municipality 1 | H7: Date:2083/03/12
A8: S.N. | B8: Description of work | C8: No. | D8: Length | E8: Breadth | F8: Height | G8: Quantity | H8: Unit | I8: Rate | J8: Amount | K8: Remark
A9: 1 | B9: Earthwork Excavation in Cutting., Roadway Excavation in all types of Soil by Manual Means ., Roadway Excavation in all types of soil as per drawing and technical specification, including removal of stumps and other deleterious matter, with all lifts and lead as per Drawing and instruction of the Engineer.
B10: -Masonary wall | C10: 1 | D10: =D20 -> 4.75 | E10: =E20 -> 0.81276034 | F10: 0.9 | G10: =PRODUCT(C10:F10) -> 3.4745504
C11: 1 | D11: =D21 -> 4.7888601 | E11: =E21 -> 0.5 | F11: 0.6 | G11: =PRODUCT(C11:F11) -> 1.436658
B12: -for pathway level | C12: 1 | D12: 4 | E12: =((83+66)/2)/12/3.281 -> 1.8922077 | F12: 0.15 | G12: =PRODUCT(C12:F12) -> 1.1353246
C13: 1 | D13: 7.4 | E13: =((55+45)/2)/12/3.281 -> 1.269938 | F13: 0.15 | G13: =PRODUCT(C13:F13) -> 1.4096312
B14: -at compound | C14: 1 | D14: =(83/12) -> 6.9166667 | E14: =(66/12) -> 5.5 | F14: =1/12/3.281 -> 0.025398761 | G14: =PRODUCT(C14:F14) -> 0.96621118
C15: 1 | D15: 1.2 | E15: 1.2 | F15: 0.025 | G15: =PRODUCT(C15:F15) -> 0.036
B16: -for dhara | C16: 1 | D16: =(43/12)/3.281 -> 1.0921467 | E16: 1.2 | F16: 0.15 | G16: =PRODUCT(C16:F16) -> 0.19658641
B17: sub-total | G17: =SUM(G10:G16) -> 8.6549619 | H17: cum | I17: 748.9 | J17: =G17*I17 -> 6481.7009
A19: 2 | B19: Providing and laying of hand pack locally available Stone soling with 150 to 200 mm thick stones and packing with smaller stone on prepared surface as per Drawing and Technical Specifications.
B20: -Masonary wall | C20: 1 | D20: =D31 -> 4.75 | E20: =E31 -> 0.81276034 | F20: 0.15 | G20: =PRODUCT(C20:F20) -> 0.57909174
C21: 1 | D21: =D33 -> 4.7888601 | E21: =E33 -> 0.5 | F21: 0.15 | G21: =PRODUCT(C21:F21) -> 0.35916451
B22: =B12 -> -for pathway level | C22: =C12 -> 1 | D22: =D12 -> 4 | E22: =E12 -> 1.8922077 | F22: 0.15 | G22: =PRODUCT(C22:F22) -> 1.1353246
C23: 1 | D23: =D13 -> 7.4 | E23: =E13 -> 1.269938 | F23: 0.15 | G23: =PRODUCT(C23:F23) -> 1.4096312
B24: =B14 -> -at compound | C24: =C14 -> 1 | D24: =D14 -> 6.9166667 | E24: =E14 -> 5.5 | F24: 0.15 | G24: =PRODUCT(C24:F24) -> 5.70625
C25: =C15 -> 1 | D25: =D15 -> 1.2 | E25: =E15 -> 1.2 | F25: 0.15 | G25: =PRODUCT(C25:F25) -> 0.216
B26: =B16 -> -for dhara | C26: =C16 -> 1 | D26: =D16 -> 1.0921467 | E26: =E16 -> 1.2 | F26: 0.15 | G26: =PRODUCT(C26:F26) -> 0.19658641
B27: sub-total | G27: =SUM(G20:G26) -> 9.6020485 | H27: cum | I27: 4458.52 | J27: =G27*I27 -> 42810.925
B28: -13% VAT for stone | J28: =0.13*G27*15452.64/5 -> 3857.802
A30: 3 | B30: Providing and laying of Plain/Reinforced Cement Concrete in Foundation complete as per Drawing and Technical Specifications, PCC Grade M 15
B31: -Masonary wall | C31: 1 | D31: =D47 -> 4.75 | E31: =F47/2 -> 0.81276034 | F31: 0.05 | G31: =PRODUCT(C31:F31) -> 0.19303058
C32: 1 | D32: =D31 -> 4.75 | E32: 0.45 | F32: 0.05 | G32: =PRODUCT(C32:F32) -> 0.106875
C33: 1 | D33: =D48 -> 4.7888601 | E33: =E48 -> 0.5 | F33: 0.05 | G33: =PRODUCT(C33:F33) -> 0.1197215
C34: 1 | D34: =D48 -> 4.7888601 | E34: =E33 -> 0.5 | F34: 0.05 | G34: =PRODUCT(C34:F34) -> 0.1197215
B35: =B22 -> -for pathway level | C35: =C22 -> 1 | D35: =D22 -> 4 | E35: =E22 -> 1.8922077 | F35: 0.05 | G35: =PRODUCT(C35:F35) -> 0.37844153
C36: 1 | D36: =D23 -> 7.4 | E36: =E23 -> 1.269938 | F36: 0.075 | G36: =PRODUCT(C36:F36) -> 0.7048156
B37: =B26 -> -for dhara | C37: =C26 -> 1 | D37: =D26 -> 1.0921467 | E37: =E26 -> 1.2 | F37: 0.05 | G37: =PRODUCT(C37:F37) -> 0.065528802
C38: 1 | D38: =((43/12)+4+4)/3.281 -> 3.5304277 | E38: 0.15 | F38: 0.15 | G38: =PRODUCT(C38:F38) -> 0.079434624
B39: sub-total | G39: =SUM(G31:G38) -> 1.7675691 | H39: cum | I39: 10964.46 | J39: =G39*I39 -> 19380.441
B40: -13% VAT for cement | J40: =0.13*G39*53818.03/15 -> 824.43478
B41: -13% VAT for sand | J41: =0.13*G39*21432.6/15 -> 328.32456
B42: -13% VAT for aggregate | J42: =0.13*G39*(25719.12+13573.98+4286.52)/15 -> 667.59326
...

Sheet M
A1: Government of Nepal
A2: Shankharapur Municipality Office
A3: Bagmati Province
A4: Sankhu, Kathmandu
A5: Detail Quantity Measurement Sheet
A6: Project:- पटाप बिबिध कार्य | I6: F.Y.: 2082/2083
A7: Location:- Shankharapur Municipality 1 | I7: Date:2083/03/12
A8: S.N. | B8: Description of work | C8: No. | D8: Length | E8: Breadth | F8: Height | G8: Quantity | H8: Unit | I8: Remark
A9: 1 | B9: Earthwork Excavation in Cutting., Roadway Excavation in all types of Soil by Manual Means ., Roadway Excavation in all types of soil as per drawing and technical specification, including removal of stumps and other deleterious matter, with all lifts and lead as per Drawing and instruction of the Engineer.
B10: -Masonary wall | C10: 1 | D10: =D20 -> 4.75 | E10: =E20 -> 0.81276034 | F10: 0.9 | G10: =PRODUCT(C10:F10) -> 3.4745504
C11: 1 | D11: =D21 -> 4.7888601 | E11: =E21 -> 0.5 | F11: 0.6 | G11: =PRODUCT(C11:F11) -> 1.436658
B12: -for pathway level | C12: 1 | D12: 4 | E12: =((83+66)/2)/12/3.281 -> 1.8922077 | F12: 0.15 | G12: =PRODUCT(C12:F12) -> 1.1353246
C13: 1 | D13: 7.4 | E13: =((55+45)/2)/12/3.281 -> 1.269938 | F13: 0.15 | G13: =PRODUCT(C13:F13) -> 1.4096312
B14: -at compound | C14: 1 | D14: =(83/12) -> 6.9166667 | E14: =(66/12) -> 5.5 | F14: =1/12/3.281 -> 0.025398761 | G14: =PRODUCT(C14:F14) -> 0.96621118
C15: 1 | D15: 1.2 | E15: 1.2 | F15: 0.025 | G15: =PRODUCT(C15:F15) -> 0.036
B16: -for dhara | C16: 1 | D16: =(43/12)/3.281 -> 1.0921467 | E16: 1.2 | F16: 0.15 | G16: =PRODUCT(C16:F16) -> 0.19658641
B17: sub-total | G17: =SUM(G10:G16) -> 8.6549619 | H17: cum
A19: 2 | B19: Providing and laying of hand pack locally available Stone soling with 150 to 200 mm thick stones and packing with smaller stone on prepared surface as per Drawing and Technical Specifications.
B20: -Masonary wall | C20: 1 | D20: =D30 -> 4.75 | E20: =E30 -> 0.81276034 | F20: 0.15 | G20: =PRODUCT(C20:F20) -> 0.57909174
C21: 1 | D21: =D32 -> 4.7888601 | E21: =E32 -> 0.5 | F21: 0.15 | G21: =PRODUCT(C21:F21) -> 0.35916451
B22: =B12 -> -for pathway level | C22: =C12 -> 1 | D22: =D12 -> 4 | E22: =E12 -> 1.8922077 | F22: 0.15 | G22: =PRODUCT(C22:F22) -> 1.1353246
C23: 1 | D23: =D13 -> 7.4 | E23: =E13 -> 1.269938 | F23: 0.15 | G23: =PRODUCT(C23:F23) -> 1.4096312
B24: =B14 -> -at compound | C24: =C14 -> 1 | D24: =D14 -> 6.9166667 | E24: =E14 -> 5.5 | F24: 0.15 | G24: =PRODUCT(C24:F24) -> 5.70625
C25: =C15 -> 1 | D25: =D15 -> 1.2 | E25: =E15 -> 1.2 | F25: 0.15 | G25: =PRODUCT(C25:F25) -> 0.216
B26: =B16 -> -for dhara | C26: =C16 -> 1 | D26: =D16 -> 1.0921467 | E26: =E16 -> 1.2 | F26: 0.15 | G26: =PRODUCT(C26:F26) -> 0.19658641
B27: sub-total | G27: =SUM(G20:G26) -> 9.6020485 | H27: cum
A29: 3 | B29: Providing and laying of Plain/Reinforced Cement Concrete in Foundation complete as per Drawing and Technical Specifications, PCC Grade M 15
B30: -Masonary wall | C30: 1 | D30: =D41 -> 4.75 | E30: =F41/2 -> 0.81276034 | F30: 0.05 | G30: =PRODUCT(C30:F30) -> 0.19303058
C31: 1 | D31: =D30 -> 4.75 | E31: 0.45 | F31: 0.05 | G31: =PRODUCT(C31:F31) -> 0.106875
C32: 1 | D32: =D42 -> 4.7888601 | E32: =E42 -> 0.5 | F32: 0.05 | G32: =PRODUCT(C32:F32) -> 0.1197215
C33: 1 | D33: =D42 -> 4.7888601 | E33: =E32 -> 0.5 | F33: 0.05 | G33: =PRODUCT(C33:F33) -> 0.1197215
B34: =B22 -> -for pathway level | C34: =C22 -> 1 | D34: =D22 -> 4 | E34: =E22 -> 1.8922077 | F34: 0.05 | G34: =PRODUCT(C34:F34) -> 0.37844153
C35: 1 | D35: =D23 -> 7.4 | E35: =E23 -> 1.269938 | F35: 0.075 | G35: =PRODUCT(C35:F35) -> 0.7048156
B36: =B26 -> -for dhara | C36: =C26 -> 1 | D36: =D26 -> 1.0921467 | E36: =E26 -> 1.2 | F36: 0.05 | G36: =PRODUCT(C36:F36) -> 0.065528802
C37: 1 | D37: =((43/12)+4+4)/3.281 -> 3.5304277 | E37: 0.15 | F37: 0.15 | G37: =PRODUCT(C37:F37) -> 0.079434624
B38: sub-total | G38: =SUM(G30:G37) -> 1.7675691 | H38: cum
A40: 4 | B40: Random Rubble Masonry, Providing and laying of Stone Masonry Work in Cement Mortar 1:6 in Foundation complete as per Drawing and Technical Specifications., Using Concrete Mixer
B41: -Masonary wall | C41: 1 | D41: 4.75 | E41: =((F41/2)+0.45)/2 -> 0.63138017 | F41: =64/12/3.281 -> 1.6255207 | G41: =PRODUCT(C41:F41) -> 4.8750272 | K41: =7 -> 7 | L41: =2 -> 2 | N41: =PI()*K41*SQRT(K41^2+L41^2) -> 160.09798
C42: 1 | D42: =(8.33/3.281)+1.75+1.5-1 -> 4.7888601 | E42: 0.5 | F42: =28/12/3.281 -> 0.7111653 | G42: =PRODUCT(C42:F42) -> 1.7028356
B43: Sub-total | G43: =SUM(G41:G42) -> 6.5778628 | H43: cum
...
