Workbook
Name description_103: [1]Abstract!$B$16
Name description_124: #REF!
Name description_247: [1]Abstract!$B$22
Name description_248: [1]Abstract!$B$23
Name description_261: [2]Abstract!$B$33
Name description_262: [1]Abstract!$B$34
Name description_276: [3]Abstract!$B$40
Name description_3: [1]Abstract!$B$169
Name description_310: #REF!
Name description_312: #REF!
Name description_5: [1]Abstract!$B$171
Name description_6: #REF!
Name description_759: [1]Abstract!$B$278
Name description_781: #REF!
Name description_783: [1]Abstract!$B$301
Name description_784: [3]Abstract!$B$300

Sheet water tank
A1: Government of Nepal
A2: Shankharapur Municipality Office
A3: Bagmati Province
A4: Sankhu, Kathmandu
A5: Detail Estimated Sheet
A6: Project:- nfdf6f]n vfg]kfgL 6\ofª\sL | H6: F.Y.: 2082/2083
A7: Location:- Shankharapur Municipality 1 | H7: Date:2082
A8: S.N. | B8: Description of work | C8: No. | D8: Length | E8: Breadth | F8: Height | G8: Quantity | H8: Unit | I8: Rate | J8: Amount | K8: Remark
A9: A | B9: Intake works
A10: 1 | B10: Earthwork in Excavation in ordinary soil
B11: -for intake | C11: 1 | D11: =Sheet1!A10 -> 1.5 | E11: =Sheet1!B10 -> 1.5 | F11: =0.15+0.075+Sheet1!C10 -> 1.2917479 | G11: =PRODUCT(C11:F11) -> 2.9064329
B12: Sub-total | G12: =SUM(G11:G11) -> 2.9064329 | H12: cum | I12: 963.05 | J12: =G12*I12 -> 2799.0402
A14: 2 | B14: Dry boulder packing work
B15: =B11 -> -for intake | C15: =C11 -> 1 | D15: =Sheet1!A10 -> 1.5 | E15: =Sheet1!B10 -> 1.5 | F15: 0.15 | G15: =PRODUCT(C15:F15) -> 0.3375
B16: Sub-total | G16: =SUM(G15:G15) -> 0.3375 | H16: cum | I16: =4493.69 -> 4493.69 | J16: =G16*I16 -> 1516.6204
B17: -13% VAT for block stone | J17: =0.13*G16*3091.19 -> 135.62596
A19: 3 | B19: Plain cement concrete (1:2:4)
B20: =B11 -> -for intake | C20: =C11 -> 1 | D20: =Sheet1!A10 -> 1.5 | E20: =Sheet1!B10 -> 1.5 | F20: 0.05 | G20: =PRODUCT(C20:F20) -> 0.1125
B21: Sub-total | G21: =SUM(G20:G20) -> 0.1125 | H21: cum | I21: 13343.7 | J21: =G21*I21 -> 1501.1662
B22: -13% VAT for sand | J22: =0.13*G21*1413.27 -> 20.669074
B23: -13% VAT for cement | J23: =0.13*G21*4096 -> 59.904
B24: -13% VAT for aggregate | J24: =0.13*G21*(368.76+737.51+1743.21) -> 41.673645
A26: 4 | B26: 20mm thick cement plaster (1:6)
B27: -for outer face wall of intake | C27: =C20 -> 1 | D27: =Sheet1!A10*2+Sheet1!B10*2 -> 6 | F27: =Sheet1!C10 -> 1.0667479 | G27: =PRODUCT(C27:F27) -> 6.4004877
B28: -for inner face wall of intake | C28: =C20 -> 1 | D28: =2*(Sheet1!A10-Sheet1!D10-Sheet1!D10)+2*(Sheet1!B10-Sheet1!D10-Sheet1!D10) -> 4.8 | F28: =Sheet1!C10 -> 1.0667479 | G28: =PRODUCT(C28:F28) -> 5.1203901
B29: Sub-total | G29: =SUM(G27:G28) -> 11.520878 | H29: sqm | I29: =49954.32/100 -> 499.5432 | J29: =G29*I29 -> 5755.1762
B30: -13% VAT for sand | J30: =0.13*G29*7463.32/100 -> 111.7792
B31: -13% VAT for cement | J31: =0.13*G29*7296/100 -> 109.27322
A33: 5 | B33: 3 mm thick cement punning
B34: =B28 -> -for inner face wall of intake | C34: =C28 -> 1 | D34: =D28 -> 4.8 | F34: =F28 -> 1.0667479 | G34: =PRODUCT(C34:F34) -> 5.1203901
B35: =B27 -> -for outer face wall of intake | C35: =C27 -> 1 | D35: =D27 -> 6 | F35: =F27 -> 1.0667479 | G35: =PRODUCT(C35:F35) -> 6.4004877
B36: - for floor area of intake 2 | C36: =C34 -> 1 | D36: =Sheet1!A10-Sheet1!D10-Sheet1!D10 -> 1.2 | E36: =Sheet1!B10-Sheet1!D10-Sheet1!D10 -> 1.2 | G36: =PRODUCT(C36:F36) -> 1.44
B37: Sub-total | G37: =SUM(G34:G36) -> 12.960878 | H37: sqm | I37: =28609.6/100 -> 286.096 | J37: =G37*I37 -> 3708.0553
B38: -13% VAT for cement | J38: =0.13*G37*6809.6/100 -> 114.73591
A40: 6 | B40: Provisional sum for other unforseen works | C40: 1 | G40: =PRODUCT(C40:F40) -> 1 | H40: PS | I40: 3000 | J40: =G40*I40 -> 3000
A42: 7 | B42: Form work for concrete work
B43: -for shear wall outer face of intake 2 | C43: 1 | D43: =Sheet1!A10*2+Sheet1!B10*2 -> 6 | F43: =Sheet1!C10 -> 1.0667479 | G43: =PRODUCT(C43:F43) -> 6.4004877
B44: -for shear wall inner face of intake 2 | C44: 1 | D44: =2*(Sheet1!A10-Sheet1!D10-Sheet1!D10)+2*(Sheet1!B10-Sheet1!D10-Sheet1!D10) -> 4.8 | F44: =Sheet1!C10 -> 1.0667479 | G44: =PRODUCT(C44:F44) -> 5.1203901
B45: -for intake 2 cover | C45: 1 | D45: =(Sheet1!A10-Sheet1!D10-Sheet1!D10) -> 1.2 | E45: =(Sheet1!B10-Sheet1!D10-Sheet1!D10) -> 1.2 | G45: =PRODUCT(C45:F45) -> 1.44
B46: Sub-total | G46: =SUM(G43:G45) -> 12.960878 | H46: sqm | I46: =11188.35/10 -> 1118.835 | J46: =G46*I46 -> 14501.084
...

Sheet Sheet1
A8: Intake size
A9: length | B9: breadth | C9: height | D9: wall thickness
A10: =1.2+D10+D10 -> 1.5 | B10: =1.2+D10+D10 -> 1.5 | C10: =3.5/3.281 -> 1.0667479 | D10: 0.15
